
# Created by Ruins mod version 14.1 Ingame Parser
# authoring Player: Divineaspect

biomestoSpawnIn=desert,desert m,desert oil field,deserthills,dunes,lush desert,mountainous desert
weight=1000
embed_into_distance=8
acceptable_target_blocks=
unacceptable_target_blocks=flowing_water,water,flowing_lava,lava
dimensions=31,17,17
allowable_overhang=2
max_leveling=12
leveling_buffer=0
preserve_water=0
preserve_lava=0
uniqueMinDistance=1500

rule1=0,100,minecraft:sandstone-0
rule2=0,100,minecraft:noteblock-0,tnt,MobSpawner:Skeleton,MobSpawner:Zombie,sandstone-0
rule3=0,100,minecraft:MediumChest,trapped_chest-5
rule4=0,100,minecraft:MediumChest,trapped_chest-4
rule5=0,100,minecraft:sandstone_stairs-2
rule6=0,100,ChestGenHook:dungeonChest:5-2
rule7=0,100,minecraft:sandstone_stairs-3
rule8=1,100,minecraft:redstone_torch-5
rule9=0,100,minecraft:stone_slab-1
rule10=0,100,minecraft:sandstone_stairs-1
rule11=0,100,minecraft:MediumChest,trapped_chest-3
rule12=2,100,minecraft:redstone_torch-1
rule13=2,100,minecraft:redstone_torch-3
rule14=2,100,minecraft:redstone_torch-4
rule15=0,100,minecraft:sandstone-2
rule16=0,100,minecraft:sandstone_stairs-0
rule17=2,100,minecraft:redstone_torch-2
rule18=0,100,minecraft:unlit_redstone_torch-5
rule19=0,100,minecraft:redstone_block-0
rule20=0,100,minecraft:glass-0
rule21=0,100,minecraft:sponge-0,tnt
rule22=0,100,minecraft:sand-0,sandstone-0
rule23=0,100,minecraft:water-0
rule24=0,100,minecraft:sandstone-1
rule25=0,100,minecraft:sand-1
rule26=0,100,minecraft:wooden_door-0
rule27=0,100,minecraft:wooden_door-1
rule28=0,100,minecraft:wooden_door-3
rule29=0,100,minecraft:sandstone_stairs-5
rule30=0,100,minecraft:fence-0
rule31=0,100,minecraft:sandstone_stairs-7
rule32=0,100,minecraft:sandstone_stairs-6
rule33=0,100,minecraft:sandstone_stairs-4
rule34=0,100,minecraft:wooden_door-2
rule35=0,100,minecraft:wooden_door-8
rule36=2,100,minecraft:torch-2
rule37=2,100,minecraft:torch-4
rule38=2,100,minecraft:torch-3
rule39=2,100,minecraft:torch-1
rule40=0,100,minecraft:planks-3
rule41=0,100,minecraft:stone_slab-9
rule42=0,100,minecraft:wooden_door-4
rule43=0,100,ChestGenHook:dungeonChest:5-3
rule44=0,100,minecraft:wooden_door-7
rule45=0,100,ChestGenHook:dungeonChest:5-4
rule46=0,100,minecraft:glass_pane-0
rule47=1,100,minecraft:torch-5
rule48=0,100,minecraft:dirt-0
rule49=0,100,minecraft:wool-4
rule50=0,100,minecraft:wool-5
rule51=0,100,minecraft:wool-9
rule52=0,100,minecraft:wool-14
rule53=0,100,minecraft:sapling-3
rule54=0,100,minecraft:wooden_door-5
rule55=0,100,ChestGenHook:dungeonChest:5-5
rule56=0,100,minecraft:wooden_door-9
rule57=0,100,minecraft:stained_hardened_clay-4
rule58=0,100,MobSpawner:Villager
rule59=0,100,minecraft:bed-9
rule60=0,100,minecraft:lava-0
rule61=0,100,minecraft:bed-1
rule62=0,100,minecraft:glowstone-0

layer
1,1,1,1,1,1,1,1,1,1,1,1,1,1,1,1,1
1,1,1,1,1,1,1,1,1,1,1,1,1,1,1,1,1
1,1,1,1,1,1,1,1,1,1,1,1,1,1,1,1,1
1,1,1,1,1,1,1,1,1,1,2,1,1,1,1,1,1
1,1,1,1,2,1,1,1,1,1,1,1,1,1,1,1,1
1,1,1,1,1,1,1,1,1,1,1,1,1,1,1,1,1
1,1,1,1,1,1,1,1,1,1,1,1,1,1,1,1,1
1,1,1,1,1,1,1,1,1,1,1,1,1,1,1,1,1
1,1,1,1,1,1,1,1,1,1,1,1,1,1,1,1,1
1,1,1,1,1,1,1,1,1,1,1,1,1,1,1,1,1
1,1,1,1,1,1,2,1,1,1,1,1,1,1,1,1,1
1,1,1,1,1,1,1,1,2,1,1,1,1,1,1,1,1
1,1,1,1,1,1,1,1,1,1,1,1,1,1,1,1,1
1,1,1,1,1,1,1,1,1,1,1,1,1,1,1,1,1
1,1,1,1,1,1,1,1,1,1,1,1,1,1,1,1,1
1,1,1,1,1,1,1,1,1,1,1,1,1,1,1,1,1
1,1,1,1,1,1,1,1,1,1,1,1,1,1,1,1,1
endlayer

layer
1,1,1,1,1,1,1,1,1,1,1,1,1,1,1,1,1
1,0,0,0,0,0,0,1,0,0,0,0,0,0,0,0,1
1,0,1,1,1,1,0,1,0,1,1,1,1,0,0,0,1
1,0,1,0,0,0,0,0,0,1,3,0,1,0,0,0,1
1,0,1,0,4,1,1,1,1,1,0,0,1,0,0,0,1
1,0,1,1,1,1,0,0,0,0,0,0,1,0,0,0,1
1,0,0,0,0,0,0,1,1,1,1,1,1,1,1,0,1
1,1,1,0,1,1,1,0,0,0,1,0,7,6,5,0,1
1,0,0,0,9,0,0,0,8,0,1,0,7,6,5,0,1
1,0,1,1,1,1,1,0,0,0,1,0,0,10,0,0,1
1,0,1,0,0,0,11,1,1,1,1,0,0,0,0,0,1
1,0,0,0,0,0,0,1,3,0,1,1,0,0,0,1,1
1,0,1,0,0,0,0,1,0,0,1,0,0,0,0,0,1
1,0,1,0,0,0,0,0,0,0,1,0,0,0,0,0,1
1,0,1,1,1,1,1,1,1,1,1,0,0,0,0,0,1
1,0,0,0,0,0,0,0,0,0,0,0,0,0,0,0,1
1,1,1,1,1,1,1,1,1,1,1,1,1,1,1,1,1
endlayer

layer
1,1,1,1,1,1,1,1,1,1,1,1,1,1,1,1,1
1,0,0,0,12,0,0,1,0,0,0,0,12,0,0,0,1
1,0,1,1,1,1,0,1,0,1,1,1,1,0,0,0,1
1,0,1,0,0,0,0,0,0,1,0,0,1,0,0,0,1
1,14,1,0,0,1,1,1,1,1,0,0,1,0,0,13,1
1,0,1,1,1,1,0,0,0,0,0,0,1,0,0,0,1
1,0,0,0,0,0,0,1,1,1,1,1,1,1,1,0,1
1,1,1,0,1,1,1,0,0,0,1,0,0,9,0,0,1
1,0,0,0,0,0,0,0,15,0,10,0,0,9,0,0,1
1,0,1,1,1,1,1,0,0,0,1,0,0,0,0,0,1
1,0,1,0,0,0,0,1,1,1,1,0,0,0,0,0,1
1,0,0,0,0,0,0,1,0,0,1,1,0,0,0,1,1
1,14,1,0,0,0,0,1,0,0,1,0,0,0,0,13,1
1,0,1,0,0,0,0,0,0,0,16,0,0,0,0,0,1
1,0,1,1,1,1,1,1,1,1,1,0,0,0,0,0,1
1,0,0,0,17,0,0,0,0,0,0,0,17,0,0,0,1
1,1,1,1,1,1,1,1,1,1,1,1,1,1,1,1,1
endlayer

layer
1,1,1,1,1,1,1,1,1,1,1,1,1,1,1,1,1
1,0,0,0,0,0,0,1,0,0,0,0,0,0,0,0,1
1,0,1,1,1,1,0,1,0,1,1,1,1,0,0,0,1
1,0,1,0,0,0,0,0,0,1,0,0,1,0,0,0,1
1,0,1,0,0,1,1,1,1,1,0,0,1,0,0,0,1
1,0,1,1,1,1,0,0,0,0,0,0,1,0,0,0,1
1,0,0,0,0,0,0,1,1,1,1,1,1,1,1,0,1
1,1,1,1,1,1,1,0,0,0,1,0,0,0,0,0,1
1,0,0,0,0,0,0,0,18,0,1,0,0,0,0,0,1
1,1,1,1,1,1,1,0,0,0,1,0,0,0,0,0,1
1,0,1,0,0,0,0,1,1,1,1,0,0,0,0,0,1
1,0,0,0,0,0,0,1,0,0,1,1,0,0,0,1,1
1,0,1,0,0,0,0,1,0,0,1,0,0,0,0,0,1
1,0,1,0,0,0,0,0,0,0,1,0,0,0,0,0,1
1,0,1,1,1,1,1,1,1,1,1,0,0,0,0,0,1
1,0,0,0,0,0,0,0,0,0,0,0,0,0,0,0,1
1,1,1,1,1,1,1,1,1,1,1,1,1,1,1,1,1
endlayer

layer
1,1,1,1,1,1,1,1,1,1,1,1,1,1,1,1,1
1,1,1,1,1,1,1,1,1,1,1,1,1,1,1,1,1
1,1,1,1,1,1,1,1,1,1,1,1,1,1,1,1,1
1,1,1,19,1,1,1,1,1,1,1,1,1,19,1,1,1
1,1,1,1,1,1,1,1,1,1,1,1,1,1,1,1,1
1,1,1,1,1,1,1,1,1,1,1,1,1,1,1,1,1
1,1,1,1,1,1,1,1,1,1,1,1,1,1,1,1,1
1,1,1,1,1,1,1,20,20,20,1,1,1,1,1,1,1
1,1,1,1,1,1,1,20,21,20,1,1,1,1,1,1,1
1,1,1,1,1,1,1,20,20,20,1,1,1,1,1,1,1
1,1,1,1,1,1,1,1,1,1,1,1,1,1,1,1,1
1,1,1,1,1,1,1,1,1,1,1,1,1,1,1,1,1
1,1,1,1,1,1,1,1,1,1,1,1,1,1,1,1,1
1,1,1,19,1,1,1,1,1,1,1,1,1,19,1,1,1
1,1,1,1,1,1,1,1,1,1,1,1,1,1,1,1,1
1,1,1,1,1,1,1,1,1,1,1,1,1,1,1,1,1
1,1,1,1,1,1,1,1,1,1,1,1,1,1,1,1,1
endlayer

layer
22,22,22,22,22,22,22,22,22,22,22,22,22,22,22,22,22
22,22,22,22,22,22,22,22,22,22,22,22,22,22,22,22,22
22,22,22,22,22,22,22,22,22,22,22,22,22,22,22,22,22
22,22,22,22,22,22,22,22,22,22,22,22,22,22,22,22,22
22,22,22,22,22,22,22,22,22,22,22,22,22,22,22,22,22
22,22,22,22,22,22,22,22,22,22,22,22,22,22,22,22,22
22,22,22,22,22,22,1,1,1,1,1,22,22,22,22,22,22
22,22,22,22,22,22,1,23,23,23,1,22,22,22,22,22,22
22,22,22,22,22,22,1,23,23,23,1,22,22,22,22,22,22
22,22,22,22,22,22,1,23,23,23,1,22,22,22,22,22,22
22,22,22,22,22,22,1,1,1,1,1,22,22,22,22,22,22
22,22,22,22,22,22,22,22,22,22,22,22,22,22,22,22,22
22,22,22,22,22,22,22,22,22,22,22,22,22,22,22,22,22
22,22,22,22,22,22,22,22,22,22,22,22,22,22,22,22,22
22,22,22,22,22,22,22,22,22,22,22,22,22,22,22,22,22
22,22,22,22,22,22,22,22,22,22,22,22,22,22,22,22,22
22,22,22,22,22,22,22,22,22,22,22,22,22,22,22,22,22
endlayer

layer
22,22,22,22,22,22,22,22,22,22,22,22,22,22,22,22,22
22,22,22,22,22,22,22,22,22,22,22,22,22,22,22,22,22
22,22,22,22,22,22,22,22,22,22,22,22,22,22,22,22,22
22,22,22,22,22,22,22,22,22,22,22,22,22,22,22,22,22
22,22,22,22,22,22,22,22,22,22,22,22,22,22,22,22,22
22,22,22,22,22,22,22,22,22,22,22,22,22,22,22,22,22
22,22,22,22,22,22,1,1,24,1,1,22,22,22,22,22,22
22,22,22,22,22,22,1,23,23,23,1,22,22,22,22,22,22
22,22,22,22,22,22,24,23,23,23,24,22,22,22,22,22,22
22,22,22,22,22,22,1,23,23,23,1,22,22,22,22,22,22
22,22,22,22,22,22,1,1,24,1,1,22,22,22,22,22,22
22,22,22,22,22,22,22,22,22,22,22,22,22,22,22,22,22
22,22,22,22,22,22,22,22,22,22,22,22,22,22,22,22,22
22,22,22,22,22,22,22,22,22,22,22,22,22,22,22,22,22
22,22,22,22,22,22,22,22,22,22,22,22,22,22,22,22,22
22,22,22,22,22,22,22,22,22,22,22,22,22,22,22,22,22
22,22,22,22,22,22,22,22,22,22,22,22,22,22,22,22,22
endlayer

layer
1,1,1,1,1,1,1,1,1,1,1,1,1,1,1,1,1
1,25,25,25,25,25,1,25,1,25,1,25,25,25,25,25,1
1,25,1,1,1,1,1,25,1,25,1,1,1,1,1,25,1
1,25,1,25,25,25,1,1,1,1,1,25,25,25,1,25,1
1,25,1,25,1,1,1,25,1,25,1,1,1,25,1,25,1
1,25,1,25,1,25,1,25,1,25,1,25,1,25,1,25,1
1,1,1,1,1,1,1,1,1,1,1,1,1,1,1,1,1
1,25,25,1,25,25,1,23,23,23,1,25,25,1,25,25,1
1,1,1,1,1,1,1,23,23,23,1,1,1,1,1,1,1
1,25,25,1,25,25,1,23,23,23,1,25,25,1,25,25,1
1,1,1,1,1,1,1,1,1,1,1,1,1,1,1,1,1
1,25,1,25,1,25,1,25,1,25,1,25,1,25,1,25,1
1,25,1,25,1,1,1,25,1,25,1,1,1,25,1,25,1
1,25,1,25,25,25,1,1,1,1,1,25,25,25,1,25,1
1,25,1,1,1,1,1,25,1,25,1,1,1,1,1,25,1
1,25,25,25,25,25,1,25,1,25,1,25,25,25,25,25,1
1,1,1,1,1,1,1,1,1,1,1,1,1,1,1,1,1
endlayer

layer
1,26,1,1,1,26,1,0,0,0,1,26,1,1,1,26,1
28,0,0,0,0,0,1,0,0,0,1,0,0,0,0,0,27
1,0,0,0,0,0,1,0,16,0,1,0,0,0,0,0,1
1,0,0,0,0,0,1,0,29,0,1,0,0,0,0,0,1
1,0,0,0,1,1,1,0,30,0,1,1,1,0,0,0,1
28,0,0,0,1,0,0,0,0,0,0,0,1,0,0,0,27
1,1,1,1,1,0,0,0,0,0,0,0,1,1,1,1,1
0,0,0,0,0,0,0,0,0,0,0,0,0,0,0,0,0
0,0,7,32,30,0,0,0,0,0,0,0,30,31,5,0,0
0,0,0,0,0,0,0,0,0,0,0,0,0,0,0,0,0
1,1,1,1,1,0,0,0,0,0,0,0,1,1,1,1,1
28,0,0,0,1,0,0,0,0,0,0,0,1,0,0,0,27
1,0,0,0,1,1,1,0,30,0,1,1,1,0,0,0,1
1,0,0,0,0,0,1,0,33,0,1,0,0,0,0,0,1
1,0,0,0,0,0,1,0,10,0,1,0,0,0,0,0,1
28,0,0,0,0,0,1,0,0,0,1,0,0,0,0,0,27
1,34,1,1,1,34,1,0,0,0,1,34,1,1,1,34,1
endlayer

layer
1,35,1,30,1,35,1,0,0,0,1,35,1,30,1,35,1
35,0,0,0,0,0,1,0,0,0,1,0,0,0,0,0,35
1,0,0,0,0,0,1,0,0,0,1,0,0,0,0,0,1
30,0,0,0,36,0,1,0,16,0,1,0,36,0,0,0,30
1,0,0,38,1,1,1,0,29,0,1,1,1,37,0,0,1
35,0,0,0,1,0,0,0,0,0,0,0,1,0,0,0,35
1,1,1,1,1,0,0,0,0,0,0,0,1,1,1,1,1
0,0,0,0,0,0,0,0,0,0,0,0,0,0,0,0,0
0,0,0,7,32,0,0,0,0,0,0,0,31,5,0,0,0
0,0,0,0,0,0,0,0,0,0,0,0,0,0,0,0,0
1,1,1,1,1,0,0,0,0,0,0,0,1,1,1,1,1
35,0,0,0,1,0,0,0,0,0,0,0,1,0,0,0,35
1,0,0,38,1,1,1,0,33,0,1,1,1,37,0,0,1
30,0,0,0,39,0,1,0,10,0,1,0,39,0,0,0,30
1,0,0,0,0,0,1,0,0,0,1,0,0,0,0,0,1
35,0,0,0,0,0,1,0,0,0,1,0,0,0,0,0,35
1,35,1,30,1,35,1,0,0,0,1,35,1,30,1,35,1
endlayer

layer
1,1,1,1,1,1,1,0,0,0,1,1,1,1,1,1,1
1,0,0,0,0,0,1,0,0,0,1,0,0,0,0,0,1
1,0,0,0,0,0,1,0,0,0,1,0,0,0,0,0,1
1,0,0,0,0,0,1,0,0,0,1,0,0,0,0,0,1
1,0,0,0,1,1,1,0,16,0,1,1,1,0,0,0,1
1,0,0,0,1,0,39,0,29,0,39,0,1,0,0,0,1
1,1,1,1,1,37,0,0,0,0,0,38,1,1,1,1,1
0,0,0,0,0,0,0,0,0,0,0,0,0,0,0,0,0
0,0,0,0,7,32,0,0,0,0,0,31,5,0,0,0,0
0,0,0,0,0,0,0,0,0,0,0,0,0,0,0,0,0
1,1,1,1,1,37,0,0,0,0,0,38,1,1,1,1,1
1,0,0,0,1,0,36,0,33,0,36,0,1,0,0,0,1
1,0,0,0,1,1,1,0,10,0,1,1,1,0,0,0,1
1,0,0,0,0,0,1,0,0,0,1,0,0,0,0,0,1
1,0,0,0,0,0,1,0,0,0,1,0,0,0,0,0,1
1,0,0,0,0,0,1,0,0,0,1,0,0,0,0,0,1
1,1,1,1,1,1,1,0,0,0,1,1,1,1,1,1,1
endlayer

layer
15,15,15,15,15,15,15,15,15,15,15,15,15,15,15,15,15
15,40,40,40,40,40,15,32,41,31,15,40,40,40,40,40,15
15,40,40,40,40,40,15,0,0,0,15,40,40,40,40,40,15
15,40,40,40,40,40,15,0,0,0,15,40,40,40,40,40,15
15,40,40,40,40,40,15,15,0,15,15,40,40,40,40,40,15
15,40,40,40,40,40,40,15,16,15,40,40,40,40,40,40,15
15,15,15,15,15,40,40,15,29,15,40,40,15,15,15,15,15
15,29,0,0,15,15,15,0,0,0,15,15,15,0,0,29,15
15,41,0,0,0,7,32,0,0,0,31,5,0,0,0,41,15
15,33,0,0,15,15,15,0,0,0,15,15,15,0,0,33,15
15,15,15,15,15,40,40,15,33,15,40,40,15,15,15,15,15
15,40,40,40,40,40,40,15,10,15,40,40,40,40,40,40,15
15,40,40,40,40,40,15,15,0,15,15,40,40,40,40,40,15
15,40,40,40,40,40,15,0,0,0,15,40,40,40,40,40,15
15,40,40,40,40,40,15,0,0,0,15,40,40,40,40,40,15
15,40,40,40,40,40,15,32,41,31,15,40,40,40,40,40,15
15,15,15,15,15,15,15,15,15,15,15,15,15,15,15,15,15
endlayer

layer
0,0,0,0,0,0,0,0,0,0,0,0,0,0,0,0,0
0,15,15,15,42,15,0,7,24,0,0,15,26,15,15,15,0
0,15,6,0,0,15,0,30,30,30,0,15,0,0,43,15,0
0,15,0,0,0,15,0,30,0,30,0,15,0,0,0,15,0
0,44,0,0,0,15,0,30,0,30,0,15,0,0,0,27,0
0,15,15,15,15,0,0,0,0,0,0,0,15,15,15,15,0
0,0,0,0,0,0,0,0,0,0,0,0,0,0,0,0,0
0,0,30,30,30,0,0,0,0,0,0,0,30,30,30,16,0
0,33,30,0,0,0,0,0,0,0,0,0,0,0,30,29,0
0,10,30,30,30,0,0,0,0,0,0,0,30,30,30,0,0
0,0,0,0,0,0,0,0,0,0,0,0,0,0,0,0,0
0,15,15,15,15,0,0,0,0,0,0,0,15,15,15,15,0
0,44,0,0,0,15,0,30,0,30,0,15,0,0,0,27,0
0,15,0,0,0,15,0,30,0,30,0,15,0,0,0,15,0
0,15,45,0,0,15,0,30,30,30,0,15,0,0,45,15,0
0,15,15,15,34,15,0,0,24,5,0,15,34,15,15,15,0
0,0,0,0,0,0,0,0,0,0,0,0,0,0,0,0,0
endlayer

layer
0,0,0,0,0,0,0,0,0,0,0,0,0,0,0,0,0
0,46,46,15,35,15,0,0,7,32,0,15,35,15,46,46,0
0,46,0,0,0,10,0,47,0,47,0,10,0,0,0,46,0
0,15,0,0,0,16,0,0,0,0,0,16,0,0,0,15,0
0,35,0,0,0,15,0,0,0,0,0,15,0,0,0,35,0
0,15,5,7,15,0,0,0,0,0,0,0,15,5,7,15,0
0,0,0,0,0,0,0,0,0,0,0,0,0,0,0,0,0
0,33,47,0,0,0,0,0,0,0,0,0,0,0,47,0,0
0,10,0,0,0,0,0,0,0,0,0,0,0,0,0,16,0
0,0,47,0,0,0,0,0,0,0,0,0,0,0,47,29,0
0,0,0,0,0,0,0,0,0,0,0,0,0,0,0,0,0
0,15,5,7,15,0,0,0,0,0,0,0,15,5,7,15,0
0,35,0,0,0,15,0,0,0,0,0,15,0,0,0,35,0
0,15,0,0,0,10,0,0,0,0,0,10,0,0,0,15,0
0,46,0,0,0,16,0,47,0,47,0,16,0,0,0,46,0
0,46,46,15,35,15,0,31,5,0,0,15,35,15,46,46,0
0,0,0,0,0,0,0,0,0,0,0,0,0,0,0,0,0
endlayer

layer
0,0,0,0,0,0,0,0,0,0,0,0,0,0,0,0,0
0,46,46,15,15,15,0,0,0,7,32,15,15,15,46,46,0
0,46,0,39,0,29,0,0,0,0,0,29,0,39,0,46,0
0,15,37,0,0,33,0,0,0,0,0,33,0,0,38,15,0
0,15,0,0,0,15,0,0,0,0,0,15,0,0,0,15,0
0,15,32,31,15,0,0,0,0,0,0,0,15,32,31,15,0
0,33,0,0,0,0,0,0,0,0,0,0,0,0,0,0,0
0,10,0,0,0,0,0,0,0,0,0,0,0,0,0,0,0
0,0,0,0,0,0,0,0,0,0,0,0,0,0,0,0,0
0,0,0,0,0,0,0,0,0,0,0,0,0,0,0,16,0
0,0,0,0,0,0,0,0,0,0,0,0,0,0,0,29,0
0,15,32,31,15,0,0,0,0,0,0,0,15,32,31,15,0
0,15,0,0,0,15,0,0,0,0,0,15,0,0,0,15,0
0,15,37,0,0,29,0,0,0,0,0,29,0,0,38,15,0
0,46,0,36,0,33,0,0,0,0,0,33,0,36,0,46,0
0,46,46,15,15,15,31,5,0,0,0,15,15,15,46,46,0
0,0,0,0,0,0,0,0,0,0,0,0,0,0,0,0,0
endlayer

layer
0,0,0,0,0,0,0,0,0,0,0,0,0,0,0,0,0
0,15,15,15,15,15,0,0,0,0,7,15,15,15,15,15,0
0,15,0,0,0,15,32,41,41,41,31,15,0,0,0,15,0
0,15,0,0,0,15,32,41,41,41,31,15,0,0,0,15,0
0,15,0,0,0,15,32,41,0,41,31,15,0,0,0,15,0
0,15,15,15,15,0,32,41,0,41,31,0,15,15,15,15,0
0,10,29,29,29,29,29,41,0,41,31,29,29,29,29,0,0
0,0,0,41,41,41,41,41,0,41,41,41,41,41,41,0,0
0,0,0,41,0,0,0,0,0,0,0,0,0,0,41,0,0
0,0,0,41,41,41,41,41,0,41,41,41,41,41,41,0,0
0,0,33,33,33,33,32,41,0,41,33,33,33,33,33,16,0
0,15,15,15,15,0,32,41,0,41,31,0,15,15,15,15,0
0,15,0,0,0,15,32,41,0,41,31,15,0,0,0,15,0
0,15,0,0,0,15,32,41,0,41,31,15,0,0,0,15,0
0,15,0,0,0,15,32,41,41,41,31,15,0,0,0,15,0
0,15,15,15,15,15,5,0,0,0,0,15,15,15,15,15,0
0,0,0,0,0,0,0,0,0,0,0,0,0,0,0,0,0
endlayer

layer
0,33,0,0,0,0,0,0,0,0,0,0,0,0,0,33,0
31,48,15,15,15,15,0,0,0,0,0,7,15,15,15,48,32
0,15,40,40,40,15,15,15,15,15,15,15,40,40,40,15,0
0,15,40,15,15,15,15,15,15,15,15,15,15,15,40,15,0
0,15,40,15,40,40,15,50,15,49,15,40,40,15,40,15,0
0,10,15,15,40,40,15,50,15,49,15,40,40,15,15,15,0
0,0,15,15,15,15,15,50,15,49,15,15,15,15,15,0,0
0,0,15,15,50,50,50,50,15,49,49,49,49,15,15,0,0
0,0,15,15,15,15,15,15,20,15,15,15,15,15,15,0,0
0,0,15,15,52,52,52,52,15,51,51,51,51,15,15,0,0
0,0,15,15,15,15,15,52,15,51,15,15,15,15,15,0,0
0,15,15,15,40,40,15,52,15,51,15,40,40,15,15,16,0
0,15,40,15,40,40,15,52,15,51,15,40,40,15,40,15,0
0,15,40,15,15,15,15,15,15,15,15,15,15,15,40,15,0
0,15,40,40,40,15,15,15,15,15,15,15,40,40,40,15,0
31,48,15,15,15,5,0,0,0,0,0,15,15,15,15,48,32
0,29,0,0,0,0,0,0,0,0,0,0,0,0,0,29,0
endlayer

layer
30,30,30,30,0,0,0,0,0,0,0,0,0,30,30,30,30
30,53,0,30,0,0,0,0,0,0,0,0,0,30,0,53,30
30,0,0,0,0,0,0,0,0,0,0,0,0,0,0,0,30
30,30,0,15,15,15,26,26,15,42,26,15,15,15,0,30,30
0,0,0,15,0,0,0,0,15,0,0,0,0,15,0,0,0
0,0,0,15,0,0,0,0,15,0,0,0,0,15,0,0,0
0,0,0,28,0,0,0,0,15,0,0,0,0,27,0,0,0
0,0,0,28,0,0,0,45,15,6,0,0,0,54,0,0,0
0,0,0,15,15,15,15,15,20,15,15,15,15,15,0,0,0
0,0,0,28,0,7,0,55,15,6,0,0,0,27,0,0,0
0,0,0,28,0,7,0,0,15,0,0,0,0,27,0,0,0
0,0,0,15,0,0,0,0,15,0,0,0,0,15,0,0,0
0,0,0,15,0,0,0,0,15,0,0,0,0,15,0,0,0
30,30,0,15,15,15,34,34,15,34,34,15,15,15,0,30,30
30,0,0,0,0,0,0,0,0,0,0,0,0,0,0,0,30
30,53,0,30,0,0,0,0,0,0,0,0,0,30,0,53,30
30,30,30,30,0,0,0,0,0,0,0,0,0,30,30,30,30
endlayer

layer
0,0,0,0,0,0,0,0,0,0,0,0,0,0,0,0,0
0,0,0,0,0,0,0,0,0,0,0,0,0,0,0,0,0
0,0,0,0,0,0,0,0,0,0,0,0,0,0,0,0,0
0,0,0,20,20,15,56,35,15,56,35,15,20,20,0,0,0
0,0,0,20,0,0,0,0,15,0,0,0,0,20,0,0,0
0,0,0,15,0,0,0,0,15,0,0,0,0,15,0,0,0
0,0,0,35,0,0,0,0,15,0,0,0,0,56,0,0,0
0,0,0,56,0,0,0,0,15,0,0,0,0,35,0,0,0
0,0,0,15,15,15,15,15,20,15,15,15,15,15,0,0,0
0,0,0,35,0,0,7,0,15,0,0,0,0,56,0,0,0
0,0,0,56,0,0,7,0,15,0,0,0,0,35,0,0,0
0,0,0,15,0,0,0,0,15,0,0,0,0,15,0,0,0
0,0,0,20,0,0,0,0,15,0,0,0,0,20,0,0,0
0,0,0,20,20,15,35,56,15,35,56,15,20,20,0,0,0
0,0,0,0,0,0,0,0,0,0,0,0,0,0,0,0,0
0,0,0,0,0,0,0,0,0,0,0,0,0,0,0,0,0
0,0,0,0,0,0,0,0,0,0,0,0,0,0,0,0,0
endlayer

layer
0,0,0,0,0,0,0,0,0,0,0,0,0,0,0,0,0
0,0,0,0,0,0,0,0,0,0,0,0,0,0,0,0,0
0,0,0,0,0,0,0,0,0,0,0,0,0,0,0,0,0
0,0,0,20,20,15,32,31,15,32,31,15,20,20,0,0,0
0,0,0,20,0,39,0,0,15,0,0,39,0,20,0,0,0
0,0,0,15,37,0,0,0,15,0,0,0,38,15,0,0,0
0,0,0,29,0,0,0,0,15,0,0,0,0,29,0,0,0
0,0,0,33,0,0,0,0,15,0,0,0,0,33,0,0,0
0,0,0,15,15,15,15,15,20,15,15,15,15,15,0,0,0
0,0,0,29,0,0,0,7,15,0,0,0,0,29,0,0,0
0,0,0,33,0,0,0,7,15,0,0,0,0,33,0,0,0
0,0,0,15,37,0,0,0,15,0,0,0,38,15,0,0,0
0,0,0,20,0,36,0,0,15,0,0,36,0,20,0,0,0
0,0,0,20,20,15,32,31,15,32,31,15,20,20,0,0,0
0,0,0,0,0,0,0,0,0,0,0,0,0,0,0,0,0
0,0,0,0,0,0,0,0,0,0,0,0,0,0,0,0,0
0,0,0,0,0,0,0,0,0,0,0,0,0,0,0,0,0
endlayer

layer
0,0,0,0,0,0,0,0,0,0,0,0,0,0,0,0,0
0,0,0,0,0,0,0,0,0,0,0,0,0,0,0,0,0
0,0,0,0,0,0,0,0,0,0,0,0,0,0,0,0,0
0,0,0,15,15,15,15,15,15,15,15,15,15,15,0,0,0
0,0,0,15,57,57,57,57,15,57,57,57,57,15,0,0,0
0,0,0,15,57,57,57,57,15,57,57,57,57,15,0,0,0
0,0,0,15,57,57,57,57,15,57,57,57,57,15,0,0,0
0,0,0,15,57,57,57,57,15,57,57,57,57,15,0,0,0
0,0,0,15,15,15,15,15,20,15,15,15,15,15,0,0,0
0,0,0,15,0,0,0,0,7,57,57,57,57,15,0,0,0
0,0,0,15,0,0,0,0,7,57,57,57,57,15,0,0,0
0,0,0,15,57,57,57,57,15,57,57,57,57,15,0,0,0
0,0,0,15,57,57,57,57,15,57,57,57,57,15,0,0,0
0,0,0,15,15,15,15,15,15,15,15,15,15,15,0,0,0
0,0,0,0,0,0,0,0,0,0,0,0,0,0,0,0,0
0,0,0,0,0,0,0,0,0,0,0,0,0,0,0,0,0
0,0,0,0,0,0,0,0,0,0,0,0,0,0,0,0,0
endlayer

layer
0,0,0,0,0,0,0,0,0,0,0,0,0,0,0,0,0
0,0,0,0,0,0,0,0,0,0,0,0,0,0,0,0,0
0,0,0,0,0,0,0,0,0,0,0,0,0,0,0,0,0
0,0,0,15,24,15,24,15,24,15,24,15,24,15,0,0,0
0,0,0,24,57,57,57,57,57,57,57,57,57,24,0,0,0
0,0,0,15,57,57,57,57,57,57,57,57,57,15,0,0,0
0,0,0,24,57,57,57,57,58,57,57,57,57,24,0,0,0
0,0,0,15,57,57,57,57,57,57,57,57,57,15,0,0,0
0,0,0,24,57,57,57,57,20,57,57,57,57,24,0,0,0
0,0,0,15,57,57,0,0,0,7,57,57,57,15,0,0,0
0,0,0,24,57,57,0,0,0,7,57,57,57,24,0,0,0
0,0,0,15,57,57,57,57,57,57,57,57,57,15,0,0,0
0,0,0,24,57,57,57,57,57,57,57,57,57,24,0,0,0
0,0,0,15,24,15,24,15,24,15,24,15,24,15,0,0,0
0,0,0,0,0,0,0,0,0,0,0,0,0,0,0,0,0
0,0,0,0,0,0,0,0,0,0,0,0,0,0,0,0,0
0,0,0,0,0,0,0,0,0,0,0,0,0,0,0,0,0
endlayer

layer
0,0,0,0,0,0,0,0,0,0,0,0,0,0,0,0,0
0,0,0,0,0,0,0,0,0,0,0,0,0,0,0,0,0
0,0,0,0,0,0,0,0,0,0,0,0,0,0,0,0,0
0,0,0,15,30,30,30,30,30,30,30,30,30,15,0,0,0
0,0,0,30,0,0,0,0,0,0,0,0,0,30,0,0,0
0,0,0,30,0,4,0,16,16,16,0,4,0,30,0,0,0
0,0,0,30,0,59,0,7,60,5,0,59,0,30,0,0,0
0,0,0,30,0,61,0,7,10,5,0,61,0,30,0,0,0
0,0,0,30,0,0,0,0,0,0,0,0,0,30,0,0,0
0,0,0,30,0,0,0,0,0,0,0,0,0,30,0,0,0
0,0,0,30,0,0,0,0,0,0,0,0,0,30,0,0,0
0,0,0,30,0,0,0,0,0,0,0,0,0,30,0,0,0
0,0,0,30,0,0,0,0,0,0,0,0,0,30,0,0,0
0,0,0,15,30,30,30,30,30,30,30,30,30,15,0,0,0
0,0,0,0,0,0,0,0,0,0,0,0,0,0,0,0,0
0,0,0,0,0,0,0,0,0,0,0,0,0,0,0,0,0
0,0,0,0,0,0,0,0,0,0,0,0,0,0,0,0,0
endlayer

layer
0,0,0,0,0,0,0,0,0,0,0,0,0,0,0,0,0
0,0,0,0,0,0,0,0,0,0,0,0,0,0,0,0,0
0,0,0,0,0,0,0,0,0,0,0,0,0,0,0,0,0
0,0,0,15,30,0,0,0,0,0,0,0,30,15,0,0,0
0,0,0,30,0,0,0,0,0,0,0,0,0,30,0,0,0
0,0,0,0,0,0,0,0,0,0,0,0,0,0,0,0,0
0,0,0,0,0,0,0,0,0,0,0,0,0,0,0,0,0
0,0,0,0,0,0,0,0,0,0,0,0,0,0,0,0,0
0,0,0,0,0,0,0,0,0,0,0,0,0,0,0,0,0
0,0,0,0,0,0,0,0,0,0,0,0,0,0,0,0,0
0,0,0,0,0,0,0,0,0,0,0,0,0,0,0,0,0
0,0,0,0,0,0,0,0,0,0,0,0,0,0,0,0,0
0,0,0,30,0,0,0,0,0,0,0,0,0,30,0,0,0
0,0,0,15,30,0,0,0,0,0,0,0,30,15,0,0,0
0,0,0,0,0,0,0,0,0,0,0,0,0,0,0,0,0
0,0,0,0,0,0,0,0,0,0,0,0,0,0,0,0,0
0,0,0,0,0,0,0,0,0,0,0,0,0,0,0,0,0
endlayer

layer
0,0,0,0,0,0,0,0,0,0,0,0,0,0,0,0,0
0,0,0,0,0,0,0,0,0,0,0,0,0,0,0,0,0
0,0,0,0,0,0,0,0,0,0,0,0,0,0,0,0,0
0,0,0,15,15,0,0,0,0,0,0,0,15,15,0,0,0
0,0,0,15,0,0,0,0,62,0,0,0,0,15,0,0,0
0,0,0,0,0,0,0,0,0,0,0,0,0,0,0,0,0
0,0,0,0,0,0,0,0,0,0,0,0,0,0,0,0,0
0,0,0,0,0,0,0,0,0,0,0,0,0,0,0,0,0
0,0,0,0,62,0,0,0,0,0,0,0,62,0,0,0,0
0,0,0,0,0,0,0,0,0,0,0,0,0,0,0,0,0
0,0,0,0,0,0,0,0,0,0,0,0,0,0,0,0,0
0,0,0,0,0,0,0,0,0,0,0,0,0,0,0,0,0
0,0,0,15,0,0,0,0,62,0,0,0,0,15,0,0,0
0,0,0,15,15,0,0,0,0,0,0,0,15,15,0,0,0
0,0,0,0,0,0,0,0,0,0,0,0,0,0,0,0,0
0,0,0,0,0,0,0,0,0,0,0,0,0,0,0,0,0
0,0,0,0,0,0,0,0,0,0,0,0,0,0,0,0,0
endlayer

layer
0,0,0,0,0,0,0,0,0,0,0,0,0,0,0,0,0
0,0,0,0,0,0,0,0,0,0,0,0,0,0,0,0,0
0,0,0,0,0,0,0,0,0,0,0,0,0,0,0,0,0
0,0,0,0,15,0,0,0,0,0,0,0,15,0,0,0,0
0,0,0,15,15,0,0,0,30,0,0,0,15,15,0,0,0
0,0,0,0,0,0,0,0,0,0,0,0,0,0,0,0,0
0,0,0,0,0,0,0,0,0,0,0,0,0,0,0,0,0
0,0,0,0,0,0,0,0,0,0,0,0,0,0,0,0,0
0,0,0,0,30,0,0,0,0,0,0,0,30,0,0,0,0
0,0,0,0,0,0,0,0,0,0,0,0,0,0,0,0,0
0,0,0,0,0,0,0,0,0,0,0,0,0,0,0,0,0
0,0,0,0,0,0,0,0,0,0,0,0,0,0,0,0,0
0,0,0,15,15,0,0,0,30,0,0,0,15,15,0,0,0
0,0,0,0,15,0,0,0,0,0,0,0,15,0,0,0,0
0,0,0,0,0,0,0,0,0,0,0,0,0,0,0,0,0
0,0,0,0,0,0,0,0,0,0,0,0,0,0,0,0,0
0,0,0,0,0,0,0,0,0,0,0,0,0,0,0,0,0
endlayer

layer
0,0,0,0,0,0,0,0,0,0,0,0,0,0,0,0,0
0,0,0,0,0,0,0,0,0,0,0,0,0,0,0,0,0
0,0,0,0,0,0,0,0,0,0,0,0,0,0,0,0,0
0,0,0,0,15,15,0,0,0,0,0,15,15,0,0,0,0
0,0,0,15,15,0,0,0,30,0,0,0,15,15,0,0,0
0,0,0,15,0,0,0,0,0,0,0,0,0,15,0,0,0
0,0,0,0,0,0,0,0,0,0,0,0,0,0,0,0,0
0,0,0,0,0,0,0,0,0,0,0,0,0,0,0,0,0
0,0,0,0,30,0,0,0,0,0,0,0,30,0,0,0,0
0,0,0,0,0,0,0,0,0,0,0,0,0,0,0,0,0
0,0,0,0,0,0,0,0,0,0,0,0,0,0,0,0,0
0,0,0,15,0,0,0,0,0,0,0,0,0,15,0,0,0
0,0,0,15,15,0,0,0,30,0,0,0,15,15,0,0,0
0,0,0,0,15,15,0,0,0,0,0,15,15,0,0,0,0
0,0,0,0,0,0,0,0,0,0,0,0,0,0,0,0,0
0,0,0,0,0,0,0,0,0,0,0,0,0,0,0,0,0
0,0,0,0,0,0,0,0,0,0,0,0,0,0,0,0,0
endlayer

layer
0,0,0,0,0,0,0,0,0,0,0,0,0,0,0,0,0
0,0,0,0,0,0,0,0,0,0,0,0,0,0,0,0,0
0,0,0,0,0,0,0,0,0,0,0,0,0,0,0,0,0
0,0,0,0,0,15,15,0,0,0,15,15,0,0,0,0,0
0,0,0,0,15,15,0,0,30,0,0,15,15,0,0,0,0
0,0,0,15,15,0,0,0,0,0,0,0,15,15,0,0,0
0,0,0,15,0,0,0,0,0,0,0,0,0,15,0,0,0
0,0,0,0,0,0,0,0,0,0,0,0,0,0,0,0,0
0,0,0,0,30,0,0,0,0,0,0,0,30,0,0,0,0
0,0,0,0,0,0,0,0,0,0,0,0,0,0,0,0,0
0,0,0,15,0,0,0,0,0,0,0,0,0,15,0,0,0
0,0,0,15,15,0,0,0,0,0,0,0,15,15,0,0,0
0,0,0,0,15,15,0,0,30,0,0,15,15,0,0,0,0
0,0,0,0,0,15,15,0,0,0,15,15,0,0,0,0,0
0,0,0,0,0,0,0,0,0,0,0,0,0,0,0,0,0
0,0,0,0,0,0,0,0,0,0,0,0,0,0,0,0,0
0,0,0,0,0,0,0,0,0,0,0,0,0,0,0,0,0
endlayer

layer
0,0,0,0,0,0,0,0,0,0,0,0,0,0,0,0,0
0,0,0,0,0,0,0,0,0,0,0,0,0,0,0,0,0
0,0,0,0,0,0,0,0,0,0,0,0,0,0,0,0,0
0,0,0,0,0,0,15,15,15,15,15,0,0,0,0,0,0
0,0,0,0,0,15,15,15,15,15,15,15,0,0,0,0,0
0,0,0,0,15,15,0,0,0,0,15,15,15,0,0,0,0
0,0,0,15,15,0,0,0,0,0,0,15,15,15,0,0,0
0,0,0,15,15,0,0,0,0,0,0,0,15,15,0,0,0
0,0,0,15,15,0,0,0,0,0,0,0,15,15,0,0,0
0,0,0,15,15,0,0,0,0,0,0,0,15,15,0,0,0
0,0,0,15,15,15,0,0,0,0,0,15,15,15,0,0,0
0,0,0,0,15,15,15,0,0,0,15,15,15,0,0,0,0
0,0,0,0,0,15,15,15,15,15,15,15,0,0,0,0,0
0,0,0,0,0,0,15,15,15,15,15,0,0,0,0,0,0
0,0,0,0,0,0,0,0,0,0,0,0,0,0,0,0,0
0,0,0,0,0,0,0,0,0,0,0,0,0,0,0,0,0
0,0,0,0,0,0,0,0,0,0,0,0,0,0,0,0,0
endlayer

layer
0,0,0,0,0,0,0,0,0,0,0,0,0,0,0,0,0
0,0,0,0,0,0,0,0,0,0,0,0,0,0,0,0,0
0,0,0,0,0,0,0,0,0,0,0,0,0,0,0,0,0
0,0,0,0,0,0,0,0,0,0,0,0,0,0,0,0,0
0,0,0,0,0,0,9,9,9,9,9,0,0,0,0,0,0
0,0,0,0,0,15,15,15,15,15,15,15,0,0,0,0,0
0,0,0,0,9,15,15,0,0,0,15,15,9,0,0,0,0
0,0,0,0,9,15,0,0,0,0,0,15,9,0,0,0,0
0,0,0,0,9,15,0,0,0,0,0,15,9,0,0,0,0
0,0,0,0,9,15,0,0,0,0,0,15,9,0,0,0,0
0,0,0,0,9,15,15,0,0,0,15,15,9,0,0,0,0
0,0,0,0,0,15,15,15,15,15,15,15,0,0,0,0,0
0,0,0,0,0,0,9,9,9,9,9,0,0,0,0,0,0
0,0,0,0,0,0,0,0,0,0,0,0,0,0,0,0,0
0,0,0,0,0,0,0,0,0,0,0,0,0,0,0,0,0
0,0,0,0,0,0,0,0,0,0,0,0,0,0,0,0,0
0,0,0,0,0,0,0,0,0,0,0,0,0,0,0,0,0
endlayer

layer
0,0,0,0,0,0,0,0,0,0,0,0,0,0,0,0,0
0,0,0,0,0,0,0,0,0,0,0,0,0,0,0,0,0
0,0,0,0,0,0,0,0,0,0,0,0,0,0,0,0,0
0,0,0,0,0,0,0,0,0,0,0,0,0,0,0,0,0
0,0,0,0,0,0,0,0,0,0,0,0,0,0,0,0,0
0,0,0,0,0,0,0,0,0,0,0,0,0,0,0,0,0
0,0,0,0,0,0,9,9,9,9,9,0,0,0,0,0,0
0,0,0,0,0,0,9,9,0,9,9,0,0,0,0,0,0
0,0,0,0,0,0,9,0,0,0,9,0,0,0,0,0,0
0,0,0,0,0,0,9,9,0,9,9,0,0,0,0,0,0
0,0,0,0,0,0,9,9,9,9,9,0,0,0,0,0,0
0,0,0,0,0,0,0,0,0,0,0,0,0,0,0,0,0
0,0,0,0,0,0,0,0,0,0,0,0,0,0,0,0,0
0,0,0,0,0,0,0,0,0,0,0,0,0,0,0,0,0
0,0,0,0,0,0,0,0,0,0,0,0,0,0,0,0,0
0,0,0,0,0,0,0,0,0,0,0,0,0,0,0,0,0
0,0,0,0,0,0,0,0,0,0,0,0,0,0,0,0,0
endlayer

