
# Created by Ruins mod version 14.1 Ingame Parser
# authoring Player: Divineaspect

biomestoSpawnIn=plains,grove,grassland,heathland,lavenderfields,prairie,savanna,steppe,shrubland,forest,foresthills,birch forest,birch forest m,boreal forest,birch forest hills,birch forest hills m,cherry blossom grove,cold tiaga,fen, 
weight=1000
embed_into_distance=3
acceptable_target_blocks=
unacceptable_target_blocks=flowing_water,water,flowing_lava,lava
dimensions=20,18,17
allowable_overhang=2
max_leveling=12
leveling_buffer=3
preserve_water=0
preserve_lava=0
uniqueMinDistance=1500

rule1=0,100,minecraft:dirt-0
rule2=0,100,minecraft:cobblestone-0
rule3=1,100,minecraft:torch-5
rule4=0,100,ChestGenHook:dungeonChest:5-5
rule5=0,100,ChestGenHook:dungeonChest:5-4
rule6=0,100,minecraft:stone_stairs-0
rule7=0,100,ChestGenHook:dungeonChest:5-3
rule8=2,100,WallSign:null:null:null:null-2
rule9=0,100,minecraft:water-8
rule10=0,100,ChestGenHook:dungeonChest:5-2
rule11=0,100,chisel:cobblestone-2
rule12=0,100,minecraft:redstone_wire-0
rule13=0,100,MobSpawner:Zombie
rule14=2,100,minecraft:torch-4
rule15=0,100,minecraft:grass-0
rule16=0,100,minecraft:trapdoor-9
rule17=0,100,minecraft:farmland-7
rule18=0,100,minecraft:water-0
rule19=0,100,minecraft:wooden_door-0
rule20=0,100,minecraft:furnace-4
rule21=0,100,minecraft:wheat-0
rule22=0,100,minecraft:waterlily-0
rule23=0,100,minecraft:fence-0
rule24=0,100,minecraft:wooden_pressure_plate-0
rule25=0,100,minecraft:wheat-3
rule26=0,100,minecraft:wheat-2
rule27=0,100,minecraft:stone_stairs-2
rule28=0,100,minecraft:stone_stairs-7
rule29=0,100,minecraft:wheat-4
rule30=0,100,minecraft:wooden_door-2
rule31=0,100,minecraft:fence_gate-1
rule32=0,100,minecraft:wooden_door-7
rule33=0,100,minecraft:wooden_door-1
rule34=0,100,minecraft:stone_stairs-1
rule35=0,100,minecraft:wooden_door-3
rule36=0,100,minecraft:carpet-10
rule37=0,100,minecraft:bookshelf-0
rule38=0,100,minecraft:enchanting_table-0
rule39=0,100,chisel:cobblestone-10
rule40=0,100,minecraft:wooden_door-8
rule41=0,100,minecraft:wooden_door-9
rule42=2,100,minecraft:torch-2
rule43=2,100,minecraft:torch-3
rule44=2,100,minecraft:torch-1
rule45=0,100,minecraft:stone_stairs-4
rule46=0,100,minecraft:stone_stairs-3
rule47=0,100,minecraft:glowstone-0
rule48=0,100,minecraft:stone_slab-11
rule49=0,100,minecraft:stone_slab-3
rule50=0,100,minecraft:planks-0
rule51=0,100,minecraft:iron_bars-0
rule52=0,100,minecraft:wooden_door-6
rule53=0,100,chisel:cobblestone-15
rule54=0,100,MobSpawner:Villager
rule55=0,100,minecraft:reeds-0
rule56=0,100,minecraft:pumpkin_stem-2
rule57=0,100,minecraft:reeds-13
rule58=0,100,minecraft:ladder-3
rule59=0,100,minecraft:reeds-2
rule60=0,100,Natura:Rare Sapling-1
rule61=0,100,Natura:N Crops-2
rule62=0,100,Natura:N Crops-1
rule63=0,100,minecraft:pumpkin_stem-0
rule64=0,100,Natura:N Crops-3
rule65=0,100,minecraft:pumpkin_stem-1
rule66=0,100,Natura:N Crops-0

layer
1,2,2,2,2,2,1,1,1,1,1,1,1,1,1,1,1
1,2,0,0,3,2,2,2,2,2,2,2,2,2,2,1,1
1,2,0,0,0,2,4,0,4,2,0,0,0,0,2,1,1
1,2,0,0,0,2,0,0,2,2,0,0,2,0,2,1,1
1,2,2,2,2,2,0,0,0,0,0,5,2,0,2,2,1
1,1,1,1,1,2,2,2,0,0,2,2,2,0,0,0,1
1,1,1,1,1,2,0,0,0,0,0,0,2,0,2,6,1
1,1,1,1,1,2,0,0,2,2,0,0,2,0,2,4,1
1,1,1,1,1,2,5,0,7,2,0,0,2,0,2,2,1
1,1,1,1,1,2,2,2,2,2,2,0,0,0,0,2,1
1,1,1,0,1,2,1,1,1,1,2,0,2,2,2,2,1
1,1,1,0,1,2,1,1,1,1,2,0,2,4,0,2,1
1,2,2,8,2,2,2,2,2,2,2,0,0,0,0,2,1
1,2,9,9,9,2,0,0,0,2,0,0,0,2,2,2,1
1,2,9,9,9,11,0,10,0,0,0,2,0,0,7,2,1
1,2,9,9,9,2,0,0,0,2,0,2,0,0,0,2,1
1,2,2,2,2,2,2,2,2,2,2,2,2,2,2,2,1
1,1,1,1,1,1,1,1,1,1,1,1,1,1,1,1,1
endlayer

layer
1,2,2,2,2,2,1,1,1,1,1,1,1,1,1,1,1
1,2,0,0,0,2,2,2,2,2,2,2,2,2,2,1,1
1,2,0,0,0,2,0,0,0,2,0,0,0,0,2,1,1
1,2,0,0,0,2,0,0,2,2,0,0,2,0,2,1,1
1,2,2,2,2,2,0,0,0,0,0,0,2,0,2,2,1
1,1,1,1,1,2,2,2,0,0,2,2,2,0,0,0,1
1,1,1,1,1,2,0,0,0,0,0,0,2,0,12,0,1
1,1,1,1,1,2,0,0,2,2,0,0,2,0,12,6,1
1,1,1,1,1,2,0,0,0,2,0,0,2,0,2,2,1
1,1,1,13,1,2,2,2,2,2,2,0,0,0,0,2,1
1,1,1,0,1,2,1,1,1,1,2,0,2,2,2,2,1
1,1,1,0,1,2,1,1,1,1,2,0,2,0,0,2,1
1,2,2,8,2,2,2,2,2,2,2,0,0,0,0,2,1
1,2,9,9,9,2,14,0,0,2,0,0,0,2,2,2,1
1,2,9,9,9,0,0,0,0,0,0,2,0,0,0,2,1
1,2,9,9,9,2,0,0,0,2,0,2,0,0,0,2,1
1,2,2,2,2,2,2,2,2,2,2,2,2,2,2,2,1
1,1,1,1,1,1,1,1,1,1,1,1,1,1,1,1,1
endlayer

layer
15,2,2,2,2,2,15,15,15,15,15,15,15,15,15,15,15
15,2,11,11,11,2,2,2,2,2,2,2,2,2,2,1,15
15,2,11,11,11,2,11,11,11,11,11,11,11,11,2,15,15
15,2,11,11,11,2,11,11,11,11,11,11,11,11,2,15,15
15,2,2,2,2,2,11,11,11,11,11,11,11,11,2,2,2
15,15,17,18,17,2,11,11,11,11,11,11,11,11,11,16,2
15,15,17,17,17,2,11,11,11,11,11,11,11,11,11,16,2
15,15,17,17,17,2,11,11,11,11,11,11,11,11,11,16,2
15,15,17,17,17,2,11,11,11,11,11,11,11,11,11,6,2
15,15,15,15,15,2,2,2,2,2,2,2,2,2,2,2,2
15,15,15,15,15,15,15,15,15,15,2,11,11,2,11,2,2
15,15,15,15,15,15,15,15,15,15,2,11,11,2,11,2,2
15,15,2,2,2,15,15,2,2,2,2,2,2,2,2,2,2
15,2,9,9,9,2,15,2,11,11,11,11,11,11,11,2,15
15,2,9,9,9,2,15,2,11,11,11,11,11,11,11,2,15
15,2,9,9,9,2,15,2,11,11,11,11,11,11,11,2,15
15,15,2,2,2,15,15,2,2,2,2,2,2,2,2,2,15
15,15,15,15,15,15,15,15,15,15,15,15,15,15,15,15,15
endlayer

layer
0,11,11,11,11,11,0,0,0,0,0,0,0,0,0,0,0
0,11,0,0,0,11,11,19,19,11,11,11,11,11,11,11,0
0,11,0,0,0,0,0,0,0,0,0,0,4,0,11,0,0
0,11,20,20,20,11,0,0,0,0,0,0,0,0,11,0,0
0,11,11,11,11,11,0,0,0,0,0,0,0,0,11,11,11
0,23,21,22,21,11,0,0,0,0,0,0,0,0,12,0,11
0,23,26,25,25,11,0,0,0,0,0,0,0,0,24,0,11
0,23,26,29,21,11,0,0,0,28,27,0,0,0,12,0,11
0,23,26,25,26,11,0,0,0,28,27,0,0,0,0,0,11
0,23,23,31,23,11,30,11,11,11,11,0,0,11,11,11,11
0,0,0,0,0,0,0,0,0,0,32,0,0,11,4,0,11
0,0,0,0,0,0,0,0,0,0,35,0,0,11,34,0,33
0,0,15,15,15,0,0,11,11,11,11,0,0,11,36,11,11
0,15,18,18,18,15,0,11,37,36,36,36,36,36,36,11,0
0,15,18,18,18,15,0,11,37,36,38,36,36,36,36,11,0
0,15,18,18,18,15,0,11,37,36,36,36,36,36,36,11,0
0,0,15,15,15,0,0,11,11,11,11,11,11,11,11,11,0
0,0,0,0,0,0,0,0,0,0,0,0,0,0,0,0,0
endlayer

layer
0,11,11,11,11,11,0,0,0,0,0,0,0,0,0,0,0
0,11,0,0,0,11,11,41,40,11,11,11,39,11,11,11,0
0,39,0,0,0,0,0,0,0,0,0,0,0,0,11,0,0
0,11,0,5,0,11,0,0,0,0,0,0,0,0,11,0,0
0,11,11,11,11,11,0,0,0,0,0,0,0,0,11,11,11
0,0,0,0,0,11,0,0,0,0,0,0,0,0,0,0,11
0,0,0,0,0,11,0,0,0,0,0,0,0,0,0,0,11
0,0,0,0,0,11,0,0,28,27,0,0,0,0,0,0,11
0,0,0,0,0,11,0,42,28,27,0,0,0,0,0,0,11
0,0,0,0,0,11,40,11,11,11,11,0,0,11,11,11,11
0,0,0,0,0,0,0,0,0,0,40,0,0,11,34,43,11
0,0,0,0,0,0,0,0,0,0,41,0,0,11,0,0,40
0,0,0,3,0,0,0,11,11,11,11,0,0,11,0,11,11
0,0,0,0,0,0,0,11,37,0,0,0,0,0,0,11,0
0,3,0,22,0,3,0,39,0,0,0,0,0,0,0,39,0
0,0,0,0,0,0,0,11,37,0,0,0,0,0,0,11,0
0,0,0,3,0,0,0,11,11,11,11,11,11,11,11,11,0
0,0,0,0,0,0,0,0,0,0,0,0,0,0,0,0,0
endlayer

layer
0,11,11,11,11,11,0,0,0,0,0,0,0,0,0,0,0
0,39,0,0,0,11,11,11,11,11,11,39,39,39,11,11,0
0,39,0,0,0,11,44,0,0,44,0,0,0,0,11,0,0
0,39,0,0,0,11,0,0,0,0,0,0,0,0,11,0,0
0,11,11,11,11,11,14,0,0,0,0,0,0,43,11,11,11
0,0,0,0,0,11,0,0,0,0,0,0,0,0,0,0,11
0,0,0,0,0,11,45,45,0,0,0,0,0,0,0,0,11
0,0,0,0,0,11,11,11,27,0,0,0,0,0,0,0,11
0,0,0,0,0,11,11,11,27,0,0,0,0,42,0,0,11
0,0,0,0,0,11,11,11,11,11,11,0,0,11,11,11,11
0,0,0,0,0,0,0,0,0,0,11,0,43,11,0,46,11
0,0,0,0,0,0,0,0,0,0,11,0,0,11,0,0,11
0,0,0,0,0,0,0,11,11,11,11,0,0,11,0,11,11
0,0,0,0,0,0,0,39,0,0,0,0,0,0,0,39,0
0,0,0,0,0,0,0,39,0,0,0,0,0,0,0,39,0
0,0,0,0,0,0,0,39,0,0,0,42,0,0,0,39,0
0,0,0,0,0,0,0,11,11,11,11,11,11,11,11,11,0
0,0,0,0,0,0,0,0,0,0,0,0,0,0,0,0,0
endlayer

layer
0,39,39,39,39,39,0,0,0,0,0,0,0,0,0,0,0
0,39,0,0,0,39,39,39,39,39,39,39,47,39,39,39,0
0,47,0,0,0,39,0,0,0,0,0,0,0,0,39,0,0
0,39,0,0,0,39,0,0,0,0,0,0,0,0,39,0,0
0,39,39,39,39,39,0,0,0,0,0,0,0,0,39,39,39
0,0,0,0,0,39,45,45,0,0,0,0,0,0,0,0,39
0,0,0,0,0,39,34,34,0,0,0,0,0,0,0,0,39
0,0,0,0,0,39,0,0,0,0,0,0,0,0,0,0,39
0,0,0,0,0,39,0,0,0,0,0,0,0,0,0,0,39
0,0,0,0,0,39,39,39,39,39,39,0,0,39,39,39,39
0,0,0,0,0,0,0,0,0,0,39,0,0,39,0,0,39
0,0,0,0,0,0,0,0,0,0,39,0,0,39,0,6,39
0,0,0,0,0,0,0,39,39,39,39,0,0,39,39,39,39
0,0,0,0,0,0,0,39,0,0,0,0,48,28,39,39,0
0,0,0,0,0,0,0,47,0,0,0,0,48,28,39,47,0
0,0,0,0,0,0,0,39,0,0,0,0,48,28,39,39,0
0,0,0,0,0,0,0,39,39,39,39,39,39,39,39,39,0
0,0,0,0,0,0,0,0,0,0,0,0,0,0,0,0,0
endlayer

layer
0,11,11,11,11,11,0,0,0,0,0,0,0,0,0,0,0
0,39,0,0,0,11,11,11,11,11,11,39,39,39,11,11,0
0,39,0,0,0,11,0,0,0,0,0,0,0,0,11,0,0
0,39,0,0,0,11,0,0,0,0,0,0,0,0,11,0,0
0,11,11,11,11,11,45,45,0,0,0,0,0,0,11,11,11
0,0,0,0,0,11,34,34,0,0,0,0,0,0,0,0,11
0,0,0,0,0,11,0,0,0,0,0,0,0,0,0,0,11
0,0,0,0,0,11,0,0,0,0,0,0,0,0,0,0,11
0,0,0,0,0,11,0,0,0,0,0,0,0,0,0,0,11
0,0,0,0,0,11,11,11,11,11,11,0,0,11,11,11,11
0,0,0,0,0,0,0,0,0,0,11,0,0,11,0,0,11
0,0,0,0,0,0,0,0,0,0,11,0,0,11,27,0,11
0,0,0,0,0,0,0,11,11,11,11,11,11,11,49,11,11
0,0,0,0,0,0,0,39,0,0,0,0,0,0,0,39,0
0,0,0,0,0,0,0,39,0,0,0,0,0,0,0,39,0
0,0,0,0,0,0,0,39,0,0,0,0,0,5,0,39,0
0,0,0,0,0,0,0,11,11,11,11,11,11,11,11,11,0
0,0,0,0,0,0,0,0,0,0,0,0,0,0,0,0,0
endlayer

layer
0,11,11,11,11,11,11,11,0,0,0,0,0,0,0,11,11
0,11,50,50,50,11,11,11,11,11,11,11,39,11,11,11,11
0,39,50,50,50,11,11,11,11,11,11,11,11,11,11,11,0
0,11,50,50,50,11,11,11,11,50,50,50,50,50,11,11,0
0,11,11,11,11,11,34,34,11,50,50,50,50,50,11,11,11
0,0,0,0,0,11,0,0,11,50,50,50,50,50,11,11,11
0,0,0,0,0,11,0,0,11,11,11,11,11,11,11,11,11
0,0,0,0,0,11,0,0,11,11,11,11,11,11,11,11,11
0,0,0,0,0,11,0,42,11,11,11,11,11,11,11,11,11
0,0,0,0,0,11,11,11,11,11,11,11,11,11,11,11,11
0,0,0,0,0,0,0,0,0,0,11,11,11,11,34,0,11
0,0,0,0,0,0,0,0,0,0,11,11,11,11,0,0,11
0,0,0,0,0,0,0,11,11,11,11,11,11,11,0,11,11
0,0,0,0,0,0,0,11,0,0,0,0,0,0,0,11,0
0,0,0,0,0,0,0,39,0,0,0,0,0,0,0,39,0
0,0,0,0,0,0,0,11,0,0,0,0,0,42,0,11,0
0,0,0,0,0,0,0,11,11,11,11,11,11,11,11,11,0
0,0,0,0,0,0,0,0,0,0,0,0,0,0,0,0,0
endlayer

layer
0,11,11,19,11,11,51,51,51,51,51,51,51,51,51,51,51
0,11,10,0,0,11,0,0,0,0,0,0,0,0,0,0,51
0,11,0,0,0,0,0,0,11,19,11,11,19,11,11,0,51
0,11,0,0,0,11,0,0,11,0,0,11,0,7,11,0,51
0,11,11,11,11,11,0,0,11,0,0,11,0,0,11,0,11
0,0,0,0,0,11,0,0,11,0,0,11,0,0,11,0,11
0,0,0,0,0,11,0,0,11,11,11,11,11,11,11,0,11
0,0,0,0,11,11,11,11,27,0,0,0,0,27,0,0,11
0,0,0,0,0,11,11,11,27,0,0,0,11,27,0,0,11
0,0,0,0,0,11,11,11,11,11,11,0,0,0,0,0,11
0,0,0,0,0,0,0,0,0,0,0,0,0,0,0,0,11
0,0,0,0,0,0,0,0,0,0,11,11,6,6,0,0,11
0,0,0,0,0,0,0,11,11,11,11,11,11,11,0,11,11
0,0,0,0,0,0,0,11,0,0,0,0,0,0,0,11,0
0,0,0,0,0,0,0,11,0,0,0,0,0,0,0,11,0
0,0,0,0,0,0,0,11,0,0,0,0,0,0,0,11,0
0,0,0,0,0,0,0,11,11,11,11,11,11,11,11,11,0
0,0,0,0,0,0,0,0,0,0,0,0,0,0,0,0,0
endlayer

layer
0,11,11,40,11,11,14,0,0,0,0,0,0,0,0,0,0
0,11,0,0,0,11,0,0,0,0,0,0,0,0,0,0,0
0,11,0,0,0,0,0,0,11,41,11,11,41,11,11,0,0
0,11,0,0,0,11,0,0,11,0,0,11,0,0,11,0,0
0,11,11,51,11,11,0,0,11,14,0,11,14,0,11,14,11
0,0,0,0,0,11,0,0,11,0,0,11,0,0,11,0,51
0,0,0,0,51,11,11,11,11,11,11,11,11,11,11,0,11
0,0,0,0,51,35,0,0,0,0,0,44,27,0,0,0,11
0,0,0,0,51,11,0,0,0,0,0,0,27,0,0,0,51
0,0,0,0,0,11,11,11,11,11,11,0,0,0,0,0,11
0,0,0,0,0,0,0,0,0,0,0,0,0,0,0,0,51
0,0,0,0,0,0,0,0,0,0,11,11,0,0,0,42,11
0,0,0,0,0,0,0,11,11,11,11,11,6,6,11,11,11
0,0,0,0,0,0,0,11,11,11,11,11,11,11,11,11,0
0,0,0,0,0,0,0,11,11,11,11,11,11,11,11,11,0
0,0,0,0,0,0,0,11,11,11,11,11,11,11,11,11,0
0,0,0,0,0,0,0,11,11,11,11,11,11,11,11,11,0
0,0,0,0,0,0,0,0,0,0,0,0,0,0,0,0,0
endlayer

layer
0,11,11,11,11,11,0,0,0,0,0,0,0,0,0,0,0
0,11,0,0,0,11,0,0,0,0,0,0,0,0,0,0,0
0,11,14,0,0,11,0,0,11,11,11,11,11,11,11,0,0
0,11,0,0,0,11,0,0,11,0,0,11,0,0,11,0,0
0,11,11,11,11,11,0,0,11,0,0,11,0,0,11,0,11
0,0,0,0,0,11,11,11,11,0,0,11,0,0,11,0,51
0,0,0,0,0,11,11,11,11,11,11,11,11,11,11,11,11
0,0,0,0,0,40,0,0,0,0,0,27,0,0,0,0,11
0,0,0,0,0,11,42,0,0,0,0,27,0,0,0,0,51
0,0,0,0,0,11,11,11,11,11,11,0,0,0,0,0,11
0,0,0,0,0,0,0,0,0,0,11,0,0,0,0,0,51
0,0,0,0,0,0,0,0,0,0,11,11,0,0,0,0,11
0,0,0,0,0,0,0,11,11,11,11,11,0,0,34,11,11
0,0,0,0,0,0,0,11,0,0,4,11,0,0,0,11,0
0,0,0,0,0,0,0,11,0,0,0,11,0,17,15,11,0
0,0,0,0,0,0,0,11,11,30,52,11,0,15,18,11,0
0,0,0,0,0,0,0,11,0,0,0,0,0,11,11,11,0
0,0,0,0,0,0,0,51,51,51,51,51,51,51,0,0,0
endlayer

layer
0,53,53,53,53,53,0,0,0,0,0,0,0,0,0,0,0
0,53,50,50,50,53,0,0,0,0,0,0,0,0,0,0,0
0,53,50,50,50,53,53,53,53,53,53,53,53,53,53,53,53
0,53,50,50,50,53,11,11,11,50,50,50,50,50,11,11,53
0,53,53,53,53,53,11,11,11,50,50,50,50,50,11,11,53
0,0,0,0,0,53,11,11,11,50,50,50,50,50,11,11,53
0,0,0,0,0,53,11,11,11,11,54,11,11,11,11,11,53
0,0,0,0,0,53,11,11,11,11,27,0,0,0,0,11,53
0,0,0,0,0,53,11,11,11,11,27,0,0,0,0,11,53
0,0,0,0,0,53,53,53,53,53,53,11,11,11,11,11,53
0,0,0,0,0,0,0,0,0,0,53,53,53,53,53,53,53
0,0,0,0,0,0,0,0,0,0,53,53,0,0,34,11,53
0,0,0,0,0,0,0,53,53,53,53,53,0,0,0,53,53
0,0,0,0,0,0,0,53,0,44,0,53,0,0,0,0,0
0,0,0,0,0,0,0,53,0,0,0,53,0,56,55,0,0
0,0,0,0,0,0,0,53,53,40,41,53,0,57,22,0,0
0,0,0,0,0,0,0,3,0,0,0,0,0,0,0,3,0
0,0,0,0,0,0,0,0,0,0,0,0,0,0,0,0,0
endlayer

layer
0,11,11,0,11,11,0,0,0,0,0,0,0,0,0,0,0
0,11,0,0,0,11,0,0,0,0,0,0,0,0,0,0,0
0,0,0,0,0,58,11,11,11,11,11,11,11,11,11,51,51
0,11,0,0,0,0,11,4,0,0,11,0,0,4,11,0,51
0,11,11,0,11,0,35,0,0,0,11,0,0,0,33,0,51
0,0,0,0,51,0,35,0,0,0,11,0,0,0,33,0,51
0,0,0,0,51,0,11,11,11,11,11,11,11,11,11,0,51
0,0,0,0,51,0,0,0,0,0,0,0,0,0,51,0,51
0,0,0,0,51,11,0,0,0,0,0,0,0,0,51,0,51
0,0,0,0,0,11,11,51,51,51,0,0,0,0,0,0,51
0,0,0,0,0,0,0,0,0,51,0,0,0,0,0,0,51
0,0,0,0,0,0,0,0,0,51,6,0,0,0,0,3,51
0,0,0,0,0,0,0,11,11,11,11,11,14,0,0,51,51
0,0,0,0,0,0,0,11,0,0,0,11,0,0,0,0,0
0,0,0,0,0,0,0,11,0,0,0,11,0,0,59,0,0
0,0,0,0,0,0,0,11,11,11,11,11,0,0,0,0,0
0,0,0,0,0,0,0,0,0,0,0,0,0,0,0,0,0
0,0,0,0,0,0,0,0,0,0,0,0,0,0,0,0,0
endlayer

layer
0,3,0,0,0,3,0,0,0,0,0,0,0,0,0,0,0
0,0,0,0,0,0,0,0,0,0,0,0,0,0,0,0,0
0,0,0,0,0,58,11,11,11,11,11,11,11,11,11,0,0
0,0,0,0,0,0,11,0,44,0,11,0,44,0,11,14,0
0,3,0,0,0,0,40,0,0,0,11,0,0,0,41,0,0
0,0,0,0,0,0,41,0,0,0,11,0,0,0,40,0,0
0,0,0,0,0,0,11,11,11,11,11,11,11,11,11,0,0
0,0,0,0,0,0,0,0,0,44,0,0,0,0,0,0,0
0,0,0,0,0,0,0,0,0,0,0,0,0,0,0,0,0
0,0,0,0,0,3,0,0,0,0,0,0,0,0,0,0,0
0,0,0,0,0,0,0,0,0,0,0,0,0,0,0,0,0
0,0,0,0,0,0,0,0,0,51,0,0,0,0,0,0,0
0,0,0,0,0,0,0,11,11,11,6,11,0,0,0,0,0
0,0,0,0,0,0,0,11,11,11,11,11,0,0,0,0,0
0,0,0,0,0,0,0,11,11,11,11,11,0,0,0,0,0
0,0,0,0,0,0,0,11,11,11,11,11,0,0,0,0,0
0,0,0,0,0,0,0,0,0,0,0,0,0,0,0,0,0
0,0,0,0,0,0,0,0,0,0,0,0,0,0,0,0,0
endlayer

layer
0,0,0,0,0,0,0,0,0,0,0,0,0,0,0,0,0
0,0,0,0,0,0,0,0,0,0,0,0,0,0,0,0,0
0,0,0,0,0,58,11,11,11,11,11,11,11,11,11,0,0
0,0,0,0,0,0,11,0,0,0,11,0,0,0,11,0,0
0,0,0,0,0,0,11,0,0,0,11,0,0,0,11,0,0
0,0,0,0,0,0,11,0,0,0,11,0,0,0,11,0,0
0,0,0,0,0,0,11,11,11,11,11,11,11,11,11,0,0
0,0,0,0,0,0,0,0,0,0,0,0,0,0,0,0,0
0,0,0,0,0,0,0,0,0,0,0,0,0,0,0,0,0
0,0,0,0,0,0,0,0,0,0,0,0,0,0,0,0,0
0,0,0,0,0,0,0,0,0,0,0,0,0,0,0,0,0
0,0,0,0,0,0,0,0,0,0,0,0,0,0,0,0,0
0,0,0,0,0,0,0,11,11,11,0,11,0,0,0,0,0
0,0,0,0,0,0,0,11,15,15,6,11,0,0,0,0,0
0,0,0,0,0,0,0,11,15,15,11,11,0,0,0,0,0
0,0,0,0,0,0,0,11,11,11,11,11,0,0,0,0,0
0,0,0,0,0,0,0,0,0,0,0,0,0,0,0,0,0
0,0,0,0,0,0,0,0,0,0,0,0,0,0,0,0,0
endlayer

layer
0,0,0,0,0,0,0,0,0,0,0,0,0,0,0,0,0
0,0,0,0,0,0,0,0,0,0,0,0,0,0,0,0,0
0,0,0,0,0,58,11,11,11,11,11,11,11,11,11,0,0
0,0,0,0,0,0,11,50,50,50,11,50,50,50,11,0,0
0,0,0,0,0,0,11,50,50,50,11,50,50,50,11,0,0
0,0,0,0,0,0,11,50,50,50,11,50,50,50,11,0,0
0,0,0,0,0,0,11,11,11,11,11,11,11,11,11,0,0
0,0,0,0,0,0,0,0,0,0,0,0,0,0,0,0,0
0,0,0,0,0,0,0,0,0,0,0,0,0,0,0,0,0
0,0,0,0,0,0,0,0,0,0,0,0,0,0,0,0,0
0,0,0,0,0,0,0,0,0,0,0,0,0,0,0,0,0
0,0,0,0,0,0,0,0,0,0,0,0,0,0,0,0,0
0,0,0,0,0,0,0,3,0,0,0,0,0,0,0,0,0
0,0,0,0,0,0,0,0,0,0,0,0,0,0,0,0,0
0,0,0,0,0,0,0,0,60,0,0,0,0,0,0,0,0
0,0,0,0,0,0,0,0,0,0,0,3,0,0,0,0,0
0,0,0,0,0,0,0,0,0,0,0,0,0,0,0,0,0
0,0,0,0,0,0,0,0,0,0,0,0,0,0,0,0,0
endlayer

layer
0,0,0,0,0,0,0,0,0,0,0,0,0,0,0,0,0
0,0,0,0,0,0,0,0,0,0,0,0,0,0,0,0,0
0,0,0,0,0,58,11,11,11,11,11,11,11,11,11,0,0
0,0,0,0,0,0,11,17,17,17,15,17,17,17,11,0,0
0,0,0,0,0,0,11,17,17,17,18,17,17,17,11,0,0
0,0,0,0,0,0,11,17,17,17,15,17,17,17,11,0,0
0,0,0,0,0,0,11,11,11,11,11,11,11,11,11,0,0
0,0,0,0,0,0,0,0,0,0,0,0,0,0,0,0,0
0,0,0,0,0,0,0,0,0,0,0,0,0,0,0,0,0
0,0,0,0,0,0,0,0,0,0,0,0,0,0,0,0,0
0,0,0,0,0,0,0,0,0,0,0,0,0,0,0,0,0
0,0,0,0,0,0,0,0,0,0,0,0,0,0,0,0,0
0,0,0,0,0,0,0,0,0,0,0,0,0,0,0,0,0
0,0,0,0,0,0,0,0,0,0,0,0,0,0,0,0,0
0,0,0,0,0,0,0,0,0,0,0,0,0,0,0,0,0
0,0,0,0,0,0,0,0,0,0,0,0,0,0,0,0,0
0,0,0,0,0,0,0,0,0,0,0,0,0,0,0,0,0
0,0,0,0,0,0,0,0,0,0,0,0,0,0,0,0,0
endlayer

layer
0,0,0,0,0,0,0,0,0,0,0,0,0,0,0,0,0
0,0,0,0,0,0,0,0,0,0,0,0,0,0,0,0,0
0,0,0,0,0,0,3,0,0,0,0,0,0,0,3,0,0
0,0,0,0,0,0,0,56,64,64,55,63,62,61,0,0,0
0,0,0,0,0,0,0,66,63,64,22,61,65,64,0,0,0
0,0,0,0,0,0,0,66,61,56,55,64,61,65,0,0,0
0,0,0,0,0,0,3,0,0,0,0,0,0,0,3,0,0
0,0,0,0,0,0,0,0,0,0,0,0,0,0,0,0,0
0,0,0,0,0,0,0,0,0,0,0,0,0,0,0,0,0
0,0,0,0,0,0,0,0,0,0,0,0,0,0,0,0,0
0,0,0,0,0,0,0,0,0,0,0,0,0,0,0,0,0
0,0,0,0,0,0,0,0,0,0,0,0,0,0,0,0,0
0,0,0,0,0,0,0,0,0,0,0,0,0,0,0,0,0
0,0,0,0,0,0,0,0,0,0,0,0,0,0,0,0,0
0,0,0,0,0,0,0,0,0,0,0,0,0,0,0,0,0
0,0,0,0,0,0,0,0,0,0,0,0,0,0,0,0,0
0,0,0,0,0,0,0,0,0,0,0,0,0,0,0,0,0
0,0,0,0,0,0,0,0,0,0,0,0,0,0,0,0,0
endlayer

layer
0,0,0,0,0,0,0,0,0,0,0,0,0,0,0,0,0
0,0,0,0,0,0,0,0,0,0,0,0,0,0,0,0,0
0,0,0,0,0,0,0,0,0,0,0,0,0,0,0,0,0
0,0,0,0,0,0,0,0,0,0,59,0,0,0,0,0,0
0,0,0,0,0,0,0,0,0,0,0,0,0,0,0,0,0
0,0,0,0,0,0,0,0,0,0,59,0,0,0,0,0,0
0,0,0,0,0,0,0,0,0,0,0,0,0,0,0,0,0
0,0,0,0,0,0,0,0,0,0,0,0,0,0,0,0,0
0,0,0,0,0,0,0,0,0,0,0,0,0,0,0,0,0
0,0,0,0,0,0,0,0,0,0,0,0,0,0,0,0,0
0,0,0,0,0,0,0,0,0,0,0,0,0,0,0,0,0
0,0,0,0,0,0,0,0,0,0,0,0,0,0,0,0,0
0,0,0,0,0,0,0,0,0,0,0,0,0,0,0,0,0
0,0,0,0,0,0,0,0,0,0,0,0,0,0,0,0,0
0,0,0,0,0,0,0,0,0,0,0,0,0,0,0,0,0
0,0,0,0,0,0,0,0,0,0,0,0,0,0,0,0,0
0,0,0,0,0,0,0,0,0,0,0,0,0,0,0,0,0
0,0,0,0,0,0,0,0,0,0,0,0,0,0,0,0,0
endlayer

