
# Created by Ruins mod version 14.1 Ingame Parser
# authoring Player: Divineaspect

weight=15
embed_into_distance=1
acceptable_target_blocks=
unacceptable_target_blocks=flowing_water,water,flowing_lava,lava
dimensions=11,16,16
allowable_overhang=2
max_leveling=2
leveling_buffer=0
preserve_water=0
preserve_lava=0

rule1=0,100,minecraft:grass-0
rule2=0,100,minecraft:dirt-0
rule3=0,100,chisel:dirt-0
rule4=0,100,chisel:marble-1
rule5=0,100,AWWayofTime:lifeEssence-1
rule6=0,100,AWWayofTime:lifeEssence-0
rule7=0,100,minecraft:planks-0
rule8=0,100,chisel:marble_slab-1
rule9=0,100,minecraft:tallgrass-1
rule10=0,100,minecraft:red_flower-0
rule11=0,100,chisel:marble_stairs.0-10
rule12=0,100,chisel:marble_stairs.0-8
rule13=0,100,chisel:marble_stairs.0-11
rule14=0,100,minecraft:yellow_flower-0
rule15=0,100,chisel:marble-11
rule16=0,100,minecraft:snow_layer-0
rule17=0,100,chisel:marble-9
rule18=0,100,minecraft:wooden_door-4
rule19=0,100,IInventory;minecraft:chest;AWWayofTime:mundanePowerCatalyst#1#0#3+AWWayofTime:mundanePowerCatalyst#1#0#4+AWWayofTime:mundanePowerCatalyst#1#0#5+AWWayofTime:mundanePowerCatalyst#1#0#12+AWWayofTime:daggerOfSacrifice#1#0#13+AWWayofTime:mundanePowerCatalyst#1#0#14+AWWayofTime:mundanePowerCatalyst#1#0#21+AWWayofTime:mundanePowerCatalyst#1#0#22+AWWayofTime:mundanePowerCatalyst#1#0#23-4
rule20=0,100,ChestGenHook:dungeonChest:5-3
rule21=0,100,minecraft:bed-3
rule22=0,100,IInventory;minecraft:furnace;AWWayofTime:lavaCrystal#1#0#1-3
rule23=0,100,minecraft:bed-11
rule24=0,100,Natura:Rare Sapling-4,BiomesOPlenty:saplings-0,BiomesOPlenty:saplings-3,BiomesOPlenty:saplings-4,BiomesOPlenty:saplings-6,BiomesOPlenty:saplings-7,BiomesOPlenty:saplings-12,BiomesOPlenty:saplings-10,BiomesOPlenty:saplings-9,BiomesOPlenty:colorizedSaplings-3,BiomesOPlenty:saplings-15,TConstruct:slime.sapling-0,BiomesOPlenty:colorizedSaplings-6,witchery:witchsapling-2,minecraft:sapling-0,minecraft:sapling-1,minecraft:sapling-2,minecraft:sapling-3,minecraft:sapling-4,minecraft:sapling-5,Natura:florasapling-1,Natura:florasapling-3,Natura:Rare Sapling-0,Natura:Rare Sapling-1,Natura:Rare Sapling-2,Natura:Rare Sapling-3,witchery:witchsapling-0,witchery:witchsapling-1
rule25=0,100,Natura:Rare Sapling-4,BiomesOPlenty:saplings-0,BiomesOPlenty:saplings-3,BiomesOPlenty:saplings-4,BiomesOPlenty:saplings-6,BiomesOPlenty:saplings-7,BiomesOPlenty:saplings-12,BiomesOPlenty:saplings-10,BiomesOPlenty:saplings-9,BiomesOPlenty:colorizedSaplings-3,BiomesOPlenty:saplings-15,TConstruct:slime.sapling-0,BiomesOPlenty:colorizedSaplings-6,witchery:witchsapling-2,minecraft:sapling-0,minecraft:sapling-1,minecraft:sapling-2,minecraft:sapling-3,minecraft:sapling-4,minecraft:sapling-5,Natura:florasapling-1,Natura:florasapling-3,Natura:Rare Sapling-0,Natura:Rare Sapling-1,Natura:Rare Sapling-2,Natura:Rare Sapling-3,witchery:witchsapling-0,witchery:witchsapling-1
rule26=0,100,AWWayofTime:bloodLight-0
rule27=0,100,chisel:marble_pillar-0
rule28=0,100,minecraft:wooden_door-8
rule29=0,100,AWWayofTime:Altar-0
rule30=2,100,minecraft:torch-2
rule31=0,100,BiomesOPlenty:flowers-0
rule32=0,100,minecraft:wooden_slab-8

layer
1,1,1,1,1,1,1,1,1,1,1,1,1,1,1,1
1,2,1,1,1,1,1,1,1,1,2,1,1,1,1,1
1,1,1,1,1,1,1,1,1,1,1,1,1,1,1,1
3,3,3,3,3,3,3,3,3,3,1,1,1,1,1,1
3,3,3,3,3,3,3,3,3,3,3,1,1,1,1,1
1,1,1,1,1,1,1,1,1,3,3,3,3,3,3,3
1,1,1,1,2,2,2,1,1,1,3,3,3,3,3,3
1,2,4,4,4,4,4,4,4,1,1,1,3,1,1,1
1,1,4,4,4,4,4,4,4,1,1,1,3,1,1,1
1,2,4,4,5,6,5,4,4,1,1,1,3,1,2,1
1,2,4,4,6,6,6,4,4,1,2,2,7,2,2,2
1,2,4,4,6,5,6,4,4,2,7,7,7,7,7,2
2,2,4,4,4,4,4,4,4,2,7,7,7,7,7,2
1,2,4,4,4,4,4,4,4,2,7,7,7,7,7,2
1,2,2,2,1,1,1,2,2,2,7,7,7,7,7,2
1,1,1,1,1,1,1,1,2,2,2,2,2,2,2,2
endlayer

layer
8,8,8,0,0,0,9,0,0,8,8,8,0,0,0,0
8,2,8,0,0,0,0,9,9,8,2,8,0,9,9,0
8,8,8,0,0,0,9,0,0,8,8,8,10,9,9,0
0,0,0,0,0,0,0,0,0,0,9,9,9,9,9,9
0,0,0,0,0,0,0,0,0,0,0,10,9,9,9,0
9,9,0,12,12,12,12,11,0,0,0,0,0,0,0,0
9,0,0,13,4,4,4,11,0,0,0,0,0,0,0,0
0,1,4,4,4,4,4,4,4,0,0,0,0,9,0,9
0,16,4,15,15,15,15,15,4,0,0,0,0,0,14,0
0,1,4,15,17,17,17,15,4,0,0,0,0,9,1,0
0,1,4,15,17,19,17,15,4,0,2,7,18,7,2,1
0,1,4,15,17,17,17,15,4,1,0,0,0,0,20,2
1,1,4,15,15,15,15,15,4,2,0,0,0,0,0,2
0,1,4,4,4,4,4,4,4,2,21,0,0,0,0,2
9,1,1,1,0,0,0,1,2,2,23,0,0,0,22,2
0,0,0,0,0,0,10,0,1,2,2,2,2,2,2,1
endlayer

layer
0,0,0,0,0,0,0,0,0,0,0,0,0,0,0,0
0,25,0,0,0,0,0,0,0,0,24,0,0,0,0,0
0,0,0,0,0,0,0,0,0,0,0,0,0,0,0,0
0,0,0,0,0,0,0,0,0,0,0,0,0,0,0,0
0,0,0,0,0,0,0,0,0,0,0,0,0,0,0,0
0,0,0,0,0,0,0,0,0,0,0,0,0,0,0,0
0,0,0,0,26,0,26,0,0,0,0,0,0,0,0,0
0,0,27,0,27,0,27,0,27,0,0,0,0,0,0,0
0,0,0,0,0,0,0,0,0,0,0,0,0,0,0,0
0,9,27,0,0,0,0,0,27,0,0,0,0,0,10,0
0,9,0,0,0,29,0,0,0,0,1,7,28,7,1,0
0,9,27,0,0,0,0,0,27,0,2,0,0,0,0,1
9,9,0,0,0,0,0,0,0,1,0,0,0,0,0,1
0,9,27,0,27,0,27,0,27,1,0,0,0,0,0,1
0,9,9,0,0,0,0,0,1,1,0,0,30,0,2,1
0,0,0,0,0,0,0,0,31,1,1,2,2,2,1,0
endlayer

layer
0,0,0,0,0,0,0,0,0,0,0,0,0,0,0,0
0,0,0,0,0,0,0,0,0,0,0,0,0,0,0,0
0,0,0,0,0,0,0,0,0,0,0,0,0,0,0,0
0,0,0,0,0,0,0,0,0,0,0,0,0,0,0,0
0,0,0,0,0,0,0,0,0,0,0,0,0,0,0,0
0,0,0,0,0,0,0,0,0,0,0,0,0,0,0,0
0,0,0,0,0,0,0,0,0,0,0,0,0,0,0,0
0,0,27,0,27,0,27,0,27,0,0,0,0,0,0,0
0,0,0,0,0,0,0,0,0,0,0,0,0,0,0,0
0,0,27,0,0,0,0,0,27,0,0,0,0,0,0,0
0,0,0,0,0,0,0,0,0,0,0,1,1,1,0,0
0,0,27,0,0,0,0,0,27,0,1,32,32,32,1,9
0,0,0,0,0,0,0,0,0,0,1,32,32,32,1,10
0,0,27,0,27,0,27,0,27,9,1,32,32,32,1,0
0,0,0,0,0,0,0,0,10,9,1,32,32,32,1,31
0,0,0,0,0,0,0,0,0,9,0,1,1,1,0,0
endlayer

layer
0,0,0,0,0,0,0,0,0,0,0,0,0,0,0,0
0,0,0,0,0,0,0,0,0,0,0,0,0,0,0,0
0,0,0,0,0,0,0,0,0,0,0,0,0,0,0,0
0,0,0,0,0,0,0,0,0,0,0,0,0,0,0,0
0,0,0,0,0,0,0,0,0,0,0,0,0,0,0,0
0,0,0,0,0,0,0,0,0,0,0,0,0,0,0,0
0,0,0,0,0,0,0,0,0,0,0,0,0,0,0,0
0,0,27,0,27,0,27,0,27,0,0,0,0,0,0,0
0,0,0,0,0,0,0,0,0,0,0,0,0,0,0,0
0,0,27,0,0,0,0,0,27,0,0,0,0,0,0,0
0,0,0,0,0,0,0,0,0,0,0,0,9,9,0,0
0,0,27,0,0,0,0,0,27,0,0,1,1,1,9,0
0,0,0,0,0,0,0,0,0,0,0,1,1,1,9,0
0,0,27,0,27,0,27,0,27,0,0,1,1,1,9,0
0,0,0,0,0,0,0,0,0,0,0,1,1,1,9,0
0,0,0,0,0,0,0,0,0,0,0,9,9,9,0,0
endlayer

layer
0,0,0,0,0,0,0,0,0,0,0,0,0,0,0,0
0,0,0,0,0,0,0,0,0,0,0,0,0,0,0,0
0,0,0,0,0,0,0,0,0,0,0,0,0,0,0,0
0,0,0,0,0,0,0,0,0,0,0,0,0,0,0,0
0,0,0,0,0,0,0,0,0,0,0,0,0,0,0,0
0,0,0,0,0,0,0,0,0,0,0,0,0,0,0,0
0,0,0,0,0,0,0,0,0,0,0,0,0,0,0,0
0,0,27,0,27,0,27,0,27,0,0,0,0,0,0,0
0,0,0,0,0,0,0,0,0,0,0,0,0,0,0,0
0,0,27,0,0,0,0,0,27,0,0,0,0,0,0,0
0,0,0,0,0,0,0,0,0,0,0,0,0,0,0,0
0,0,27,0,0,0,0,0,27,0,0,9,9,9,0,0
0,0,0,0,0,0,0,0,0,0,0,0,31,9,0,0
0,0,27,0,27,0,27,0,27,0,0,0,0,0,0,0
0,0,0,0,0,0,0,0,0,0,0,9,9,0,0,0
0,0,0,0,0,0,0,0,0,0,0,0,0,0,0,0
endlayer

layer
0,0,0,0,0,0,0,0,0,0,0,0,0,0,0,0
0,0,0,0,0,0,0,0,0,0,0,0,0,0,0,0
0,0,0,0,0,0,0,0,0,0,0,0,0,0,0,0
0,0,0,0,0,0,0,0,0,0,0,0,0,0,0,0
0,0,0,0,0,0,0,0,0,0,0,0,0,0,0,0
0,0,0,0,0,0,0,0,0,0,0,0,0,0,0,0
0,0,0,0,0,0,0,0,0,0,0,0,0,0,0,0
0,13,15,15,15,15,15,15,15,11,0,0,0,0,0,0
0,13,15,0,0,0,0,0,15,11,0,0,0,0,0,0
0,13,15,0,0,0,0,0,15,11,0,0,0,0,0,0
0,13,15,0,0,0,0,0,15,11,0,0,0,0,0,0
0,13,15,0,0,0,0,0,15,11,0,0,0,0,0,0
0,13,15,0,0,0,0,0,15,11,0,0,0,0,0,0
0,13,15,15,15,15,15,15,15,11,0,0,0,0,0,0
0,0,0,0,0,0,0,0,0,0,0,0,0,0,0,0
0,0,0,0,0,0,0,0,0,0,0,0,0,0,0,0
endlayer

layer
0,0,0,0,0,0,0,0,0,0,0,0,0,0,0,0
0,0,0,0,0,0,0,0,0,0,0,0,0,0,0,0
0,0,0,0,0,0,0,0,0,0,0,0,0,0,0,0
0,0,0,0,0,0,0,0,0,0,0,0,0,0,0,0
0,0,0,0,0,0,0,0,0,0,0,0,0,0,0,0
0,0,0,0,0,0,0,0,0,0,0,0,0,0,0,0
0,0,0,0,0,0,0,0,0,0,0,0,0,0,0,0
0,0,13,15,15,26,15,15,11,0,0,0,0,0,0,0
0,0,13,0,0,0,0,0,11,0,0,0,0,0,0,0
0,0,13,0,0,0,0,0,11,0,0,0,0,0,0,0
0,0,13,0,0,0,0,0,11,0,0,0,0,0,0,0
0,0,13,0,0,0,0,0,11,0,0,0,0,0,0,0
0,0,13,0,0,0,0,0,11,0,0,0,0,0,0,0
0,0,13,15,15,26,15,15,11,0,0,0,0,0,0,0
0,0,0,0,0,0,0,0,0,0,0,0,0,0,0,0
0,0,0,0,0,0,0,0,0,0,0,0,0,0,0,0
endlayer

layer
0,0,0,0,0,0,0,0,0,0,0,0,0,0,0,0
0,0,0,0,0,0,0,0,0,0,0,0,0,0,0,0
0,0,0,0,0,0,0,0,0,0,0,0,0,0,0,0
0,0,0,0,0,0,0,0,0,0,0,0,0,0,0,0
0,0,0,0,0,0,0,0,0,0,0,0,0,0,0,0
0,0,0,0,0,0,0,0,0,0,0,0,0,0,0,0
0,0,0,0,0,0,0,0,0,0,0,0,0,0,0,0
0,0,0,13,15,15,15,11,0,0,0,0,0,0,0,0
0,0,0,13,0,0,0,11,0,0,0,0,0,0,0,0
0,0,0,13,0,0,0,11,0,0,0,0,0,0,0,0
0,0,0,13,0,0,0,11,0,0,0,0,0,0,0,0
0,0,0,13,0,0,0,11,0,0,0,0,0,0,0,0
0,0,0,13,0,0,0,11,0,0,0,0,0,0,0,0
0,0,0,13,15,15,15,11,0,0,0,0,0,0,0,0
0,0,0,0,0,0,0,0,0,0,0,0,0,0,0,0
0,0,0,0,0,0,0,0,0,0,0,0,0,0,0,0
endlayer

layer
0,0,0,0,0,0,0,0,0,0,0,0,0,0,0,0
0,0,0,0,0,0,0,0,0,0,0,0,0,0,0,0
0,0,0,0,0,0,0,0,0,0,0,0,0,0,0,0
0,0,0,0,0,0,0,0,0,0,0,0,0,0,0,0
0,0,0,0,0,0,0,0,0,0,0,0,0,0,0,0
0,0,0,0,0,0,0,0,0,0,0,0,0,0,0,0
0,0,0,0,0,0,0,0,0,0,0,0,0,0,0,0
0,0,0,0,13,15,11,0,0,0,0,0,0,0,0,0
0,0,0,0,13,0,11,0,0,0,0,0,0,0,0,0
0,0,0,0,13,0,11,0,0,0,0,0,0,0,0,0
0,0,0,0,13,0,11,0,0,0,0,0,0,0,0,0
0,0,0,0,13,0,11,0,0,0,0,0,0,0,0,0
0,0,0,0,13,0,11,0,0,0,0,0,0,0,0,0
0,0,0,0,13,15,11,0,0,0,0,0,0,0,0,0
0,0,0,0,0,0,0,0,0,0,0,0,0,0,0,0
0,0,0,0,0,0,0,0,0,0,0,0,0,0,0,0
endlayer

layer
0,0,0,0,0,0,0,0,0,0,0,0,0,0,0,0
0,0,0,0,0,0,0,0,0,0,0,0,0,0,0,0
0,0,0,0,0,0,0,0,0,0,0,0,0,0,0,0
0,0,0,0,0,0,0,0,0,0,0,0,0,0,0,0
0,0,0,0,0,0,0,0,0,0,0,0,0,0,0,0
0,0,0,0,0,0,0,0,0,0,0,0,0,0,0,0
0,0,0,0,0,0,0,0,0,0,0,0,0,0,0,0
0,0,0,0,0,8,0,0,0,0,0,0,0,0,0,0
0,0,0,0,0,8,0,0,0,0,0,0,0,0,0,0
0,0,0,0,0,8,0,0,0,0,0,0,0,0,0,0
0,0,0,0,0,8,0,0,0,0,0,0,0,0,0,0
0,0,0,0,0,8,0,0,0,0,0,0,0,0,0,0
0,0,0,0,0,8,0,0,0,0,0,0,0,0,0,0
0,0,0,0,0,8,0,0,0,0,0,0,0,0,0,0
0,0,0,0,0,0,0,0,0,0,0,0,0,0,0,0
0,0,0,0,0,0,0,0,0,0,0,0,0,0,0,0
endlayer

