
# Created by Ruins mod version 14.1 Ingame Parser
# authoring Player: Divineaspect

weight=15
embed_into_distance=1
acceptable_target_blocks=
unacceptable_target_blocks=flowing_water,water,flowing_lava,lava
dimensions=11,16,16
allowable_overhang=2
max_leveling=2
leveling_buffer=0
preserve_water=0
preserve_lava=0

rule1=0,100,minecraft:grass-0
rule2=0,100,minecraft:dirt-0
rule3=0,100,chisel:dirt-0
rule4=0,100,chisel:marble-1
rule5=0,100,minecraft:planks-0
rule6=0,100,IInventory;minecraft:dispenser;Botania:fertilizer#64#0#4-1
rule7=0,100,chisel:marble_slab-1
rule8=0,100,minecraft:tallgrass-1
rule9=0,100,minecraft:red_flower-0
rule10=0,100,chisel:marble_stairs.0-10
rule11=0,100,chisel:marble_stairs.0-8
rule12=0,100,chisel:marble_stairs.0-11
rule13=0,100,minecraft:yellow_flower-0
rule14=0,100,chisel:marble-11
rule15=0,100,minecraft:snow_layer-0
rule16=0,100,minecraft:wooden_door-4
rule17=0,100,ChestGenHook:dungeonChest:5-3
rule18=0,100,minecraft:bed-3
rule19=0,100,minecraft:furnace-3
rule20=0,100,minecraft:bed-11
rule21=0,100,Natura:Rare Sapling-4,BiomesOPlenty:saplings-0,BiomesOPlenty:saplings-3,BiomesOPlenty:saplings-4,BiomesOPlenty:saplings-6,BiomesOPlenty:saplings-7,BiomesOPlenty:saplings-12,BiomesOPlenty:saplings-10,BiomesOPlenty:saplings-9,BiomesOPlenty:colorizedSaplings-3,BiomesOPlenty:saplings-15,TConstruct:slime.sapling-0,BiomesOPlenty:colorizedSaplings-6,witchery:witchsapling-2,minecraft:sapling-0,minecraft:sapling-1,minecraft:sapling-2,minecraft:sapling-3,minecraft:sapling-4,minecraft:sapling-5,Natura:florasapling-1,Natura:florasapling-3,Natura:Rare Sapling-0,Natura:Rare Sapling-1,Natura:Rare Sapling-2,Natura:Rare Sapling-3,witchery:witchsapling-0,witchery:witchsapling-1
rule22=0,100,Natura:Rare Sapling-4,BiomesOPlenty:saplings-0,BiomesOPlenty:saplings-3,BiomesOPlenty:saplings-4,BiomesOPlenty:saplings-6,BiomesOPlenty:saplings-7,BiomesOPlenty:saplings-12,BiomesOPlenty:saplings-10,BiomesOPlenty:saplings-9,BiomesOPlenty:colorizedSaplings-3,BiomesOPlenty:saplings-15,TConstruct:slime.sapling-0,BiomesOPlenty:colorizedSaplings-6,witchery:witchsapling-2,minecraft:sapling-0,minecraft:sapling-1,minecraft:sapling-2,minecraft:sapling-3,minecraft:sapling-4,minecraft:sapling-5,Natura:florasapling-1,Natura:florasapling-3,Natura:Rare Sapling-0,Natura:Rare Sapling-1,Natura:Rare Sapling-2,Natura:Rare Sapling-3,witchery:witchsapling-0,witchery:witchsapling-1
rule23=0,100,chisel:marble_pillar-0
rule24=0,100,minecraft:wooden_door-8
rule25=0,100,minecraft:heavy_weighted_pressure_plate-0
rule26=2,100,minecraft:torch-2
rule27=0,100,BiomesOPlenty:flowers-0
rule28=0,100,minecraft:wooden_slab-8
rule29=0,100,Botania:livingwood-5

layer
1,1,1,1,1,1,1,1,1,1,1,1,1,1,1,1
1,2,1,1,1,1,1,1,1,1,2,1,1,1,1,1
1,1,1,1,1,1,1,1,1,1,1,1,1,1,1,1
3,3,3,3,3,3,3,3,3,3,1,1,1,1,1,1
3,3,3,3,3,3,3,3,3,3,3,1,1,1,1,1
1,1,1,1,1,1,1,1,1,3,3,3,3,3,3,3
1,1,1,1,2,2,2,1,1,1,3,3,3,3,3,3
1,2,4,4,4,4,4,4,4,1,1,1,3,1,1,1
1,1,4,4,4,4,4,4,4,1,1,1,3,1,1,1
1,2,4,4,4,4,4,4,4,1,1,1,3,1,2,1
1,2,4,4,4,6,4,4,4,1,2,2,5,2,2,2
1,2,4,4,4,4,4,4,4,2,5,5,5,5,5,2
2,2,4,4,4,4,4,4,4,2,5,5,5,5,5,2
1,2,4,4,4,4,4,4,4,2,5,5,5,5,5,2
1,2,2,2,1,1,1,2,2,2,5,5,5,5,5,2
1,1,1,1,1,1,1,1,2,2,2,2,2,2,2,2
endlayer

layer
7,7,7,0,0,0,8,0,0,7,7,7,0,0,0,0
7,2,7,0,0,0,0,8,8,7,2,7,0,8,8,0
7,7,7,0,0,0,8,0,0,7,7,7,9,8,8,0
0,0,0,0,0,0,0,0,0,0,8,8,8,8,8,8
0,0,0,0,0,0,0,0,0,0,0,9,8,8,8,0
8,8,0,11,11,11,11,10,0,0,0,0,0,0,0,0
8,0,0,12,4,4,4,10,0,0,0,0,0,0,0,0
0,1,4,4,4,4,4,4,4,0,0,0,0,8,0,8
0,15,4,14,14,14,14,14,4,0,0,0,0,0,13,0
0,1,4,14,1,1,1,14,4,0,0,0,0,8,1,0
0,1,4,14,1,1,1,14,4,0,2,5,16,5,2,1
0,1,4,14,1,1,1,14,4,1,0,0,0,0,17,2
1,1,4,14,14,14,14,14,4,2,0,0,0,0,0,2
0,1,4,4,4,4,4,4,4,2,18,0,0,0,0,2
8,1,1,1,0,0,0,1,2,2,20,0,0,0,19,2
0,0,0,0,0,0,9,0,1,2,2,2,2,2,2,1
endlayer

layer
0,0,0,0,0,0,0,0,0,0,0,0,0,0,0,0
0,22,0,0,0,0,0,0,0,0,21,0,0,0,0,0
0,0,0,0,0,0,0,0,0,0,0,0,0,0,0,0
0,0,0,0,0,0,0,0,0,0,0,0,0,0,0,0
0,0,0,0,0,0,0,0,0,0,0,0,0,0,0,0
0,0,0,0,0,0,0,0,0,0,0,0,0,0,0,0
0,0,0,0,0,0,0,0,0,0,0,0,0,0,0,0
0,0,23,0,23,0,23,0,23,0,0,0,0,0,0,0
0,0,0,0,0,0,0,0,0,0,0,0,0,0,0,0
0,8,23,0,0,0,0,0,23,0,0,0,0,0,9,0
0,8,0,0,0,25,0,0,0,0,1,5,24,5,1,0
0,8,23,0,0,0,0,0,23,0,2,0,0,0,0,1
8,8,0,0,0,0,0,0,0,1,0,0,0,0,0,1
0,8,23,0,23,0,23,0,23,1,0,0,0,0,0,1
0,8,8,0,0,0,0,0,1,1,0,0,26,0,2,1
0,0,0,0,0,0,0,0,27,1,1,2,2,2,1,0
endlayer

layer
0,0,0,0,0,0,0,0,0,0,0,0,0,0,0,0
0,0,0,0,0,0,0,0,0,0,0,0,0,0,0,0
0,0,0,0,0,0,0,0,0,0,0,0,0,0,0,0
0,0,0,0,0,0,0,0,0,0,0,0,0,0,0,0
0,0,0,0,0,0,0,0,0,0,0,0,0,0,0,0
0,0,0,0,0,0,0,0,0,0,0,0,0,0,0,0
0,0,0,0,0,0,0,0,0,0,0,0,0,0,0,0
0,0,23,0,23,0,23,0,23,0,0,0,0,0,0,0
0,0,0,0,0,0,0,0,0,0,0,0,0,0,0,0
0,0,23,0,0,0,0,0,23,0,0,0,0,0,0,0
0,0,0,0,0,0,0,0,0,0,0,1,1,1,0,0
0,0,23,0,0,0,0,0,23,0,1,28,28,28,1,8
0,0,0,0,0,0,0,0,0,0,1,28,28,28,1,9
0,0,23,0,23,0,23,0,23,8,1,28,28,28,1,0
0,0,0,0,0,0,0,0,9,8,1,28,28,28,1,27
0,0,0,0,0,0,0,0,0,8,0,1,1,1,0,0
endlayer

layer
0,0,0,0,0,0,0,0,0,0,0,0,0,0,0,0
0,0,0,0,0,0,0,0,0,0,0,0,0,0,0,0
0,0,0,0,0,0,0,0,0,0,0,0,0,0,0,0
0,0,0,0,0,0,0,0,0,0,0,0,0,0,0,0
0,0,0,0,0,0,0,0,0,0,0,0,0,0,0,0
0,0,0,0,0,0,0,0,0,0,0,0,0,0,0,0
0,0,0,0,0,0,0,0,0,0,0,0,0,0,0,0
0,0,23,0,23,0,23,0,23,0,0,0,0,0,0,0
0,0,0,0,0,0,0,0,0,0,0,0,0,0,0,0
0,0,23,0,0,0,0,0,23,0,0,0,0,0,0,0
0,0,0,0,0,0,0,0,0,0,0,0,8,8,0,0
0,0,23,0,0,0,0,0,23,0,0,1,1,1,8,0
0,0,0,0,0,0,0,0,0,0,0,1,1,1,8,0
0,0,23,0,23,0,23,0,23,0,0,1,1,1,8,0
0,0,0,0,0,0,0,0,0,0,0,1,1,1,8,0
0,0,0,0,0,0,0,0,0,0,0,8,8,8,0,0
endlayer

layer
0,0,0,0,0,0,0,0,0,0,0,0,0,0,0,0
0,0,0,0,0,0,0,0,0,0,0,0,0,0,0,0
0,0,0,0,0,0,0,0,0,0,0,0,0,0,0,0
0,0,0,0,0,0,0,0,0,0,0,0,0,0,0,0
0,0,0,0,0,0,0,0,0,0,0,0,0,0,0,0
0,0,0,0,0,0,0,0,0,0,0,0,0,0,0,0
0,0,0,0,0,0,0,0,0,0,0,0,0,0,0,0
0,0,23,0,23,0,23,0,23,0,0,0,0,0,0,0
0,0,0,0,0,0,0,0,0,0,0,0,0,0,0,0
0,0,23,0,0,0,0,0,23,0,0,0,0,0,0,0
0,0,0,0,0,0,0,0,0,0,0,0,0,0,0,0
0,0,23,0,0,0,0,0,23,0,0,8,8,8,0,0
0,0,0,0,0,0,0,0,0,0,0,0,27,8,0,0
0,0,23,0,23,0,23,0,23,0,0,0,0,0,0,0
0,0,0,0,0,0,0,0,0,0,0,8,8,0,0,0
0,0,0,0,0,0,0,0,0,0,0,0,0,0,0,0
endlayer

layer
0,0,0,0,0,0,0,0,0,0,0,0,0,0,0,0
0,0,0,0,0,0,0,0,0,0,0,0,0,0,0,0
0,0,0,0,0,0,0,0,0,0,0,0,0,0,0,0
0,0,0,0,0,0,0,0,0,0,0,0,0,0,0,0
0,0,0,0,0,0,0,0,0,0,0,0,0,0,0,0
0,0,0,0,0,0,0,0,0,0,0,0,0,0,0,0
0,0,0,0,0,0,0,0,0,0,0,0,0,0,0,0
0,12,14,14,14,14,14,14,14,10,0,0,0,0,0,0
0,12,14,0,0,0,0,0,14,10,0,0,0,0,0,0
0,12,14,0,0,0,0,0,14,10,0,0,0,0,0,0
0,12,14,0,0,0,0,0,14,10,0,0,0,0,0,0
0,12,14,0,0,0,0,0,14,10,0,0,0,0,0,0
0,12,14,0,0,0,0,0,14,10,0,0,0,0,0,0
0,12,14,14,14,14,14,14,14,10,0,0,0,0,0,0
0,0,0,0,0,0,0,0,0,0,0,0,0,0,0,0
0,0,0,0,0,0,0,0,0,0,0,0,0,0,0,0
endlayer

layer
0,0,0,0,0,0,0,0,0,0,0,0,0,0,0,0
0,0,0,0,0,0,0,0,0,0,0,0,0,0,0,0
0,0,0,0,0,0,0,0,0,0,0,0,0,0,0,0
0,0,0,0,0,0,0,0,0,0,0,0,0,0,0,0
0,0,0,0,0,0,0,0,0,0,0,0,0,0,0,0
0,0,0,0,0,0,0,0,0,0,0,0,0,0,0,0
0,0,0,0,0,0,0,0,0,0,0,0,0,0,0,0
0,0,12,14,14,29,14,14,10,0,0,0,0,0,0,0
0,0,12,0,0,0,0,0,10,0,0,0,0,0,0,0
0,0,12,0,0,0,0,0,10,0,0,0,0,0,0,0
0,0,12,0,0,0,0,0,10,0,0,0,0,0,0,0
0,0,12,0,0,0,0,0,10,0,0,0,0,0,0,0
0,0,12,0,0,0,0,0,10,0,0,0,0,0,0,0
0,0,12,14,14,29,14,14,10,0,0,0,0,0,0,0
0,0,0,0,0,0,0,0,0,0,0,0,0,0,0,0
0,0,0,0,0,0,0,0,0,0,0,0,0,0,0,0
endlayer

layer
0,0,0,0,0,0,0,0,0,0,0,0,0,0,0,0
0,0,0,0,0,0,0,0,0,0,0,0,0,0,0,0
0,0,0,0,0,0,0,0,0,0,0,0,0,0,0,0
0,0,0,0,0,0,0,0,0,0,0,0,0,0,0,0
0,0,0,0,0,0,0,0,0,0,0,0,0,0,0,0
0,0,0,0,0,0,0,0,0,0,0,0,0,0,0,0
0,0,0,0,0,0,0,0,0,0,0,0,0,0,0,0
0,0,0,12,14,14,14,10,0,0,0,0,0,0,0,0
0,0,0,12,0,0,0,10,0,0,0,0,0,0,0,0
0,0,0,12,0,0,0,10,0,0,0,0,0,0,0,0
0,0,0,12,0,0,0,10,0,0,0,0,0,0,0,0
0,0,0,12,0,0,0,10,0,0,0,0,0,0,0,0
0,0,0,12,0,0,0,10,0,0,0,0,0,0,0,0
0,0,0,12,14,14,14,10,0,0,0,0,0,0,0,0
0,0,0,0,0,0,0,0,0,0,0,0,0,0,0,0
0,0,0,0,0,0,0,0,0,0,0,0,0,0,0,0
endlayer

layer
0,0,0,0,0,0,0,0,0,0,0,0,0,0,0,0
0,0,0,0,0,0,0,0,0,0,0,0,0,0,0,0
0,0,0,0,0,0,0,0,0,0,0,0,0,0,0,0
0,0,0,0,0,0,0,0,0,0,0,0,0,0,0,0
0,0,0,0,0,0,0,0,0,0,0,0,0,0,0,0
0,0,0,0,0,0,0,0,0,0,0,0,0,0,0,0
0,0,0,0,0,0,0,0,0,0,0,0,0,0,0,0
0,0,0,0,12,14,10,0,0,0,0,0,0,0,0,0
0,0,0,0,12,0,10,0,0,0,0,0,0,0,0,0
0,0,0,0,12,0,10,0,0,0,0,0,0,0,0,0
0,0,0,0,12,0,10,0,0,0,0,0,0,0,0,0
0,0,0,0,12,0,10,0,0,0,0,0,0,0,0,0
0,0,0,0,12,0,10,0,0,0,0,0,0,0,0,0
0,0,0,0,12,14,10,0,0,0,0,0,0,0,0,0
0,0,0,0,0,0,0,0,0,0,0,0,0,0,0,0
0,0,0,0,0,0,0,0,0,0,0,0,0,0,0,0
endlayer

layer
0,0,0,0,0,0,0,0,0,0,0,0,0,0,0,0
0,0,0,0,0,0,0,0,0,0,0,0,0,0,0,0
0,0,0,0,0,0,0,0,0,0,0,0,0,0,0,0
0,0,0,0,0,0,0,0,0,0,0,0,0,0,0,0
0,0,0,0,0,0,0,0,0,0,0,0,0,0,0,0
0,0,0,0,0,0,0,0,0,0,0,0,0,0,0,0
0,0,0,0,0,0,0,0,0,0,0,0,0,0,0,0
0,0,0,0,0,7,0,0,0,0,0,0,0,0,0,0
0,0,0,0,0,7,0,0,0,0,0,0,0,0,0,0
0,0,0,0,0,7,0,0,0,0,0,0,0,0,0,0
0,0,0,0,0,7,0,0,0,0,0,0,0,0,0,0
0,0,0,0,0,7,0,0,0,0,0,0,0,0,0,0
0,0,0,0,0,7,0,0,0,0,0,0,0,0,0,0
0,0,0,0,0,7,0,0,0,0,0,0,0,0,0,0
0,0,0,0,0,0,0,0,0,0,0,0,0,0,0,0
0,0,0,0,0,0,0,0,0,0,0,0,0,0,0,0
endlayer

