
# Created by Ruins mod version 14.1 Ingame Parser
# authoring Player: Divineaspect

weight=15
embed_into_distance=1
acceptable_target_blocks=
unacceptable_target_blocks=flowing_water,water,flowing_lava,lava
dimensions=11,16,16
allowable_overhang=2
max_leveling=2
leveling_buffer=0
preserve_water=0
preserve_lava=0

rule1=0,100,minecraft:grass-0
rule2=0,100,minecraft:dirt-0
rule3=0,100,chisel:dirt-0
rule4=0,100,chisel:marble-1
rule5=0,100,minecraft:planks-0
rule6=0,100,chisel:marble_slab-1
rule7=0,100,minecraft:tallgrass-1
rule8=0,100,minecraft:red_flower-0
rule9=0,100,chisel:marble_stairs.0-10
rule10=0,100,chisel:marble_stairs.0-8
rule11=0,100,chisel:marble_stairs.0-11
rule12=0,100,minecraft:yellow_flower-0
rule13=0,100,chisel:marble-11
rule14=0,100,ThermalFoundation:FluidRedstone-3
rule15=0,100,minecraft:wooden_door-0
rule16=0,100,ThermalFoundation:FluidRedstone-2
rule17=0,100,ThermalFoundation:FluidRedstone-1
rule18=0,100,ChestGenHook:dungeonChest:5-3
rule19=0,100,minecraft:bed-3
rule20=0,100,minecraft:furnace-3
rule21=0,100,minecraft:bed-11
rule22=0,100,Natura:Rare Sapling-4,BiomesOPlenty:saplings-0,BiomesOPlenty:saplings-3,BiomesOPlenty:saplings-4,BiomesOPlenty:saplings-6,BiomesOPlenty:saplings-7,BiomesOPlenty:saplings-12,BiomesOPlenty:saplings-10,BiomesOPlenty:saplings-9,BiomesOPlenty:colorizedSaplings-3,BiomesOPlenty:saplings-15,TConstruct:slime.sapling-0,BiomesOPlenty:colorizedSaplings-6,witchery:witchsapling-2,minecraft:sapling-0,minecraft:sapling-1,minecraft:sapling-2,minecraft:sapling-3,minecraft:sapling-4,minecraft:sapling-5,Natura:florasapling-1,Natura:florasapling-3,Natura:Rare Sapling-0,Natura:Rare Sapling-1,Natura:Rare Sapling-2,Natura:Rare Sapling-3,witchery:witchsapling-0,witchery:witchsapling-1
rule23=0,100,Natura:Rare Sapling-4,BiomesOPlenty:saplings-0,BiomesOPlenty:saplings-3,BiomesOPlenty:saplings-4,BiomesOPlenty:saplings-6,BiomesOPlenty:saplings-7,BiomesOPlenty:saplings-12,BiomesOPlenty:saplings-10,BiomesOPlenty:saplings-9,BiomesOPlenty:colorizedSaplings-3,BiomesOPlenty:saplings-15,TConstruct:slime.sapling-0,BiomesOPlenty:colorizedSaplings-6,witchery:witchsapling-2,minecraft:sapling-0,minecraft:sapling-1,minecraft:sapling-2,minecraft:sapling-3,minecraft:sapling-4,minecraft:sapling-5,Natura:florasapling-1,Natura:florasapling-3,Natura:Rare Sapling-0,Natura:Rare Sapling-1,Natura:Rare Sapling-2,Natura:Rare Sapling-3,witchery:witchsapling-0,witchery:witchsapling-1
rule24=0,100,chisel:marble_pillar-0
rule25=0,100,minecraft:wooden_door-8
rule26=0,100,minecraft:redstone_block-0
rule27=2,100,minecraft:torch-2
rule28=0,100,BiomesOPlenty:flowers-0
rule29=2,100,minecraft:redstone_torch-3
rule30=2,100,minecraft:redstone_torch-4
rule31=0,100,minecraft:wooden_slab-8
rule32=1,100,minecraft:redstone_torch-5
rule33=0,100,ThermalFoundation:FluidRedstone-0

layer
1,1,1,1,1,1,1,1,1,1,1,1,1,1,1,1
1,2,1,1,1,1,1,1,1,1,2,1,1,1,1,1
1,1,1,1,1,1,1,1,1,1,1,1,1,1,1,1
3,3,3,3,3,3,3,3,3,3,1,1,1,1,1,1
3,3,3,3,3,3,3,3,3,3,3,1,1,1,1,1
1,1,1,1,1,1,1,1,1,3,3,3,3,3,3,3
1,1,1,1,2,2,2,1,1,1,3,3,3,3,3,3
1,2,4,4,4,4,4,4,4,1,1,1,3,1,1,1
1,1,4,4,4,4,4,4,4,1,1,1,3,1,1,1
1,2,4,4,4,4,4,4,4,1,1,1,3,1,2,1
1,2,4,4,4,4,4,4,4,1,2,2,5,2,2,2
1,2,4,4,4,4,4,4,4,2,5,5,5,5,5,2
2,2,4,4,4,4,4,4,4,2,5,5,5,5,5,2
1,2,4,4,4,4,4,4,4,2,5,5,5,5,5,2
1,2,2,2,1,1,1,2,2,2,5,5,5,5,5,2
1,1,1,1,1,1,1,1,2,2,2,2,2,2,2,2
endlayer

layer
6,6,6,0,0,0,7,0,0,6,6,6,0,0,0,0
6,1,6,7,7,7,0,7,7,6,1,6,0,7,7,0
6,6,6,7,7,7,7,0,0,6,6,6,8,7,7,0
0,0,0,0,0,0,0,0,0,0,7,7,7,7,7,7
0,0,0,0,0,0,0,0,0,0,0,8,7,7,7,0
7,7,0,10,10,10,10,9,0,0,0,0,0,0,0,0
7,0,0,11,4,4,4,9,7,7,0,0,0,0,0,0
7,1,4,4,4,4,4,4,4,7,8,0,0,7,0,7
7,7,4,13,13,13,13,13,4,0,0,7,0,7,12,0
7,1,4,13,14,6,14,13,4,0,0,0,0,7,1,0
0,1,4,13,16,17,16,13,4,0,2,5,15,5,2,1
0,1,4,13,17,17,17,13,4,1,0,0,0,0,18,2
1,1,4,13,13,13,13,13,4,2,0,0,0,0,0,2
0,1,4,4,4,4,4,4,4,2,19,0,0,0,0,2
7,1,1,1,7,0,0,1,2,2,21,0,0,0,20,2
0,0,0,7,7,7,8,0,1,2,2,2,2,2,2,1
endlayer

layer
0,0,0,0,0,0,0,0,0,0,0,0,0,0,0,0
0,23,0,0,0,0,0,0,0,0,22,0,0,0,0,0
0,0,0,0,0,0,0,0,0,0,0,0,0,0,0,0
0,0,0,0,0,0,0,0,0,0,0,0,0,0,0,0
0,0,0,0,0,0,0,0,0,0,0,0,0,0,0,0
0,0,0,0,0,0,0,0,0,0,0,0,0,0,0,0
0,0,0,0,0,0,0,0,0,0,0,0,0,0,0,0
0,0,24,0,24,0,24,0,24,0,0,0,0,0,0,0
0,0,0,0,0,0,0,0,0,0,0,0,0,0,0,0
0,7,24,0,0,0,0,0,24,0,0,0,0,0,8,0
0,7,0,0,0,0,0,0,0,0,1,5,25,5,1,0
0,7,24,0,0,17,0,0,24,0,2,0,0,0,0,1
7,7,0,0,0,26,0,0,0,1,0,0,0,0,0,1
0,7,24,0,24,0,24,0,24,1,0,0,0,0,0,1
0,7,7,12,0,0,0,0,1,1,0,0,27,0,2,1
0,0,0,0,0,0,0,0,28,1,1,2,2,2,1,0
endlayer

layer
0,0,0,0,0,0,0,0,0,0,0,0,0,0,0,0
0,0,0,0,0,0,0,0,0,0,0,0,0,0,0,0
0,0,0,0,0,0,0,0,0,0,0,0,0,0,0,0
0,0,0,0,0,0,0,0,0,0,0,0,0,0,0,0
0,0,0,0,0,0,0,0,0,0,0,0,0,0,0,0
0,0,0,0,0,0,0,0,0,0,0,0,0,0,0,0
0,0,0,0,0,0,0,0,0,0,0,0,0,0,0,0
0,0,24,0,24,0,24,0,24,0,0,0,0,0,0,0
0,0,0,0,0,0,0,0,0,0,0,0,0,0,0,0
0,0,24,30,0,0,0,29,24,0,0,0,0,0,0,0
0,0,0,0,0,0,0,0,0,0,0,1,1,1,0,0
0,0,24,30,0,17,0,29,24,0,1,31,31,31,1,7
0,0,0,0,0,0,0,0,0,0,1,31,31,31,1,8
0,0,24,0,24,0,24,0,24,7,1,31,31,31,1,0
0,0,0,0,0,0,0,0,8,7,1,31,31,31,1,28
0,0,0,0,0,0,0,0,0,7,0,1,1,1,0,0
endlayer

layer
0,0,0,0,0,0,0,0,0,0,0,0,0,0,0,0
0,0,0,0,0,0,0,0,0,0,0,0,0,0,0,0
0,0,0,0,0,0,0,0,0,0,0,0,0,0,0,0
0,0,0,0,0,0,0,0,0,0,0,0,0,0,0,0
0,0,0,0,0,0,0,0,0,0,0,0,0,0,0,0
0,0,0,0,0,0,0,0,0,0,0,0,0,0,0,0
0,0,0,0,0,0,0,0,0,0,0,0,0,0,0,0
0,0,24,0,24,0,24,0,24,0,0,0,0,0,0,0
0,0,0,0,0,0,0,0,0,0,0,0,0,0,0,0
0,0,24,0,0,0,0,0,24,0,0,0,0,0,0,0
0,0,0,0,0,0,0,0,0,0,0,0,7,7,0,0
0,0,24,0,0,17,0,0,24,0,0,1,1,1,7,0
0,0,0,0,0,0,0,0,0,0,0,1,1,1,7,0
0,0,24,0,24,0,24,0,24,0,0,1,1,1,7,0
0,0,0,0,0,0,0,0,0,0,0,1,1,1,7,0
0,0,0,0,0,0,0,0,0,0,0,7,7,7,0,0
endlayer

layer
0,0,0,0,0,0,0,0,0,0,0,0,0,0,0,0
0,0,0,0,0,0,0,0,0,0,0,0,0,0,0,0
0,0,0,0,0,0,0,0,0,0,0,0,0,0,0,0
0,0,0,0,0,0,0,0,0,0,0,0,0,0,0,0
0,0,0,0,0,0,0,0,0,0,0,0,0,0,0,0
0,0,0,0,0,0,0,0,0,0,0,0,0,0,0,0
0,0,0,0,0,0,0,0,0,0,0,0,0,0,0,0
0,0,24,0,24,0,24,0,24,0,0,0,0,0,0,0
0,0,0,0,0,0,0,0,0,0,0,0,0,0,0,0
0,0,24,0,0,0,0,0,24,0,0,0,0,0,0,0
0,0,0,0,0,0,0,0,0,0,0,0,0,0,0,0
0,0,24,0,0,17,0,0,24,0,0,7,7,7,0,0
0,0,0,0,0,0,0,0,0,0,0,0,28,7,0,0
0,0,24,0,24,0,24,0,24,0,0,0,0,0,0,0
0,0,0,0,0,0,0,0,0,0,0,7,7,0,0,0
0,0,0,0,0,0,0,0,0,0,0,0,0,0,0,0
endlayer

layer
0,0,0,0,0,0,0,0,0,0,0,0,0,0,0,0
0,0,0,0,0,0,0,0,0,0,0,0,0,0,0,0
0,0,0,0,0,0,0,0,0,0,0,0,0,0,0,0
0,0,0,0,0,0,0,0,0,0,0,0,0,0,0,0
0,0,0,0,0,0,0,0,0,0,0,0,0,0,0,0
0,0,0,0,0,0,0,0,0,0,0,0,0,0,0,0
0,0,0,0,0,0,0,0,0,0,0,0,0,0,0,0
0,11,13,13,13,13,13,13,13,9,0,0,0,0,0,0
0,11,13,0,0,0,0,0,13,9,0,0,0,0,0,0
0,11,13,0,0,0,0,0,13,9,0,0,0,0,0,0
0,11,13,0,0,0,0,0,13,9,0,0,0,0,0,0
0,11,13,0,0,17,0,0,13,9,0,0,0,0,0,0
0,11,13,0,0,0,0,0,13,9,0,0,0,0,0,0
0,11,13,13,13,13,13,13,13,9,0,0,0,0,0,0
0,0,0,0,0,0,0,0,0,0,0,0,0,0,0,0
0,0,0,0,0,0,0,0,0,0,0,0,0,0,0,0
endlayer

layer
0,0,0,0,0,0,0,0,0,0,0,0,0,0,0,0
0,0,0,0,0,0,0,0,0,0,0,0,0,0,0,0
0,0,0,0,0,0,0,0,0,0,0,0,0,0,0,0
0,0,0,0,0,0,0,0,0,0,0,0,0,0,0,0
0,0,0,0,0,0,0,0,0,0,0,0,0,0,0,0
0,0,0,0,0,0,0,0,0,0,0,0,0,0,0,0
0,0,0,0,0,0,0,0,0,0,0,0,0,0,0,0
0,0,11,13,13,32,13,13,9,0,0,0,0,0,0,0
0,0,11,0,0,0,0,0,9,0,0,0,0,0,0,0
0,0,11,0,0,0,0,0,9,0,0,0,0,0,0,0
0,0,11,0,0,0,0,0,9,0,0,0,0,0,0,0
0,0,11,0,0,17,0,0,9,0,0,0,0,0,0,0
0,0,11,0,0,0,0,0,9,0,0,0,0,0,0,0
0,0,11,13,13,32,13,13,9,0,0,0,0,0,0,0
0,0,0,0,0,0,0,0,0,0,0,0,0,0,0,0
0,0,0,0,0,0,0,0,0,0,0,0,0,0,0,0
endlayer

layer
0,0,0,0,0,0,0,0,0,0,0,0,0,0,0,0
0,0,0,0,0,0,0,0,0,0,0,0,0,0,0,0
0,0,0,0,0,0,0,0,0,0,0,0,0,0,0,0
0,0,0,0,0,0,0,0,0,0,0,0,0,0,0,0
0,0,0,0,0,0,0,0,0,0,0,0,0,0,0,0
0,0,0,0,0,0,0,0,0,0,0,0,0,0,0,0
0,0,0,0,0,0,0,0,0,0,0,0,0,0,0,0
0,0,0,11,13,13,13,9,0,0,0,0,0,0,0,0
0,0,0,11,0,0,0,9,0,0,0,0,0,0,0,0
0,0,0,11,0,0,0,9,0,0,0,0,0,0,0,0
0,0,0,11,0,0,0,9,0,0,0,0,0,0,0,0
0,0,0,11,0,17,0,9,0,0,0,0,0,0,0,0
0,0,0,11,0,13,0,9,0,0,0,0,0,0,0,0
0,0,0,11,13,13,13,9,0,0,0,0,0,0,0,0
0,0,0,0,0,0,0,0,0,0,0,0,0,0,0,0
0,0,0,0,0,0,0,0,0,0,0,0,0,0,0,0
endlayer

layer
0,0,0,0,0,0,0,0,0,0,0,0,0,0,0,0
0,0,0,0,0,0,0,0,0,0,0,0,0,0,0,0
0,0,0,0,0,0,0,0,0,0,0,0,0,0,0,0
0,0,0,0,0,0,0,0,0,0,0,0,0,0,0,0
0,0,0,0,0,0,0,0,0,0,0,0,0,0,0,0
0,0,0,0,0,0,0,0,0,0,0,0,0,0,0,0
0,0,0,0,0,0,0,0,0,0,0,0,0,0,0,0
0,0,0,0,11,13,9,0,0,0,0,0,0,0,0,0
0,0,0,0,11,0,9,0,0,0,0,0,0,0,0,0
0,0,0,0,11,0,9,0,0,0,0,0,0,0,0,0
0,0,0,0,11,0,9,0,0,0,0,0,0,0,0,0
0,0,0,0,11,17,9,0,0,0,0,0,0,0,0,0
0,0,0,0,11,33,9,0,0,0,0,0,0,0,0,0
0,0,0,0,11,13,9,0,0,0,0,0,0,0,0,0
0,0,0,0,0,0,0,0,0,0,0,0,0,0,0,0
0,0,0,0,0,0,0,0,0,0,0,0,0,0,0,0
endlayer

layer
0,0,0,0,0,0,0,0,0,0,0,0,0,0,0,0
0,0,0,0,0,0,0,0,0,0,0,0,0,0,0,0
0,0,0,0,0,0,0,0,0,0,0,0,0,0,0,0
0,0,0,0,0,0,0,0,0,0,0,0,0,0,0,0
0,0,0,0,0,0,0,0,0,0,0,0,0,0,0,0
0,0,0,0,0,0,0,0,0,0,0,0,0,0,0,0
0,0,0,0,0,0,0,0,0,0,0,0,0,0,0,0
0,0,0,0,0,6,0,0,0,0,0,0,0,0,0,0
0,0,0,0,0,6,0,0,0,0,0,0,0,0,0,0
0,0,0,0,0,6,0,0,0,0,0,0,0,0,0,0
0,0,0,0,0,6,0,0,0,0,0,0,0,0,0,0
0,0,0,0,0,6,0,0,0,0,0,0,0,0,0,0
0,0,0,0,0,6,0,0,0,0,0,0,0,0,0,0
0,0,0,0,0,6,0,0,0,0,0,0,0,0,0,0
0,0,0,0,0,0,0,0,0,0,0,0,0,0,0,0
0,0,0,0,0,0,0,0,0,0,0,0,0,0,0,0
endlayer

