
# Created by Ruins mod version 14.1 Ingame Parser
# authoring Player: Divineaspect

weight=15
embed_into_distance=1
acceptable_target_blocks=
unacceptable_target_blocks=flowing_water,water,flowing_lava,lava
dimensions=11,16,16
allowable_overhang=2
max_leveling=2
leveling_buffer=0
preserve_water=0
preserve_lava=0

rule1=0,100,minecraft:grass-0
rule2=0,100,minecraft:dirt-0
rule3=0,100,chisel:dirt-0
rule4=0,100,chisel:marble-1
rule5=0,100,ThermalFoundation:FluidCryotheum-3
rule6=0,100,ThermalFoundation:FluidCryotheum-4
rule7=0,100,minecraft:planks-0
rule8=0,100,ThermalFoundation:FluidCryotheum-2
rule9=0,100,IInventory;minecraft:dispenser;minecraft:bucket#1#0#0-5
rule10=0,100,ThermalFoundation:FluidCryotheum-1
rule11=0,100,ThermalFoundation:FluidCryotheum-0
rule12=0,100,chisel:marble_slab-1
rule13=0,100,minecraft:tallgrass-1
rule14=0,100,minecraft:red_flower-0
rule15=0,100,chisel:marble_stairs.0-10
rule16=0,100,chisel:marble_stairs.0-8
rule17=0,100,chisel:marble_stairs.0-11
rule18=0,100,minecraft:yellow_flower-0
rule19=0,100,chisel:marble-11
rule20=0,100,minecraft:snow_layer-0
rule21=0,100,minecraft:wooden_door-4
rule22=0,100,ChestGenHook:dungeonChest:5-3
rule23=0,100,minecraft:packed_ice-0
rule24=0,100,minecraft:bed-3
rule25=0,100,minecraft:furnace-3
rule26=0,100,minecraft:bed-11
rule27=0,100,Natura:Rare Sapling-4,BiomesOPlenty:saplings-0,BiomesOPlenty:saplings-3,BiomesOPlenty:saplings-4,BiomesOPlenty:saplings-6,BiomesOPlenty:saplings-7,BiomesOPlenty:saplings-12,BiomesOPlenty:saplings-10,BiomesOPlenty:saplings-9,BiomesOPlenty:colorizedSaplings-3,BiomesOPlenty:saplings-15,TConstruct:slime.sapling-0,BiomesOPlenty:colorizedSaplings-6,witchery:witchsapling-2,minecraft:sapling-0,minecraft:sapling-1,minecraft:sapling-2,minecraft:sapling-3,minecraft:sapling-4,minecraft:sapling-5,Natura:florasapling-1,Natura:florasapling-3,Natura:Rare Sapling-0,Natura:Rare Sapling-1,Natura:Rare Sapling-2,Natura:Rare Sapling-3,witchery:witchsapling-0,witchery:witchsapling-1
rule28=0,100,Natura:Rare Sapling-4,BiomesOPlenty:saplings-0,BiomesOPlenty:saplings-3,BiomesOPlenty:saplings-4,BiomesOPlenty:saplings-6,BiomesOPlenty:saplings-7,BiomesOPlenty:saplings-12,BiomesOPlenty:saplings-10,BiomesOPlenty:saplings-9,BiomesOPlenty:colorizedSaplings-3,BiomesOPlenty:saplings-15,TConstruct:slime.sapling-0,BiomesOPlenty:colorizedSaplings-6,witchery:witchsapling-2,minecraft:sapling-0,minecraft:sapling-1,minecraft:sapling-2,minecraft:sapling-3,minecraft:sapling-4,minecraft:sapling-5,Natura:florasapling-1,Natura:florasapling-3,Natura:Rare Sapling-0,Natura:Rare Sapling-1,Natura:Rare Sapling-2,Natura:Rare Sapling-3,witchery:witchsapling-0,witchery:witchsapling-1
rule29=0,100,chisel:marble_pillar-0
rule30=0,100,minecraft:wooden_door-8
rule31=0,100,minecraft:heavy_weighted_pressure_plate-0
rule32=2,100,minecraft:torch-2
rule33=0,100,BiomesOPlenty:flowers-0
rule34=0,100,minecraft:wooden_slab-8

layer
1,1,1,1,1,1,1,1,1,1,1,1,1,1,1,1
1,2,1,1,1,1,1,1,1,1,2,1,1,1,1,1
1,1,1,1,1,1,1,1,1,1,1,1,1,1,1,1
3,3,3,3,3,3,3,3,3,3,1,1,1,1,1,1
3,3,3,3,3,3,3,3,3,3,3,1,1,1,1,1
1,1,1,1,1,1,1,1,1,3,3,3,3,3,3,3
1,1,1,1,2,2,2,1,1,1,3,3,3,3,3,3
1,2,4,4,4,4,4,4,4,1,1,1,3,1,1,1
1,1,4,4,4,4,4,4,4,1,1,1,3,1,1,1
1,2,4,4,5,6,5,4,4,1,1,1,3,1,2,1
1,2,4,4,8,9,8,4,4,1,2,2,7,2,2,2
1,2,4,4,10,11,10,4,4,2,7,7,7,7,7,2
2,2,4,4,4,12,4,4,4,2,7,7,7,7,7,2
1,2,4,4,4,4,4,4,4,2,7,7,7,7,7,2
1,2,2,2,1,2,1,2,2,2,7,7,7,7,7,2
1,1,1,1,1,1,1,1,2,2,2,2,2,2,2,2
endlayer

layer
12,12,12,0,0,0,13,0,0,12,12,12,0,0,0,0
12,2,12,0,0,0,0,13,13,12,2,12,0,13,13,0
12,12,12,0,0,0,13,0,0,12,12,12,14,13,13,0
0,0,0,0,0,0,0,0,0,0,13,13,13,13,13,13
0,0,0,0,0,0,0,0,0,0,0,14,13,13,13,0
13,13,0,16,16,16,16,15,0,0,0,0,0,0,0,0
13,0,0,17,4,4,4,15,0,0,0,0,0,0,0,0
0,1,4,4,4,4,4,4,4,0,0,0,0,13,0,13
0,20,4,19,19,19,19,19,4,0,0,0,0,0,18,0
0,1,4,19,19,19,19,19,4,0,0,0,0,13,1,0
0,1,4,19,19,19,19,19,4,0,2,7,21,7,2,1
0,1,4,19,19,19,19,19,4,1,0,0,0,0,22,2
1,1,4,19,19,23,19,19,4,2,0,0,0,0,0,2
0,1,4,4,4,4,4,4,4,2,24,0,0,0,0,2
13,1,1,1,0,0,0,1,2,2,26,0,0,0,25,2
0,0,0,0,0,0,14,0,1,2,2,2,2,2,2,1
endlayer

layer
0,0,0,0,0,0,0,0,0,0,0,0,0,0,0,0
0,28,0,0,0,0,0,0,0,0,27,0,0,0,0,0
0,0,0,0,0,0,0,0,0,0,0,0,0,0,0,0
0,0,0,0,0,0,0,0,0,0,0,0,0,0,0,0
0,0,0,0,0,0,0,0,0,0,0,0,0,0,0,0
0,0,0,0,0,0,0,0,0,0,0,0,0,0,0,0
0,0,0,0,0,0,0,0,0,0,0,0,0,0,0,0
0,0,29,0,29,0,29,0,29,0,0,0,0,0,0,0
0,0,0,0,0,0,0,0,0,0,0,0,0,0,0,0
0,13,29,0,0,0,0,0,29,0,0,0,0,0,14,0
0,13,0,0,0,31,0,0,0,0,1,7,30,7,1,0
0,13,29,0,20,0,0,0,29,20,2,0,0,0,0,1
13,13,0,0,0,23,0,0,0,1,0,0,0,0,0,1
0,13,29,0,29,12,29,0,29,1,0,0,0,0,0,1
0,13,13,0,0,0,0,0,1,1,0,0,32,0,2,1
0,0,0,0,0,0,0,0,33,1,1,2,2,2,1,0
endlayer

layer
0,0,0,0,0,0,0,0,0,0,0,0,0,0,0,0
0,0,0,0,0,0,0,0,0,0,0,0,0,0,0,0
0,0,0,0,0,0,0,0,0,0,0,0,0,0,0,0
0,0,0,0,0,0,0,0,0,0,0,0,0,0,0,0
0,0,0,0,0,0,0,0,0,0,0,0,0,0,0,0
0,0,0,0,0,0,0,0,0,0,0,0,0,0,0,0
0,0,0,0,0,0,0,0,0,0,0,0,0,0,0,0
0,0,29,0,29,0,29,0,29,0,0,0,0,0,0,0
0,0,0,0,0,0,0,0,0,0,0,0,0,0,0,0
0,0,29,0,0,0,0,0,29,0,0,0,0,0,0,0
0,0,0,0,0,0,0,0,0,0,0,1,1,1,0,0
0,0,29,0,0,0,0,0,29,0,1,34,34,34,1,13
0,0,0,0,0,0,0,0,0,0,1,34,34,34,1,14
0,0,29,0,29,0,29,0,29,13,1,34,34,34,1,0
0,0,0,0,0,0,0,0,14,13,1,34,34,34,1,33
0,0,0,0,0,0,0,0,0,13,0,1,1,1,0,0
endlayer

layer
0,0,0,0,0,0,0,0,0,0,0,0,0,0,0,0
0,0,0,0,0,0,0,0,0,0,0,0,0,0,0,0
0,0,0,0,0,0,0,0,0,0,0,0,0,0,0,0
0,0,0,0,0,0,0,0,0,0,0,0,0,0,0,0
0,0,0,0,0,0,0,0,0,0,0,0,0,0,0,0
0,0,0,0,0,0,0,0,0,0,0,0,0,0,0,0
0,0,0,0,0,0,0,0,0,0,0,0,0,0,0,0
0,0,29,0,29,0,29,0,29,0,0,0,0,0,0,0
0,0,0,0,0,0,0,0,0,0,0,0,0,0,0,0
0,0,29,0,0,0,0,0,29,0,0,0,0,0,0,0
0,0,0,0,0,0,0,0,0,0,0,0,13,13,0,0
0,0,29,0,0,0,0,0,29,0,0,1,1,1,13,0
0,0,0,0,0,0,0,0,0,0,0,1,1,1,13,0
0,0,29,0,29,0,29,0,29,0,0,1,1,1,13,0
0,0,0,0,0,0,0,0,0,0,0,1,1,1,13,0
0,0,0,0,0,0,0,0,0,0,0,13,13,13,0,0
endlayer

layer
0,0,0,0,0,0,0,0,0,0,0,0,0,0,0,0
0,0,0,0,0,0,0,0,0,0,0,0,0,0,0,0
0,0,0,0,0,0,0,0,0,0,0,0,0,0,0,0
0,0,0,0,0,0,0,0,0,0,0,0,0,0,0,0
0,0,0,0,0,0,0,0,0,0,0,0,0,0,0,0
0,0,0,0,0,0,0,0,0,0,0,0,0,0,0,0
0,0,0,0,0,0,0,0,0,0,0,0,0,0,0,0
0,0,29,0,29,0,29,0,29,0,0,0,0,0,0,0
0,0,0,0,0,0,0,0,0,0,0,0,0,0,0,0
0,0,29,0,0,0,0,0,29,0,0,0,0,0,0,0
0,0,0,0,0,0,0,0,0,0,0,0,0,0,0,0
0,0,29,0,0,0,0,0,29,0,0,13,13,13,0,0
0,0,0,0,0,0,0,0,0,0,0,0,33,13,0,0
0,0,29,0,29,0,29,0,29,0,0,0,0,0,0,0
0,0,0,0,0,0,0,0,0,0,0,13,13,0,0,0
0,0,0,0,0,0,0,0,0,0,0,0,0,0,0,0
endlayer

layer
0,0,0,0,0,0,0,0,0,0,0,0,0,0,0,0
0,0,0,0,0,0,0,0,0,0,0,0,0,0,0,0
0,0,0,0,0,0,0,0,0,0,0,0,0,0,0,0
0,0,0,0,0,0,0,0,0,0,0,0,0,0,0,0
0,0,0,0,0,0,0,0,0,0,0,0,0,0,0,0
0,0,0,0,0,0,0,0,0,0,0,0,0,0,0,0
0,0,0,0,0,0,0,0,0,0,0,0,0,0,0,0
0,17,19,19,19,19,19,19,19,15,0,0,0,0,0,0
0,17,19,0,0,0,0,0,19,15,0,0,0,0,0,0
0,17,19,0,0,0,0,0,19,15,0,0,0,0,0,0
0,17,19,0,0,0,0,0,19,15,0,0,0,0,0,0
0,17,19,0,0,0,0,0,19,15,0,0,0,0,0,0
0,17,19,0,0,0,0,0,19,15,0,0,0,0,0,0
0,17,19,19,19,19,19,19,19,15,0,0,0,0,0,0
0,0,0,0,0,0,0,0,0,0,0,0,0,0,0,0
0,0,0,0,0,0,0,0,0,0,0,0,0,0,0,0
endlayer

layer
0,0,0,0,0,0,0,0,0,0,0,0,0,0,0,0
0,0,0,0,0,0,0,0,0,0,0,0,0,0,0,0
0,0,0,0,0,0,0,0,0,0,0,0,0,0,0,0
0,0,0,0,0,0,0,0,0,0,0,0,0,0,0,0
0,0,0,0,0,0,0,0,0,0,0,0,0,0,0,0
0,0,0,0,0,0,0,0,0,0,0,0,0,0,0,0
0,0,0,0,0,0,0,0,0,0,0,0,0,0,0,0
0,0,17,19,19,23,19,19,15,0,0,0,0,0,0,0
0,0,17,0,0,0,0,0,15,0,0,0,0,0,0,0
0,0,17,0,0,0,0,0,15,0,0,0,0,0,0,0
0,0,17,0,0,0,0,0,15,0,0,0,0,0,0,0
0,0,17,0,0,0,0,0,15,0,0,0,0,0,0,0
0,0,17,0,0,0,0,0,15,0,0,0,0,0,0,0
0,0,17,19,19,23,19,19,15,0,0,0,0,0,0,0
0,0,0,0,0,0,0,0,0,0,0,0,0,0,0,0
0,0,0,0,0,0,0,0,0,0,0,0,0,0,0,0
endlayer

layer
0,0,0,0,0,0,0,0,0,0,0,0,0,0,0,0
0,0,0,0,0,0,0,0,0,0,0,0,0,0,0,0
0,0,0,0,0,0,0,0,0,0,0,0,0,0,0,0
0,0,0,0,0,0,0,0,0,0,0,0,0,0,0,0
0,0,0,0,0,0,0,0,0,0,0,0,0,0,0,0
0,0,0,0,0,0,0,0,0,0,0,0,0,0,0,0
0,0,0,0,0,0,0,0,0,0,0,0,0,0,0,0
0,0,0,17,19,19,19,15,0,0,0,0,0,0,0,0
0,0,0,17,0,0,0,15,0,0,0,0,0,0,0,0
0,0,0,17,0,0,0,15,0,0,0,0,0,0,0,0
0,0,0,17,0,0,0,15,0,0,0,0,0,0,0,0
0,0,0,17,0,0,0,15,0,0,0,0,0,0,0,0
0,0,0,17,0,0,0,15,0,0,0,0,0,0,0,0
0,0,0,17,19,19,19,15,0,0,0,0,0,0,0,0
0,0,0,0,0,0,0,0,0,0,0,0,0,0,0,0
0,0,0,0,0,0,0,0,0,0,0,0,0,0,0,0
endlayer

layer
0,0,0,0,0,0,0,0,0,0,0,0,0,0,0,0
0,0,0,0,0,0,0,0,0,0,0,0,0,0,0,0
0,0,0,0,0,0,0,0,0,0,0,0,0,0,0,0
0,0,0,0,0,0,0,0,0,0,0,0,0,0,0,0
0,0,0,0,0,0,0,0,0,0,0,0,0,0,0,0
0,0,0,0,0,0,0,0,0,0,0,0,0,0,0,0
0,0,0,0,0,0,0,0,0,0,0,0,0,0,0,0
0,0,0,0,17,19,15,0,0,0,0,0,0,0,0,0
0,0,0,0,17,0,15,0,0,0,0,0,0,0,0,0
0,0,0,0,17,0,15,0,0,0,0,0,0,0,0,0
0,0,0,0,17,0,15,0,0,0,0,0,0,0,0,0
0,0,0,0,17,0,15,0,0,0,0,0,0,0,0,0
0,0,0,0,17,0,15,0,0,0,0,0,0,0,0,0
0,0,0,0,17,19,15,0,0,0,0,0,0,0,0,0
0,0,0,0,0,0,0,0,0,0,0,0,0,0,0,0
0,0,0,0,0,0,0,0,0,0,0,0,0,0,0,0
endlayer

layer
0,0,0,0,0,0,0,0,0,0,0,0,0,0,0,0
0,0,0,0,0,0,0,0,0,0,0,0,0,0,0,0
0,0,0,0,0,0,0,0,0,0,0,0,0,0,0,0
0,0,0,0,0,0,0,0,0,0,0,0,0,0,0,0
0,0,0,0,0,0,0,0,0,0,0,0,0,0,0,0
0,0,0,0,0,0,0,0,0,0,0,0,0,0,0,0
0,0,0,0,0,0,0,0,0,0,0,0,0,0,0,0
0,0,0,0,0,12,0,0,0,0,0,0,0,0,0,0
0,0,0,0,0,12,0,0,0,0,0,0,0,0,0,0
0,0,0,0,0,12,0,0,0,0,0,0,0,0,0,0
0,0,0,0,0,12,0,0,0,0,0,0,0,0,0,0
0,0,0,0,0,12,0,0,0,0,0,0,0,0,0,0
0,0,0,0,0,12,0,0,0,0,0,0,0,0,0,0
0,0,0,0,0,12,0,0,0,0,0,0,0,0,0,0
0,0,0,0,0,0,0,0,0,0,0,0,0,0,0,0
0,0,0,0,0,0,0,0,0,0,0,0,0,0,0,0
endlayer

