
# Created by Ruins mod version 14.1 Ingame Parser
# authoring Player: Divineaspect

biomesToSpawnIn=Hell,Boneyard,Corrupted Sands,Phantasmagoric Inferno,Polar Chasm,Undergarden,Visceral Heap
weight=100
embed_into_distance=-30
acceptable_target_blocks=lava
unacceptable_target_blocks=
dimensions=70,11,11
allowable_overhang=0
max_leveling=2
leveling_buffer=0
preserve_water=0
preserve_lava=0

rule1=0,100,Natura:Thornvines-8
rule2=0,100,Natura:Thornvines-1
rule3=0,100,Natura:Thornvines-4
rule4=0,100,minecraft:nether_brick_stairs-6
rule5=0,100,minecraft:nether_brick_stairs-4
rule6=0,100,minecraft:nether_brick-0
rule7=0,100,minecraft:lava-14
rule8=0,100,minecraft:nether_brick_stairs-7
rule9=0,100,minecraft:lava-2
rule10=0,100,minecraft:nether_brick_stairs-5
rule11=0,100,Natura:Thornvines-2
rule12=0,100,minecraft:lava-0
rule13=0,100,minecraft:lava-4
rule14=0,100,minecraft:lava-6
rule15=0,100,minecraft:nether_brick_stairs-3
rule16=0,100,minecraft:nether_brick_fence-0
rule17=0,100,minecraft:nether_brick_stairs-2
rule18=0,100,minecraft:nether_brick_stairs-1
rule19=0,20,ChestGenHook:dungeonChest:5-5
rule20=0,100,minecraft:nether_brick_stairs-0
rule21=0,20,ChestGenHook:dungeonChest:5-4
rule22=0,100,MobSpawner:Blaze,minecraft:glowstone-0
rule23=0,100,minecraft:lava-10
rule24=0,20,ChestGenHook:dungeonChest:5-2
rule25=0,20,ChestGenHook:dungeonChest:5-3
rule26=0,100,minecraft:glowstone-0
rule27=0,100,minecraft:ladder-3
rule28=0,100,minecraft:ladder-2
rule29=0,100,Natura:Obelisk-0
rule30=0,100,minecraft:stone_slab-6
rule31=0,100,minecraft:ladder-5
rule32=0,100,MobSpawner:PigZombie,minecraft:glowstone-0
rule33=0,100,minecraft:fire-1
rule34=0,100,minecraft:ladder-4
rule35=0,100,minecraft:stone_slab-14
rule36=0,100,minecraft:soul_sand-0
rule37=0,100,MobSpawner:Skeleton,minecraft:glowstone-0
rule38=0,100,minecraft:nether_wart-3
rule39=0,100,BiomesOPlenty:plants-13
rule40=0,100,minecraft:nether_wart-1
rule41=0,100,minecraft:nether_wart-2
rule42=0,100,minecraft:double_stone_slab-6
rule43=0,100,minecraft:trapped_chest-4
rule44=0,100,MobSpawner:primitivemobs.BlazingJuggernaut,minecraft:glowstone-0

layer
0,0,0,0,0,0,0,0,0,0,0
0,0,0,0,1,1,1,1,0,0,0
0,3,0,0,0,0,0,0,0,2,0
0,3,0,5,5,5,5,4,0,2,0
0,3,0,8,6,7,6,4,0,0,0
0,3,0,8,7,9,7,4,0,2,0
0,0,0,8,6,7,6,4,0,0,0
0,0,0,8,10,10,10,10,0,2,0
0,3,0,0,0,0,0,0,0,2,0
0,0,11,11,11,11,11,11,11,0,0
0,0,0,0,0,0,0,0,0,0,0
endlayer

layer
0,0,0,0,0,0,0,0,0,0,0
0,0,1,1,1,1,1,1,1,0,0
0,3,6,6,6,6,6,6,6,2,0
0,3,6,12,9,13,9,12,6,2,0
0,3,6,9,13,14,13,9,6,2,0
0,3,6,13,14,0,14,13,6,2,0
0,3,6,9,13,14,13,9,6,2,0
0,3,6,12,9,13,9,12,6,2,0
0,3,6,6,6,6,6,6,6,2,0
0,0,11,11,11,11,11,11,11,0,0
0,0,0,0,0,0,0,0,0,0,0
endlayer

layer
0,0,0,0,0,0,0,0,0,0,0
0,0,0,0,0,0,0,0,0,0,0
0,0,6,17,16,16,16,15,6,0,0
0,0,18,19,0,0,0,19,18,0,0
0,0,16,0,0,0,0,0,16,0,0
0,0,16,0,0,0,0,0,16,0,0
0,0,16,0,0,0,0,0,16,0,0
0,0,20,21,0,0,0,21,20,0,0
0,0,6,17,16,16,16,15,6,0,0
0,0,0,0,0,0,0,0,0,0,0
0,0,0,0,0,0,0,0,0,0,0
endlayer

layer
0,0,0,0,0,0,0,0,0,0,0
0,0,0,0,0,0,0,0,0,0,0
0,0,6,16,0,0,0,16,6,0,0
0,0,16,0,0,0,0,0,16,0,0
0,0,0,0,0,0,0,0,0,0,0
0,0,0,0,0,0,0,0,0,0,0
0,0,0,0,0,0,0,0,0,0,0
0,0,16,0,0,0,0,0,16,0,0
0,0,6,16,0,0,0,16,6,0,0
0,0,0,0,0,0,0,0,0,0,0
0,0,0,0,0,0,0,0,0,0,0
endlayer

layer
0,0,0,0,0,0,0,0,0,0,0
0,0,0,0,0,0,0,0,0,0,0
0,0,6,16,0,0,0,16,6,0,0
0,0,16,0,0,0,0,0,16,0,0
0,0,0,0,0,0,0,0,0,0,0
0,0,0,0,0,0,0,0,0,0,0
0,0,0,0,0,0,0,0,0,0,0
0,0,16,0,0,0,0,0,16,0,0
0,0,6,16,0,0,0,16,6,0,0
0,0,0,0,0,0,0,0,0,0,0
0,0,0,0,0,0,0,0,0,0,0
endlayer

layer
0,0,0,0,0,0,0,0,0,0,0
0,0,0,0,0,0,0,0,0,0,0
0,0,6,4,0,0,0,8,6,0,0
0,0,10,0,0,0,0,0,10,0,0
0,0,0,0,0,0,0,0,0,0,0
0,0,0,0,0,22,0,0,0,0,0
0,0,0,0,0,0,0,0,0,0,0
0,0,5,0,0,0,0,0,5,0,0
0,0,6,4,0,0,0,8,6,0,0
0,0,0,0,0,0,0,0,0,0,0
0,0,0,0,0,0,0,0,0,0,0
endlayer

layer
0,0,0,0,0,0,0,0,0,0,0
0,8,5,5,5,5,5,5,5,4,0
0,8,6,6,6,6,6,6,6,4,0
0,8,6,6,6,6,6,6,6,4,0
0,8,6,6,16,16,16,6,6,4,0
0,8,6,6,16,23,16,6,6,4,0
0,8,6,6,16,16,16,6,6,4,0
0,8,6,6,6,6,6,6,6,4,0
0,8,6,6,6,6,6,6,6,4,0
0,8,10,10,10,10,10,10,10,10,0
0,0,0,0,0,0,0,0,0,0,0
endlayer

layer
0,0,0,0,0,0,0,0,0,0,0
0,6,6,6,6,6,6,6,6,6,0
0,6,24,0,0,0,6,17,0,6,0
0,6,0,0,0,0,0,0,0,6,0
0,0,0,0,16,16,16,0,0,0,0
0,0,0,0,16,23,16,0,0,0,0
0,0,0,0,16,16,16,0,0,0,0
0,6,0,0,0,0,0,0,0,6,0
0,6,0,15,6,0,0,0,25,6,0
0,6,6,6,6,6,6,6,6,6,0
0,0,0,0,0,0,0,0,0,0,0
endlayer

layer
0,0,0,0,0,0,0,0,0,0,0
0,6,6,6,6,6,6,6,6,6,0
0,6,0,0,0,6,17,0,0,6,0
0,6,0,0,0,0,0,0,0,6,0
0,0,0,0,0,0,0,0,0,0,0
0,0,0,0,0,23,0,0,0,0,0
0,0,0,0,0,0,0,0,0,0,0
0,6,0,0,0,0,0,0,0,6,0
0,6,0,0,15,6,0,0,0,6,0
0,6,6,6,6,6,6,6,6,6,0
0,0,0,0,0,0,0,0,0,0,0
endlayer

layer
0,0,0,0,0,0,0,0,0,0,0
0,6,6,6,6,6,6,6,6,6,0
0,6,0,0,6,17,0,0,0,6,0
0,6,0,0,0,0,0,0,0,6,0
0,0,0,0,0,0,0,0,0,0,0
0,0,0,0,0,23,0,0,0,0,0
0,0,0,0,0,0,0,0,0,0,0
0,6,0,0,0,0,0,0,0,6,0
0,6,0,0,0,15,6,0,0,6,0
0,6,6,6,6,6,6,6,6,6,0
0,0,0,0,0,0,0,0,0,0,0
endlayer

layer
0,0,0,0,0,0,0,0,0,0,0
0,6,6,6,6,6,6,6,6,6,0
0,6,0,6,17,0,0,0,0,6,0
0,6,0,0,0,0,0,0,0,6,0
0,6,0,0,0,0,0,0,0,6,0
0,6,0,0,0,23,0,0,0,6,0
0,6,0,0,0,0,0,0,0,6,0
0,6,0,0,0,0,0,0,0,6,0
0,6,0,0,0,0,15,6,0,6,0
0,6,6,6,6,6,6,6,6,6,0
0,0,0,0,0,0,0,0,0,0,0
endlayer

layer
0,0,0,0,0,0,0,0,0,0,0
0,6,6,6,6,6,6,6,6,6,0
0,6,6,17,0,0,0,0,0,6,0
0,6,0,0,0,0,0,0,0,6,0
0,6,0,0,0,0,0,0,0,6,0
0,6,0,0,0,23,0,0,0,6,0
0,6,0,0,0,0,0,0,0,6,0
0,6,0,0,0,0,0,0,0,6,0
0,6,0,0,0,0,0,15,6,6,0
0,6,6,6,6,6,6,6,6,6,0
0,0,0,0,0,0,0,0,0,0,0
endlayer

layer
5,5,5,5,5,5,5,5,5,5,5
8,6,6,6,6,6,6,6,6,6,4
8,6,17,0,0,0,0,0,0,6,4
8,6,6,6,6,6,6,6,6,6,4
8,6,6,6,26,26,26,6,6,6,4
8,6,6,6,26,23,26,6,6,6,4
8,6,6,6,26,26,26,6,6,6,4
8,6,6,6,6,6,6,6,6,6,4
8,6,0,0,0,0,0,0,15,6,4
8,6,6,6,6,6,6,6,6,6,4
10,10,10,10,10,10,10,10,10,10,10
endlayer

layer
6,6,6,17,15,6,17,15,6,6,6
6,19,0,0,0,0,0,0,0,19,6
6,0,0,0,0,0,0,0,0,0,6
18,0,0,0,0,0,0,0,0,0,18
20,0,0,0,0,7,0,0,0,0,20
6,28,0,0,7,9,7,0,0,27,6
18,0,0,0,0,7,0,0,0,0,18
20,0,0,0,0,0,0,0,0,0,20
6,0,0,0,0,0,0,0,0,0,6
6,21,0,0,0,0,0,0,0,21,6
6,6,6,17,15,6,17,15,6,6,6
endlayer

layer
6,16,6,0,0,6,0,0,6,16,6
16,0,0,0,0,0,0,0,0,0,16
6,0,0,0,0,0,0,0,0,0,6
0,0,0,0,0,0,0,0,0,0,0
0,0,0,0,0,7,0,0,0,0,0
6,28,0,0,7,0,7,0,0,27,6
0,0,0,0,0,7,0,0,0,0,0
0,0,0,0,0,0,0,0,0,0,0
6,0,0,0,0,0,0,0,0,0,6
16,0,0,0,0,0,0,0,0,0,16
6,16,6,0,0,6,0,0,6,16,6
endlayer

layer
6,6,6,4,8,6,4,8,6,6,6
6,0,0,0,0,0,0,0,0,0,6
6,0,0,0,0,0,0,0,0,0,6
10,0,0,0,0,0,0,0,0,0,10
5,0,0,0,0,7,0,0,0,0,5
6,28,0,0,7,0,7,0,0,27,6
10,0,0,0,0,7,0,0,0,0,10
5,0,0,0,0,0,0,0,0,0,5
6,0,0,0,0,0,0,0,0,0,6
6,0,0,0,0,0,0,0,0,0,6
6,6,6,4,8,6,4,8,6,6,6
endlayer

layer
6,6,6,6,6,6,6,6,6,6,6
6,4,10,10,6,0,6,10,10,0,6
6,4,0,8,6,0,6,4,0,8,6
6,5,5,8,6,5,6,4,5,8,6
6,6,6,6,6,7,6,6,6,6,6
6,28,0,8,7,0,7,4,0,27,6
6,6,6,6,6,7,6,6,6,6,6
6,10,10,8,6,10,6,10,10,8,6
6,4,0,8,6,0,6,4,0,8,6
6,4,5,8,6,0,6,4,5,0,6
6,6,6,6,6,6,6,6,6,6,6
endlayer

layer
6,6,6,6,6,6,6,6,6,6,6
6,6,6,6,6,6,6,6,6,0,6
6,6,29,30,30,29,30,30,29,6,6
6,6,30,12,9,13,9,12,30,6,6
6,6,30,9,13,14,13,9,30,6,6
6,28,29,13,14,0,14,13,29,27,6
6,6,30,9,13,14,13,9,30,6,6
6,6,30,12,9,13,9,12,30,6,6
6,6,29,30,30,29,30,30,29,6,6
6,6,6,6,6,6,6,6,6,0,6
6,6,6,6,6,6,6,6,6,6,6
endlayer

layer
30,20,30,0,0,6,0,0,30,20,30
15,6,17,0,0,31,0,0,15,6,17
30,18,0,0,0,0,0,0,0,18,30
0,0,0,0,0,0,0,0,0,0,0
0,0,0,0,0,0,0,0,0,0,0
18,0,33,0,0,32,0,0,0,0,18
0,0,0,0,0,0,0,0,0,0,0
0,0,0,0,0,0,0,0,0,0,0
30,20,0,0,0,0,0,0,0,20,30
15,6,17,0,0,34,0,0,15,0,17
30,18,30,0,0,6,0,0,30,18,30
endlayer

layer
0,5,0,0,0,6,0,0,0,5,0
8,6,4,0,0,31,0,0,15,6,4
0,10,0,0,0,0,0,0,0,10,0
0,0,0,0,0,0,0,0,0,0,0
0,0,0,0,0,0,0,0,0,0,0
20,0,0,0,0,21,0,0,0,0,20
0,0,0,0,0,0,0,0,0,0,0
0,0,0,0,0,0,0,0,0,0,0
0,5,0,0,0,0,0,0,0,5,0
8,6,4,0,0,34,0,0,8,0,4
0,10,0,0,0,6,0,0,0,10,0
endlayer

layer
0,20,0,0,0,6,0,0,0,20,0
15,6,17,0,0,31,0,0,8,6,17
0,18,0,0,0,0,0,0,0,18,0
0,0,0,0,0,0,0,0,0,0,0
0,0,0,0,0,0,0,0,0,0,0
18,0,0,0,0,0,0,0,0,0,18
0,0,0,0,0,0,0,0,0,0,0
0,0,0,0,0,0,0,0,0,0,0
0,20,0,0,0,0,0,0,0,20,0
15,6,17,0,0,34,0,0,15,0,17
0,18,0,0,0,6,0,0,0,18,0
endlayer

layer
35,5,35,0,0,6,0,0,35,5,35
8,6,4,35,35,31,35,35,8,6,4
35,10,6,0,6,6,6,0,6,10,35
0,35,0,0,0,6,0,0,0,35,0
0,35,6,0,21,6,21,0,6,35,0
20,0,6,6,6,6,6,6,6,0,20
0,35,6,0,19,6,19,0,6,35,0
0,35,0,0,0,6,0,0,0,35,0
35,5,6,0,6,6,6,0,6,5,35
8,6,4,35,35,34,35,35,8,0,4
35,10,35,0,0,6,0,0,35,10,35
endlayer

layer
6,6,6,6,6,6,6,6,6,6,6
6,6,6,6,6,31,6,6,6,6,6
6,6,36,36,6,6,6,36,36,6,6
6,6,36,36,36,30,36,36,36,6,6
6,6,6,36,36,30,36,36,6,6,6
18,6,6,30,30,37,30,30,6,6,18
6,6,6,36,36,30,36,36,6,6,6
6,6,36,36,36,30,36,36,36,6,6
6,6,36,36,6,6,6,36,36,6,6
6,6,6,6,6,34,6,6,6,6,6
6,6,6,6,6,6,6,6,6,6,6
endlayer

layer
6,6,6,6,6,6,6,6,6,6,6
6,0,0,0,0,0,0,0,0,0,6
6,0,38,38,16,0,16,38,38,0,6
6,0,41,39,40,0,38,39,38,0,6
6,0,16,40,38,0,38,38,16,0,6
6,24,0,0,0,0,0,0,0,25,6
6,0,16,38,38,0,38,38,16,0,6
6,0,38,39,38,0,38,39,38,0,6
6,18,38,38,16,0,16,38,38,18,6
6,0,0,0,0,0,0,0,0,0,6
6,6,6,6,6,6,6,6,6,6,6
endlayer

layer
6,6,6,6,6,6,6,6,6,6,6
6,0,0,0,0,0,0,0,0,0,6
6,0,0,0,16,0,16,0,0,0,6
6,0,0,0,0,0,0,0,0,0,6
6,0,16,0,0,0,0,0,16,0,6
6,0,0,0,0,0,0,0,0,0,6
6,0,16,0,0,0,0,0,16,0,6
6,18,0,0,0,0,0,0,0,18,6
6,0,0,0,16,0,16,0,0,0,6
6,0,0,0,0,0,0,0,0,0,6
6,6,6,6,6,6,6,6,6,6,6
endlayer

layer
6,6,6,6,6,6,6,6,6,6,6
6,0,0,0,0,0,0,0,0,0,6
6,0,0,0,16,0,16,0,0,0,6
6,0,0,0,0,0,0,0,0,0,6
6,0,16,0,0,0,0,0,16,0,6
6,0,0,0,0,0,0,0,0,0,6
6,18,16,0,0,0,0,0,16,18,6
6,0,0,0,0,0,0,0,0,0,6
6,0,0,0,16,0,16,0,0,0,6
6,0,0,0,0,0,0,0,0,0,6
6,6,6,6,6,6,6,6,6,6,6
endlayer

layer
6,6,6,6,6,6,6,6,6,6,6
6,6,6,6,6,6,6,6,6,6,6
6,6,6,6,6,6,6,6,6,6,6
6,6,6,30,30,30,6,26,6,6,6
6,6,6,30,42,30,6,6,6,6,6
6,18,6,30,30,30,30,30,6,18,6
6,0,6,6,6,30,42,30,6,0,6
6,0,6,26,6,30,30,30,6,0,6
6,0,6,6,6,6,6,6,6,0,6
6,6,6,6,6,6,6,6,6,6,6
6,6,6,6,6,6,6,6,6,6,6
endlayer

layer
6,16,16,16,16,6,16,16,16,16,6
16,0,0,0,8,17,0,0,0,0,16
16,0,0,0,0,0,0,0,0,0,16
16,0,0,0,0,0,0,26,0,0,16
16,0,0,0,43,0,0,0,0,0,16
6,0,0,0,0,0,0,0,0,0,6
16,0,0,0,0,0,43,0,0,0,16
16,0,0,26,0,0,0,0,0,0,16
16,0,0,0,0,0,0,0,0,0,16
16,0,0,0,0,15,4,0,0,0,16
6,16,16,16,16,6,16,16,16,16,6
endlayer

layer
6,0,0,0,0,6,0,0,0,0,6
0,0,0,8,17,0,0,0,0,0,0
0,0,0,0,0,0,0,0,0,0,0
0,0,0,0,0,0,0,22,0,0,0
0,0,0,0,0,0,0,0,0,0,0
6,0,0,0,0,0,0,0,0,0,6
0,0,0,0,0,0,0,0,0,0,0
0,0,0,44,0,0,0,0,0,0,0
0,0,0,0,0,0,0,0,0,0,0
0,0,0,0,0,0,15,4,0,0,0
6,0,0,0,0,6,0,0,0,0,6
endlayer

layer
6,4,0,0,0,6,0,0,0,8,6
10,0,8,17,0,0,0,0,0,0,10
0,0,0,0,0,0,0,0,0,0,0
0,0,0,0,0,0,0,26,0,0,0
0,0,0,0,0,0,0,0,0,0,0
6,0,0,0,0,0,0,0,0,0,6
0,0,0,0,0,0,0,0,0,0,0
0,0,0,26,0,0,0,0,0,0,0
0,0,0,0,0,0,0,0,0,0,0
5,0,0,0,0,0,0,15,4,0,5
6,4,0,0,0,6,0,0,0,8,6
endlayer

layer
6,15,4,0,8,6,4,0,8,17,6
20,6,17,0,0,0,0,0,0,6,20
10,0,0,0,0,0,0,0,0,0,10
0,0,0,0,0,0,0,26,0,0,0
5,0,0,0,0,0,0,0,0,0,5
6,0,0,0,0,0,0,0,0,0,6
10,0,0,0,0,0,0,0,0,0,10
0,0,0,26,0,0,0,0,0,0,0
5,0,0,0,0,0,0,0,0,0,5
18,6,0,0,0,0,0,0,15,6,18
6,15,4,0,8,6,4,0,8,17,6
endlayer

layer
16,16,6,6,6,6,6,6,6,16,16
16,0,0,0,0,6,6,6,17,25,16
6,20,6,6,6,6,6,6,6,20,6
6,6,6,6,6,6,6,26,6,6,6
6,6,6,6,6,6,6,6,6,6,6
6,6,6,6,6,6,6,6,6,6,6
6,6,6,6,6,6,6,6,6,6,6
6,6,6,26,6,6,6,6,6,6,6
6,18,6,6,6,6,6,6,6,18,6
16,24,15,6,6,6,0,0,0,0,16
16,16,6,6,6,6,6,6,6,16,16
endlayer

layer
16,16,6,6,6,6,6,6,6,16,16
16,0,0,0,0,0,0,0,0,0,16
6,0,0,0,0,0,20,20,20,0,6
6,0,0,0,0,0,15,26,17,0,6
0,0,0,0,0,0,15,18,17,0,0
6,0,0,0,0,0,0,0,0,0,0
0,0,15,20,17,0,0,0,0,0,0
6,0,15,26,17,0,0,0,0,0,6
6,0,18,18,18,0,0,0,0,0,6
16,0,0,0,0,0,0,0,0,0,16
16,16,6,6,6,6,6,6,6,16,16
endlayer

layer
16,16,6,6,6,6,6,6,6,16,16
16,0,0,0,0,0,0,0,0,0,16
6,0,0,0,0,0,0,0,0,0,6
6,0,0,0,0,0,0,26,0,0,6
0,0,0,0,0,0,0,0,0,0,0
6,0,0,0,0,0,0,0,0,0,0
0,0,0,0,0,0,0,0,0,0,0
6,0,0,26,0,0,0,0,0,0,6
6,0,0,0,0,0,0,0,0,0,6
16,0,0,0,0,0,0,0,0,0,16
16,16,6,6,6,6,6,6,6,16,16
endlayer

layer
0,8,6,6,6,6,6,6,6,4,0
5,0,0,0,0,0,0,0,0,0,5
6,0,0,0,0,0,0,0,0,0,6
6,0,0,0,0,0,0,26,0,0,6
0,0,0,0,0,0,0,0,0,0,0
6,0,0,0,0,0,0,0,0,0,0
0,0,0,0,0,0,0,0,0,0,0
6,0,0,26,0,0,0,0,0,0,6
6,0,0,0,0,0,0,0,0,0,6
10,0,0,0,0,0,0,0,0,0,10
0,8,6,6,6,6,6,6,6,4,0
endlayer

layer
6,6,6,6,6,6,6,6,6,6,6
6,6,0,0,6,6,6,6,6,6,6
6,0,0,0,6,6,16,16,16,6,6
6,0,0,0,6,6,16,26,16,6,6
6,6,6,6,6,6,16,16,16,6,6
6,6,6,6,6,6,6,6,6,6,6
6,6,16,16,16,6,6,6,6,6,6
6,6,16,26,16,6,6,0,0,0,6
6,6,16,16,16,6,6,0,0,0,6
6,6,6,6,6,6,6,0,0,6,6
6,6,6,6,6,6,6,6,6,6,6
endlayer

layer
15,20,20,20,20,0,0,0,0,0,0
15,6,6,6,17,0,0,0,0,0,0
15,6,0,6,17,0,0,0,0,0,0
15,6,6,6,17,0,0,26,0,0,0
18,18,18,18,17,0,0,0,0,0,0
0,0,0,0,0,0,0,0,0,0,0
0,0,0,0,0,0,15,20,20,20,17
0,0,0,26,0,0,15,6,6,6,17
0,0,0,0,0,0,15,6,0,6,17
0,0,0,0,0,0,15,6,6,6,17
0,0,0,0,0,0,18,18,18,18,17
endlayer

layer
0,0,0,0,0,0,0,0,0,0,0
0,15,20,17,0,0,0,0,0,0,0
0,15,26,17,0,0,0,0,0,0,0
0,15,18,18,0,0,0,26,0,0,0
0,0,0,0,0,0,0,0,0,0,0
0,0,0,0,0,0,0,0,0,0,0
0,0,0,0,0,0,0,0,0,0,0
0,0,0,26,0,0,0,20,20,17,0
0,0,0,0,0,0,0,15,26,17,0
0,0,0,0,0,0,0,15,18,17,0
0,0,0,0,0,0,0,0,0,0,0
endlayer

layer
0,0,0,0,0,0,0,0,0,0,0
0,0,0,0,0,0,0,0,0,0,0
0,0,26,0,0,0,0,0,0,0,0
0,0,0,0,0,0,0,26,0,0,0
0,0,0,0,0,0,0,0,0,0,0
0,0,0,0,0,0,0,0,0,0,0
0,0,0,0,0,0,0,0,0,0,0
0,0,0,26,0,0,0,0,0,0,0
0,0,0,0,0,0,0,0,26,0,0
0,0,0,0,0,0,0,0,0,0,0
0,0,0,0,0,0,0,0,0,0,0
endlayer

layer
0,0,0,0,0,0,0,0,0,0,0
0,0,0,0,0,0,0,0,0,0,0
0,0,26,0,0,0,0,0,0,0,0
0,0,0,0,0,0,0,26,0,0,0
0,0,0,0,0,0,0,0,0,0,0
0,0,0,0,0,0,0,0,0,0,0
0,0,0,0,0,0,0,0,0,0,0
0,0,0,26,0,0,0,0,0,0,0
0,0,0,0,0,0,0,0,26,0,0
0,0,0,0,0,0,0,0,0,0,0
0,0,0,0,0,0,0,0,0,0,0
endlayer

layer
0,0,0,0,0,0,0,0,0,0,0
0,0,0,0,0,0,0,0,0,0,0
0,0,26,0,0,0,0,0,0,0,0
0,0,0,0,0,0,0,26,0,0,0
0,0,0,0,0,0,0,0,0,0,0
0,0,0,0,0,0,0,0,0,0,0
0,0,0,0,0,0,0,0,0,0,0
0,0,0,26,0,0,0,0,0,0,0
0,0,0,0,0,0,0,0,26,0,0
0,0,0,0,0,0,0,0,0,0,0
0,0,0,0,0,0,0,0,0,0,0
endlayer

layer
0,0,0,0,0,0,0,0,0,0,0
0,0,0,0,0,0,0,0,0,0,0
0,0,26,0,0,0,0,0,0,0,0
0,0,0,0,0,0,0,26,0,0,0
0,0,0,0,0,0,0,0,0,0,0
0,0,0,0,0,0,0,0,0,0,0
0,0,0,0,0,0,0,0,0,0,0
0,0,0,26,0,0,0,0,0,0,0
0,0,0,0,0,0,0,0,26,0,0
0,0,0,0,0,0,0,0,0,0,0
0,0,0,0,0,0,0,0,0,0,0
endlayer

layer
0,0,0,0,0,0,0,0,0,0,0
0,0,0,0,0,0,0,0,0,0,0
0,0,26,0,0,0,0,0,0,0,0
0,0,0,0,0,0,0,26,0,0,0
0,0,0,0,0,0,0,0,0,0,0
0,0,0,0,0,0,0,0,0,0,0
0,0,0,0,0,0,0,0,0,0,0
0,0,0,26,0,0,0,0,0,0,0
0,0,0,0,0,0,0,0,26,0,0
0,0,0,0,0,0,0,0,0,0,0
0,0,0,0,0,0,0,0,0,0,0
endlayer

layer
0,0,0,0,0,0,0,0,0,0,0
0,0,0,0,0,0,0,0,0,0,0
0,0,26,0,0,0,0,0,0,0,0
0,0,0,0,0,0,0,26,0,0,0
0,0,0,0,0,0,0,0,0,0,0
0,0,0,0,0,0,0,0,0,0,0
0,0,0,0,0,0,0,0,0,0,0
0,0,0,26,0,0,0,0,0,0,0
0,0,0,0,0,0,0,0,26,0,0
0,0,0,0,0,0,0,0,0,0,0
0,0,0,0,0,0,0,0,0,0,0
endlayer

layer
0,0,0,0,0,0,0,0,0,0,0
0,0,0,0,0,0,0,0,0,0,0
0,0,26,0,0,0,0,0,0,0,0
0,0,0,0,0,0,0,26,0,0,0
0,0,0,0,0,0,0,0,0,0,0
0,0,0,0,0,0,0,0,0,0,0
0,0,0,0,0,0,0,0,0,0,0
0,0,3,26,0,0,0,0,0,0,0
0,0,0,11,0,0,0,0,26,0,0
0,0,0,0,0,0,0,0,0,0,0
0,0,0,0,0,0,0,0,0,0,0
endlayer

layer
0,0,0,0,0,0,0,0,0,0,0
0,0,0,0,0,0,0,0,0,0,0
0,0,26,0,0,0,0,0,0,0,0
0,0,0,0,0,0,0,26,0,0,0
0,0,0,0,0,0,0,0,0,0,0
0,0,0,0,0,0,0,0,0,0,0
0,0,0,0,0,0,0,0,0,0,0
0,0,3,26,2,0,0,0,0,0,0
0,0,0,11,0,0,0,0,26,0,0
0,0,0,0,0,0,0,0,0,0,0
0,0,0,0,0,0,0,0,0,0,0
endlayer

layer
0,0,0,0,0,0,0,0,0,0,0
0,0,0,0,0,0,0,0,0,0,0
0,0,26,0,0,0,0,0,0,0,0
0,0,0,0,0,0,0,26,0,0,0
0,0,0,0,0,0,0,0,0,0,0
0,0,0,0,0,0,0,0,0,0,0
0,0,0,0,0,0,0,0,0,0,0
0,0,0,26,0,0,0,0,0,0,0
0,0,0,0,0,0,0,0,26,0,0
0,0,0,0,0,0,0,0,0,0,0
0,0,0,0,0,0,0,0,0,0,0
endlayer

layer
0,0,0,0,0,0,0,0,0,0,0
0,0,0,0,0,0,0,0,0,0,0
0,0,26,0,0,0,0,0,0,0,0
0,0,0,0,0,0,0,26,0,0,0
0,0,0,0,0,0,0,0,0,0,0
0,0,0,0,0,0,0,0,0,0,0
0,0,0,0,0,0,0,0,0,0,0
0,0,0,26,0,0,0,0,0,0,0
0,0,0,0,0,0,0,0,26,0,0
0,0,0,0,0,0,0,0,0,0,0
0,0,0,0,0,0,0,0,0,0,0
endlayer

layer
0,0,0,0,0,0,0,0,0,0,0
0,0,0,0,0,0,0,0,0,0,0
0,0,26,0,0,0,0,0,0,0,0
0,0,0,0,0,0,0,26,0,0,0
0,0,0,0,0,0,0,0,0,0,0
0,0,0,0,0,0,0,0,0,0,0
0,0,0,0,0,0,0,0,0,0,0
0,0,0,26,0,0,0,0,0,0,0
0,0,0,0,0,0,0,0,26,0,0
0,0,0,0,0,0,0,0,0,0,0
0,0,0,0,0,0,0,0,0,0,0
endlayer

layer
0,0,0,0,0,0,0,0,0,0,0
0,0,0,0,0,0,0,0,0,0,0
0,0,26,0,0,0,0,1,0,0,0
0,0,0,0,0,0,0,26,2,0,0
0,0,0,0,0,0,0,11,0,0,0
0,0,0,0,0,0,0,0,0,0,0
0,0,0,0,0,0,0,0,0,0,0
0,0,0,26,0,0,0,0,0,0,0
0,0,0,0,0,0,0,0,26,0,0
0,0,0,0,0,0,0,0,0,0,0
0,0,0,0,0,0,0,0,0,0,0
endlayer

layer
0,0,0,0,0,0,0,0,0,0,0
0,0,0,0,0,0,0,0,0,0,0
0,0,26,0,0,0,0,0,0,0,0
0,0,0,0,0,0,0,26,0,0,0
0,0,0,0,0,0,0,0,0,0,0
0,0,0,0,0,0,0,0,0,0,0
0,0,0,0,0,0,0,0,0,0,0
0,0,0,26,0,0,0,0,0,0,0
0,0,0,0,0,0,0,0,26,2,0
0,0,0,0,0,0,0,0,11,0,0
0,0,0,0,0,0,0,0,0,0,0
endlayer

layer
0,0,0,0,0,0,0,0,0,0,0
0,0,1,0,0,0,0,0,0,0,0
0,3,26,2,0,0,0,0,0,0,0
0,0,11,0,0,0,0,26,0,0,0
0,0,0,0,0,0,0,0,0,0,0
0,0,0,0,0,0,0,0,0,0,0
0,0,0,0,0,0,0,0,0,0,0
0,0,0,26,0,0,0,0,0,0,0
0,0,0,0,0,0,0,0,26,0,0
0,0,0,0,0,0,0,0,0,0,0
0,0,0,0,0,0,0,0,0,0,0
endlayer

layer
0,0,0,0,0,0,0,0,0,0,0
0,0,0,0,0,0,0,0,0,0,0
0,0,26,0,0,0,0,0,0,0,0
0,0,0,0,0,0,0,26,0,0,0
0,0,0,0,0,0,0,0,0,0,0
0,0,0,0,0,0,0,0,0,0,0
0,0,0,0,0,0,0,0,0,0,0
0,0,0,26,0,0,0,0,0,0,0
0,0,0,0,0,0,0,0,26,0,0
0,0,0,0,0,0,0,0,0,0,0
0,0,0,0,0,0,0,0,0,0,0
endlayer

layer
0,0,0,0,0,0,0,0,0,0,0
0,0,0,0,0,0,0,0,0,0,0
0,0,26,0,0,0,0,0,0,0,0
0,0,0,0,0,0,0,26,0,0,0
0,0,0,0,0,0,0,0,0,0,0
0,0,0,0,0,0,0,0,0,0,0
0,0,0,0,0,0,0,0,0,0,0
0,0,0,26,0,0,0,0,0,0,0
0,0,0,0,0,0,0,0,26,0,0
0,0,0,0,0,0,0,0,0,0,0
0,0,0,0,0,0,0,0,0,0,0
endlayer

layer
0,0,0,0,0,0,0,0,0,0,0
0,0,0,0,0,0,0,0,0,0,0
0,0,26,0,0,0,0,0,0,0,0
0,0,0,0,0,0,0,26,0,0,0
0,0,0,0,0,0,0,0,0,0,0
0,0,0,0,0,0,0,0,0,0,0
0,0,0,0,0,0,0,0,0,0,0
0,0,0,26,0,0,0,0,0,0,0
0,0,0,0,0,0,0,0,26,0,0
0,0,0,0,0,0,0,0,0,0,0
0,0,0,0,0,0,0,0,0,0,0
endlayer

layer
0,0,0,0,0,0,0,0,0,0,0
0,0,0,0,0,0,0,0,0,0,0
0,0,26,0,0,0,0,0,0,0,0
0,0,0,0,0,0,0,26,0,0,0
0,0,0,0,0,0,0,0,0,0,0
0,0,0,0,0,0,0,0,0,0,0
0,0,0,0,0,0,0,0,0,0,0
0,0,0,26,0,0,0,0,0,0,0
0,0,0,0,0,0,0,0,26,0,0
0,0,0,0,0,0,0,0,0,0,0
0,0,0,0,0,0,0,0,0,0,0
endlayer

layer
0,0,0,0,0,0,0,0,0,0,0
0,0,0,0,0,0,0,0,0,0,0
0,0,26,0,0,0,0,0,0,0,0
0,0,0,0,0,0,0,26,0,0,0
0,0,0,0,0,0,0,0,0,0,0
0,0,0,0,0,0,0,0,0,0,0
0,0,0,0,0,0,0,0,0,0,0
0,0,0,26,0,0,0,0,0,0,0
0,0,0,0,0,0,0,0,26,0,0
0,0,0,0,0,0,0,0,0,0,0
0,0,0,0,0,0,0,0,0,0,0
endlayer

layer
0,0,0,0,0,0,0,0,0,0,0
0,0,0,0,0,0,0,0,0,0,0
0,0,26,0,0,0,0,0,0,0,0
0,0,0,0,0,0,0,26,0,0,0
0,0,0,0,0,0,0,0,0,0,0
0,0,0,0,0,0,0,0,0,0,0
0,0,0,0,0,0,0,0,0,0,0
0,0,0,26,0,0,0,0,0,0,0
0,0,0,0,0,0,0,0,26,0,0
0,0,0,0,0,0,0,0,0,0,0
0,0,0,0,0,0,0,0,0,0,0
endlayer

layer
0,0,0,0,0,0,0,0,0,0,0
0,0,0,0,0,0,0,0,0,0,0
0,0,26,0,0,0,0,0,0,0,0
0,0,0,0,0,0,0,26,0,0,0
0,0,0,0,0,0,0,0,0,0,0
0,0,0,0,0,0,0,0,0,0,0
0,0,0,0,0,0,0,0,0,0,0
0,0,0,26,0,0,0,0,0,0,0
0,0,0,0,0,0,0,0,26,0,0
0,0,0,0,0,0,0,0,0,0,0
0,0,0,0,0,0,0,0,0,0,0
endlayer

layer
0,0,0,0,0,0,0,0,0,0,0
0,0,0,0,0,0,0,0,0,0,0
0,0,26,0,0,0,0,0,0,0,0
0,0,0,0,0,0,0,26,0,0,0
0,0,0,0,0,0,0,0,0,0,0
0,0,0,0,0,0,0,0,0,0,0
0,0,0,0,0,0,0,0,0,0,0
0,0,0,26,0,0,0,0,0,0,0
0,0,0,0,0,0,0,0,26,0,0
0,0,0,0,0,0,0,0,0,0,0
0,0,0,0,0,0,0,0,0,0,0
endlayer

layer
0,0,0,0,0,0,0,0,0,0,0
0,0,0,0,0,0,0,0,0,0,0
0,0,26,0,0,0,0,0,0,0,0
0,0,0,0,0,0,0,26,0,0,0
0,0,0,0,0,0,0,0,0,0,0
0,0,0,0,0,0,0,0,0,0,0
0,0,0,0,0,0,0,0,0,0,0
0,0,0,26,0,0,0,0,0,0,0
0,0,0,0,0,0,0,0,26,0,0
0,0,0,0,0,0,0,0,0,0,0
0,0,0,0,0,0,0,0,0,0,0
endlayer

layer
0,0,0,0,0,0,0,0,0,0,0
0,0,0,0,0,0,0,0,0,0,0
0,0,26,0,0,0,0,0,0,0,0
0,0,0,0,0,0,0,26,0,0,0
0,0,0,0,0,0,0,0,0,0,0
0,0,0,0,0,0,0,0,0,0,0
0,0,0,0,0,0,0,0,0,0,0
0,0,0,26,0,0,0,0,0,0,0
0,0,0,0,0,0,0,0,26,0,0
0,0,0,0,0,0,0,0,0,0,0
0,0,0,0,0,0,0,0,0,0,0
endlayer

layer
0,0,0,0,0,0,0,0,0,0,0
0,0,0,0,0,0,0,0,0,0,0
0,0,26,0,0,0,0,0,0,0,0
0,0,0,0,0,0,0,26,0,0,0
0,0,0,0,0,0,0,0,0,0,0
0,0,0,0,0,0,0,0,0,0,0
0,0,0,0,0,0,0,0,0,0,0
0,0,0,26,0,0,0,0,0,0,0
0,0,0,0,0,0,0,0,26,0,0
0,0,0,0,0,0,0,0,0,0,0
0,0,0,0,0,0,0,0,0,0,0
endlayer

layer
0,0,0,0,0,0,0,0,0,0,0
0,0,0,0,0,0,0,0,0,0,0
0,0,26,0,0,0,0,1,0,0,0
0,0,0,0,0,0,0,26,2,0,0
0,0,0,0,0,0,0,0,0,0,0
0,0,0,0,0,0,0,0,0,0,0
0,0,0,0,0,0,0,0,0,0,0
0,0,0,26,0,0,0,0,0,0,0
0,0,0,0,0,0,0,0,26,0,0
0,0,0,0,0,0,0,0,0,0,0
0,0,0,0,0,0,0,0,0,0,0
endlayer

layer
0,0,0,0,0,0,0,0,0,0,0
0,0,1,0,0,0,0,0,0,0,0
0,3,26,2,0,0,0,1,0,0,0
0,0,0,0,0,0,0,26,2,0,0
0,0,0,0,0,0,0,11,0,0,0
0,0,0,0,0,0,0,0,0,0,0
0,0,0,0,0,0,0,0,0,0,0
0,0,0,26,0,0,0,0,0,0,0
0,0,0,0,0,0,0,0,26,2,0
0,0,0,0,0,0,0,0,11,0,0
0,0,0,0,0,0,0,0,0,0,0
endlayer

layer
0,0,0,0,0,0,0,0,0,0,0
0,0,1,0,0,0,0,0,0,0,0
0,3,26,0,0,0,0,0,0,0,0
0,0,0,0,0,0,0,26,2,0,0
0,0,0,0,0,0,0,0,0,0,0
0,0,0,0,0,0,0,0,0,0,0
0,0,0,0,0,0,0,0,0,0,0
0,0,3,26,2,0,0,0,0,0,0
0,0,0,11,0,0,0,0,26,0,0
0,0,0,0,0,0,0,0,0,0,0
0,0,0,0,0,0,0,0,0,0,0
endlayer

layer
0,0,0,0,0,0,0,0,0,0,0
0,0,0,0,0,0,0,0,0,0,0
0,0,26,0,0,0,0,0,0,0,0
0,0,0,0,0,0,0,0,0,0,0
0,0,0,0,0,0,0,0,0,0,0
0,0,0,0,0,0,0,0,0,0,0
0,0,0,0,0,0,0,0,0,0,0
0,0,0,26,0,0,0,0,0,0,0
0,0,0,0,0,0,0,0,0,0,0
0,0,0,0,0,0,0,0,0,0,0
0,0,0,0,0,0,0,0,0,0,0
endlayer

layer
0,0,0,0,0,0,0,0,0,0,0
0,0,0,0,0,0,0,0,0,0,0
0,0,26,0,0,0,0,0,0,0,0
0,0,0,0,0,0,0,0,0,0,0
0,0,0,0,0,0,0,0,0,0,0
0,0,0,0,0,0,0,0,0,0,0
0,0,0,0,0,0,0,0,0,0,0
0,0,0,26,0,0,0,0,0,0,0
0,0,0,0,0,0,0,0,0,0,0
0,0,0,0,0,0,0,0,0,0,0
0,0,0,0,0,0,0,0,0,0,0
endlayer

layer
0,0,0,0,0,0,0,0,0,0,0
0,0,0,0,0,0,0,0,0,0,0
0,0,26,0,0,0,0,0,0,0,0
0,0,0,0,0,0,0,0,0,0,0
0,0,0,0,0,0,0,0,0,0,0
0,0,0,0,0,0,0,0,0,0,0
0,0,0,0,0,0,0,0,0,0,0
0,0,0,0,0,0,0,0,0,0,0
0,0,0,0,0,0,0,0,0,0,0
0,0,0,0,0,0,0,0,0,0,0
0,0,0,0,0,0,0,0,0,0,0
endlayer

layer
0,0,0,0,0,0,0,0,0,0,0
0,0,0,0,0,0,0,0,0,0,0
0,0,26,0,0,0,0,0,0,0,0
0,0,0,0,0,0,0,0,0,0,0
0,0,0,0,0,0,0,0,0,0,0
0,0,0,0,0,0,0,0,0,0,0
0,0,0,0,0,0,0,0,0,0,0
0,0,0,0,0,0,0,0,0,0,0
0,0,0,0,0,0,0,0,0,0,0
0,0,0,0,0,0,0,0,0,0,0
0,0,0,0,0,0,0,0,0,0,0
endlayer

