
# Created by Ruins mod version 14.1 Ingame Parser
# authoring Player: Divineaspect

weight=100
embed_into_distance=5
acceptable_target_blocks=water
dimensions=8,7,7
allowable_overhang=0
max_leveling=2
leveling_buffer=0
preserve_water=0
preserve_lava=0

rule1=0,100,minecraft:leaves-7
rule2=0,100,minecraft:leaves-15
rule3=0,100,minecraft:log-3
rule4=0,100,MobSpawner:fossil.Coelacanth,MobSpawner:fossil.Liopleurodon,MobSpawner:fossil.Nautilus,MobSpawner:primitivemobs.LilyLurker,MobSpawner:primitivemobs.Chameleon
rule5=0,100,minecraft:grass-0
rule6=0,100,minecraft:dirt-0
rule7=0,100,minecraft:vine-1
rule8=0,100,ChestGenHook:strongholdLibrary:5-2,ChestGenHook:dungeonChest:5-2,ChestGenHook:villageBlacksmith:5-2
rule9=0,100,minecraft:vine-2
rule10=0,100,Natura:Rare Sapling-2,fossil:palaeorapheSapling-0,BiomesOPlenty:colorizedSaplings-6,BiomesOPlenty:saplings-7,rule6=0,100,BiomesOPlenty:colorizedSaplings-2,BiomesOPlenty:colorizedSaplings-4,minecraft:sapling-3,Natura:Rare Sapling-4

layer
0,0,0,1,0,0,0
0,1,1,1,1,1,0
0,1,2,2,2,1,0
1,1,1,3,2,1,1
0,1,2,2,2,1,0
0,1,2,2,2,1,0
0,0,0,2,0,0,0
endlayer

layer
0,0,0,0,0,0,0
0,0,0,0,0,0,0
0,0,1,1,1,0,0
0,0,1,1,1,0,0
0,0,1,1,1,0,0
0,0,0,0,0,0,0
0,0,0,0,0,0,0
endlayer

layer
0,0,0,0,0,0,0
0,0,0,0,0,0,0
0,0,1,1,1,0,0
0,0,1,4,1,0,0
0,0,1,1,1,0,0
0,0,0,0,0,0,0
0,0,0,0,0,0,0
endlayer

layer
0,0,0,0,0,0,0
0,0,0,0,0,0,0
0,0,1,1,1,0,0
0,0,1,1,1,0,0
0,0,1,1,1,0,0
0,0,0,0,0,0,0
0,0,0,0,0,0,0
endlayer

layer
0,0,0,0,0,0,0
0,0,1,1,1,0,0
0,1,1,1,1,1,0
0,1,1,3,1,1,0
0,1,1,1,1,1,0
0,0,1,1,1,0,0
0,0,0,0,0,0,0
endlayer

layer
0,0,1,1,1,0,0
0,1,2,1,1,1,0
1,2,1,5,1,1,1
1,1,5,6,5,1,1
1,1,1,5,1,1,1
0,1,1,1,1,1,0
0,0,1,1,1,0,0
endlayer

layer
0,0,0,0,0,0,0
0,0,0,1,0,0,0
0,0,1,8,1,7,0
0,1,1,5,1,0,0
0,0,1,1,1,1,0
0,0,9,1,9,0,0
0,0,0,0,0,0,0
endlayer

layer
0,0,0,0,0,0,0
0,0,0,0,0,0,0
0,0,0,1,0,0,0
0,0,0,10,0,0,0
0,0,1,1,0,0,0
0,0,0,0,0,0,0
0,0,0,0,0,0,0
endlayer

