
# Created by Ruins mod version 13.8 Ingame Parser
# authoring Player: Divineaspect

weight=20
embed_into_distance=1
acceptable_target_blocks=
unacceptable_target_blocks=flowing_water,water,flowing_lava,lava
dimensions=18,15,15
allowable_overhang=2
max_leveling=3
leveling_buffer=0
preserve_water=0
preserve_lava=0

rule1=0,100,minecraft:stonebrick-0
rule2=0,100,minecraft:grass-0
rule3=0,100,minecraft:stone_brick_stairs-3
rule4=0,100,minecraft:lava-0
rule5=0,100,chisel:chisel.cobblestone-9
rule6=0,100,minecraft:water-0
rule7=0,100,minecraft:stonebrick-3
rule8=0,100,ChestGenHook:dungeonChest:5-5
rule9=0,100,StevesWorkshop:production_table-1
rule10=0,100,BiblioCraft:BiblioWorkbench-0
rule11=0,100,minecraft:furnace-2
rule12=0,100,minecraft:stone_brick_stairs-0
rule13=0,100,TConstruct:FurnaceSlab-8
rule14=2,100,WallSign:Contraband:null:null:null-4
rule15=0,100,ChestGenHook:dungeonChest:5-4
rule16=0,100,IInventory;IronChest:BlockIronChest;RandomThings:spectreKey#1#0#0+Thaumcraft:blockCustomPlant#1#1#14+Thaumcraft:blockCustomPlant#1#2#20+Thaumcraft:blockCustomPlant#1#2#21+Thaumcraft:blockCustomPlant#1#2#22+Thaumcraft:blockCustomPlant#1#2#27+Thaumcraft:blockCustomPlant#1#2#29+Thaumcraft:blockCustomPlant#1#2#30+Thaumcraft:blockCustomPlant#1#2#34+Thaumcraft:blockCustomPlant#1#2#38+Thaumcraft:blockCustomPlant#1#2#46+Thaumcraft:blockCustomPlant#1#2#50+Thaumcraft:ItemResource#1#1#53+Thaumcraft:blockCustomPlant#1#0#56+Thaumcraft:blockCustomPlant#1#2#58+Thaumcraft:blockCustomPlant#1#0#66+Thaumcraft:blockCustomPlant#1#0#67+Thaumcraft:blockCustomPlant#1#2#70+Thaumcraft:blockCustomPlant#1#2#73+Thaumcraft:blockCustomPlant#1#2#74+Thaumcraft:blockCustomPlant#1#0#76+Thaumcraft:blockCustomPlant#1#0#77+Thaumcraft:blockCustomPlant#1#2#81+Thaumcraft:blockCustomPlant#1#2#85+Thaumcraft:blockCustomPlant#1#2#86+Thaumcraft:blockCustomPlant#1#2#87+Thaumcraft:blockCustomPlant#1#2#88+Thaumcraft:blockCustomPlant#1#2#91+Thaumcraft:blockCustomPlant#1#2#92+Thaumcraft:blockCustomPlant#1#2#101+Thaumcraft:blockCustomPlant#1#2#102+Thaumcraft:blockCustomPlant#1#2#103-6
rule17=0,100,minecraft:hopper-2
rule18=0,100,minecraft:anvil-7
rule19=0,100,minecraft:stone_brick_stairs-6
rule20=0,100,minecraft:stone_brick_stairs-1
rule21=2,100,WallSign:And Purify:Your Spirits:Together:null-2
rule22=0,100,ChestGenHook:dungeonChest:5-2
rule23=0,100,chisel:chisel.blockRedstone-7
rule24=2,100,WallSign:Leave:Tools of Sin:Behind:null-2
rule25=0,100,minecraft:cobblestone_wall-0
rule26=0,100,minecraft:stone_brick_stairs-5
rule27=0,100,TConstruct:FurnaceSlab-0
rule28=0,100,minecraft:stone_brick_stairs-2
rule29=0,100,minecraft:stone_brick_stairs-4
rule30=0,100,minecraft:obsidian-0
rule31=0,100,chisel:chisel.fenceIron-7
rule32=0,100,chisel:chisel.blockCarpetFloor-1
rule33=0,100,minecraft:stone_slab-13
rule34=0,100,BiblioCraft:BiblioIronLantern-0
rule35=0,100,minecraft:planks-1
rule36=0,100,MobSpawner:witchery.witchhunter
rule37=0,100,minecraft:spruce_stairs-1
rule38=0,100,BiblioCraft:BiblioSeats-2
rule39=0,100,TConstruct:decoration.stoneladder-5
rule40=0,100,witchery:altar-0
rule41=0,100,minecraft:double_stone_slab-5
rule42=0,100,Thaumcraft:blockCosmeticOpaque-0
rule43=0,100,minecraft:stone_brick_stairs-7
rule44=0,100,minecraft:stone_slab-5
rule45=0,100,BiblioCraft:BiblioLantern-0
rule46=0,100,minecraft:spruce_stairs-5
rule47=0,100,minecraft:wooden_slab-9
rule48=0,100,minecraft:spruce_stairs-4
rule49=0,100,minecraft:log-9
rule50=0,100,minecraft:fence-0
rule51=0,100,minecraft:bed-9
rule52=0,100,minecraft:bed-1
rule53=0,100,BiblioCraft:BiblioDesk-1
rule54=0,100,minecraft:bed-3
rule55=0,100,minecraft:bed-11
rule56=0,100,minecraft:spruce_stairs-0

layer
1,1,1,1,1,1,1,1,1,1,1,2,1,1,1
1,1,1,1,1,1,1,1,1,1,1,1,1,1,1
1,1,4,3,1,1,1,1,1,1,1,1,1,1,1
1,1,1,1,1,1,1,1,1,1,1,1,1,1,1
1,1,1,1,1,1,1,1,1,1,1,1,1,1,1
1,1,1,1,1,1,1,1,1,1,1,1,1,1,1
1,1,1,1,1,1,1,1,1,1,1,1,1,1,1
1,1,1,1,1,1,1,1,1,1,1,1,1,1,1
2,1,1,1,1,1,1,1,1,1,1,1,1,1,1
2,1,1,1,1,1,1,1,1,5,5,5,5,5,5
1,1,1,1,1,1,1,1,1,5,1,1,1,1,1
1,1,1,1,1,1,1,1,1,5,1,2,2,2,2
1,1,1,1,1,1,1,5,5,5,5,2,6,6,2
1,1,1,1,1,1,1,1,1,1,1,2,6,6,2
1,1,1,1,1,1,1,1,1,1,1,2,2,2,2
endlayer

layer
1,1,1,1,1,1,1,1,1,1,1,0,1,1,7
1,12,11,0,10,0,9,8,9,0,1,1,1,8,1
1,4,13,0,0,0,0,0,0,0,0,0,0,3,1
1,1,11,0,0,0,0,0,0,1,0,0,0,0,1
1,0,0,0,0,0,0,0,0,1,0,0,0,0,1
1,0,0,0,0,0,14,0,0,0,0,0,0,3,1
1,0,18,0,0,17,16,15,15,0,1,1,1,15,1
1,1,19,1,12,1,1,1,1,1,1,0,1,1,7
0,1,15,2,2,1,1,0,0,0,0,0,0,0,0
0,1,20,2,2,1,0,0,0,0,0,0,0,0,0
1,1,0,1,1,1,1,0,1,0,0,0,0,0,0
1,22,21,0,0,0,1,0,0,0,0,0,0,0,0
1,23,0,0,0,0,0,0,0,0,0,0,0,0,0
1,22,24,0,0,0,1,0,0,0,0,0,0,0,0
1,1,1,1,1,1,1,0,1,0,0,0,0,0,0
endlayer

layer
25,1,1,1,1,1,1,1,1,1,25,0,25,1,25
1,0,27,0,0,0,0,0,0,0,1,1,1,26,1
26,28,27,0,0,0,0,0,0,0,0,0,0,0,3
20,0,27,0,0,0,0,0,0,20,0,0,0,0,1
12,0,0,0,0,0,0,0,0,12,0,0,0,0,1
29,0,0,0,0,0,0,0,0,0,0,0,0,0,3
1,0,0,0,0,0,30,15,15,0,1,1,1,29,1
25,1,1,1,0,1,1,1,1,1,25,0,25,1,25
0,25,20,0,0,1,25,0,0,0,0,0,0,0,0
0,25,0,0,0,25,0,0,0,0,0,0,0,0,0
25,1,0,1,31,1,25,0,25,0,0,0,0,0,0
1,0,0,0,0,0,1,0,0,0,0,0,0,0,0
31,32,0,0,0,0,0,0,0,0,0,0,0,0,0
1,0,0,0,0,0,1,0,0,0,0,0,0,0,0
25,1,31,1,31,1,25,0,25,0,0,0,0,0,0
endlayer

layer
25,1,1,1,1,1,1,1,1,1,25,0,25,1,25
1,19,0,0,0,0,0,0,0,0,1,1,1,1,1
1,19,0,0,0,0,0,0,0,0,0,0,0,0,0
1,19,0,0,0,0,0,0,0,26,0,0,0,0,1
1,19,0,0,0,0,0,0,0,29,0,0,0,0,1
1,19,0,0,0,0,0,0,0,0,0,0,0,0,0
1,19,0,0,0,0,0,0,0,0,1,1,1,1,1
25,1,20,1,0,1,1,1,1,1,25,0,25,1,25
0,25,0,0,0,1,25,0,0,0,0,0,0,0,0
0,25,0,0,0,25,0,0,0,0,0,0,0,0,0
25,1,0,1,31,1,25,0,25,0,0,0,0,0,0
1,0,0,0,0,0,1,0,0,0,0,0,0,0,0
31,0,0,0,0,0,33,0,0,0,0,0,0,0,0
1,0,0,0,0,0,1,34,0,0,0,0,0,0,0
25,1,31,1,31,1,25,0,25,0,0,0,0,0,0
endlayer

layer
25,1,1,1,1,1,1,1,1,1,25,0,25,1,25
1,35,35,35,35,35,35,35,35,35,1,1,1,1,1
1,35,35,35,35,35,35,35,35,35,35,1,33,0,33
1,35,35,35,35,35,35,35,35,35,35,1,33,0,1
1,35,35,35,35,35,35,35,35,36,35,1,33,0,1
1,35,35,35,35,35,35,35,35,35,35,1,33,0,33
1,35,37,35,35,35,35,35,35,35,1,1,1,1,1
25,1,0,1,1,1,1,1,1,1,25,0,25,1,25
0,1,0,0,0,1,1,19,0,0,0,0,0,0,0
0,1,0,0,0,1,19,0,0,0,0,0,0,0,0
1,1,1,1,1,1,1,29,29,0,0,0,0,0,0
1,26,26,26,26,26,1,1,19,0,0,0,0,0,0
1,33,33,33,33,33,1,1,19,0,0,0,0,0,0
1,29,29,29,29,29,1,1,19,0,0,0,0,0,0
1,1,1,1,1,1,1,26,26,0,0,0,0,0,0
endlayer

layer
25,1,1,1,1,1,1,1,1,1,25,0,25,1,25
1,0,39,38,0,38,0,38,0,0,1,1,1,1,1
1,0,0,38,0,38,0,38,0,0,0,1,20,1,1
1,0,0,0,0,0,0,0,0,40,0,0,0,1,1
1,0,0,0,0,0,0,0,0,40,0,0,0,1,1
1,0,0,38,0,38,0,38,0,0,0,1,12,1,1
1,0,0,38,0,38,0,38,0,0,1,1,1,1,1
25,1,0,1,41,1,0,1,1,1,25,0,25,1,25
0,25,0,0,0,25,0,25,0,0,0,0,0,0,0
0,25,0,0,0,25,0,25,0,0,0,0,0,0,0
25,25,25,25,25,25,0,25,25,0,0,0,0,0,0
25,0,0,0,0,0,0,0,25,0,0,0,0,0,0
25,0,0,0,0,0,0,0,25,0,0,0,0,0,0
25,0,0,0,0,0,0,0,25,0,0,0,0,0,0
25,25,25,25,25,25,25,25,25,0,0,0,0,0,0
endlayer

layer
7,1,1,1,1,1,1,1,1,1,7,0,7,1,25
20,0,39,0,0,0,0,0,0,0,0,1,20,1,1
12,0,0,0,0,0,0,0,0,0,0,20,0,42,20
1,0,0,0,0,0,0,0,0,32,0,0,0,42,0
1,0,0,0,0,0,0,0,0,32,0,0,0,42,0
20,0,0,0,0,0,0,0,0,0,0,12,0,42,12
12,0,0,0,0,0,0,0,0,0,0,1,12,1,1
7,1,0,1,0,1,0,1,1,1,7,0,7,1,25
0,0,0,0,0,0,0,0,0,0,0,0,0,0,0
0,0,0,0,0,0,0,0,0,0,0,0,0,0,0
34,0,0,0,0,0,0,0,34,0,0,0,0,0,0
0,0,0,0,0,0,0,0,0,0,0,0,0,0,0
0,0,0,0,0,0,0,0,0,0,0,0,0,0,0
0,0,0,0,0,0,0,0,0,0,0,0,0,0,0
34,0,0,0,0,0,0,0,34,0,0,0,0,0,0
endlayer

layer
1,1,1,1,1,1,1,1,1,1,1,1,20,1,7
0,0,39,0,0,0,0,0,0,0,0,1,0,1,1
0,0,0,0,0,0,0,0,0,0,0,0,0,42,0
1,0,0,0,0,0,0,0,0,0,0,0,0,42,0
1,0,0,0,0,0,0,0,0,0,0,0,0,42,0
0,0,0,0,0,0,0,0,0,0,0,0,0,42,0
0,0,0,0,0,0,0,0,0,0,0,1,0,1,1
1,1,1,1,1,1,1,1,1,1,1,1,12,1,7
0,3,33,0,34,0,33,28,0,0,0,0,0,0,0
0,0,0,0,0,0,0,0,0,0,0,0,0,0,0
0,0,0,0,0,0,0,0,0,0,0,0,0,0,0
0,0,0,0,0,0,0,0,0,0,0,0,0,0,0
0,0,0,0,0,0,0,0,0,0,0,0,0,0,0
0,0,0,0,0,0,0,0,0,0,0,0,0,0,0
0,0,0,0,0,0,0,0,0,0,0,0,0,0,0
endlayer

layer
1,1,1,1,1,1,1,19,0,43,1,1,0,0,31
0,0,39,0,0,0,0,0,0,0,0,1,0,1,1
0,0,0,0,0,0,0,0,0,0,0,0,0,42,0
1,0,0,0,0,0,0,0,0,0,0,0,0,42,0
1,0,0,0,0,0,0,0,0,0,0,0,0,42,0
0,0,0,0,0,0,0,0,0,0,0,0,0,42,0
0,0,0,0,0,0,0,0,0,0,0,1,0,1,1
1,1,1,1,1,1,1,19,0,43,1,1,0,0,31
0,0,44,44,44,44,44,0,0,0,0,31,31,31,31
0,0,0,0,0,0,0,0,0,0,0,0,0,0,0
0,0,0,0,0,0,0,0,0,0,0,0,0,0,0
0,0,0,0,0,0,0,0,0,0,0,0,0,0,0
0,0,0,0,0,0,0,0,0,0,0,0,0,0,0
0,0,0,0,0,0,0,0,0,0,0,0,0,0,0
0,0,0,0,0,0,0,0,0,0,0,0,0,0,0
endlayer

layer
1,1,1,1,1,1,1,1,1,1,1,1,0,0,0
26,46,39,46,46,46,45,0,0,0,45,1,0,12,12
29,47,47,47,47,47,0,0,0,0,0,26,0,42,26
1,47,47,47,47,47,0,0,0,0,0,0,0,42,0
1,47,47,47,47,47,0,0,0,0,0,0,0,42,0
26,47,47,47,47,47,0,0,0,0,0,29,0,42,29
29,48,48,48,48,48,45,0,0,0,45,1,0,20,20
1,1,1,1,1,1,1,1,1,1,1,1,0,0,0
0,0,0,0,0,0,0,0,0,0,0,0,0,0,0
0,0,0,0,0,0,0,0,0,0,0,0,0,0,0
0,0,0,0,0,0,0,0,0,0,0,0,0,0,0
0,0,0,0,0,0,0,0,0,0,0,0,0,0,0
0,0,0,0,0,0,0,0,0,0,0,0,0,0,0
0,0,0,0,0,0,0,0,0,0,0,0,0,0,0
0,0,0,0,0,0,0,0,0,0,0,0,0,0,0
endlayer

layer
49,49,49,49,49,49,49,49,49,49,49,49,49,0,0
1,8,0,51,8,51,50,0,0,0,0,1,0,0,0
1,53,0,52,0,52,50,0,0,0,0,1,12,12,12
1,0,0,0,0,0,50,0,0,0,0,1,0,0,1
1,0,0,0,0,0,50,0,0,0,0,1,0,0,1
1,53,0,54,0,54,50,0,0,0,0,1,20,20,20
1,0,15,55,15,55,50,0,0,0,0,1,0,0,0
49,49,49,49,49,49,49,49,49,49,49,49,49,0,0
37,37,37,37,37,37,37,37,37,37,37,37,37,0,0
0,0,0,0,0,0,0,0,0,0,0,0,0,0,0
0,0,0,0,0,0,0,0,0,0,0,0,0,0,0
0,0,0,0,0,0,0,0,0,0,0,0,0,0,0
0,0,0,0,0,0,0,0,0,0,0,0,0,0,0
0,0,0,0,0,0,0,0,0,0,0,0,0,0,0
0,0,0,0,0,0,0,0,0,0,0,0,0,0,0
endlayer

layer
56,56,56,56,56,56,56,56,56,56,56,56,56,0,0
1,19,0,0,0,0,0,0,0,0,43,1,19,0,0
1,0,0,0,0,0,0,0,0,0,0,1,0,0,0
20,0,0,0,0,0,0,0,0,0,0,1,12,44,0
12,0,0,0,0,0,0,0,0,0,0,1,20,44,0
1,0,0,0,0,0,0,0,0,0,0,1,0,0,0
1,19,0,0,0,0,0,0,0,0,43,1,19,0,0
37,37,37,37,37,37,37,37,37,37,37,37,37,0,0
0,0,0,0,0,0,0,0,0,0,0,0,0,0,0
0,0,0,0,0,0,0,0,0,0,0,0,0,0,0
0,0,0,0,0,0,0,0,0,0,0,0,0,0,0
0,0,0,0,0,0,0,0,0,0,0,0,0,0,0
0,0,0,0,0,0,0,0,0,0,0,0,0,0,0
0,0,0,0,0,0,0,0,0,0,0,0,0,0,0
0,0,0,0,0,0,0,0,0,0,0,0,0,0,0
endlayer

layer
56,56,56,56,56,56,56,56,56,56,56,56,56,0,0
49,49,49,49,49,49,49,49,49,49,49,49,49,0,0
1,0,0,0,0,0,0,0,0,0,0,1,0,0,0
26,0,0,0,0,0,0,0,0,0,0,20,0,0,0
29,0,0,0,0,0,0,0,0,0,0,12,0,0,0
1,0,0,0,0,0,0,0,0,0,0,1,0,0,0
49,49,49,49,49,49,49,49,49,49,49,49,49,0,0
37,37,37,37,37,37,37,37,37,37,37,37,37,0,0
0,0,0,0,0,0,0,0,0,0,0,0,0,0,0
0,0,0,0,0,0,0,0,0,0,0,0,0,0,0
0,0,0,0,0,0,0,0,0,0,0,0,0,0,0
0,0,0,0,0,0,0,0,0,0,0,0,0,0,0
0,0,0,0,0,0,0,0,0,0,0,0,0,0,0
0,0,0,0,0,0,0,0,0,0,0,0,0,0,0
0,0,0,0,0,0,0,0,0,0,0,0,0,0,0
endlayer

layer
0,0,0,0,0,0,0,0,0,0,0,0,0,0,0
56,56,56,56,56,56,56,56,56,56,56,56,56,0,0
1,19,0,0,0,0,0,0,0,0,43,1,19,0,0
1,0,0,0,0,0,0,0,0,0,0,26,0,0,0
1,0,0,0,0,0,0,0,0,0,0,29,0,0,0
1,19,0,0,0,0,0,0,0,0,43,1,19,0,0
37,37,37,37,37,37,37,37,37,37,37,37,37,0,0
0,0,0,0,0,0,0,0,0,0,0,0,0,0,0
0,0,0,0,0,0,0,0,0,0,0,0,0,0,0
0,0,0,0,0,0,0,0,0,0,0,0,0,0,0
0,0,0,0,0,0,0,0,0,0,0,0,0,0,0
0,0,0,0,0,0,0,0,0,0,0,0,0,0,0
0,0,0,0,0,0,0,0,0,0,0,0,0,0,0
0,0,0,0,0,0,0,0,0,0,0,0,0,0,0
0,0,0,0,0,0,0,0,0,0,0,0,0,0,0
endlayer

layer
0,0,0,0,0,0,0,0,0,0,0,0,0,0,0
56,56,56,56,56,56,56,56,56,56,56,56,56,0,0
49,49,49,49,49,49,49,49,49,49,49,49,49,0,0
1,0,0,0,0,0,0,0,0,0,0,1,0,0,0
1,0,0,0,0,0,0,0,0,0,0,1,0,0,0
49,49,49,49,49,49,49,49,49,49,49,49,49,0,0
37,37,37,37,37,37,37,37,37,37,37,37,37,0,0
0,0,0,0,0,0,0,0,0,0,0,0,0,0,0
0,0,0,0,0,0,0,0,0,0,0,0,0,0,0
0,0,0,0,0,0,0,0,0,0,0,0,0,0,0
0,0,0,0,0,0,0,0,0,0,0,0,0,0,0
0,0,0,0,0,0,0,0,0,0,0,0,0,0,0
0,0,0,0,0,0,0,0,0,0,0,0,0,0,0
0,0,0,0,0,0,0,0,0,0,0,0,0,0,0
0,0,0,0,0,0,0,0,0,0,0,0,0,0,0
endlayer

layer
0,0,0,0,0,0,0,0,0,0,0,0,0,0,0
0,0,0,0,0,0,0,0,0,0,0,0,0,0,0
56,56,56,56,56,56,56,56,56,56,56,56,56,0,0
1,19,0,0,0,0,0,0,0,0,43,1,19,0,0
1,19,0,0,0,0,0,0,0,0,43,1,19,0,0
37,37,37,37,37,37,37,37,37,37,37,37,37,0,0
0,0,0,0,0,0,0,0,0,0,0,0,0,0,0
0,0,0,0,0,0,0,0,0,0,0,0,0,0,0
0,0,0,0,0,0,0,0,0,0,0,0,0,0,0
0,0,0,0,0,0,0,0,0,0,0,0,0,0,0
0,0,0,0,0,0,0,0,0,0,0,0,0,0,0
0,0,0,0,0,0,0,0,0,0,0,0,0,0,0
0,0,0,0,0,0,0,0,0,0,0,0,0,0,0
0,0,0,0,0,0,0,0,0,0,0,0,0,0,0
0,0,0,0,0,0,0,0,0,0,0,0,0,0,0
endlayer

layer
0,0,0,0,0,0,0,0,0,0,0,0,0,0,0
0,0,0,0,0,0,0,0,0,0,0,0,0,0,0
56,56,56,56,56,56,56,56,56,56,56,56,56,0,0
49,49,49,49,49,49,49,49,49,49,49,49,49,0,0
49,49,49,49,49,49,49,49,49,49,49,49,49,0,0
37,37,37,37,37,37,37,37,37,37,37,37,37,0,0
0,0,0,0,0,0,0,0,0,0,0,0,0,0,0
0,0,0,0,0,0,0,0,0,0,0,0,0,0,0
0,0,0,0,0,0,0,0,0,0,0,0,0,0,0
0,0,0,0,0,0,0,0,0,0,0,0,0,0,0
0,0,0,0,0,0,0,0,0,0,0,0,0,0,0
0,0,0,0,0,0,0,0,0,0,0,0,0,0,0
0,0,0,0,0,0,0,0,0,0,0,0,0,0,0
0,0,0,0,0,0,0,0,0,0,0,0,0,0,0
0,0,0,0,0,0,0,0,0,0,0,0,0,0,0
endlayer

layer
0,0,0,0,0,0,0,0,0,0,0,0,0,0,0
0,0,0,0,0,0,0,0,0,0,0,0,0,0,0
0,0,0,0,0,0,0,0,0,0,0,0,0,0,0
56,56,56,56,56,56,56,56,56,56,56,56,56,0,0
37,37,37,37,37,37,37,37,37,37,37,37,37,0,0
0,0,0,0,0,0,0,0,0,0,0,0,0,0,0
0,0,0,0,0,0,0,0,0,0,0,0,0,0,0
0,0,0,0,0,0,0,0,0,0,0,0,0,0,0
0,0,0,0,0,0,0,0,0,0,0,0,0,0,0
0,0,0,0,0,0,0,0,0,0,0,0,0,0,0
0,0,0,0,0,0,0,0,0,0,0,0,0,0,0
0,0,0,0,0,0,0,0,0,0,0,0,0,0,0
0,0,0,0,0,0,0,0,0,0,0,0,0,0,0
0,0,0,0,0,0,0,0,0,0,0,0,0,0,0
0,0,0,0,0,0,0,0,0,0,0,0,0,0,0
endlayer

