
# Created by Ruins mod version 14.1 Ingame Parser
# authoring Player: Divineaspect

weight=100
embed_into_distance=0
acceptable_target_blocks=
unacceptable_target_blocks=flowing_water,water,flowing_lava,lava
dimensions=5,7,7
allowable_overhang=0
max_leveling=2
leveling_buffer=0
preserve_water=0
preserve_lava=0

rule1=0,100,minecraft:stonebrick-0
rule2=0,100,minecraft:stone_slab-5
rule3=0,100,minecraft:stone_brick_stairs-0
rule4=0,100,minecraft:stone_brick_stairs-3
rule5=0,100,minecraft:stone_brick_stairs-2
rule6=0,100,minecraft:stone_brick_stairs-1
rule7=0,100,minecraft:stonebrick-3
rule8=0,100,erebus:gaeanKeystone-0

layer
1,2,2,2,2,2,1
2,4,3,3,3,3,2
2,4,0,0,0,5,2
2,4,0,0,0,5,2
2,4,0,0,0,5,2
2,4,6,6,6,5,2
1,2,2,2,2,2,1
endlayer

layer
1,0,0,0,0,0,1
0,0,0,0,0,0,0
0,0,1,3,1,0,0
0,0,4,7,5,0,0
0,0,1,6,1,0,0
0,0,0,0,0,0,0
1,0,0,0,0,0,1
endlayer

layer
1,0,0,0,0,0,1
0,0,0,0,0,0,0
0,0,1,0,1,0,0
0,0,0,0,0,0,0
0,0,1,0,1,0,0
0,0,0,0,0,0,0
1,0,0,0,0,0,1
endlayer

layer
1,0,0,0,0,0,1
0,0,0,0,0,0,0
0,0,1,0,1,0,0
0,0,0,0,0,0,0
0,0,1,0,1,0,0
0,0,0,0,0,0,0
1,0,0,0,0,0,1
endlayer

layer
7,0,0,0,0,0,7
0,0,0,0,0,0,0
0,0,2,2,2,0,0
0,0,2,8,2,0,0
0,0,2,2,2,0,0
0,0,0,0,0,0,0
7,0,0,0,0,0,7
endlayer

