
# Created by Ruins mod version 14.1 Ingame Parser
# authoring Player: Divineaspect

weight=1000
embed_into_distance=60
acceptable_target_blocks=
unacceptable_target_blocks=
dimensions=69,17,38
allowable_overhang=5
max_leveling=5
leveling_buffer=0
preserve_water=0
preserve_lava=0
uniqueMinDistance=1000

rule1=0,100,minecraft:stonebrick-0
rule2=0,100,minecraft:redstone_ore-0
rule3=0,100,minecraft:double_stone_slab-0
rule4=0,100,minecraft:lava-8
rule5=0,100,minecraft:lit_redstone_ore-0
rule6=0,100,preserveBlock
rule7=0,100,ChestGenHook:dungeonChest:5-2,Minecraft:obsidian-0,redstone_block-0
rule8=0,100,minecraft:stone_slab-13
rule9=0,100,minecraft:stone_slab-5
rule10=0,100,minecraft:stone_slab-8
rule11=0,100,minecraft:stone_slab-0
rule12=0,100,minecraft:stone_brick_stairs-0
rule13=0,100,minecraft:stone_brick_stairs-2
rule14=0,80,minecraft:lava-0
rule15=0,100,minecraft:stone_brick_stairs-3
rule16=0,80,ChestGenHook:dungeonChest:5-3
rule17=0,100,minecraft:stone_brick_stairs-1
rule18=0,100,minecraft:iron_bars-0
rule19=0,100,minecraft:end_portal_frame-3
rule20=0,100,minecraft:stone_brick_stairs-7
rule21=0,100,minecraft:stone_brick_stairs-6
rule22=0,100,minecraft:stone_brick_stairs-5
rule23=0,100,minecraft:stone_brick_stairs-4
rule24=0,100,minecraft:redstone_block-0
rule25=0,100,ChestGenHook:dungeonChest:5-4
rule26=0,80,MobSpawner:Enderman
rule27=0,100,ChestGenHook:dungeonChest:5-5,minecraft:obsidian-0,minecraft:iron_bars-0 
rule28=0,100,minecraft:obsidian-0
rule29=0,100,minecraft:double_stone_slab-5
rule30=0,100,IInventory;minecraft:dispenser;minecraft:water_bucket#1#0#0-0
rule31=0,100,minecraft:wooden_pressure_plate-0

layer
1,1,1,1,1,1,1,1,2,1,1,1,1,1,1,1,1,1,3,1,1,1,1,1,2,1,1,1,1,1,1,1,1,1,1,1,1,1
1,1,1,1,1,1,1,1,2,1,1,1,1,1,1,1,1,1,3,1,1,4,1,1,2,1,1,1,1,1,1,1,1,1,1,1,1,1
1,1,4,1,1,1,1,1,2,1,1,1,1,1,4,1,1,1,3,1,1,1,1,1,2,1,1,1,1,1,1,1,1,1,1,1,1,1
1,1,1,1,1,1,1,3,3,3,1,1,1,1,1,1,1,1,3,1,1,1,1,1,2,3,1,1,1,1,1,1,1,1,5,2,2,2
1,1,1,1,1,1,3,1,1,1,3,1,1,1,1,1,1,1,3,1,1,1,1,1,2,1,1,1,1,1,1,1,1,1,2,1,1,1
3,3,2,2,2,2,3,1,1,1,3,2,2,2,2,3,3,3,3,1,1,1,1,1,2,1,1,1,1,1,1,1,1,1,2,1,1,1
1,1,1,1,1,1,3,1,1,1,3,1,1,1,1,1,1,1,3,1,1,1,1,1,2,1,1,1,1,1,1,1,1,1,2,1,1,1
1,1,1,1,1,1,1,3,3,3,1,1,1,1,1,1,1,1,3,1,1,1,1,1,2,1,1,1,2,2,2,1,1,1,2,1,1,1
1,1,4,1,1,1,1,1,1,1,1,1,1,1,4,1,1,1,3,1,1,1,1,1,2,2,2,2,2,0,2,2,2,2,2,1,1,1
1,1,1,1,1,1,1,1,1,1,1,1,1,1,1,1,1,1,3,1,1,1,1,1,2,1,1,1,2,2,2,1,1,1,2,1,1,1
1,1,1,1,1,1,1,1,2,1,1,1,1,1,1,1,1,1,3,1,1,1,1,1,2,1,1,1,1,1,1,1,1,1,2,1,1,1
1,1,1,1,1,4,1,1,5,1,1,4,1,1,1,1,1,1,3,1,1,1,1,1,2,1,1,1,1,1,1,1,1,1,2,1,1,1
1,1,1,1,1,1,1,1,2,1,1,1,1,1,1,1,1,1,3,1,1,1,1,1,2,1,1,1,1,1,1,1,1,1,2,1,1,1
1,1,1,1,1,1,1,1,5,1,1,1,1,1,1,1,1,1,3,3,3,3,2,2,2,1,1,1,1,1,1,1,1,3,2,1,1,1
1,1,1,1,1,1,1,1,3,1,1,1,1,1,1,1,1,1,3,1,1,1,1,1,1,1,1,1,1,1,1,1,1,1,2,1,1,1
1,1,1,1,1,4,1,1,3,1,1,4,1,1,1,1,1,1,3,1,1,1,1,1,1,1,1,1,1,1,1,1,1,1,2,1,1,1
1,1,1,1,1,1,1,1,3,1,1,1,1,1,1,1,1,1,3,1,1,1,1,1,1,1,1,1,1,1,1,1,1,1,2,1,1,1
endlayer

layer
1,1,1,1,1,1,1,0,0,0,1,1,1,1,1,1,1,0,0,0,1,1,1,0,0,0,1,1,1,1,1,1,6,6,6,1,4,1
1,0,0,1,0,0,0,0,0,0,0,0,0,1,0,0,1,0,0,0,1,4,1,0,0,0,1,1,1,1,1,1,1,1,1,1,1,1
1,0,4,1,0,0,0,0,0,0,0,0,0,1,4,0,1,0,0,0,1,1,1,0,0,0,9,8,0,0,7,0,0,0,0,0,0,0
1,1,1,1,0,0,1,12,12,12,1,0,0,1,1,1,1,0,0,0,1,6,1,0,0,0,11,3,10,0,0,0,0,0,0,0,0,0
0,0,0,0,0,0,15,14,14,14,13,0,0,0,0,0,0,0,0,0,1,6,1,0,0,0,9,8,0,0,7,0,0,0,0,0,0,0
0,0,0,0,0,0,15,14,14,14,13,0,0,0,0,0,0,0,0,0,1,6,1,0,0,0,1,1,1,1,1,1,1,0,0,0,1,1
0,0,0,0,0,0,15,14,14,14,13,0,0,0,0,0,0,0,0,0,1,6,1,0,0,0,1,7,13,0,15,16,1,0,0,0,1,1
1,1,1,1,0,0,1,17,1,17,1,0,0,1,1,1,1,0,0,0,1,6,1,0,0,0,0,0,0,0,0,0,0,0,0,0,1,6
1,0,4,1,0,0,0,0,1,0,0,0,0,1,4,0,1,0,0,0,1,6,1,0,0,0,0,0,0,0,0,0,0,0,0,0,1,6
1,0,0,1,0,0,0,0,17,0,0,0,0,1,0,0,1,0,0,0,1,6,1,0,0,0,0,0,0,0,0,0,0,0,0,0,1,6
1,0,0,0,1,1,1,0,0,0,1,1,1,1,0,0,1,0,0,0,1,1,1,0,0,0,1,7,13,0,15,16,1,0,0,0,1,6
1,0,0,0,0,4,1,0,0,0,1,4,0,0,0,0,1,0,0,0,1,1,1,0,0,0,1,1,1,1,1,1,1,0,0,0,1,6
1,0,0,0,0,0,1,0,0,0,1,0,0,0,0,0,1,0,0,0,0,0,0,0,0,0,0,0,16,0,0,8,9,0,0,0,1,6
1,0,0,0,0,0,1,0,0,0,1,0,0,0,0,0,1,0,0,0,0,0,0,0,0,0,0,0,0,0,10,3,11,0,0,0,1,6
1,0,0,0,0,0,1,0,0,0,1,0,0,0,0,0,1,0,0,0,0,0,0,0,0,0,0,0,16,0,0,8,9,0,0,0,1,1
1,0,0,0,0,4,1,0,0,0,1,4,0,0,0,0,1,0,0,0,1,1,1,1,1,1,1,1,1,1,1,1,1,0,0,0,1,4
1,1,1,1,1,1,1,0,0,0,1,1,1,1,1,1,1,0,0,0,1,1,4,1,1,1,1,1,1,1,1,1,1,0,0,0,1,1
endlayer

layer
1,1,1,1,1,18,1,0,0,0,1,18,1,1,1,1,1,0,0,0,1,1,1,0,0,0,1,6,6,6,6,6,6,6,6,1,4,1
1,0,0,1,0,0,0,0,0,0,0,0,0,1,0,0,1,0,0,0,1,4,18,0,0,0,1,1,1,1,1,1,1,1,1,1,18,1
1,0,4,18,0,0,0,0,0,0,0,0,0,18,4,0,1,0,0,0,1,1,1,0,0,0,0,0,9,8,0,0,0,0,0,0,0,0
1,1,18,1,0,0,0,19,19,19,0,0,0,1,18,1,1,0,0,0,1,6,1,0,0,0,0,0,11,3,10,0,0,0,0,0,0,0
0,0,0,0,0,0,19,0,0,0,19,0,0,0,0,0,0,0,0,0,1,6,1,0,0,0,0,0,9,8,0,0,0,0,0,0,0,0
0,0,0,0,0,0,19,0,0,0,19,0,0,0,0,0,0,0,0,0,1,6,1,0,0,0,1,1,1,1,1,1,1,0,0,0,1,1
0,0,0,0,0,0,19,0,0,0,19,0,0,0,0,0,0,0,0,0,1,6,1,0,0,0,1,13,0,0,0,15,1,0,0,0,1,1
1,1,18,1,0,0,0,19,19,19,0,0,0,1,18,1,1,0,0,0,1,6,1,0,0,0,0,0,0,0,0,0,0,0,0,0,1,6
1,0,4,18,0,0,0,0,17,0,0,0,0,18,4,0,1,0,0,0,1,6,1,0,0,0,0,0,0,0,0,0,0,0,0,0,1,6
1,0,0,1,0,0,0,0,0,0,0,0,0,1,0,0,1,0,0,0,1,6,1,0,0,0,0,0,0,0,0,0,0,0,0,0,1,6
1,0,0,0,1,18,1,0,0,0,1,18,1,1,0,0,1,0,0,0,1,1,1,0,0,0,1,13,0,0,0,15,1,0,0,0,1,6
1,0,0,0,0,4,18,0,0,0,18,4,0,0,0,0,1,0,0,0,1,1,1,0,0,0,1,1,1,1,1,1,1,0,0,0,1,6
1,0,0,0,0,0,1,0,0,0,1,0,0,0,0,0,1,0,0,0,0,0,0,0,0,0,0,0,0,8,9,0,0,0,0,0,1,6
1,0,0,0,0,0,1,0,0,0,1,0,0,0,0,0,1,0,0,0,0,0,0,0,0,0,0,0,10,3,11,0,0,0,0,0,1,6
1,0,0,0,0,0,1,0,0,0,1,0,0,0,0,0,1,0,0,0,0,0,0,0,0,0,0,0,0,8,9,0,0,0,0,0,1,1
1,0,0,0,0,4,18,0,0,0,18,4,0,0,0,0,1,0,0,0,1,1,18,1,1,1,1,1,1,1,1,1,1,0,0,0,18,4
1,1,1,1,1,1,1,0,0,0,1,1,1,1,1,1,1,0,0,0,1,1,4,1,6,6,6,6,6,6,6,1,1,0,0,0,1,1
endlayer

layer
1,1,1,1,1,18,1,0,0,0,1,18,1,1,1,1,1,0,0,0,1,1,1,0,0,0,1,6,6,6,6,6,6,6,6,1,4,1
1,0,0,1,0,0,0,0,0,0,0,0,0,1,0,0,1,0,0,0,1,4,18,0,0,0,1,1,1,1,1,1,1,1,1,1,18,1
1,0,4,18,0,0,0,0,0,0,0,0,0,18,4,0,1,0,0,0,1,1,1,0,0,0,0,0,0,0,9,8,0,0,0,0,0,0
1,1,18,1,0,0,0,0,0,0,0,0,0,1,18,1,1,0,0,0,1,6,1,0,0,0,0,0,0,0,11,3,10,0,0,0,0,0
0,0,0,0,0,0,0,0,0,0,0,0,0,0,0,0,0,0,0,0,1,6,1,0,0,0,0,0,0,0,9,8,0,0,0,0,0,0
0,0,0,0,0,0,0,0,0,0,0,0,0,0,0,0,0,0,0,0,1,6,1,0,0,0,1,1,1,1,1,1,1,0,0,0,1,1
0,0,0,0,0,0,0,0,0,0,0,0,0,0,0,0,0,0,0,0,1,6,1,0,0,0,1,0,0,0,0,0,1,0,0,0,1,1
1,1,18,1,0,0,0,0,0,0,0,0,0,1,18,1,1,0,0,0,1,6,1,0,0,0,0,0,0,0,0,0,0,0,0,0,1,6
1,0,4,18,0,0,0,0,0,0,0,0,0,18,4,0,1,0,0,0,1,6,1,0,0,0,0,0,0,0,0,0,0,0,0,0,1,6
1,0,0,1,0,0,0,0,0,0,0,0,0,1,0,0,1,0,0,0,1,6,1,0,0,0,0,0,0,0,0,0,0,0,0,0,1,6
1,0,0,0,1,18,1,0,0,0,1,18,1,1,0,0,1,0,0,0,1,1,1,0,0,0,1,0,0,0,0,0,1,0,0,0,1,6
1,0,0,0,0,4,18,0,0,0,18,4,0,0,0,0,1,0,0,0,1,1,1,0,0,0,1,1,1,1,1,1,1,0,0,0,1,6
1,0,0,0,0,0,1,0,0,0,1,0,0,0,0,0,1,0,0,0,0,0,0,0,0,0,0,8,9,0,0,0,0,0,0,0,1,6
1,0,0,0,0,0,1,0,0,0,1,0,0,0,0,0,1,0,0,0,0,0,0,0,0,0,10,3,11,0,0,0,0,0,0,0,1,6
1,0,0,0,0,0,1,0,0,0,1,0,0,0,0,0,1,0,0,0,0,0,0,0,0,0,0,8,9,0,0,0,0,0,0,0,1,1
1,0,0,0,0,4,18,0,0,0,18,4,0,0,0,0,1,0,0,0,1,1,18,1,1,1,1,1,1,1,1,1,1,0,0,0,18,4
1,1,1,1,1,1,1,0,0,0,1,1,1,1,1,1,1,0,0,0,1,1,4,1,6,6,6,6,6,6,6,1,1,0,0,0,1,1
endlayer

layer
1,1,1,1,1,1,1,21,0,20,1,1,1,1,1,1,1,21,0,20,1,1,1,21,0,20,1,6,6,6,6,6,6,6,6,1,14,1
1,1,1,1,0,0,22,22,0,22,22,0,0,1,1,1,1,21,0,20,1,14,1,21,0,20,1,1,1,1,1,1,1,1,1,1,1,1
1,1,14,1,0,0,0,0,0,0,0,0,0,1,14,1,1,21,0,20,1,1,1,21,0,0,0,0,0,0,0,0,9,8,22,22,22,22
1,1,1,1,21,0,0,0,0,0,0,0,20,1,1,1,1,21,0,20,1,6,1,21,0,0,0,0,0,0,0,0,11,3,10,0,0,0
22,0,0,22,21,0,0,0,0,0,0,0,20,22,22,22,22,21,0,20,1,6,1,21,0,0,0,0,0,0,0,0,9,21,0,0,23,23
0,0,0,0,0,0,0,0,0,0,0,0,0,0,0,0,0,0,0,20,1,6,1,21,0,20,1,1,1,1,1,1,1,21,0,20,1,1
23,0,0,23,21,0,0,0,0,0,0,0,23,23,23,23,23,21,0,20,1,6,1,21,0,20,1,0,0,0,0,0,1,21,0,20,1,1
1,1,1,1,21,0,0,0,0,0,0,0,20,1,1,1,1,21,0,20,1,6,1,21,0,0,22,0,0,0,0,0,22,0,0,20,1,6
1,1,14,1,0,0,0,0,0,0,0,0,0,1,14,1,1,21,0,20,1,6,1,21,0,0,0,0,0,0,0,0,0,0,0,20,1,6
1,1,1,1,0,0,23,23,0,23,23,0,0,1,1,1,1,21,0,20,1,6,1,21,0,0,23,0,0,0,0,0,23,0,0,20,1,6
1,0,0,0,1,1,1,21,0,20,1,1,1,1,0,0,1,21,0,20,1,1,1,21,0,20,1,0,0,0,0,0,1,21,0,20,1,6
1,0,0,0,1,14,1,21,0,20,1,14,1,0,0,0,1,21,0,20,1,1,1,21,0,20,1,1,1,1,1,1,1,21,0,20,1,6
1,0,0,0,1,1,1,21,0,20,1,1,1,0,0,0,1,21,0,22,22,22,0,0,0,20,9,0,0,0,0,0,0,0,0,20,1,6
1,0,0,0,1,1,1,21,0,20,1,1,1,0,0,0,1,21,0,0,0,0,0,0,10,3,11,0,0,0,0,0,0,0,0,20,1,6
1,0,0,0,1,1,1,21,0,20,1,1,1,0,0,0,1,21,0,20,23,23,23,23,23,8,9,0,0,0,0,0,0,0,0,20,1,1
1,0,0,0,1,14,1,21,0,20,1,14,1,0,0,0,1,21,0,20,1,1,1,1,1,1,1,1,1,1,1,1,1,21,0,20,1,14
1,1,1,1,1,1,1,21,0,20,1,1,1,1,1,1,1,21,0,20,1,1,14,1,6,6,6,6,6,6,6,1,1,21,0,20,1,1
endlayer

layer
1,1,1,1,1,1,1,1,1,1,1,1,1,1,1,1,1,1,1,1,1,1,1,1,1,1,1,1,1,1,1,1,1,1,1,1,1,1
1,1,1,1,24,1,1,1,22,1,1,1,24,1,1,1,1,1,1,1,1,1,1,1,1,1,1,1,1,1,1,1,1,1,1,1,1,1
1,1,1,1,1,1,22,0,0,0,22,1,1,1,1,1,1,1,1,1,1,1,1,1,1,1,1,21,0,0,0,0,0,0,9,9,1,1
1,1,1,1,1,21,0,0,0,0,0,20,1,1,1,1,1,1,1,1,1,1,1,1,1,1,1,21,0,0,0,0,0,0,11,1,1,1
1,1,1,1,1,0,0,0,0,0,0,0,1,1,1,1,1,1,1,1,1,1,1,1,1,1,1,21,0,0,0,0,0,0,3,1,1,1
1,1,1,1,21,0,0,0,0,0,0,0,20,1,1,1,1,1,1,1,1,1,1,1,1,1,1,1,1,1,1,1,1,12,3,1,1,1
1,1,1,1,1,0,0,0,0,0,0,0,1,1,1,1,1,1,1,1,1,1,1,1,1,1,1,1,22,22,22,1,1,1,3,1,1,1
1,1,1,1,1,21,0,0,0,0,0,20,1,1,1,1,1,1,1,1,1,1,1,1,1,1,1,21,10,10,10,20,1,1,3,1,1,1
1,1,1,1,1,1,23,0,0,0,23,1,1,1,1,1,1,1,1,1,1,1,1,1,3,3,3,3,10,0,10,3,3,3,3,3,1,1
1,1,1,1,24,1,1,1,23,1,1,1,24,1,1,1,1,1,1,1,1,1,1,1,3,1,1,21,10,10,10,20,1,1,1,1,1,1
1,1,1,1,1,1,1,1,1,1,1,1,1,1,1,1,1,1,1,1,1,1,1,1,3,1,1,1,23,23,23,1,1,1,1,1,1,1
1,1,1,1,1,1,1,1,1,1,1,1,1,1,1,1,1,1,1,1,1,1,1,1,3,17,1,1,1,1,1,1,1,1,1,1,1,1
1,1,1,1,1,1,1,1,1,1,1,1,1,1,1,1,1,1,1,1,1,1,1,1,3,0,0,0,0,0,0,20,1,1,1,1,1,1
1,1,1,1,1,1,1,1,1,1,1,1,1,1,1,1,1,1,1,1,1,1,1,1,11,0,0,0,0,0,0,20,1,1,1,1,1,1
1,1,1,1,1,1,1,1,1,1,1,1,1,1,1,1,1,1,1,1,1,1,1,9,9,0,0,0,0,0,0,20,1,1,1,1,1,1
1,1,1,1,1,1,1,1,1,1,1,1,1,1,1,1,1,1,1,1,1,1,1,1,1,1,1,1,1,1,1,1,1,1,1,1,1,1
1,1,1,1,1,1,1,1,1,1,1,1,1,1,1,1,1,1,1,1,1,1,1,1,1,1,1,1,1,1,1,1,1,1,1,1,1,1
endlayer

layer
6,6,6,0,0,0,0,0,0,0,0,0,0,0,6,6,6,6,6,6,6,1,1,1,1,1,1,1,1,4,1,1,1,1,1,1,1,1
6,6,6,0,16,1,1,1,0,1,1,1,7,0,6,6,6,6,6,6,6,1,0,0,0,0,16,1,1,1,1,0,0,0,0,0,0,1
6,6,6,0,1,4,1,0,0,0,1,4,1,0,6,6,6,6,6,6,6,1,0,0,0,0,0,17,0,0,0,0,0,0,0,0,0,1
6,6,6,0,1,1,0,0,0,0,0,1,1,0,6,6,6,6,6,6,6,1,0,0,0,0,0,0,0,0,0,0,0,0,0,0,0,1
6,6,6,0,1,0,0,0,0,0,0,0,1,0,6,6,6,6,6,6,6,1,0,0,0,12,12,12,0,0,0,0,0,0,0,0,0,1
6,6,6,0,0,0,0,0,0,0,0,0,0,0,6,6,6,6,6,6,6,1,0,0,0,15,4,1,13,0,15,1,7,0,0,0,0,1
6,6,6,0,1,0,0,0,0,0,0,0,1,0,6,6,6,6,6,6,6,1,0,0,0,17,1,0,0,0,0,0,1,0,0,0,0,1
6,6,6,0,1,1,0,0,0,0,0,1,1,0,6,6,6,6,6,6,6,1,0,0,0,0,0,0,0,0,0,0,0,0,0,0,0,1
6,6,6,0,1,4,1,0,0,0,1,4,1,0,6,6,6,6,6,6,6,1,0,0,0,0,0,0,0,0,0,0,0,0,0,0,0,1
6,6,6,0,16,1,1,1,0,1,1,1,7,0,6,6,6,6,6,6,6,1,0,0,0,0,0,0,0,0,0,0,0,0,0,0,0,1
6,6,6,0,0,0,0,0,0,0,0,0,0,0,6,6,6,6,6,6,6,1,0,0,0,0,1,0,0,0,0,0,1,12,0,12,12,1
6,6,6,6,6,6,6,6,6,6,6,6,6,6,6,6,6,6,6,6,6,1,0,0,0,0,16,1,13,0,15,1,4,13,0,1,1,1
6,6,6,6,6,6,6,6,6,6,6,6,6,6,6,6,6,6,6,6,6,1,0,0,0,0,0,0,0,0,0,17,17,13,0,0,0,1
6,6,6,6,6,6,6,6,6,6,6,6,6,6,6,6,6,6,6,6,6,1,0,0,0,0,0,0,0,0,0,0,0,0,0,1,1,1
6,6,6,6,6,6,6,6,6,6,6,6,6,6,6,6,6,6,6,6,6,1,0,0,0,0,0,0,0,0,0,12,0,0,0,1,1,1
6,6,6,6,6,6,6,6,6,6,6,6,6,6,6,6,6,6,6,6,6,1,0,0,0,0,0,0,1,18,1,1,25,0,0,1,1,1
6,6,6,6,6,6,6,6,6,6,6,6,6,6,6,6,6,6,6,6,6,1,1,1,1,1,1,1,1,4,1,1,1,1,1,1,1,1
endlayer

layer
6,6,6,0,0,0,0,0,0,0,0,0,0,0,6,6,6,6,6,6,6,1,1,13,0,15,1,1,1,4,1,1,1,1,1,1,1,1
6,6,6,0,26,1,1,1,0,1,1,1,26,0,6,6,6,6,6,6,6,1,0,0,0,0,0,1,1,18,1,0,0,0,0,0,0,1
6,6,6,0,1,4,18,0,0,0,18,4,1,0,6,6,6,6,6,6,6,1,0,0,0,0,0,0,0,0,0,0,0,0,0,0,0,1
6,6,6,0,1,18,18,0,0,0,18,18,1,0,6,6,6,6,6,6,6,1,0,0,0,0,0,0,0,0,0,0,0,0,0,0,0,1
6,6,6,0,1,0,0,0,0,0,0,0,1,0,6,6,6,6,6,6,6,1,0,0,0,18,18,0,0,0,0,0,0,0,0,0,0,1
6,6,6,0,0,0,0,0,0,0,0,0,0,0,6,6,6,6,6,6,6,1,0,0,0,18,4,1,0,0,0,1,0,0,0,0,0,1
6,6,6,0,1,0,0,0,0,0,0,0,1,0,6,6,6,6,6,6,6,1,0,0,0,18,1,0,0,0,0,0,1,0,0,0,0,1
6,6,6,0,1,18,18,0,0,0,18,18,1,0,6,6,6,6,6,6,6,1,0,0,0,0,0,0,0,0,0,0,0,0,0,0,0,1
6,6,6,0,1,4,18,0,0,0,18,4,1,0,6,6,6,6,6,6,6,1,0,0,0,0,0,0,0,0,0,0,0,0,0,0,0,1
6,6,6,0,26,1,1,1,0,1,1,1,26,0,6,6,6,6,6,6,6,1,0,0,0,0,0,0,0,0,0,0,0,0,0,0,0,1
6,6,6,0,0,0,0,0,0,0,0,0,0,0,6,6,6,6,6,6,6,1,0,0,0,0,1,0,0,0,0,0,1,18,0,0,0,1
6,6,6,6,6,6,6,6,6,6,6,6,6,6,6,6,6,6,6,6,6,1,0,0,0,0,0,1,0,0,0,1,4,18,0,12,12,1
6,6,6,6,6,6,6,6,6,6,6,6,6,6,6,6,6,6,6,6,6,1,0,0,0,0,0,0,0,0,0,0,18,18,0,1,1,1
6,6,6,6,6,6,6,6,6,6,6,6,6,6,6,6,6,6,6,6,6,1,0,0,0,0,0,0,0,0,0,0,0,0,0,1,1,1
6,6,6,6,6,6,6,6,6,6,6,6,6,6,6,6,6,6,6,6,6,1,0,0,0,0,0,0,0,0,0,0,0,0,20,1,1,1
6,6,6,6,6,6,6,6,6,6,6,6,6,6,6,6,6,6,6,6,6,1,0,0,0,0,0,0,1,18,1,1,0,0,20,1,1,1
6,6,6,6,6,6,6,6,6,6,6,6,6,6,6,6,6,6,6,6,6,1,1,1,1,1,1,1,6,4,6,1,1,1,1,1,1,1
endlayer

layer
6,6,6,0,0,0,0,0,0,0,0,0,0,0,6,6,6,6,6,6,6,1,1,0,0,0,1,1,1,4,1,1,1,1,1,1,1,1
6,6,6,0,0,1,1,1,0,1,1,1,0,0,6,6,6,6,6,6,6,1,0,0,0,0,0,1,1,18,1,0,0,0,0,0,0,1
6,6,6,0,1,4,18,0,0,0,18,4,1,0,6,6,6,6,6,6,6,1,0,0,0,0,0,22,0,0,0,0,0,0,0,0,0,1
6,6,6,0,1,18,18,0,0,0,18,18,1,0,6,6,6,6,6,6,6,1,0,0,0,0,0,0,0,0,0,0,0,0,0,0,0,1
6,6,6,0,1,0,0,0,0,0,0,0,1,0,6,6,6,6,6,6,6,1,0,0,0,18,18,23,0,0,0,0,0,0,0,0,0,1
6,6,6,0,0,0,0,0,0,0,0,0,0,0,6,6,6,6,6,6,6,1,0,0,0,18,4,1,0,0,0,1,0,0,0,0,0,1
6,6,6,0,1,0,0,0,0,0,0,0,1,0,6,6,6,6,6,6,6,1,0,0,0,18,1,0,0,0,0,0,1,0,0,0,0,1
6,6,6,0,1,18,18,0,0,0,18,18,1,0,6,6,6,6,6,6,6,1,0,0,0,0,0,0,0,0,0,0,0,0,0,0,0,1
6,6,6,0,1,4,18,0,0,0,18,4,1,0,6,6,6,6,6,6,6,1,0,0,0,0,0,0,0,0,0,0,0,0,0,0,0,1
6,6,6,0,0,1,1,1,0,1,1,1,0,0,6,6,6,6,6,6,6,1,0,0,0,0,0,0,0,0,0,0,0,0,0,0,0,1
6,6,6,0,0,0,0,0,0,0,0,0,0,0,6,6,6,6,6,6,6,1,0,0,0,0,1,0,0,0,0,0,1,18,0,0,0,1
6,6,6,6,6,6,6,6,6,6,6,6,6,6,6,6,6,6,6,6,6,1,0,0,0,0,0,1,0,0,0,1,4,18,0,0,0,1
6,6,6,6,6,6,6,6,6,6,6,6,6,6,6,6,6,6,6,6,6,1,0,0,0,0,0,0,0,0,0,22,18,18,0,12,12,1
6,6,6,6,6,6,6,6,6,6,6,6,6,6,6,6,6,6,6,6,6,1,0,0,0,0,0,0,0,0,0,0,0,0,0,1,1,1
6,6,6,6,6,6,6,6,6,6,6,6,6,6,6,6,6,6,6,6,6,1,0,0,0,0,0,0,0,0,0,23,0,20,1,1,1,1
6,6,6,6,6,6,6,6,6,6,6,6,6,6,6,6,6,6,6,6,6,1,0,0,0,0,0,0,1,18,1,1,0,20,1,1,1,1
6,6,6,6,6,6,6,6,6,6,6,6,6,6,6,6,6,6,6,6,6,1,1,1,1,1,1,1,6,4,6,1,1,1,1,1,1,1
endlayer

layer
6,6,6,1,1,1,1,1,1,1,1,1,1,1,6,6,6,6,6,6,6,1,1,21,0,20,1,1,1,4,1,1,1,1,1,1,1,1
6,0,6,1,1,1,1,1,1,1,1,1,1,1,6,6,6,6,6,6,6,1,0,0,0,0,0,1,1,18,1,0,0,0,0,0,8,1
6,0,6,1,1,4,1,0,0,0,1,4,1,1,6,6,6,6,6,6,6,1,0,0,0,0,0,1,0,0,0,0,0,0,0,0,0,1
6,0,6,1,1,1,0,0,0,0,0,1,1,1,6,6,6,6,6,6,6,1,0,0,0,0,0,1,0,0,0,0,0,0,0,0,0,1
6,0,6,1,1,0,0,0,0,0,0,0,1,1,6,6,6,6,6,6,6,1,0,0,0,1,1,1,0,0,0,0,0,0,0,0,0,1
6,0,6,1,1,0,0,0,0,0,0,0,1,1,6,6,6,6,6,6,6,1,0,0,0,1,14,1,21,0,20,1,0,0,0,0,0,1
6,0,6,1,1,0,0,0,0,0,0,0,1,1,6,6,6,6,6,6,6,1,0,0,0,1,1,0,0,0,0,0,1,0,0,0,0,1
6,0,6,1,1,1,0,0,0,0,0,1,1,1,6,6,6,6,6,6,6,1,0,0,0,0,22,0,0,0,0,0,22,0,0,0,0,1
6,0,6,1,1,4,1,0,0,0,1,4,1,1,6,6,6,6,6,6,6,1,0,0,0,0,0,0,0,0,0,0,0,0,0,0,0,1
6,0,6,1,1,1,1,1,1,1,1,1,1,1,6,0,6,6,6,6,6,1,0,0,0,0,23,0,0,0,0,0,23,0,0,0,0,1
6,0,6,1,1,1,1,1,1,1,1,1,1,1,6,0,6,6,6,6,6,1,0,0,0,0,1,0,0,0,0,0,1,1,0,0,0,1
6,0,6,6,6,6,6,6,6,6,6,6,6,6,6,0,6,6,6,6,6,1,0,0,0,0,0,1,21,0,20,1,14,1,0,0,0,1
6,0,0,0,0,0,0,0,0,0,0,0,0,0,0,0,6,6,6,6,6,1,0,0,0,0,0,0,0,0,0,1,1,1,0,0,0,1
6,6,6,6,6,6,6,6,6,6,6,6,6,6,6,6,6,6,6,6,6,1,0,0,0,0,0,0,0,0,0,1,0,0,0,0,0,1
6,6,6,6,6,6,6,6,6,6,6,6,6,6,6,6,6,6,6,6,6,1,0,0,0,0,0,0,0,0,0,1,20,1,13,0,0,1
6,6,6,6,6,6,6,6,6,6,6,6,6,6,6,6,6,6,6,6,6,1,8,0,0,0,0,0,1,18,1,1,20,1,13,0,0,1
6,6,6,6,6,6,6,6,6,6,6,6,6,6,6,6,6,6,6,6,6,1,1,1,1,1,1,1,6,4,6,1,1,1,1,1,1,1
endlayer

layer
6,6,6,6,6,6,6,6,6,6,6,6,6,6,6,6,6,6,6,6,6,1,1,1,1,1,1,1,1,4,1,1,1,1,1,1,1,1
6,6,6,6,6,1,1,1,1,1,1,1,6,6,6,6,6,6,6,6,6,1,0,0,0,1,1,1,1,18,1,0,0,0,0,20,27,1
6,6,6,6,1,14,1,1,1,1,1,14,1,6,6,6,6,6,6,6,6,1,0,0,0,1,1,1,0,0,0,0,0,0,0,20,22,1
6,6,6,6,1,1,1,0,0,0,1,1,1,6,6,6,6,6,6,6,6,1,0,0,0,0,1,1,0,0,0,0,0,0,0,0,0,1
6,6,6,6,1,1,0,0,0,0,0,1,1,6,6,6,6,6,6,6,6,1,0,0,0,1,1,1,1,1,1,1,1,1,0,0,0,1
6,6,6,6,1,1,0,0,0,0,0,1,1,6,6,6,6,6,6,6,6,1,0,0,0,1,1,1,1,1,1,1,1,1,0,0,0,1
6,6,6,6,1,1,0,0,0,0,0,1,1,6,6,6,6,6,6,6,6,1,0,0,0,1,1,1,22,22,22,1,1,1,0,0,0,1
6,6,6,6,1,1,1,0,0,0,1,1,1,6,6,6,6,6,6,6,6,1,0,0,0,1,1,21,0,0,0,20,1,1,0,0,0,1
6,6,6,6,1,14,1,1,1,1,1,14,1,6,6,6,6,6,6,6,6,1,0,0,0,1,1,21,0,0,0,20,1,1,0,0,0,1
6,6,6,6,6,1,1,1,1,1,1,1,6,6,6,6,6,6,6,6,6,1,0,0,0,1,1,21,0,0,0,20,1,1,0,0,0,1
6,6,6,6,6,6,6,6,6,6,6,6,6,6,6,6,6,6,6,6,6,1,0,0,0,1,1,1,23,23,23,1,1,1,0,0,0,1
6,6,6,6,6,6,6,6,6,6,6,6,6,6,6,6,6,6,6,6,6,1,0,0,0,1,1,1,1,1,1,1,1,1,0,0,0,1
6,6,6,6,6,6,6,6,6,6,6,6,6,6,6,6,6,6,6,6,6,1,0,0,0,1,1,1,1,1,1,1,1,1,0,0,0,1
6,6,6,6,6,6,6,6,6,6,6,6,6,6,6,6,6,6,6,6,6,1,0,0,0,0,0,0,0,0,0,1,1,0,0,0,0,1
6,6,6,6,6,6,6,6,6,6,6,6,6,6,6,6,6,6,6,6,6,1,23,23,0,0,0,0,0,0,0,1,1,13,0,0,0,1
6,6,6,6,6,6,6,6,6,6,6,6,6,6,6,6,6,6,6,6,6,1,7,21,0,0,0,0,1,18,1,1,1,13,0,0,0,1
6,6,6,6,6,6,6,6,6,6,6,6,6,6,6,6,6,6,6,6,6,1,1,1,1,1,1,1,1,4,1,1,1,1,1,1,1,1
endlayer

layer
6,6,6,6,6,6,6,6,6,6,6,6,6,6,6,6,6,6,6,6,6,1,1,1,1,1,1,1,1,4,1,1,1,1,1,1,1,1
6,6,6,6,6,6,6,6,6,6,6,6,6,6,6,6,6,6,6,6,6,1,0,0,0,1,1,1,1,18,1,0,0,0,0,18,0,1
6,6,6,6,6,1,1,1,1,1,1,1,6,6,6,6,6,6,6,6,6,1,0,0,0,1,1,1,0,0,0,0,0,0,0,18,18,1
6,6,6,6,6,1,1,1,1,1,1,1,6,6,6,6,6,6,6,6,6,1,0,0,0,0,17,17,0,0,0,0,0,0,0,0,0,1
6,6,6,6,6,1,1,1,1,1,1,1,6,6,6,6,6,6,6,6,6,1,0,0,0,18,0,0,18,18,18,18,18,18,0,0,0,1
6,6,6,6,6,1,1,1,1,1,1,1,6,6,6,6,6,6,6,6,6,1,0,0,0,18,0,0,0,0,0,0,0,18,0,0,0,1
6,6,6,6,6,1,1,1,1,1,1,1,6,6,6,6,6,6,6,6,6,1,0,0,0,18,0,0,0,0,0,0,0,18,0,0,0,1
6,6,6,6,6,1,1,1,1,1,1,1,6,6,6,6,6,6,6,6,6,1,0,0,0,18,0,0,18,18,18,0,0,18,0,0,0,1
6,6,6,6,6,1,1,1,1,1,1,1,6,6,6,6,6,6,6,6,6,1,0,0,0,18,0,0,18,0,18,0,0,18,0,0,0,1
6,6,6,6,6,6,6,6,6,6,6,6,6,6,6,6,6,6,6,6,6,1,0,0,0,18,0,0,18,18,18,0,0,18,0,0,0,1
6,6,6,6,6,6,6,6,6,6,6,6,6,6,6,6,6,6,6,6,6,1,0,0,0,18,0,0,0,0,0,0,0,18,0,0,0,1
6,6,6,6,6,6,6,6,6,6,6,6,6,6,6,6,6,6,6,6,6,1,0,0,0,18,0,0,0,0,0,0,0,18,0,0,0,1
6,6,6,6,6,6,6,6,6,6,6,6,6,6,6,6,6,6,6,6,6,1,0,0,0,18,18,18,18,18,18,0,0,18,0,0,0,1
6,6,6,6,6,6,6,6,6,6,6,6,6,6,6,6,6,6,6,6,6,1,0,0,0,0,0,0,0,0,0,0,0,0,0,0,0,1
6,6,6,6,6,6,6,6,6,6,6,6,6,6,6,6,6,6,6,6,6,1,18,18,0,0,0,0,0,0,0,0,0,0,0,0,0,1
6,6,6,6,6,6,6,6,6,6,6,6,6,6,6,6,6,6,6,6,6,1,0,18,0,0,0,0,1,18,1,0,0,0,0,0,0,1
6,6,6,6,6,6,6,6,6,6,6,6,6,6,6,6,6,6,6,6,6,1,1,1,1,1,1,1,1,4,1,1,1,1,1,1,1,1
endlayer

layer
0,0,0,0,0,0,0,0,0,0,0,0,0,0,0,0,0,0,0,0,0,1,1,1,1,1,1,1,1,4,1,1,1,1,1,1,1,1
0,0,0,0,0,0,0,0,0,0,0,0,0,0,0,0,0,0,0,0,0,1,0,0,20,13,0,0,1,18,1,0,0,0,0,0,0,1
0,0,0,0,0,0,0,0,0,0,0,0,0,0,0,0,0,0,0,0,0,1,0,0,20,13,0,0,0,0,0,0,0,0,0,0,0,1
0,0,0,0,0,0,0,0,0,0,0,0,0,0,0,0,0,0,0,0,0,1,0,0,0,0,0,0,0,0,0,0,0,0,0,0,0,1
0,0,0,0,0,0,0,0,0,0,0,0,0,0,0,0,0,0,0,0,0,1,0,0,0,0,0,0,0,0,0,0,0,0,0,0,0,1
0,0,0,0,0,0,0,0,0,0,0,0,0,0,0,0,0,0,0,0,0,1,0,0,0,0,0,0,0,0,0,0,0,0,0,0,0,1
0,0,0,0,0,0,0,0,0,0,0,0,0,0,0,0,0,0,0,0,0,1,0,0,0,0,0,0,0,0,0,0,0,0,0,0,0,1
0,0,0,0,0,0,0,0,0,0,0,0,0,0,0,0,0,0,0,0,0,1,0,0,0,0,0,0,18,18,18,0,0,0,0,0,0,1
0,0,0,0,0,0,0,0,0,0,0,0,0,0,0,0,0,0,0,0,0,1,0,0,0,0,0,0,18,0,18,0,0,0,0,0,0,1
0,0,0,0,0,0,0,0,0,0,0,0,0,0,0,0,0,0,0,0,0,1,0,0,0,0,0,0,18,18,18,0,0,0,0,0,0,1
0,0,0,0,0,0,0,0,0,0,0,0,0,0,0,0,0,0,0,0,0,1,0,0,0,0,0,0,0,0,0,0,0,0,0,0,0,1
0,0,0,0,0,0,0,0,0,0,0,0,0,0,0,0,0,0,0,0,0,1,0,0,0,0,0,0,0,0,0,0,0,0,0,0,0,1
0,0,0,0,0,0,0,0,0,0,0,0,0,0,0,0,0,0,0,0,0,1,0,0,0,0,0,0,0,0,0,0,0,0,0,0,0,1
0,0,0,0,0,0,0,0,0,0,0,0,0,0,0,0,0,0,0,0,0,1,0,0,0,0,0,0,0,0,0,0,0,0,0,0,0,1
0,0,0,0,0,0,0,0,0,0,0,0,0,0,0,0,0,0,0,0,0,1,0,0,0,0,0,0,0,0,0,0,0,0,0,0,0,1
0,0,0,0,0,0,0,0,0,0,0,0,0,0,0,0,0,0,0,0,0,1,0,0,0,0,0,0,1,18,1,0,0,0,0,0,0,1
0,0,0,0,0,0,0,0,0,0,0,0,0,0,0,0,0,0,0,0,0,1,1,1,1,1,1,1,1,4,1,1,1,1,1,1,1,1
endlayer

layer
0,0,0,0,0,0,0,0,0,0,0,0,0,0,0,0,0,0,0,0,0,1,1,1,1,1,1,1,1,14,1,1,1,1,1,1,1,1
0,0,0,0,0,0,0,0,0,0,0,0,0,0,0,0,0,0,0,0,0,1,1,1,13,0,0,0,1,1,1,0,0,0,0,0,0,1
0,0,0,0,0,0,0,0,0,0,0,0,0,0,0,0,0,0,0,0,0,1,1,1,13,0,0,0,0,0,0,0,0,0,0,0,0,1
0,0,0,0,0,0,0,0,0,0,0,0,0,0,0,0,0,0,0,0,0,1,22,22,0,0,0,0,0,0,0,0,0,0,0,0,0,1
0,0,0,0,0,0,0,0,0,0,0,0,0,0,0,0,0,0,0,0,0,1,0,0,0,0,0,0,0,0,0,0,0,0,0,0,0,1
0,0,0,0,0,0,0,0,0,0,0,0,0,0,0,0,0,0,0,0,0,1,0,0,0,0,0,0,0,0,0,0,0,0,0,0,0,1
0,0,0,0,0,0,0,0,0,0,0,0,0,0,0,0,0,0,0,0,0,1,0,0,0,0,0,0,0,0,0,0,0,0,0,0,0,1
0,0,0,0,0,0,0,0,0,0,0,0,0,0,0,0,0,0,0,0,0,1,0,0,0,0,0,0,18,18,18,0,0,0,0,0,0,1
0,0,0,0,0,0,0,0,0,0,0,0,0,0,0,0,0,0,0,0,0,1,0,0,0,0,0,0,18,0,18,0,0,0,0,0,0,1
0,0,0,0,0,0,0,0,0,0,0,0,0,0,0,0,0,0,0,0,0,1,0,0,0,0,0,0,18,18,18,0,0,0,0,0,0,1
0,0,0,0,0,0,0,0,0,0,0,0,0,0,0,0,0,0,0,0,0,1,0,0,0,0,0,0,0,0,0,0,0,0,0,0,0,1
0,0,0,0,0,0,0,0,0,0,0,0,0,0,0,0,0,0,0,0,0,1,0,0,0,0,0,0,0,0,0,0,0,0,0,0,0,1
0,0,0,0,0,0,0,0,0,0,0,0,0,0,0,0,0,0,0,0,0,1,0,0,0,0,0,0,0,0,0,0,0,0,0,0,0,1
0,0,0,0,0,0,0,0,0,0,0,0,0,0,0,0,0,0,0,0,0,1,0,0,0,0,0,0,0,0,0,0,0,0,0,0,0,1
0,0,0,0,0,0,0,0,0,0,0,0,0,0,0,0,0,0,0,0,0,1,0,0,0,0,0,0,0,0,0,0,0,0,0,0,0,1
0,0,0,0,0,0,0,0,0,0,0,0,0,0,0,0,0,0,0,0,0,1,0,0,0,0,0,0,1,1,1,0,0,0,0,0,0,1
0,0,0,0,0,0,0,0,0,0,0,0,0,0,0,0,0,0,0,0,0,1,1,1,1,1,1,1,1,14,1,1,1,1,1,1,1,1
endlayer

layer
0,0,0,0,0,0,0,0,0,0,0,0,0,0,0,0,0,0,0,0,0,1,1,1,1,1,1,1,1,1,1,1,1,1,1,1,1,1
0,0,0,0,0,0,0,0,0,0,0,0,0,0,0,0,0,0,0,0,0,1,0,0,0,0,0,0,1,1,1,0,0,0,0,0,0,1
0,0,0,0,0,0,0,0,0,0,0,0,0,0,0,0,0,0,0,0,0,1,0,0,0,0,0,0,20,1,21,0,0,0,0,0,0,1
0,0,0,0,0,0,0,0,0,0,0,0,0,0,0,0,0,0,0,0,0,1,12,12,0,0,0,0,20,1,21,0,0,0,0,0,0,1
0,0,0,0,0,0,0,0,0,0,0,0,0,0,0,0,0,0,0,0,0,1,22,22,0,0,0,0,20,1,21,0,0,0,0,0,0,1
0,0,0,0,0,0,0,0,0,0,0,0,0,0,0,0,0,0,0,0,0,1,0,0,0,0,0,0,20,1,21,0,0,0,0,0,0,1
0,0,0,0,0,0,0,0,0,0,0,0,0,0,0,0,0,0,0,0,0,1,0,0,0,0,0,0,20,1,21,0,0,0,0,0,0,1
0,0,0,0,0,0,0,0,0,0,0,0,0,0,0,0,0,0,0,0,0,1,1,23,23,23,23,23,1,1,1,23,23,23,23,23,1,1
0,0,0,0,0,0,0,0,0,0,0,0,0,0,0,0,0,0,0,0,0,1,1,1,1,1,1,1,1,0,1,1,1,1,1,1,1,1
0,0,0,0,0,0,0,0,0,0,0,0,0,0,0,0,0,0,0,0,0,1,1,22,22,22,22,22,1,1,1,22,22,22,22,22,1,1
0,0,0,0,0,0,0,0,0,0,0,0,0,0,0,0,0,0,0,0,0,1,0,0,0,0,0,0,20,1,21,0,0,0,0,0,0,1
0,0,0,0,0,0,0,0,0,0,0,0,0,0,0,0,0,0,0,0,0,1,0,0,0,0,0,0,20,1,21,0,0,0,0,0,0,1
0,0,0,0,0,0,0,0,0,0,0,0,0,0,0,0,0,0,0,0,0,1,0,0,0,0,0,0,20,1,21,0,0,0,0,0,0,1
0,0,0,0,0,0,0,0,0,0,0,0,0,0,0,0,0,0,0,0,0,1,0,0,0,0,0,0,20,1,21,0,0,0,0,0,0,1
0,0,0,0,0,0,0,0,0,0,0,0,0,0,0,0,0,0,0,0,0,1,0,0,0,0,0,0,20,1,21,0,0,0,0,0,0,1
0,0,0,0,0,0,0,0,0,0,0,0,0,0,0,0,0,0,0,0,0,1,0,0,0,0,0,0,1,1,1,0,0,0,0,0,0,1
0,0,0,0,0,0,0,0,0,0,0,0,0,0,0,0,0,0,0,0,0,1,1,1,1,1,1,1,1,1,1,1,1,1,1,1,1,1
endlayer

layer
0,0,0,0,0,0,0,0,0,0,0,0,0,0,0,0,0,0,0,0,0,1,1,1,1,1,1,1,1,3,1,1,1,1,1,1,1,1
0,0,0,0,0,0,0,0,0,0,0,0,0,0,0,0,0,0,0,0,0,1,0,0,0,0,0,20,1,3,1,1,1,1,1,1,1,1
0,0,0,0,0,0,0,0,0,0,0,0,0,0,0,0,0,0,0,0,0,1,0,0,0,0,0,20,1,3,1,1,1,1,1,1,1,1
0,0,0,0,0,0,0,0,0,0,0,0,0,0,0,0,0,0,0,0,0,1,0,0,1,1,1,1,1,3,1,1,1,1,1,1,1,1
0,0,0,0,0,0,0,0,0,0,0,0,0,0,0,0,0,0,0,0,0,1,12,12,1,1,1,1,1,3,1,1,1,1,1,1,1,1
0,0,0,0,0,0,0,0,0,0,0,0,0,0,0,0,0,0,0,0,0,1,1,3,1,1,3,3,3,3,3,3,3,1,1,1,1,1
0,0,0,0,0,0,0,0,0,0,0,0,0,0,0,0,0,0,0,0,0,1,1,3,1,1,3,1,1,1,1,1,3,1,1,1,1,1
0,0,0,0,0,0,0,0,0,0,0,0,0,0,0,0,0,0,0,0,0,1,1,3,1,1,3,1,0,0,0,1,3,1,1,1,1,1
0,0,0,0,0,0,0,0,0,0,0,0,0,0,0,0,0,0,0,0,0,1,1,3,3,3,3,1,0,0,0,1,3,3,3,3,3,3
0,0,0,0,0,0,0,0,0,0,0,0,0,0,0,0,0,0,0,0,0,1,1,3,1,1,3,1,0,0,0,1,3,1,3,1,1,1
0,0,0,0,0,0,0,0,0,0,0,0,0,0,0,0,0,0,0,0,0,1,1,3,1,1,3,1,1,1,1,1,3,1,3,1,1,1
0,0,0,0,0,0,0,0,0,0,0,0,0,0,0,0,0,0,0,0,0,1,1,3,1,1,3,3,3,3,3,3,3,1,3,1,1,1
0,0,0,0,0,0,0,0,0,0,0,0,0,0,0,0,0,0,0,0,0,1,1,3,1,1,1,1,1,1,1,1,1,1,3,1,1,1
0,0,0,0,0,0,0,0,0,0,0,0,0,0,0,0,0,0,0,0,0,3,3,3,1,1,1,1,1,1,1,1,1,1,3,1,1,1
0,0,0,0,0,0,0,0,0,0,0,0,0,0,0,0,0,0,0,0,0,1,1,1,1,1,1,1,1,1,1,1,1,1,3,1,1,1
0,0,0,0,0,0,0,0,0,0,0,0,0,0,0,0,0,0,0,0,0,1,1,1,1,1,1,1,1,1,1,1,1,1,3,1,1,1
0,0,0,0,0,0,0,0,0,0,0,0,0,0,0,0,0,0,0,0,0,1,1,1,1,1,1,1,1,1,1,1,1,1,3,1,1,1
endlayer

layer
0,0,0,0,0,0,0,0,0,0,0,0,0,0,0,0,0,0,0,0,0,1,1,1,1,1,1,1,0,0,0,1,1,1,1,1,1,1
0,0,0,0,0,0,0,0,0,0,0,0,0,0,0,0,0,0,0,0,0,1,0,0,0,0,0,0,0,0,0,0,0,0,0,27,1,1
0,0,0,0,0,0,0,0,0,0,0,0,0,0,0,0,0,0,0,0,0,1,0,0,0,0,0,0,0,0,0,0,0,0,0,0,16,1
0,0,0,0,0,0,0,0,0,0,0,0,0,0,0,0,0,0,0,0,0,1,0,0,0,0,0,0,0,0,0,0,0,0,0,0,0,1
0,0,0,0,0,0,0,0,0,0,0,0,0,0,0,0,0,0,0,0,0,1,0,0,0,0,0,0,0,0,0,0,0,0,0,0,0,1
0,0,0,0,0,0,0,0,0,0,0,0,0,0,0,0,0,0,0,0,0,1,0,0,0,0,0,0,0,0,0,0,0,0,0,0,0,1
0,0,0,0,0,0,0,0,0,0,0,0,0,0,0,0,0,0,0,0,0,1,0,0,0,0,0,18,18,18,18,18,0,0,0,0,0,1
0,0,0,0,0,0,0,0,0,0,0,0,0,0,0,0,0,0,0,0,0,1,0,0,0,0,0,18,0,0,0,18,0,0,0,0,0,0
0,0,0,0,0,0,0,0,0,0,0,0,0,0,0,0,0,0,0,0,0,1,0,0,0,0,0,18,0,28,0,18,0,0,0,0,0,0
0,0,0,0,0,0,0,0,0,0,0,0,0,0,0,0,0,0,0,0,0,1,0,0,0,0,0,18,0,0,0,18,0,0,0,0,0,0
0,0,0,0,0,0,0,0,0,0,0,0,0,0,0,0,0,0,0,0,0,1,0,0,0,0,0,18,18,18,18,18,0,0,0,0,0,1
0,0,0,0,0,0,0,0,0,0,0,0,0,0,0,0,0,0,0,0,0,1,0,0,0,0,0,0,0,0,0,0,0,0,0,0,0,1
0,0,0,0,0,0,0,0,0,0,0,0,0,0,0,0,0,0,0,0,0,0,0,0,0,0,0,0,0,0,0,0,0,0,0,0,0,1
0,0,0,0,0,0,0,0,0,0,0,0,0,0,0,0,0,0,0,0,0,0,0,0,0,1,12,12,12,1,1,1,13,0,0,0,0,1
0,0,0,0,0,0,0,0,0,0,0,0,0,0,0,0,0,0,0,0,0,0,0,0,0,15,0,0,0,0,0,20,13,0,0,0,0,1
0,0,0,0,0,0,0,0,0,0,0,0,0,0,0,0,0,0,0,0,0,1,0,0,0,15,0,25,0,25,0,20,13,0,0,0,0,1
0,0,0,0,0,0,0,0,0,0,0,0,0,0,0,0,0,0,0,0,0,1,1,1,1,1,1,1,1,1,1,1,1,0,0,0,1,1
endlayer

layer
0,0,0,0,0,0,0,0,0,0,0,0,0,0,0,0,0,0,0,0,0,1,1,1,1,1,1,1,0,0,0,1,1,1,1,1,1,1
0,0,0,0,0,0,0,0,0,0,0,0,0,0,0,0,0,0,0,0,0,1,0,0,0,0,0,0,0,0,0,0,0,0,0,1,14,1
0,0,0,0,0,0,0,0,0,0,0,0,0,0,0,0,0,0,0,0,0,1,0,0,0,0,0,0,0,0,0,0,0,0,0,0,1,1
0,0,0,0,0,0,0,0,0,0,0,0,0,0,0,0,0,0,0,0,0,1,0,0,0,0,0,0,0,0,0,0,0,0,0,0,0,1
0,0,0,0,0,0,0,0,0,0,0,0,0,0,0,0,0,0,0,0,0,1,0,0,0,0,0,0,0,0,0,0,0,0,0,0,0,1
0,0,0,0,0,0,0,0,0,0,0,0,0,0,0,0,0,0,0,0,0,1,0,0,0,0,0,0,0,0,0,0,0,0,0,0,0,1
0,0,0,0,0,0,0,0,0,0,0,0,0,0,0,0,0,0,0,0,0,1,0,0,0,0,0,18,18,18,18,18,0,0,0,0,0,1
0,0,0,0,0,0,0,0,0,0,0,0,0,0,0,0,0,0,0,0,0,1,0,0,0,0,0,18,0,28,0,18,0,0,0,0,0,0
0,0,0,0,0,0,0,0,0,0,0,0,0,0,0,0,0,0,0,0,0,1,0,0,0,0,0,18,28,26,28,18,0,0,0,0,0,0
0,0,0,0,0,0,0,0,0,0,0,0,0,0,0,0,0,0,0,0,0,1,0,0,0,0,0,18,0,28,0,18,0,0,0,0,0,0
0,0,0,0,0,0,0,0,0,0,0,0,0,0,0,0,0,0,0,0,0,1,0,0,0,0,0,18,18,18,18,18,0,0,0,0,0,1
0,0,0,0,0,0,0,0,0,0,0,0,0,0,0,0,0,0,0,0,0,1,0,0,0,0,0,0,0,0,0,0,0,0,0,0,0,1
0,0,0,0,0,0,0,0,0,0,0,0,0,0,0,0,0,0,0,0,0,0,0,0,0,0,0,0,0,0,0,0,0,0,0,0,0,1
0,0,0,0,0,0,0,0,0,0,0,0,0,0,0,0,0,0,0,0,0,0,0,0,0,1,18,18,18,1,1,13,0,0,0,0,0,1
0,0,0,0,0,0,0,0,0,0,0,0,0,0,0,0,0,0,0,0,0,0,0,0,0,18,0,0,0,0,20,13,0,0,0,0,0,1
0,0,0,0,0,0,0,0,0,0,0,0,0,0,0,0,0,0,0,0,0,1,0,0,0,18,0,0,0,0,20,13,0,0,0,0,0,1
0,0,0,0,0,0,0,0,0,0,0,0,0,0,0,0,0,0,0,0,0,1,1,1,1,1,1,1,1,1,1,1,1,0,0,0,1,1
endlayer

layer
0,0,0,0,0,0,0,0,0,0,0,0,0,0,0,0,0,0,0,0,0,1,1,1,1,1,1,1,0,0,0,1,1,1,1,1,1,1
0,0,0,0,0,0,0,0,0,0,0,0,0,0,0,0,0,0,0,0,0,1,0,0,0,0,0,0,0,0,0,0,0,0,0,0,1,1
0,0,0,0,0,0,0,0,0,0,0,0,0,0,0,0,0,0,0,0,0,1,0,0,0,0,0,0,0,0,0,0,0,0,0,0,0,1
0,0,0,0,0,0,0,0,0,0,0,0,0,0,0,0,0,0,0,0,0,1,0,0,0,0,0,0,0,0,0,0,0,0,0,0,0,1
0,0,0,0,0,0,0,0,0,0,0,0,0,0,0,0,0,0,0,0,0,1,0,0,0,0,0,0,0,0,0,0,0,0,0,0,0,1
0,0,0,0,0,0,0,0,0,0,0,0,0,0,0,0,0,0,0,0,0,1,0,0,0,0,0,0,0,0,0,0,0,0,0,0,0,1
0,0,0,0,0,0,0,0,0,0,0,0,0,0,0,0,0,0,0,0,0,1,0,0,0,0,0,18,18,18,18,18,0,0,0,0,0,1
0,0,0,0,0,0,0,0,0,0,0,0,0,0,0,0,0,0,0,0,0,1,0,0,0,0,0,18,0,0,0,18,0,0,0,0,0,0
0,0,0,0,0,0,0,0,0,0,0,0,0,0,0,0,0,0,0,0,0,1,0,0,0,0,0,18,0,28,0,18,0,0,0,0,0,0
0,0,0,0,0,0,0,0,0,0,0,0,0,0,0,0,0,0,0,0,0,1,0,0,0,0,0,18,0,0,0,18,0,0,0,0,0,0
0,0,0,0,0,0,0,0,0,0,0,0,0,0,0,0,0,0,0,0,0,1,0,0,0,0,0,18,18,18,18,18,0,0,0,0,0,1
0,0,0,0,0,0,0,0,0,0,0,0,0,0,0,0,0,0,0,0,0,1,0,0,0,0,0,0,0,0,0,0,0,0,0,0,0,1
0,0,0,0,0,0,0,0,0,0,0,0,0,0,0,0,0,0,0,0,0,0,0,0,0,0,0,0,0,0,0,0,0,0,0,0,0,1
0,0,0,0,0,0,0,0,0,0,0,0,0,0,0,0,0,0,0,0,0,0,0,0,0,1,18,18,18,1,13,0,0,0,0,0,0,1
0,0,0,0,0,0,0,0,0,0,0,0,0,0,0,0,0,0,0,0,0,0,0,0,0,18,0,0,0,20,13,0,0,0,0,0,0,1
0,0,0,0,0,0,0,0,0,0,0,0,0,0,0,0,0,0,0,0,0,1,0,0,0,18,0,0,0,20,13,0,0,0,0,0,0,1
0,0,0,0,0,0,0,0,0,0,0,0,0,0,0,0,0,0,0,0,0,1,1,1,1,1,1,1,1,1,1,1,1,0,0,0,1,1
endlayer

layer
0,0,0,0,0,0,0,0,0,0,0,0,0,0,0,0,0,0,0,0,0,1,1,1,1,1,1,1,21,0,20,1,1,1,1,1,1,1
0,0,0,0,0,0,0,0,0,0,0,0,0,0,0,0,0,0,0,0,0,1,0,0,0,0,0,0,0,0,0,0,0,0,0,0,0,1
0,0,0,0,0,0,0,0,0,0,0,0,0,0,0,0,0,0,0,0,0,1,0,0,0,0,0,0,0,0,0,0,0,0,0,0,0,1
0,0,0,0,0,0,0,0,0,0,0,0,0,0,0,0,0,0,0,0,0,1,0,0,0,0,0,0,0,0,0,0,0,0,0,0,0,1
0,0,0,0,0,0,0,0,0,0,0,0,0,0,0,0,0,0,0,0,0,1,0,0,0,0,0,0,0,0,0,0,0,0,0,0,0,1
0,0,0,0,0,0,0,0,0,0,0,0,0,0,0,0,0,0,0,0,0,1,0,0,0,0,0,0,0,0,0,0,0,0,0,0,0,1
0,0,0,0,0,0,0,0,0,0,0,0,0,0,0,0,0,0,0,0,0,1,0,0,0,0,0,18,18,18,18,18,0,0,0,0,0,1
0,0,0,0,0,0,0,0,0,0,0,0,0,0,0,0,0,0,0,0,0,1,0,0,0,0,0,18,0,0,0,18,0,0,0,0,0,22
0,0,0,0,0,0,0,0,0,0,0,0,0,0,0,0,0,0,0,0,0,1,0,0,0,0,0,18,0,0,0,18,0,0,0,0,0,0
0,0,0,0,0,0,0,0,0,0,0,0,0,0,0,0,0,0,0,0,0,1,0,0,0,0,0,18,0,0,0,18,0,0,0,0,0,23
0,0,0,0,0,0,0,0,0,0,0,0,0,0,0,0,0,0,0,0,0,1,0,0,0,0,0,18,18,18,18,18,0,0,0,0,0,1
0,0,0,0,0,0,0,0,0,0,0,0,0,0,0,0,0,0,0,0,0,1,0,0,0,0,0,0,0,0,0,0,0,0,0,0,0,1
0,0,0,0,0,0,0,0,0,0,0,0,0,0,0,0,0,0,0,0,0,22,0,0,0,0,0,0,0,0,0,0,0,0,0,0,0,1
0,0,0,0,0,0,0,0,0,0,0,0,0,0,0,0,0,0,0,0,0,0,0,0,0,1,1,1,1,13,0,0,0,0,0,0,0,1
0,0,0,0,0,0,0,0,0,0,0,0,0,0,0,0,0,0,0,0,0,23,0,0,0,1,0,0,20,13,0,0,0,0,0,0,0,1
0,0,0,0,0,0,0,0,0,0,0,0,0,0,0,0,0,0,0,0,0,1,0,0,0,1,0,0,20,13,0,0,0,0,0,0,0,1
0,0,0,0,0,0,0,0,0,0,0,0,0,0,0,0,0,0,0,0,0,1,1,1,1,1,1,1,1,1,1,1,1,21,0,20,1,1
endlayer

layer
0,0,0,0,0,0,0,0,0,0,0,0,0,0,0,0,0,0,0,0,0,1,1,1,1,1,1,1,1,1,1,1,1,1,1,1,1,1
0,0,0,0,0,0,0,0,0,0,0,0,0,0,0,0,0,0,0,0,0,1,21,22,22,1,0,1,21,22,20,1,1,1,21,22,22,1
0,0,0,0,0,0,0,0,0,0,0,0,0,0,0,0,0,0,0,0,0,1,21,8,20,1,0,1,21,8,20,1,0,1,21,8,20,1
0,0,0,0,0,0,0,0,0,0,0,0,0,0,0,0,0,0,0,0,0,1,23,23,23,1,0,1,23,23,23,1,0,1,21,23,23,1
0,0,0,0,0,0,0,0,0,0,0,0,0,0,0,0,0,0,0,0,0,1,1,1,1,1,1,1,1,1,1,1,1,1,1,1,1,1
0,0,0,0,0,0,0,0,0,0,0,0,0,0,0,0,0,0,0,0,0,1,0,0,0,1,0,1,0,0,0,1,0,1,0,0,0,1
0,0,0,0,0,0,0,0,0,0,0,0,0,0,0,0,0,0,0,0,0,1,1,1,1,1,1,1,1,1,1,1,1,1,1,1,1,1
0,0,0,0,0,0,0,0,0,0,0,0,0,0,0,0,0,0,0,0,0,1,21,22,22,1,0,1,1,1,1,1,0,1,22,22,20,1
0,0,0,0,0,0,0,0,0,0,0,0,0,0,0,0,0,0,0,0,0,1,21,8,20,1,0,1,1,0,1,1,0,1,21,8,20,1
0,0,0,0,0,0,0,0,0,0,0,0,0,0,0,0,0,0,0,0,0,1,23,23,23,1,0,1,1,1,1,1,0,1,23,23,20,1
0,0,0,0,0,0,0,0,0,0,0,0,0,0,0,0,0,0,0,0,0,1,1,1,1,1,1,1,1,1,1,1,1,1,1,1,1,1
0,0,0,0,0,0,0,0,0,0,0,0,0,0,0,0,0,0,0,0,0,1,0,0,0,1,0,1,0,0,0,1,0,1,0,0,0,1
0,0,0,0,0,0,0,0,0,0,0,0,0,0,0,0,0,0,0,0,0,1,1,1,1,1,1,1,1,1,1,1,1,1,1,1,1,1
0,0,0,0,0,0,0,0,0,0,0,0,0,0,0,0,0,0,0,0,0,1,21,22,22,1,0,1,13,0,0,0,0,0,0,0,0,1
0,0,0,0,0,0,0,0,0,0,0,0,0,0,0,0,0,0,0,0,0,1,21,8,20,1,0,1,13,0,0,0,0,0,0,0,0,1
0,0,0,0,0,0,0,0,0,0,0,0,0,0,0,0,0,0,0,0,0,1,21,23,23,1,0,1,13,0,0,0,0,0,0,0,0,1
0,0,0,0,0,0,0,0,0,0,0,0,0,0,0,0,0,0,0,0,0,1,1,1,1,1,1,1,1,1,1,1,1,1,1,1,1,1
endlayer

layer
0,0,0,0,0,0,0,0,0,0,0,0,0,0,0,0,0,0,0,0,0,1,1,1,1,1,1,1,1,1,1,1,1,1,1,1,1,1
0,0,0,0,0,0,0,0,0,0,0,0,0,0,0,0,0,0,0,0,0,1,1,1,1,1,1,1,1,1,1,1,1,1,1,1,1,1
0,0,0,0,0,0,0,0,0,0,0,0,0,0,0,0,0,0,0,0,0,1,1,1,1,1,1,1,1,1,1,1,1,1,1,1,1,1
0,0,0,0,0,0,0,0,0,0,0,0,0,0,0,0,0,0,0,0,0,1,1,1,1,1,1,1,1,1,1,1,1,1,1,1,1,1
0,0,0,0,0,0,0,0,0,0,0,0,0,0,0,0,0,0,0,0,0,1,1,1,1,1,1,1,1,1,1,1,1,1,1,1,1,1
0,0,0,0,0,0,0,0,0,0,0,0,0,0,0,0,0,0,0,0,0,1,1,1,1,1,1,1,1,1,1,1,1,1,1,1,1,1
0,0,0,0,0,0,0,0,0,0,0,0,0,0,0,0,0,0,0,0,0,1,1,1,1,1,1,1,1,1,1,1,1,1,1,1,1,1
0,0,0,0,0,0,0,0,0,0,0,0,0,0,0,0,0,0,0,0,0,1,1,1,1,1,1,1,1,1,1,1,1,1,1,1,1,1
0,0,0,0,0,0,0,0,0,0,0,0,0,0,0,0,0,0,0,0,0,1,1,3,3,3,3,3,1,0,1,1,1,1,1,1,1,1
0,0,0,0,0,0,0,0,0,0,0,0,0,0,0,0,0,0,0,0,0,1,1,3,1,1,1,1,1,1,1,1,1,1,1,3,1,1
0,0,0,0,0,0,0,0,0,0,0,0,0,0,0,0,0,0,0,0,0,1,1,3,1,1,1,1,1,1,1,1,1,1,1,3,1,1
0,0,0,0,0,0,0,0,0,0,0,0,0,0,0,0,0,0,0,0,0,1,1,3,1,1,1,1,1,1,1,1,1,1,1,3,1,1
0,0,0,0,0,0,0,0,0,0,0,0,0,0,0,0,0,0,0,0,0,1,1,3,1,1,1,1,1,1,1,1,1,1,1,3,1,1
0,0,0,0,0,0,0,0,0,0,0,0,0,0,0,0,0,0,0,0,0,1,1,3,1,1,1,13,0,0,0,0,20,1,1,3,1,1
0,0,0,0,0,0,0,0,0,0,0,0,0,0,0,0,0,0,0,0,0,1,1,3,3,3,3,13,0,0,0,0,20,1,3,3,1,1
0,0,0,0,0,0,0,0,0,0,0,0,0,0,0,0,0,0,0,0,0,1,1,1,1,1,1,13,0,0,0,0,20,1,1,1,1,1
0,0,0,0,0,0,0,0,0,0,0,0,0,0,0,0,0,0,0,0,0,1,1,1,1,1,1,1,1,1,1,1,1,1,1,1,1,1
endlayer

layer
0,0,0,0,0,0,0,0,0,0,0,0,0,0,0,0,0,0,0,0,0,1,1,1,1,1,1,1,1,1,1,1,1,1,1,1,1,1
0,0,0,0,0,0,0,0,0,0,0,0,0,0,0,0,0,0,0,0,0,1,0,27,0,27,0,13,0,0,0,0,0,0,0,0,0,1
0,0,0,0,0,0,0,0,0,0,0,0,0,0,0,0,0,0,0,0,0,1,7,0,0,0,0,1,0,0,0,0,0,0,0,0,0,1
0,0,0,0,0,0,0,0,0,0,0,0,0,0,0,0,0,0,0,0,0,1,0,0,26,0,0,13,0,0,0,0,0,0,0,0,0,1
0,0,0,0,0,0,0,0,0,0,0,0,0,0,0,0,0,0,0,0,0,1,7,0,0,0,0,1,0,0,0,1,1,1,0,0,0,1
0,0,0,0,0,0,0,0,0,0,0,0,0,0,0,0,0,0,0,0,0,1,0,0,0,0,0,13,0,0,0,1,4,1,0,0,0,1
0,0,0,0,0,0,0,0,0,0,0,0,0,0,0,0,0,0,0,0,0,1,17,1,17,1,17,1,0,0,0,1,1,1,0,0,0,1
0,0,0,0,0,0,0,0,0,0,0,0,0,0,0,0,0,0,0,0,0,1,0,0,0,0,0,0,0,0,0,1,4,1,0,0,0,1
0,0,0,0,0,0,0,0,0,0,0,0,0,0,0,0,0,0,0,0,0,1,0,0,0,0,0,0,0,0,0,1,1,1,0,0,0,1
0,0,0,0,0,0,0,0,0,0,0,0,0,0,0,0,0,0,0,0,0,1,0,0,0,0,0,0,0,0,0,1,4,1,0,0,0,1
0,0,0,0,0,0,0,0,0,0,0,0,0,0,0,0,0,0,0,0,0,1,0,0,0,1,1,1,1,1,1,1,1,1,0,0,0,1
0,0,0,0,0,0,0,0,0,0,0,0,0,0,0,0,0,0,0,0,0,1,0,0,0,1,4,1,4,1,4,1,4,1,0,0,0,1
0,0,0,0,0,0,0,0,0,0,0,0,0,0,0,0,0,0,0,0,0,1,0,0,0,1,1,1,1,1,1,1,1,1,0,0,0,1
0,0,0,0,0,0,0,0,0,0,0,0,0,0,0,0,0,0,0,0,0,1,0,0,0,0,0,0,0,0,0,0,1,13,0,0,0,1
0,0,0,0,0,0,0,0,0,0,0,0,0,0,0,0,0,0,0,0,0,1,0,0,0,0,0,0,0,0,0,0,1,13,0,0,0,1
0,0,0,0,0,0,0,0,0,0,0,0,0,0,0,0,0,0,0,0,0,1,0,0,0,0,0,0,0,0,0,0,1,13,0,0,0,1
0,0,0,0,0,0,0,0,0,0,0,0,0,0,0,0,0,0,0,0,0,1,1,1,1,1,1,1,1,1,1,1,1,1,1,1,1,1
endlayer

layer
0,0,0,0,0,0,0,0,0,0,0,0,0,0,0,0,0,0,0,0,0,1,1,1,1,1,1,1,1,1,1,1,1,1,1,1,1,1
0,0,0,0,0,0,0,0,0,0,0,0,0,0,0,0,0,0,0,0,0,1,0,0,0,0,0,18,0,0,0,0,0,0,0,0,0,1
0,0,0,0,0,0,0,0,0,0,0,0,0,0,0,0,0,0,0,0,0,1,0,0,0,0,0,1,0,0,0,0,0,0,0,0,0,1
0,0,0,0,0,0,0,0,0,0,0,0,0,0,0,0,0,0,0,0,0,1,0,0,0,0,0,18,0,0,0,0,0,0,0,0,0,1
0,0,0,0,0,0,0,0,0,0,0,0,0,0,0,0,0,0,0,0,0,1,0,0,0,0,0,1,0,0,0,1,1,1,0,0,0,1
0,0,0,0,0,0,0,0,0,0,0,0,0,0,0,0,0,0,0,0,0,1,0,0,0,0,0,18,0,0,0,18,4,18,0,0,0,1
0,0,0,0,0,0,0,0,0,0,0,0,0,0,0,0,0,0,0,0,0,1,18,1,18,1,18,1,0,0,0,1,0,1,0,0,0,1
0,0,0,0,0,0,0,0,0,0,0,0,0,0,0,0,0,0,0,0,0,1,0,0,0,0,0,0,0,0,0,1,4,1,0,0,0,1
0,0,0,0,0,0,0,0,0,0,0,0,0,0,0,0,0,0,0,0,0,1,0,0,0,0,0,0,0,0,0,1,0,1,0,0,0,1
0,0,0,0,0,0,0,0,0,0,0,0,0,0,0,0,0,0,0,0,0,1,0,0,0,0,0,0,0,0,0,18,4,1,0,0,0,1
0,0,0,0,0,0,0,0,0,0,0,0,0,0,0,0,0,0,0,0,0,1,0,0,0,1,18,1,1,1,18,1,0,1,0,0,0,1
0,0,0,0,0,0,0,0,0,0,0,0,0,0,0,0,0,0,0,0,0,1,0,0,0,1,4,0,4,0,4,0,4,18,0,0,0,1
0,0,0,0,0,0,0,0,0,0,0,0,0,0,0,0,0,0,0,0,0,1,0,0,0,1,1,1,18,1,1,1,1,1,0,0,0,1
0,0,0,0,0,0,0,0,0,0,0,0,0,0,0,0,0,0,0,0,0,1,0,0,0,0,0,0,0,0,0,1,13,0,0,0,0,1
0,0,0,0,0,0,0,0,0,0,0,0,0,0,0,0,0,0,0,0,0,1,0,0,0,0,0,0,0,0,0,1,13,0,0,0,0,1
0,0,0,0,0,0,0,0,0,0,0,0,0,0,0,0,0,0,0,0,0,1,0,0,0,0,0,0,0,0,0,1,13,0,0,0,0,1
0,0,0,0,0,0,0,0,0,0,0,0,0,0,0,0,0,0,0,0,0,1,1,1,1,1,1,1,1,1,1,1,1,1,1,1,1,1
endlayer

layer
0,0,0,0,0,0,0,0,0,0,0,0,0,0,0,0,0,0,0,0,0,1,1,1,1,1,1,1,1,1,1,1,1,1,1,1,1,1
0,0,0,0,0,0,0,0,0,0,0,0,0,0,0,0,0,0,0,0,0,1,0,0,0,0,0,18,0,0,0,0,0,0,0,0,0,1
0,0,0,0,0,0,0,0,0,0,0,0,0,0,0,0,0,0,0,0,0,1,0,0,0,0,0,1,0,0,0,0,0,0,0,0,0,1
0,0,0,0,0,0,0,0,0,0,0,0,0,0,0,0,0,0,0,0,0,1,0,0,0,0,0,18,0,0,0,0,0,0,0,0,0,1
0,0,0,0,0,0,0,0,0,0,0,0,0,0,0,0,0,0,0,0,0,1,0,0,0,0,0,1,0,0,0,1,1,1,0,0,0,1
0,0,0,0,0,0,0,0,0,0,0,0,0,0,0,0,0,0,0,0,0,1,0,0,0,0,0,18,0,0,0,18,4,18,0,0,0,1
0,0,0,0,0,0,0,0,0,0,0,0,0,0,0,0,0,0,0,0,0,1,18,1,18,1,18,1,0,0,0,1,0,1,0,0,0,1
0,0,0,0,0,0,0,0,0,0,0,0,0,0,0,0,0,0,0,0,0,1,0,0,0,0,0,0,0,0,0,1,4,1,0,0,0,1
0,0,0,0,0,0,0,0,0,0,0,0,0,0,0,0,0,0,0,0,0,1,0,0,0,0,0,0,0,0,0,1,0,1,0,0,0,1
0,0,0,0,0,0,0,0,0,0,0,0,0,0,0,0,0,0,0,0,0,1,0,0,0,0,0,0,0,0,0,18,4,1,0,0,0,1
0,0,0,0,0,0,0,0,0,0,0,0,0,0,0,0,0,0,0,0,0,1,0,0,0,1,18,1,1,1,18,1,0,1,0,0,0,1
0,0,0,0,0,0,0,0,0,0,0,0,0,0,0,0,0,0,0,0,0,1,0,0,0,1,4,0,4,0,4,0,4,18,0,0,0,1
0,0,0,0,0,0,0,0,0,0,0,0,0,0,0,0,0,0,0,0,0,1,0,0,0,1,1,1,18,1,1,1,1,1,0,0,0,1
0,0,0,0,0,0,0,0,0,0,0,0,0,0,0,0,0,0,0,0,0,1,0,0,0,0,0,0,0,0,1,13,0,0,0,0,0,1
0,0,0,0,0,0,0,0,0,0,0,0,0,0,0,0,0,0,0,0,0,1,0,0,0,0,0,0,0,0,1,13,0,0,0,0,0,1
0,0,0,0,0,0,0,0,0,0,0,0,0,0,0,0,0,0,0,0,0,1,0,0,0,0,0,0,0,0,1,13,0,0,0,0,0,1
0,0,0,0,0,0,0,0,0,0,0,0,0,0,0,0,0,0,0,0,0,1,1,1,1,1,1,1,1,1,1,1,1,1,1,1,1,1
endlayer

layer
0,0,0,0,0,0,0,0,0,0,0,0,0,0,0,0,0,0,0,0,0,1,1,1,1,1,1,1,1,1,1,1,1,1,1,1,1,1
0,0,0,0,0,0,0,0,0,0,0,0,0,0,0,0,0,0,0,0,0,1,0,0,0,0,0,21,0,0,0,0,0,0,0,0,0,1
0,0,0,0,0,0,0,0,0,0,0,0,0,0,0,0,0,0,0,0,0,1,0,0,0,0,0,1,0,0,0,0,0,0,0,0,0,1
0,0,0,0,0,0,0,0,0,0,0,0,0,0,0,0,0,0,0,0,0,1,0,0,0,0,0,21,0,0,0,0,0,0,0,0,0,1
0,0,0,0,0,0,0,0,0,0,0,0,0,0,0,0,0,0,0,0,0,1,0,0,0,0,0,1,0,0,0,1,1,1,0,0,0,1
0,0,0,0,0,0,0,0,0,0,0,0,0,0,0,0,0,0,0,0,0,1,0,0,0,0,0,21,0,0,0,18,4,18,0,0,0,1
0,0,0,0,0,0,0,0,0,0,0,0,0,0,0,0,0,0,0,0,0,1,22,1,22,1,22,1,0,0,0,1,0,1,0,0,0,1
0,0,0,0,0,0,0,0,0,0,0,0,0,0,0,0,0,0,0,0,0,1,0,0,0,0,0,0,0,0,0,1,4,1,0,0,0,1
0,0,0,0,0,0,0,0,0,0,0,0,0,0,0,0,0,0,0,0,0,1,0,0,0,0,0,0,0,0,0,1,0,1,0,0,0,1
0,0,0,0,0,0,0,0,0,0,0,0,0,0,0,0,0,0,0,0,0,1,0,0,0,0,0,0,0,0,0,18,4,1,0,0,0,1
0,0,0,0,0,0,0,0,0,0,0,0,0,0,0,0,0,0,0,0,0,1,0,0,0,1,18,1,1,1,18,1,0,1,0,0,0,1
0,0,0,0,0,0,0,0,0,0,0,0,0,0,0,0,0,0,0,0,0,1,0,0,0,1,4,0,4,0,4,0,4,18,0,0,0,1
0,0,0,0,0,0,0,0,0,0,0,0,0,0,0,0,0,0,0,0,0,1,0,0,0,1,1,1,1,1,1,1,1,1,0,0,0,1
0,0,0,0,0,0,0,0,0,0,0,0,0,0,0,0,0,0,0,0,0,1,0,0,0,0,0,0,0,1,13,0,0,0,0,0,0,1
0,0,0,0,0,0,0,0,0,0,0,0,0,0,0,0,0,0,0,0,0,1,0,0,0,0,0,0,0,1,13,0,0,0,0,0,0,1
0,0,0,0,0,0,0,0,0,0,0,0,0,0,0,0,0,0,0,0,0,1,0,0,0,0,0,0,0,1,13,0,0,0,0,0,0,1
0,0,0,0,0,0,0,0,0,0,0,0,0,0,0,0,0,0,0,0,0,1,1,1,1,1,1,1,1,1,1,1,1,1,1,1,1,1
endlayer

layer
0,0,0,0,0,0,0,0,0,0,0,0,0,0,0,0,0,0,0,0,0,1,1,1,1,1,1,1,1,1,1,1,1,1,1,1,1,1
0,0,0,0,0,0,0,0,0,0,0,0,0,0,0,0,0,0,0,0,0,1,0,0,0,0,0,1,0,0,0,0,0,0,0,0,0,1
0,0,0,0,0,0,0,0,0,0,0,0,0,0,0,0,0,0,0,0,0,1,0,0,0,0,0,1,0,0,0,0,0,0,0,0,0,1
0,0,0,0,0,0,0,0,0,0,0,0,0,0,0,0,0,0,0,0,0,1,0,0,0,0,0,1,0,0,0,0,0,0,0,0,0,1
0,0,0,0,0,0,0,0,0,0,0,0,0,0,0,0,0,0,0,0,0,1,0,0,0,0,0,1,0,0,0,1,1,1,0,0,0,1
0,0,0,0,0,0,0,0,0,0,0,0,0,0,0,0,0,0,0,0,0,1,0,0,0,0,0,1,0,0,0,1,14,1,0,0,0,1
0,0,0,0,0,0,0,0,0,0,0,0,0,0,0,0,0,0,0,0,0,1,1,1,1,1,1,1,0,0,0,1,1,1,0,0,0,1
0,0,0,0,0,0,0,0,0,0,0,0,0,0,0,0,0,0,0,0,0,1,0,0,0,0,0,0,0,0,0,1,14,1,0,0,0,1
0,0,0,0,0,0,0,0,0,0,0,0,0,0,0,0,0,0,0,0,0,1,0,0,0,0,0,0,0,0,0,1,1,1,0,0,0,1
0,0,0,0,0,0,0,0,0,0,0,0,0,0,0,0,0,0,0,0,0,1,0,0,0,0,0,0,0,0,0,1,14,1,0,0,0,1
0,0,0,0,0,0,0,0,0,0,0,0,0,0,0,0,0,0,0,0,0,1,0,0,0,1,1,1,1,1,1,1,1,1,0,0,0,1
0,0,0,0,0,0,0,0,0,0,0,0,0,0,0,0,0,0,0,0,0,1,0,0,0,1,14,1,14,1,14,1,14,1,0,0,0,1
0,0,0,0,0,0,0,0,0,0,0,0,0,0,0,0,0,0,0,0,0,1,0,0,0,1,1,1,1,1,1,1,1,1,0,0,0,1
0,0,0,0,0,0,0,0,0,0,0,0,0,0,0,0,0,0,0,0,0,1,0,0,0,0,0,0,1,13,0,0,0,0,0,0,0,1
0,0,0,0,0,0,0,0,0,0,0,0,0,0,0,0,0,0,0,0,0,1,0,0,0,0,0,0,1,13,0,0,0,0,0,0,0,1
0,0,0,0,0,0,0,0,0,0,0,0,0,0,0,0,0,0,0,0,0,1,0,0,0,0,0,0,1,13,0,0,0,0,0,0,0,1
0,0,0,0,0,0,0,0,0,0,0,0,0,0,0,0,0,0,0,0,0,1,1,1,1,1,1,1,1,1,1,1,1,1,1,1,1,1
endlayer

layer
0,0,0,0,0,0,0,0,0,0,0,0,0,0,0,0,0,0,0,0,0,1,1,1,1,1,1,1,1,1,1,1,1,1,1,1,1,1
0,0,0,0,0,0,0,0,0,0,0,0,0,0,0,0,0,0,0,0,0,1,1,1,1,1,1,1,1,1,1,1,1,1,1,1,1,1
0,0,0,0,0,0,0,0,0,0,0,0,0,0,0,0,0,0,0,0,0,1,1,1,1,1,1,1,1,1,1,1,1,1,1,1,1,1
0,0,0,0,0,0,0,0,0,0,0,0,0,0,0,0,0,0,0,0,0,1,1,1,1,1,1,1,1,1,1,1,1,1,1,1,1,1
0,0,0,0,0,0,0,0,0,0,0,0,0,0,0,0,0,0,0,0,0,1,1,1,1,1,1,1,1,1,1,1,1,1,1,1,1,1
0,0,0,0,0,0,0,0,0,0,0,0,0,0,0,0,0,0,0,0,0,1,1,1,1,1,1,1,1,1,1,1,1,1,1,1,1,1
0,0,0,0,0,0,0,0,0,0,0,0,0,0,0,0,0,0,0,0,0,1,1,1,1,1,1,1,1,1,1,1,1,1,1,1,1,1
0,0,0,0,0,0,0,0,0,0,0,0,0,0,0,0,0,0,0,0,0,1,1,1,1,1,1,1,1,1,1,1,1,1,1,1,1,1
0,0,0,0,0,0,0,0,0,0,0,0,0,0,0,0,0,0,0,0,0,1,1,1,1,1,1,1,1,0,1,1,1,1,1,1,1,1
0,0,0,0,0,0,0,0,0,0,0,0,0,0,0,0,0,0,0,0,0,1,1,1,1,1,1,1,1,1,1,1,1,1,1,1,1,1
0,0,0,0,0,0,0,0,0,0,0,0,0,0,0,0,0,0,0,0,0,1,1,1,1,1,1,1,1,1,1,1,1,1,1,1,1,1
0,0,0,0,0,0,0,0,0,0,0,0,0,0,0,0,0,0,0,0,0,1,1,1,1,1,1,1,1,1,1,1,1,1,1,1,1,1
0,0,0,0,0,0,0,0,0,0,0,0,0,0,0,0,0,0,0,0,0,1,1,1,1,1,1,1,1,1,1,1,1,1,1,1,1,1
0,0,0,0,0,0,0,0,0,0,0,0,0,0,0,0,0,0,0,0,0,1,1,1,1,1,1,1,13,0,0,0,0,1,1,1,1,1
0,0,0,0,0,0,0,0,0,0,0,0,0,0,0,0,0,0,0,0,0,1,1,1,1,1,1,1,13,0,0,0,0,1,1,1,1,1
0,0,0,0,0,0,0,0,0,0,0,0,0,0,0,0,0,0,0,0,0,1,1,1,1,1,1,1,13,0,0,0,0,1,1,1,1,1
0,0,0,0,0,0,0,0,0,0,0,0,0,0,0,0,0,0,0,0,0,1,1,1,1,1,1,1,1,1,1,1,1,1,1,1,1,1
endlayer

layer
0,0,0,0,0,0,0,0,0,0,0,0,0,0,0,0,0,0,0,0,0,1,1,1,1,1,1,1,1,1,1,1,1,1,1,1,1,1
0,0,0,0,0,0,0,0,0,0,0,0,0,0,0,0,0,0,0,0,0,1,1,27,18,0,0,0,0,0,0,0,0,0,18,27,1,1
0,0,0,0,0,0,0,0,0,0,0,0,0,0,0,0,0,0,0,0,0,1,7,18,18,0,0,0,0,0,0,0,0,0,18,18,16,1
0,0,0,0,0,0,0,0,0,0,0,0,0,0,0,0,0,0,0,0,0,1,18,18,0,0,0,0,0,0,0,0,0,0,0,18,18,1
0,0,0,0,0,0,0,0,0,0,0,0,0,0,0,0,0,0,0,0,0,1,0,0,0,1,1,13,9,9,9,15,1,1,0,0,0,1
0,0,0,0,0,0,0,0,0,0,0,0,0,0,0,0,0,0,0,0,0,1,0,0,0,1,0,0,0,0,0,0,0,1,0,0,0,1
0,0,0,0,0,0,0,0,0,0,0,0,0,0,0,0,0,0,0,0,0,1,0,0,0,17,0,1,0,0,0,1,0,17,0,0,0,1
0,0,0,0,0,0,0,0,0,0,0,0,0,0,0,0,0,0,0,0,0,1,0,0,0,9,0,0,0,0,0,0,0,9,0,0,0,1
0,0,0,0,0,0,0,0,0,0,0,0,0,0,0,0,0,0,0,0,0,1,0,0,0,9,0,0,0,0,0,0,0,9,0,0,0,1
0,0,0,0,0,0,0,0,0,0,0,0,0,0,0,0,0,0,0,0,0,1,0,0,0,9,0,0,0,0,0,0,0,9,0,0,0,1
0,0,0,0,0,0,0,0,0,0,0,0,0,0,0,0,0,0,0,0,0,1,0,0,0,12,0,1,0,0,0,1,0,12,0,0,0,1
0,0,0,0,0,0,0,0,0,0,0,0,0,0,0,0,0,0,0,0,0,1,0,0,0,1,0,0,0,0,0,0,0,1,0,0,0,1
0,0,0,0,0,0,0,0,0,0,0,0,0,0,0,0,0,0,0,0,0,1,0,0,0,1,1,13,9,9,9,15,1,1,0,0,0,1
0,0,0,0,0,0,0,0,0,0,0,0,0,0,0,0,0,0,0,0,0,1,18,18,0,0,0,0,0,0,0,0,0,18,0,0,12,1
0,0,0,0,0,0,0,0,0,0,0,0,0,0,0,0,0,0,0,0,0,1,7,18,18,0,0,0,0,0,0,0,0,18,0,0,1,1
0,0,0,0,0,0,0,0,0,0,0,0,0,0,0,0,0,0,0,0,0,1,1,25,18,0,0,0,0,0,0,0,0,18,25,0,1,1
0,0,0,0,0,0,0,0,0,0,0,0,0,0,0,0,0,0,0,0,0,1,1,1,1,1,1,1,1,1,1,1,1,1,1,1,1,1
endlayer

layer
0,0,0,0,0,0,0,0,0,0,0,0,0,0,0,0,0,0,0,0,0,1,1,1,1,1,1,1,1,1,1,1,1,1,1,1,1,1
0,0,0,0,0,0,0,0,0,0,0,0,0,0,0,0,0,0,0,0,0,1,14,1,0,0,0,0,0,0,0,0,0,0,0,1,14,1
0,0,0,0,0,0,0,0,0,0,0,0,0,0,0,0,0,0,0,0,0,1,1,0,0,0,0,0,0,0,0,0,0,0,0,0,1,1
0,0,0,0,0,0,0,0,0,0,0,0,0,0,0,0,0,0,0,0,0,1,0,0,0,0,0,0,0,0,0,0,0,0,0,0,0,1
0,0,0,0,0,0,0,0,0,0,0,0,0,0,0,0,0,0,0,0,0,1,0,0,0,1,13,0,0,0,0,0,15,1,0,0,0,1
0,0,0,0,0,0,0,0,0,0,0,0,0,0,0,0,0,0,0,0,0,1,0,0,0,17,0,0,0,0,0,0,0,17,0,0,0,1
0,0,0,0,0,0,0,0,0,0,0,0,0,0,0,0,0,0,0,0,0,1,0,0,0,0,0,0,0,0,0,0,0,0,0,0,0,1
0,0,0,0,0,0,0,0,0,0,0,0,0,0,0,0,0,0,0,0,0,1,0,0,0,0,0,0,0,0,0,0,0,0,0,0,0,1
0,0,0,0,0,0,0,0,0,0,0,0,0,0,0,0,0,0,0,0,0,1,0,0,0,0,0,0,0,0,0,0,0,0,0,0,0,1
0,0,0,0,0,0,0,0,0,0,0,0,0,0,0,0,0,0,0,0,0,1,0,0,0,0,0,0,0,0,0,0,0,0,0,0,0,1
0,0,0,0,0,0,0,0,0,0,0,0,0,0,0,0,0,0,0,0,0,1,0,0,0,0,0,0,0,0,0,0,0,0,0,0,0,1
0,0,0,0,0,0,0,0,0,0,0,0,0,0,0,0,0,0,0,0,0,1,0,0,0,12,0,0,0,0,0,0,0,12,0,0,0,1
0,0,0,0,0,0,0,0,0,0,0,0,0,0,0,0,0,0,0,0,0,1,0,0,0,1,13,18,18,18,18,18,15,1,0,0,0,1
0,0,0,0,0,0,0,0,0,0,0,0,0,0,0,0,0,0,0,0,0,1,0,0,0,0,0,0,0,0,0,0,0,18,0,0,0,1
0,0,0,0,0,0,0,0,0,0,0,0,0,0,0,0,0,0,0,0,0,1,1,0,0,0,0,0,0,0,0,0,0,18,0,0,12,1
0,0,0,0,0,0,0,0,0,0,0,0,0,0,0,0,0,0,0,0,0,1,14,1,0,0,0,0,0,0,0,0,0,18,0,20,1,1
0,0,0,0,0,0,0,0,0,0,0,0,0,0,0,0,0,0,0,0,0,1,1,1,1,1,1,1,1,1,1,1,1,1,1,1,1,1
endlayer

layer
0,0,0,0,0,0,0,0,0,0,0,0,0,0,0,0,0,0,0,0,0,1,1,1,1,1,1,1,1,1,1,1,1,1,1,1,1,1
0,0,0,0,0,0,0,0,0,0,0,0,0,0,0,0,0,0,0,0,0,1,1,0,0,0,0,0,0,0,0,0,0,0,0,0,1,1
0,0,0,0,0,0,0,0,0,0,0,0,0,0,0,0,0,0,0,0,0,1,0,0,0,0,0,0,0,0,0,0,0,0,0,0,0,1
0,0,0,0,0,0,0,0,0,0,0,0,0,0,0,0,0,0,0,0,0,1,0,0,0,0,0,0,0,0,0,0,0,0,0,0,0,1
0,0,0,0,0,0,0,0,0,0,0,0,0,0,0,0,0,0,0,0,0,1,0,0,0,1,0,0,0,0,0,0,0,1,0,0,0,1
0,0,0,0,0,0,0,0,0,0,0,0,0,0,0,0,0,0,0,0,0,1,0,0,0,0,0,0,0,0,0,0,0,0,0,0,0,1
0,0,0,0,0,0,0,0,0,0,0,0,0,0,0,0,0,0,0,0,0,1,0,0,0,0,0,0,0,0,0,0,0,0,0,0,0,1
0,0,0,0,0,0,0,0,0,0,0,0,0,0,0,0,0,0,0,0,0,1,0,0,0,0,0,0,28,28,28,0,0,0,0,0,0,1
0,0,0,0,0,0,0,0,0,0,0,0,0,0,0,0,0,0,0,0,0,1,0,0,0,0,0,0,28,28,28,0,0,0,0,0,0,1
0,0,0,0,0,0,0,0,0,0,0,0,0,0,0,0,0,0,0,0,0,1,0,0,0,0,0,0,28,28,28,0,0,0,0,0,0,1
0,0,0,0,0,0,0,0,0,0,0,0,0,0,0,0,0,0,0,0,0,1,0,0,0,0,0,0,0,0,0,0,0,0,0,0,0,1
0,0,0,0,0,0,0,0,0,0,0,0,0,0,0,0,0,0,0,0,0,1,0,0,0,0,0,0,0,0,0,0,0,0,0,0,0,1
0,0,0,0,0,0,0,0,0,0,0,0,0,0,0,0,0,0,0,0,0,1,0,0,0,1,0,0,0,0,0,0,0,1,0,0,0,1
0,0,0,0,0,0,0,0,0,0,0,0,0,0,0,0,0,0,0,0,0,1,0,0,0,0,0,0,0,0,0,0,0,18,0,0,0,1
0,0,0,0,0,0,0,0,0,0,0,0,0,0,0,0,0,0,0,0,0,1,0,0,0,0,0,0,0,0,0,0,0,18,0,0,0,1
0,0,0,0,0,0,0,0,0,0,0,0,0,0,0,0,0,0,0,0,0,1,1,0,0,0,0,0,0,0,0,0,0,18,8,13,0,1
0,0,0,0,0,0,0,0,0,0,0,0,0,0,0,0,0,0,0,0,0,1,1,1,1,1,1,1,1,1,1,1,1,1,1,1,1,1
endlayer

layer
0,0,0,0,0,0,0,0,0,0,0,0,0,0,0,0,0,0,0,0,0,1,1,1,1,1,1,1,1,1,1,1,1,1,1,1,1,1
0,0,0,0,0,0,0,0,0,0,0,0,0,0,0,0,0,0,0,0,0,1,0,0,0,0,0,0,0,0,0,0,0,0,0,0,0,1
0,0,0,0,0,0,0,0,0,0,0,0,0,0,0,0,0,0,0,0,0,1,0,0,0,0,0,0,0,0,0,0,0,0,0,0,0,1
0,0,0,0,0,0,0,0,0,0,0,0,0,0,0,0,0,0,0,0,0,1,0,0,0,0,0,0,0,0,0,0,0,0,0,0,0,1
0,0,0,0,0,0,0,0,0,0,0,0,0,0,0,0,0,0,0,0,0,1,0,0,0,1,0,0,0,0,0,0,0,1,0,0,0,1
0,0,0,0,0,0,0,0,0,0,0,0,0,0,0,0,0,0,0,0,0,1,0,0,0,0,0,0,0,0,0,0,0,0,0,0,0,1
0,0,0,0,0,0,0,0,0,0,0,0,0,0,0,0,0,0,0,0,0,1,0,0,0,0,0,0,0,0,0,0,0,0,0,0,0,1
0,0,0,0,0,0,0,0,0,0,0,0,0,0,0,0,0,0,0,0,0,1,0,0,0,0,0,0,28,28,28,0,0,0,0,0,0,1
0,0,0,0,0,0,0,0,0,0,0,0,0,0,0,0,0,0,0,0,0,1,0,0,0,0,0,0,28,26,28,0,0,0,0,0,0,1
0,0,0,0,0,0,0,0,0,0,0,0,0,0,0,0,0,0,0,0,0,1,0,0,0,0,0,0,28,28,28,0,0,0,0,0,0,1
0,0,0,0,0,0,0,0,0,0,0,0,0,0,0,0,0,0,0,0,0,1,0,0,0,0,0,0,0,0,0,0,0,0,0,0,0,1
0,0,0,0,0,0,0,0,0,0,0,0,0,0,0,0,0,0,0,0,0,1,0,0,0,0,0,0,0,0,0,0,0,0,0,0,0,1
0,0,0,0,0,0,0,0,0,0,0,0,0,0,0,0,0,0,0,0,0,1,0,0,0,1,0,0,0,0,0,0,0,1,18,18,18,1
0,0,0,0,0,0,0,0,0,0,0,0,0,0,0,0,0,0,0,0,0,1,0,0,0,0,0,0,0,0,0,0,0,18,8,0,0,1
0,0,0,0,0,0,0,0,0,0,0,0,0,0,0,0,0,0,0,0,0,1,0,0,0,0,0,0,0,0,0,0,0,18,17,0,0,1
0,0,0,0,0,0,0,0,0,0,0,0,0,0,0,0,0,0,0,0,0,1,0,0,0,0,0,0,0,0,0,0,0,18,0,0,0,1
0,0,0,0,0,0,0,0,0,0,0,0,0,0,0,0,0,0,0,0,0,1,1,1,1,1,1,1,1,1,1,1,1,1,1,1,1,1
endlayer

layer
0,0,0,0,0,0,0,0,0,0,0,0,0,0,0,0,0,0,0,0,0,1,1,1,1,1,1,1,1,1,1,1,1,1,1,1,1,1
0,0,0,0,0,0,0,0,0,0,0,0,0,0,0,0,0,0,0,0,0,1,0,0,0,0,0,0,0,0,0,0,0,0,0,0,0,1
0,0,0,0,0,0,0,0,0,0,0,0,0,0,0,0,0,0,0,0,0,1,0,0,0,0,0,0,0,0,0,0,0,0,0,0,0,1
0,0,0,0,0,0,0,0,0,0,0,0,0,0,0,0,0,0,0,0,0,1,0,0,0,0,0,0,0,0,0,0,0,0,0,0,0,1
0,0,0,0,0,0,0,0,0,0,0,0,0,0,0,0,0,0,0,0,0,1,0,0,0,1,0,0,0,0,0,0,0,1,0,0,0,1
0,0,0,0,0,0,0,0,0,0,0,0,0,0,0,0,0,0,0,0,0,1,0,0,0,0,0,0,0,0,0,0,0,0,0,0,0,1
0,0,0,0,0,0,0,0,0,0,0,0,0,0,0,0,0,0,0,0,0,1,0,0,0,0,0,0,0,0,0,0,0,0,0,0,0,1
0,0,0,0,0,0,0,0,0,0,0,0,0,0,0,0,0,0,0,0,0,1,0,0,0,0,0,0,28,28,28,0,0,0,0,0,0,1
0,0,0,0,0,0,0,0,0,0,0,0,0,0,0,0,0,0,0,0,0,1,0,0,0,0,0,0,28,28,28,0,0,0,0,0,0,1
0,0,0,0,0,0,0,0,0,0,0,0,0,0,0,0,0,0,0,0,0,1,0,0,0,0,0,0,28,28,28,0,0,0,0,0,0,1
0,0,0,0,0,0,0,0,0,0,0,0,0,0,0,0,0,0,0,0,0,1,0,0,0,0,0,0,0,0,0,0,0,0,0,0,0,1
0,0,0,0,0,0,0,0,0,0,0,0,0,0,0,0,0,0,0,0,0,1,0,0,0,0,0,0,0,0,0,0,0,0,0,0,0,1
0,0,0,0,0,0,0,0,0,0,0,0,0,0,0,0,0,0,0,0,0,1,0,0,0,1,0,0,0,0,0,0,0,1,18,18,18,1
0,0,0,0,0,0,0,0,0,0,0,0,0,0,0,0,0,0,0,0,0,1,0,0,0,0,0,0,0,0,0,0,0,18,0,15,8,1
0,0,0,0,0,0,0,0,0,0,0,0,0,0,0,0,0,0,0,0,0,1,0,0,0,0,0,0,0,0,0,0,0,18,0,0,0,1
0,0,0,0,0,0,0,0,0,0,0,0,0,0,0,0,0,0,0,0,0,1,0,0,0,0,0,0,0,0,0,0,0,18,0,0,0,1
0,0,0,0,0,0,0,0,0,0,0,0,0,0,0,0,0,0,0,0,0,1,1,1,1,1,1,1,1,1,1,1,1,1,1,1,1,1
endlayer

layer
0,0,0,0,0,0,0,0,0,0,0,0,0,0,0,0,0,0,0,0,0,1,1,1,1,1,1,1,1,1,1,1,1,1,1,1,1,1
0,0,0,0,0,0,0,0,0,0,0,0,0,0,0,0,0,0,0,0,0,1,22,22,22,22,22,22,22,22,22,22,22,22,22,22,20,1
0,0,0,0,0,0,0,0,0,0,0,0,0,0,0,0,0,0,0,0,0,1,21,8,8,0,0,0,0,0,0,0,0,0,8,8,20,1
0,0,0,0,0,0,0,0,0,0,0,0,0,0,0,0,0,0,0,0,0,1,21,8,8,23,0,0,0,0,0,0,0,23,8,8,20,1
0,0,0,0,0,0,0,0,0,0,0,0,0,0,0,0,0,0,0,0,0,1,21,0,20,1,21,0,0,0,0,0,20,1,21,0,20,1
0,0,0,0,0,0,0,0,0,0,0,0,0,0,0,0,0,0,0,0,0,1,21,0,0,22,0,0,0,0,0,0,0,22,0,0,20,1
0,0,0,0,0,0,0,0,0,0,0,0,0,0,0,0,0,0,0,0,0,1,21,0,0,0,0,0,0,0,0,0,0,0,0,0,20,1
0,0,0,0,0,0,0,0,0,0,0,0,0,0,0,0,0,0,0,0,0,1,21,0,0,0,0,0,0,0,0,0,0,0,0,0,20,1
0,0,0,0,0,0,0,0,0,0,0,0,0,0,0,0,0,0,0,0,0,1,21,0,0,0,0,0,0,28,0,0,0,0,0,0,20,1
0,0,0,0,0,0,0,0,0,0,0,0,0,0,0,0,0,0,0,0,0,1,21,0,0,0,0,0,0,0,0,0,0,0,0,0,20,1
0,0,0,0,0,0,0,0,0,0,0,0,0,0,0,0,0,0,0,0,0,1,21,0,0,0,0,0,0,0,0,0,0,0,0,0,20,1
0,0,0,0,0,0,0,0,0,0,0,0,0,0,0,0,0,0,0,0,0,1,21,0,0,23,0,0,0,0,0,0,0,23,0,0,20,1
0,0,0,0,0,0,0,0,0,0,0,0,0,0,0,0,0,0,0,0,0,1,21,0,20,1,21,0,0,0,0,0,20,1,21,0,20,1
0,0,0,0,0,0,0,0,0,0,0,0,0,0,0,0,0,0,0,0,0,1,21,8,8,22,0,0,0,0,0,0,0,22,0,0,0,1
0,0,0,0,0,0,0,0,0,0,0,0,0,0,0,0,0,0,0,0,0,1,21,8,8,0,0,0,0,0,0,0,0,0,0,0,12,1
0,0,0,0,0,0,0,0,0,0,0,0,0,0,0,0,0,0,0,0,0,1,21,23,23,23,23,23,23,23,23,23,23,23,0,0,8,1
0,0,0,0,0,0,0,0,0,0,0,0,0,0,0,0,0,0,0,0,0,1,1,1,1,1,1,1,1,1,1,1,1,1,1,1,1,1
endlayer

layer
0,0,0,0,0,0,0,0,0,0,0,0,0,0,0,0,0,0,0,0,0,1,1,1,1,1,1,1,1,1,1,1,1,1,1,1,1,1
0,0,0,0,0,0,0,0,0,0,0,0,0,0,0,0,0,0,0,0,0,1,1,1,1,1,1,1,1,1,1,1,1,1,1,1,1,1
0,0,0,0,0,0,0,0,0,0,0,0,0,0,0,0,0,0,0,0,0,1,1,14,14,1,1,1,1,1,1,1,1,1,14,14,1,1
0,0,0,0,0,0,0,0,0,0,0,0,0,0,0,0,0,0,0,0,0,1,1,14,14,1,1,1,1,1,1,1,1,1,14,14,1,1
0,0,0,0,0,0,0,0,0,0,0,0,0,0,0,0,0,0,0,0,0,1,1,1,1,14,1,21,8,8,8,20,1,14,1,1,1,1
0,0,0,0,0,0,0,0,0,0,0,0,0,0,0,0,0,0,0,0,0,1,1,1,1,1,8,8,8,8,8,8,8,1,1,1,1,1
0,0,0,0,0,0,0,0,0,0,0,0,0,0,0,0,0,0,0,0,0,1,1,1,1,22,8,0,0,0,0,0,8,22,1,1,1,1
0,0,0,0,0,0,0,0,0,0,0,0,0,0,0,0,0,0,0,0,0,1,1,1,1,8,8,0,0,0,0,0,8,8,1,1,1,1
0,0,0,0,0,0,0,0,0,0,0,0,0,0,0,0,0,0,0,0,0,1,1,1,1,8,8,0,0,0,0,0,8,8,1,1,1,1
0,0,0,0,0,0,0,0,0,0,0,0,0,0,0,0,0,0,0,0,0,1,1,1,1,8,8,0,0,0,0,0,8,8,1,1,1,1
0,0,0,0,0,0,0,0,0,0,0,0,0,0,0,0,0,0,0,0,0,1,1,1,1,23,8,0,0,0,0,0,8,23,1,1,1,1
0,0,0,0,0,0,0,0,0,0,0,0,0,0,0,0,0,0,0,0,0,1,1,1,1,1,8,8,8,8,8,8,8,1,1,1,1,1
0,0,0,0,0,0,0,0,0,0,0,0,0,0,0,0,0,0,0,0,0,1,1,1,1,14,1,21,8,8,8,20,1,14,1,1,1,1
0,0,0,0,0,0,0,0,0,0,0,0,0,0,0,0,0,0,0,0,0,1,1,14,14,1,1,1,1,1,1,1,1,1,0,0,0,1
0,0,0,0,0,0,0,0,0,0,0,0,0,0,0,0,0,0,0,0,0,1,1,14,14,1,1,1,1,1,1,1,1,1,0,0,0,1
0,0,0,0,0,0,0,0,0,0,0,0,0,0,0,0,0,0,0,0,0,1,1,1,1,1,1,1,1,1,1,1,1,1,1,13,0,1
0,0,0,0,0,0,0,0,0,0,0,0,0,0,0,0,0,0,0,0,0,1,1,1,1,1,1,1,1,1,1,1,1,1,1,1,1,1
endlayer

layer
0,0,0,0,0,0,0,0,0,0,0,0,0,0,0,0,0,0,0,0,0,1,1,1,1,1,1,1,1,1,1,1,1,1,1,1,1,1
0,0,0,0,0,0,0,0,0,0,0,0,0,0,0,0,0,0,0,0,0,1,1,1,1,0,0,0,20,13,0,0,0,0,1,1,1,1
0,0,0,0,0,0,0,0,0,0,0,0,0,0,0,0,0,0,0,0,0,1,1,3,1,0,0,0,0,0,0,0,0,0,1,3,1,1
0,0,0,0,0,0,0,0,0,0,0,0,0,0,0,0,0,0,0,0,0,1,1,1,1,0,0,0,0,0,0,0,0,0,1,1,1,1
0,0,0,0,0,0,0,0,0,0,0,0,0,0,0,0,0,0,0,0,0,1,0,0,0,11,11,11,11,11,11,11,11,11,0,0,0,1
0,0,0,0,0,0,0,0,0,0,0,0,0,0,0,0,0,0,0,0,0,1,0,0,0,11,28,12,12,12,12,12,28,11,0,0,0,1
0,0,0,0,0,0,0,0,0,0,0,0,0,0,0,0,0,0,0,0,0,1,0,0,0,11,15,1,22,22,22,1,13,11,0,0,0,1
0,0,0,0,0,0,0,0,0,0,0,0,0,0,0,0,0,0,0,0,0,1,23,0,0,11,15,21,0,0,0,20,13,11,0,0,0,1
0,0,0,0,0,0,0,0,0,0,0,0,0,0,0,0,0,0,0,0,0,1,17,0,0,11,15,21,0,0,0,20,13,11,0,0,0,1
0,0,0,0,0,0,0,0,0,0,0,0,0,0,0,0,0,0,0,0,0,1,0,0,0,11,15,21,0,0,0,20,13,11,0,0,0,1
0,0,0,0,0,0,0,0,0,0,0,0,0,0,0,0,0,0,0,0,0,1,0,0,0,11,15,1,23,23,23,1,13,11,0,0,0,1
0,0,0,0,0,0,0,0,0,0,0,0,0,0,0,0,0,0,0,0,0,1,0,0,0,11,28,17,17,17,17,17,28,11,0,0,0,1
0,0,0,0,0,0,0,0,0,0,0,0,0,0,0,0,0,0,0,0,0,1,0,0,0,11,11,11,11,11,11,11,11,11,0,0,0,1
0,0,0,0,0,0,0,0,0,0,0,0,0,0,0,0,0,0,0,0,0,1,1,1,1,0,0,0,0,0,0,0,0,0,0,0,0,1
0,0,0,0,0,0,0,0,0,0,0,0,0,0,0,0,0,0,0,0,0,1,1,3,1,0,0,0,0,0,0,0,0,0,0,0,0,1
0,0,0,0,0,0,0,0,0,0,0,0,0,0,0,0,0,0,0,0,0,1,1,1,1,0,0,0,0,0,0,0,0,0,0,0,0,1
0,0,0,0,0,0,0,0,0,0,0,0,0,0,0,0,0,0,0,0,0,1,1,1,1,1,1,1,1,1,1,1,1,1,1,1,1,1
endlayer

layer
0,0,0,0,0,0,0,0,0,0,0,0,0,0,0,0,0,0,0,0,0,1,1,1,1,1,1,1,1,1,1,1,1,1,1,1,1,1
0,0,0,0,0,0,0,0,0,0,0,0,0,0,0,0,0,0,0,0,0,1,0,0,0,0,0,20,13,0,0,0,0,0,0,0,0,1
0,0,0,0,0,0,0,0,0,0,0,0,0,0,0,0,0,0,0,0,0,1,0,0,0,0,0,0,0,0,0,0,0,0,0,0,0,1
0,0,0,0,0,0,0,0,0,0,0,0,0,0,0,0,0,0,0,0,0,1,0,0,0,0,0,0,0,0,0,0,0,0,0,0,0,1
0,0,0,0,0,0,0,0,0,0,0,0,0,0,0,0,0,0,0,0,0,1,0,0,0,0,0,0,0,0,0,0,0,0,0,0,0,1
0,0,0,0,0,0,0,0,0,0,0,0,0,0,0,0,0,0,0,0,0,1,0,0,0,0,28,0,0,0,0,0,28,0,0,0,0,1
0,0,0,0,0,0,0,0,0,0,0,0,0,0,0,0,0,0,0,0,0,1,23,0,0,0,0,15,12,12,12,13,0,0,0,0,0,1
0,0,0,0,0,0,0,0,0,0,0,0,0,0,0,0,0,0,0,0,0,1,17,0,0,0,0,15,21,22,22,13,0,0,0,0,0,1
0,0,0,0,0,0,0,0,0,0,0,0,0,0,0,0,0,0,0,0,0,1,0,0,0,0,0,15,21,0,20,13,0,0,0,0,0,1
0,0,0,0,0,0,0,0,0,0,0,0,0,0,0,0,0,0,0,0,0,1,0,0,0,0,0,15,23,23,20,13,0,0,0,0,0,1
0,0,0,0,0,0,0,0,0,0,0,0,0,0,0,0,0,0,0,0,0,1,0,0,0,0,0,17,17,17,17,13,0,0,0,0,0,1
0,0,0,0,0,0,0,0,0,0,0,0,0,0,0,0,0,0,0,0,0,1,0,0,0,0,28,0,0,0,0,0,28,0,0,0,0,1
0,0,0,0,0,0,0,0,0,0,0,0,0,0,0,0,0,0,0,0,0,1,0,0,0,0,0,0,0,0,0,0,0,0,0,0,0,1
0,0,0,0,0,0,0,0,0,0,0,0,0,0,0,0,0,0,0,0,0,1,0,0,0,0,0,0,0,0,0,0,0,0,0,0,0,1
0,0,0,0,0,0,0,0,0,0,0,0,0,0,0,0,0,0,0,0,0,1,0,0,0,0,0,0,0,0,0,0,0,0,0,0,0,1
0,0,0,0,0,0,0,0,0,0,0,0,0,0,0,0,0,0,0,0,0,1,0,0,0,0,0,0,0,0,0,0,0,0,0,0,0,1
0,0,0,0,0,0,0,0,0,0,0,0,0,0,0,0,0,0,0,0,0,1,1,1,1,1,1,1,1,1,1,1,1,1,1,1,1,1
endlayer

layer
0,0,0,0,0,0,0,0,0,0,0,0,0,0,0,0,0,0,0,0,0,1,1,1,1,1,1,1,1,1,1,1,1,1,1,1,1,1
0,0,0,0,0,0,0,0,0,0,0,0,0,0,0,0,0,0,0,0,0,1,0,0,0,0,20,13,0,0,0,0,0,0,0,0,0,1
0,0,0,0,0,0,0,0,0,0,0,0,0,0,0,0,0,0,0,0,0,1,0,0,0,0,0,0,0,0,0,0,0,0,0,0,0,1
0,0,0,0,0,0,0,0,0,0,0,0,0,0,0,0,0,0,0,0,0,1,0,0,0,0,0,0,0,0,0,0,0,0,0,0,0,1
0,0,0,0,0,0,0,0,0,0,0,0,0,0,0,0,0,0,0,0,0,1,0,0,0,0,0,0,0,0,0,0,0,0,0,0,0,1
0,0,0,0,0,0,0,0,0,0,0,0,0,0,0,0,0,0,0,0,0,1,23,0,0,0,28,0,0,0,0,0,28,0,0,0,0,1
0,0,0,0,0,0,0,0,0,0,0,0,0,0,0,0,0,0,0,0,0,1,17,0,0,0,0,0,0,0,0,0,0,0,0,0,0,1
0,0,0,0,0,0,0,0,0,0,0,0,0,0,0,0,0,0,0,0,0,1,0,0,0,0,0,0,12,12,12,0,0,0,0,0,0,1
0,0,0,0,0,0,0,0,0,0,0,0,0,0,0,0,0,0,0,0,0,1,0,0,0,0,0,0,15,0,13,0,0,0,0,0,0,1
0,0,0,0,0,0,0,0,0,0,0,0,0,0,0,0,0,0,0,0,0,1,0,0,0,0,0,0,15,17,13,0,0,0,0,0,0,1
0,0,0,0,0,0,0,0,0,0,0,0,0,0,0,0,0,0,0,0,0,1,0,0,0,0,0,0,0,0,0,0,0,0,0,0,0,1
0,0,0,0,0,0,0,0,0,0,0,0,0,0,0,0,0,0,0,0,0,1,0,0,0,0,28,0,0,0,0,0,28,0,0,0,0,1
0,0,0,0,0,0,0,0,0,0,0,0,0,0,0,0,0,0,0,0,0,1,0,0,0,0,0,0,0,0,0,0,0,0,0,0,0,1
0,0,0,0,0,0,0,0,0,0,0,0,0,0,0,0,0,0,0,0,0,1,0,0,0,0,0,0,0,0,0,0,0,0,0,0,0,1
0,0,0,0,0,0,0,0,0,0,0,0,0,0,0,0,0,0,0,0,0,1,0,0,0,0,0,0,0,0,0,0,0,0,0,0,0,1
0,0,0,0,0,0,0,0,0,0,0,0,0,0,0,0,0,0,0,0,0,1,0,0,0,0,0,0,0,0,0,0,0,0,0,0,0,1
0,0,0,0,0,0,0,0,0,0,0,0,0,0,0,0,0,0,0,0,0,1,1,1,1,1,1,1,1,1,1,1,1,1,1,1,1,1
endlayer

layer
0,0,0,0,0,0,0,0,0,0,0,0,0,0,0,0,0,0,0,0,0,1,1,1,1,1,1,1,1,1,1,1,1,1,1,1,1,1
0,0,0,0,0,0,0,0,0,0,0,0,0,0,0,0,0,0,0,0,0,1,1,1,1,20,13,0,0,0,0,0,0,0,1,1,1,1
0,0,0,0,0,0,0,0,0,0,0,0,0,0,0,0,0,0,0,0,0,1,1,3,1,0,0,0,0,0,0,0,0,0,1,3,1,1
0,0,0,0,0,0,0,0,0,0,0,0,0,0,0,0,0,0,0,0,0,1,1,1,1,0,0,0,0,0,0,0,0,0,1,1,1,1
0,0,0,0,0,0,0,0,0,0,0,0,0,0,0,0,0,0,0,0,0,1,23,0,0,0,0,0,0,0,0,0,0,0,0,0,0,1
0,0,0,0,0,0,0,0,0,0,0,0,0,0,0,0,0,0,0,0,0,1,17,0,0,0,24,0,0,0,0,0,24,0,0,0,0,1
0,0,0,0,0,0,0,0,0,0,0,0,0,0,0,0,0,0,0,0,0,1,0,0,0,0,0,0,0,0,0,0,0,0,0,0,0,1
0,0,0,0,0,0,0,0,0,0,0,0,0,0,0,0,0,0,0,0,0,1,0,0,0,0,0,0,0,0,0,0,0,0,0,0,0,1
0,0,0,0,0,0,0,0,0,0,0,0,0,0,0,0,0,0,0,0,0,1,0,0,0,0,0,0,0,0,0,0,0,0,0,0,0,1
0,0,0,0,0,0,0,0,0,0,0,0,0,0,0,0,0,0,0,0,0,1,0,0,0,0,0,0,0,0,0,0,0,0,0,0,0,1
0,0,0,0,0,0,0,0,0,0,0,0,0,0,0,0,0,0,0,0,0,1,0,0,0,0,0,0,0,0,0,0,0,0,0,0,0,1
0,0,0,0,0,0,0,0,0,0,0,0,0,0,0,0,0,0,0,0,0,1,0,0,0,0,24,0,0,0,0,0,24,0,0,0,0,1
0,0,0,0,0,0,0,0,0,0,0,0,0,0,0,0,0,0,0,0,0,1,0,0,0,0,0,0,0,0,0,0,0,0,0,0,0,1
0,0,0,0,0,0,0,0,0,0,0,0,0,0,0,0,0,0,0,0,0,1,0,0,0,0,0,0,0,0,0,0,0,0,1,1,1,1
0,0,0,0,0,0,0,0,0,0,0,0,0,0,0,0,0,0,0,0,0,1,0,0,0,0,0,0,0,0,0,0,0,0,1,3,1,1
0,0,0,0,0,0,0,0,0,0,0,0,0,0,0,0,0,0,0,0,0,1,0,0,0,0,0,0,0,0,0,0,0,0,1,1,1,1
0,0,0,0,0,0,0,0,0,0,0,0,0,0,0,0,0,0,0,0,0,1,1,1,1,1,1,1,1,1,1,1,1,1,1,1,1,1
endlayer

layer
0,0,0,0,0,0,0,0,0,0,0,0,0,0,0,0,0,0,0,0,0,1,1,1,1,1,1,1,1,1,1,1,1,1,1,1,1,1
0,0,0,0,0,0,0,0,0,0,0,0,0,0,0,0,0,0,0,0,0,1,0,0,20,13,0,0,0,0,0,0,0,18,0,0,0,1
0,0,0,0,0,0,0,0,0,0,0,0,0,0,0,0,0,0,0,0,0,1,0,0,0,0,0,0,0,0,0,0,0,18,0,0,0,1
0,0,0,0,0,0,0,0,0,0,0,0,0,0,0,0,0,0,0,0,0,1,23,0,0,0,0,0,0,0,0,0,0,18,0,0,18,1
0,0,0,0,0,0,0,0,0,0,0,0,0,0,0,0,0,0,0,0,0,1,17,0,0,0,0,0,0,0,0,0,0,18,18,18,18,1
0,0,0,0,0,0,0,0,0,0,0,0,0,0,0,0,0,0,0,0,0,1,0,0,0,0,28,0,0,0,0,0,28,0,0,0,0,1
0,0,0,0,0,0,0,0,0,0,0,0,0,0,0,0,0,0,0,0,0,1,0,0,0,0,0,0,0,0,0,0,0,0,0,0,0,1
0,0,0,0,0,0,0,0,0,0,0,0,0,0,0,0,0,0,0,0,0,1,0,0,0,0,0,0,0,0,0,0,0,0,0,0,0,1
0,0,0,0,0,0,0,0,0,0,0,0,0,0,0,0,0,0,0,0,0,1,0,0,0,0,0,0,0,0,0,0,0,0,0,0,0,1
0,0,0,0,0,0,0,0,0,0,0,0,0,0,0,0,0,0,0,0,0,1,0,0,0,0,0,0,0,0,0,0,0,0,0,0,0,1
0,0,0,0,0,0,0,0,0,0,0,0,0,0,0,0,0,0,0,0,0,1,0,0,0,0,0,0,0,0,0,0,0,0,0,0,0,1
0,0,0,0,0,0,0,0,0,0,0,0,0,0,0,0,0,0,0,0,0,1,0,0,0,0,28,0,0,0,0,0,28,0,0,0,0,1
0,0,0,0,0,0,0,0,0,0,0,0,0,0,0,0,0,0,0,0,0,1,18,18,18,18,0,0,0,0,0,0,0,18,18,18,18,1
0,0,0,0,0,0,0,0,0,0,0,0,0,0,0,0,0,0,0,0,0,1,0,0,0,18,0,0,0,0,0,0,0,18,0,0,0,1
0,0,0,0,0,0,0,0,0,0,0,0,0,0,0,0,0,0,0,0,0,1,0,0,0,18,0,0,0,0,0,0,0,18,0,0,0,1
0,0,0,0,0,0,0,0,0,0,0,0,0,0,0,0,0,0,0,0,0,1,0,0,0,18,0,0,0,0,0,0,0,18,0,0,0,1
0,0,0,0,0,0,0,0,0,0,0,0,0,0,0,0,0,0,0,0,0,1,1,1,1,1,1,1,1,1,1,1,1,1,1,1,1,1
endlayer

layer
0,0,0,0,0,0,0,0,0,0,0,0,0,0,0,0,0,0,0,0,0,1,1,1,1,1,1,1,1,1,1,1,1,1,1,1,1,1
0,0,0,0,0,0,0,0,0,0,0,0,0,0,0,0,0,0,0,0,0,1,0,20,13,0,0,0,0,0,0,0,0,0,0,0,0,1
0,0,0,0,0,0,0,0,0,0,0,0,0,0,0,0,0,0,0,0,0,1,23,0,0,0,0,0,0,0,0,0,0,0,0,0,0,1
0,0,0,0,0,0,0,0,0,0,0,0,0,0,0,0,0,0,0,0,0,1,17,0,0,0,0,0,0,0,0,0,0,0,0,0,0,1
0,0,0,0,0,0,0,0,0,0,0,0,0,0,0,0,0,0,0,0,0,1,0,0,0,0,0,0,0,0,0,0,0,0,0,0,0,1
0,0,0,0,0,0,0,0,0,0,0,0,0,0,0,0,0,0,0,0,0,1,0,0,0,0,28,0,0,0,0,0,28,0,0,0,0,1
0,0,0,0,0,0,0,0,0,0,0,0,0,0,0,0,0,0,0,0,0,1,0,0,0,0,0,0,0,0,0,0,0,0,0,0,0,1
0,0,0,0,0,0,0,0,0,0,0,0,0,0,0,0,0,0,0,0,0,1,0,0,0,0,0,0,0,0,0,0,0,0,0,0,0,1
0,0,0,0,0,0,0,0,0,0,0,0,0,0,0,0,0,0,0,0,0,1,0,0,0,0,0,0,0,0,0,0,0,0,0,0,0,1
0,0,0,0,0,0,0,0,0,0,0,0,0,0,0,0,0,0,0,0,0,1,0,0,0,0,0,0,0,0,0,0,0,0,0,0,0,1
0,0,0,0,0,0,0,0,0,0,0,0,0,0,0,0,0,0,0,0,0,1,0,0,0,0,0,0,0,0,0,0,0,0,0,0,0,1
0,0,0,0,0,0,0,0,0,0,0,0,0,0,0,0,0,0,0,0,0,1,0,0,0,0,28,0,0,0,0,0,28,0,0,0,0,1
0,0,0,0,0,0,0,0,0,0,0,0,0,0,0,0,0,0,0,0,0,1,0,0,0,0,0,0,0,0,0,0,0,0,0,0,0,1
0,0,0,0,0,0,0,0,0,0,0,0,0,0,0,0,0,0,0,0,0,1,0,0,0,0,0,0,0,0,0,0,0,0,0,0,0,1
0,0,0,0,0,0,0,0,0,0,0,0,0,0,0,0,0,0,0,0,0,1,0,0,0,0,0,0,0,0,0,0,0,0,0,0,0,1
0,0,0,0,0,0,0,0,0,0,0,0,0,0,0,0,0,0,0,0,0,1,0,0,0,0,0,0,0,0,0,0,0,0,0,0,0,1
0,0,0,0,0,0,0,0,0,0,0,0,0,0,0,0,0,0,0,0,0,1,1,1,1,1,1,1,1,1,1,1,1,1,1,1,1,1
endlayer

layer
0,0,0,0,0,0,0,0,0,0,0,0,0,0,0,0,0,0,0,0,0,1,1,1,1,1,1,1,1,1,1,1,1,1,1,1,1,1
0,0,0,0,0,0,0,0,0,0,0,0,0,0,0,0,0,0,0,0,0,1,1,13,0,0,0,0,0,0,0,0,0,0,0,0,0,1
0,0,0,0,0,0,0,0,0,0,0,0,0,0,0,0,0,0,0,0,0,1,17,8,8,0,0,0,0,0,0,0,0,0,0,0,0,1
0,0,0,0,0,0,0,0,0,0,0,0,0,0,0,0,0,0,0,0,0,1,0,8,8,0,0,0,0,0,0,0,0,0,0,0,0,1
0,0,0,0,0,0,0,0,0,0,0,0,0,0,0,0,0,0,0,0,0,1,0,0,0,0,0,0,0,0,0,0,0,0,0,0,0,1
0,0,0,0,0,0,0,0,0,0,0,0,0,0,0,0,0,0,0,0,0,1,0,0,0,0,28,0,0,0,0,0,28,0,0,0,0,1
0,0,0,0,0,0,0,0,0,0,0,0,0,0,0,0,0,0,0,0,0,1,0,0,0,0,0,0,0,0,0,0,0,0,0,0,0,1
0,0,0,0,0,0,0,0,0,0,0,0,0,0,0,0,0,0,0,0,0,1,0,0,0,0,0,0,0,0,0,0,0,0,0,0,0,1
0,0,0,0,0,0,0,0,0,0,0,0,0,0,0,0,0,0,0,0,0,1,0,0,0,0,0,0,0,0,0,0,0,0,0,0,0,1
0,0,0,0,0,0,0,0,0,0,0,0,0,0,0,0,0,0,0,0,0,1,0,0,0,0,0,0,0,0,0,0,0,0,0,0,0,1
0,0,0,0,0,0,0,0,0,0,0,0,0,0,0,0,0,0,0,0,0,1,0,0,0,0,0,0,0,0,0,0,0,0,0,0,0,1
0,0,0,0,0,0,0,0,0,0,0,0,0,0,0,0,0,0,0,0,0,1,0,0,0,0,28,0,0,0,0,0,28,0,0,0,0,1
0,0,0,0,0,0,0,0,0,0,0,0,0,0,0,0,0,0,0,0,0,1,0,0,0,0,0,0,0,0,0,0,0,0,0,0,0,1
0,0,0,0,0,0,0,0,0,0,0,0,0,0,0,0,0,0,0,0,0,1,0,0,0,0,0,0,0,0,0,0,0,0,0,0,0,1
0,0,0,0,0,0,0,0,0,0,0,0,0,0,0,0,0,0,0,0,0,1,0,0,0,0,0,0,0,0,0,0,0,0,0,0,0,1
0,0,0,0,0,0,0,0,0,0,0,0,0,0,0,0,0,0,0,0,0,1,0,0,0,0,0,0,0,0,0,0,0,0,0,0,0,1
0,0,0,0,0,0,0,0,0,0,0,0,0,0,0,0,0,0,0,0,0,1,1,1,1,1,1,1,1,1,1,1,1,1,1,1,1,1
endlayer

layer
0,0,0,0,0,0,0,0,0,0,0,0,0,0,0,0,0,0,0,0,0,1,1,1,1,1,1,1,1,1,1,1,1,1,1,1,1,1
0,0,0,0,0,0,0,0,0,0,0,0,0,0,0,0,0,0,0,0,0,1,0,0,0,0,0,0,0,0,0,0,0,0,0,0,0,1
0,0,0,0,0,0,0,0,0,0,0,0,0,0,0,0,0,0,0,0,0,1,0,0,9,0,0,0,0,0,0,0,0,0,0,0,0,1
0,0,0,0,0,0,0,0,0,0,0,0,0,0,0,0,0,0,0,0,0,1,0,9,29,29,1,0,0,0,0,0,0,0,0,0,0,1
0,0,0,0,0,0,0,0,0,0,0,0,0,0,0,0,0,0,0,0,0,1,0,0,29,1,1,1,1,1,1,1,1,1,0,0,0,1
0,0,0,0,0,0,0,0,0,0,0,0,0,0,0,0,0,0,0,0,0,1,0,0,1,1,1,1,1,1,1,1,1,1,0,0,0,1
0,0,0,0,0,0,0,0,0,0,0,0,0,0,0,0,0,0,0,0,0,1,0,0,0,1,1,22,22,22,22,20,1,1,0,0,0,1
0,0,0,0,0,0,0,0,0,0,0,0,0,0,0,0,0,0,0,0,0,1,0,0,0,1,1,21,1,1,1,20,1,1,0,0,0,1
0,0,0,0,0,0,0,0,0,0,0,0,0,0,0,0,0,0,0,0,0,1,0,0,0,1,1,21,1,0,1,20,1,1,0,0,0,1
0,0,0,0,0,0,0,0,0,0,0,0,0,0,0,0,0,0,0,0,0,1,0,0,0,1,1,21,1,1,1,20,1,1,0,0,0,1
0,0,0,0,0,0,0,0,0,0,0,0,0,0,0,0,0,0,0,0,0,1,0,0,0,1,1,23,23,23,23,23,1,1,0,0,0,1
0,0,0,0,0,0,0,0,0,0,0,0,0,0,0,0,0,0,0,0,0,1,0,0,0,1,1,1,1,1,1,1,1,1,0,0,0,1
0,0,0,0,0,0,0,0,0,0,0,0,0,0,0,0,0,0,0,0,0,1,0,0,0,1,1,1,1,1,1,1,1,1,0,0,0,1
0,0,0,0,0,0,0,0,0,0,0,0,0,0,0,0,0,0,0,0,0,1,0,0,0,0,0,0,0,0,0,0,0,0,0,0,0,1
0,0,0,0,0,0,0,0,0,0,0,0,0,0,0,0,0,0,0,0,0,1,0,0,0,0,0,0,0,0,0,0,0,0,0,0,0,1
0,0,0,0,0,0,0,0,0,0,0,0,0,0,0,0,0,0,0,0,0,1,0,0,0,0,0,0,0,0,0,0,0,0,0,0,0,1
0,0,0,0,0,0,0,0,0,0,0,0,0,0,0,0,0,0,0,0,0,1,1,1,1,1,1,1,1,1,1,1,1,1,1,1,1,1
endlayer

layer
0,0,0,0,0,0,0,0,0,0,0,0,0,0,0,0,0,0,0,0,0,1,1,1,1,1,1,1,1,1,1,1,1,1,1,1,1,1
0,0,0,0,0,0,0,0,0,0,0,0,0,0,0,0,0,0,0,0,0,1,0,0,0,0,1,1,1,1,1,1,1,1,1,1,1,1
0,0,0,0,0,0,0,0,0,0,0,0,0,0,0,0,0,0,0,0,0,1,0,0,0,0,1,1,1,1,1,1,1,1,1,1,1,1
0,0,0,0,0,0,0,0,0,0,0,0,0,0,0,0,0,0,0,0,0,1,0,0,0,0,9,1,1,1,1,1,1,1,1,1,1,1
0,0,0,0,0,0,0,0,0,0,0,0,0,0,0,0,0,0,0,0,0,1,0,0,0,9,1,1,1,1,1,1,1,1,1,1,1,1
0,0,0,0,0,0,0,0,0,0,0,0,0,0,0,0,0,0,0,0,0,1,1,1,9,1,1,1,0,0,0,1,1,1,1,1,1,1
0,0,0,0,0,0,0,0,0,0,0,0,0,0,0,0,0,0,0,0,0,1,1,1,1,1,1,1,0,27,0,1,1,1,1,1,1,1
0,0,0,0,0,0,0,0,0,0,0,0,0,0,0,0,0,0,0,0,0,1,1,1,1,1,0,0,0,0,0,0,0,1,1,1,1,1
0,0,0,0,0,0,0,0,0,0,0,0,0,0,0,0,0,0,0,0,0,1,1,1,1,1,0,7,0,0,0,16,0,1,1,1,1,1
0,0,0,0,0,0,0,0,0,0,0,0,0,0,0,0,0,0,0,0,0,1,1,1,1,1,0,0,0,0,0,0,0,1,1,1,1,1
0,0,0,0,0,0,0,0,0,0,0,0,0,0,0,0,0,0,0,0,0,1,1,1,1,1,1,1,0,25,0,1,1,1,1,1,1,1
0,0,0,0,0,0,0,0,0,0,0,0,0,0,0,0,0,0,0,0,0,1,1,1,1,1,1,1,0,0,0,1,1,1,1,1,1,1
0,0,0,0,0,0,0,0,0,0,0,0,0,0,0,0,0,0,0,0,0,1,1,1,1,1,1,1,1,1,1,1,1,1,1,1,1,1
0,0,0,0,0,0,0,0,0,0,0,0,0,0,0,0,0,0,0,0,0,1,1,1,1,1,1,1,1,1,1,1,1,1,1,1,1,1
0,0,0,0,0,0,0,0,0,0,0,0,0,0,0,0,0,0,0,0,0,1,1,1,1,1,1,1,1,1,1,1,1,1,1,1,1,1
0,0,0,0,0,0,0,0,0,0,0,0,0,0,0,0,0,0,0,0,0,1,1,1,1,1,1,1,1,1,1,1,1,1,1,1,1,1
0,0,0,0,0,0,0,0,0,0,0,0,0,0,0,0,0,0,0,0,0,1,1,1,1,1,1,1,1,1,1,1,1,1,1,1,1,1
endlayer

layer
0,0,0,0,0,0,0,0,0,0,0,0,0,0,0,0,0,0,0,0,0,1,1,1,1,1,1,1,1,1,1,1,1,1,1,1,1,1
0,0,0,0,0,0,0,0,0,0,0,0,0,0,0,0,0,0,0,0,0,1,0,0,0,0,0,0,16,1,0,0,0,0,0,0,0,1
0,0,0,0,0,0,0,0,0,0,0,0,0,0,0,0,0,0,0,0,0,1,0,0,0,0,0,0,0,1,0,0,0,0,0,27,0,1
0,0,0,0,0,0,0,0,0,0,0,0,0,0,0,0,0,0,0,0,0,1,0,0,0,0,0,0,16,1,0,0,0,0,0,0,0,1
0,0,0,0,0,0,0,0,0,0,0,0,0,0,0,0,0,0,0,0,0,1,0,0,0,0,0,0,1,1,1,0,13,0,0,0,0,1
0,0,0,0,0,0,0,0,0,0,0,0,0,0,0,0,0,0,0,0,0,1,0,0,0,0,0,1,0,0,0,1,0,0,0,0,0,1
0,0,0,0,0,0,0,0,0,0,0,0,0,0,0,0,0,0,0,0,0,1,0,0,0,0,1,1,0,0,0,1,1,0,0,0,0,1
0,0,0,0,0,0,0,0,0,0,0,0,0,0,0,0,0,0,0,0,0,1,0,0,0,15,0,0,0,0,0,0,0,13,0,0,0,1
0,0,0,0,0,0,0,0,0,0,0,0,0,0,0,0,0,0,0,0,0,1,0,0,0,15,0,0,0,0,0,0,0,13,0,0,0,1
0,0,0,0,0,0,0,0,0,0,0,0,0,0,0,0,0,0,0,0,0,1,0,0,0,15,0,0,0,0,0,0,0,13,0,0,0,1
0,0,0,0,0,0,0,0,0,0,0,0,0,0,0,0,0,0,0,0,0,1,0,0,0,0,1,1,0,0,0,1,1,0,0,0,0,1
0,0,0,0,0,0,0,0,0,0,0,0,0,0,0,0,0,0,0,0,0,1,0,0,0,0,0,1,0,0,0,1,0,0,0,0,0,1
0,0,0,0,0,0,0,0,0,0,0,0,0,0,0,0,0,0,0,0,0,1,0,0,0,0,0,0,17,17,17,0,0,0,0,0,0,1
0,0,0,0,0,0,0,0,0,0,0,0,0,0,0,0,0,0,0,0,0,1,0,0,0,0,0,0,0,0,0,0,0,0,0,0,0,1
0,0,0,0,0,0,0,0,0,0,0,0,0,0,0,0,0,0,0,0,0,1,0,25,0,0,0,0,0,0,0,0,0,0,0,25,0,1
0,0,0,0,0,0,0,0,0,0,0,0,0,0,0,0,0,0,0,0,0,1,0,0,0,0,0,0,0,0,0,0,0,0,0,0,0,1
0,0,0,0,0,0,0,0,0,0,0,0,0,0,0,0,0,0,0,0,0,1,1,1,1,1,1,1,1,1,1,1,1,1,1,1,1,1
endlayer

layer
0,0,0,0,0,0,0,0,0,0,0,0,0,0,0,0,0,0,0,0,0,1,1,1,1,1,1,1,1,1,1,1,1,1,1,1,1,1
0,0,0,0,0,0,0,0,0,0,0,0,0,0,0,0,0,0,0,0,0,1,0,0,0,0,0,0,0,18,0,0,0,0,0,0,0,1
0,0,0,0,0,0,0,0,0,0,0,0,0,0,0,0,0,0,0,0,0,1,0,0,0,0,0,0,0,18,0,0,0,0,0,1,0,1
0,0,0,0,0,0,0,0,0,0,0,0,0,0,0,0,0,0,0,0,0,1,0,0,0,0,0,0,0,18,0,0,0,0,0,0,0,1
0,0,0,0,0,0,0,0,0,0,0,0,0,0,0,0,0,0,0,0,0,1,0,0,0,0,0,0,18,18,18,13,0,0,0,0,0,1
0,0,0,0,0,0,0,0,0,0,0,0,0,0,0,0,0,0,0,0,0,1,0,0,0,0,0,1,0,0,0,1,0,0,0,0,0,1
0,0,0,0,0,0,0,0,0,0,0,0,0,0,0,0,0,0,0,0,0,1,0,0,0,0,1,1,0,0,0,1,1,0,0,0,0,1
0,0,0,0,0,0,0,0,0,0,0,0,0,0,0,0,0,0,0,0,0,1,0,0,0,18,0,0,0,0,0,0,0,18,0,0,0,1
0,0,0,0,0,0,0,0,0,0,0,0,0,0,0,0,0,0,0,0,0,1,0,0,0,18,0,0,0,1,0,0,0,18,0,0,0,1
0,0,0,0,0,0,0,0,0,0,0,0,0,0,0,0,0,0,0,0,0,1,0,0,0,18,0,0,0,0,0,0,0,18,0,0,0,1
0,0,0,0,0,0,0,0,0,0,0,0,0,0,0,0,0,0,0,0,0,1,0,0,0,0,1,1,0,0,0,1,1,0,0,0,0,1
0,0,0,0,0,0,0,0,0,0,0,0,0,0,0,0,0,0,0,0,0,1,0,0,0,0,0,1,0,0,0,1,0,0,0,0,0,1
0,0,0,0,0,0,0,0,0,0,0,0,0,0,0,0,0,0,0,0,0,1,0,0,0,0,0,0,18,18,18,0,0,0,0,0,0,1
0,0,0,0,0,0,0,0,0,0,0,0,0,0,0,0,0,0,0,0,0,1,0,0,0,0,0,0,0,0,0,0,0,0,0,0,0,1
0,0,0,0,0,0,0,0,0,0,0,0,0,0,0,0,0,0,0,0,0,1,0,1,0,0,0,0,0,0,0,0,0,0,0,1,0,1
0,0,0,0,0,0,0,0,0,0,0,0,0,0,0,0,0,0,0,0,0,1,0,0,0,0,0,0,0,0,0,0,0,0,0,0,0,1
0,0,0,0,0,0,0,0,0,0,0,0,0,0,0,0,0,0,0,0,0,1,1,1,1,1,1,1,1,1,1,1,1,1,1,1,1,1
endlayer

layer
0,0,0,0,0,0,0,0,0,0,0,0,0,0,0,0,0,0,0,0,0,1,1,1,1,1,1,1,1,1,1,1,1,1,1,1,1,1
0,0,0,0,0,0,0,0,0,0,0,0,0,0,0,0,0,0,0,0,0,1,1,0,0,0,0,0,0,1,0,0,0,0,18,18,18,1
0,0,0,0,0,0,0,0,0,0,0,0,0,0,0,0,0,0,0,0,0,1,0,0,0,0,0,0,0,1,0,0,0,0,18,14,18,1
0,0,0,0,0,0,0,0,0,0,0,0,0,0,0,0,0,0,0,0,0,1,0,0,0,0,0,0,0,1,0,0,0,0,18,18,18,1
0,0,0,0,0,0,0,0,0,0,0,0,0,0,0,0,0,0,0,0,0,1,0,0,0,0,0,0,18,18,13,0,0,0,0,0,0,1
0,0,0,0,0,0,0,0,0,0,0,0,0,0,0,0,0,0,0,0,0,1,0,0,0,0,0,1,0,0,0,1,0,0,0,0,0,1
0,0,0,0,0,0,0,0,0,0,0,0,0,0,0,0,0,0,0,0,0,1,0,0,0,0,1,1,0,0,0,1,1,0,0,0,0,1
0,0,0,0,0,0,0,0,0,0,0,0,0,0,0,0,0,0,0,0,0,1,0,0,0,18,0,0,0,1,0,0,0,18,0,0,0,1
0,0,0,0,0,0,0,0,0,0,0,0,0,0,0,0,0,0,0,0,0,1,0,0,0,18,0,0,1,1,1,0,0,18,0,0,0,1
0,0,0,0,0,0,0,0,0,0,0,0,0,0,0,0,0,0,0,0,0,1,0,0,0,18,0,0,0,1,0,0,0,18,0,0,0,1
0,0,0,0,0,0,0,0,0,0,0,0,0,0,0,0,0,0,0,0,0,1,0,0,0,0,1,1,0,0,0,1,1,0,0,0,0,1
0,0,0,0,0,0,0,0,0,0,0,0,0,0,0,0,0,0,0,0,0,1,0,0,0,0,0,1,0,0,0,1,0,0,0,0,0,1
0,0,0,0,0,0,0,0,0,0,0,0,0,0,0,0,0,0,0,0,0,1,0,0,0,0,0,0,18,18,18,0,0,0,0,0,0,1
0,0,0,0,0,0,0,0,0,0,0,0,0,0,0,0,0,0,0,0,0,1,18,18,18,0,0,0,0,0,0,0,0,0,18,18,18,1
0,0,0,0,0,0,0,0,0,0,0,0,0,0,0,0,0,0,0,0,0,1,18,14,18,0,0,0,0,0,0,0,0,0,18,14,18,1
0,0,0,0,0,0,0,0,0,0,0,0,0,0,0,0,0,0,0,0,0,1,18,18,18,0,0,0,0,0,0,0,0,0,18,18,18,1
0,0,0,0,0,0,0,0,0,0,0,0,0,0,0,0,0,0,0,0,0,1,1,1,1,1,1,1,1,1,1,1,1,1,1,1,1,1
endlayer

layer
0,0,0,0,0,0,0,0,0,0,0,0,0,0,0,0,0,0,0,0,0,6,6,6,6,6,6,6,6,6,6,6,6,6,6,6,6,6
0,0,0,0,0,0,0,0,0,0,0,0,0,0,0,0,0,0,0,0,0,6,1,1,1,1,1,1,1,1,1,1,1,1,1,1,1,6
0,0,0,0,0,0,0,0,0,0,0,0,0,0,0,0,0,0,0,0,0,6,1,0,0,0,0,0,0,1,0,0,0,0,0,1,1,6
0,0,0,0,0,0,0,0,0,0,0,0,0,0,0,0,0,0,0,0,0,6,1,0,0,0,0,0,0,1,0,0,0,0,0,0,1,6
0,0,0,0,0,0,0,0,0,0,0,0,0,0,0,0,0,0,0,0,0,6,1,0,0,0,0,0,1,13,0,0,0,0,0,0,1,6
0,0,0,0,0,0,0,0,0,0,0,0,0,0,0,0,0,0,0,0,0,6,1,0,0,0,0,1,0,1,0,1,0,0,0,0,1,6
0,0,0,0,0,0,0,0,0,0,0,0,0,0,0,0,0,0,0,0,0,6,1,0,0,0,1,1,0,0,0,1,1,0,0,0,1,6
0,0,0,0,0,0,0,0,0,0,0,0,0,0,0,0,0,0,0,0,0,6,1,0,0,18,0,0,0,0,0,0,0,18,0,0,1,6
0,0,0,0,0,0,0,0,0,0,0,0,0,0,0,0,0,0,0,0,0,6,1,0,0,18,0,0,0,1,0,0,0,18,0,0,1,6
0,0,0,0,0,0,0,0,0,0,0,0,0,0,0,0,0,0,0,0,0,6,1,0,0,18,0,0,0,0,0,0,0,18,0,0,1,6
0,0,0,0,0,0,0,0,0,0,0,0,0,0,0,0,0,0,0,0,0,6,1,0,0,0,1,1,0,0,0,1,1,0,0,0,1,6
0,0,0,0,0,0,0,0,0,0,0,0,0,0,0,0,0,0,0,0,0,6,1,0,0,0,0,1,0,0,0,1,0,0,0,0,1,6
0,0,0,0,0,0,0,0,0,0,0,0,0,0,0,0,0,0,0,0,0,6,1,0,0,0,0,0,18,18,18,0,0,0,0,0,1,6
0,0,0,0,0,0,0,0,0,0,0,0,0,0,0,0,0,0,0,0,0,6,1,0,0,0,0,0,0,0,0,0,0,0,0,0,1,6
0,0,0,0,0,0,0,0,0,0,0,0,0,0,0,0,0,0,0,0,0,6,1,1,0,0,0,0,0,0,0,0,0,0,0,1,1,6
0,0,0,0,0,0,0,0,0,0,0,0,0,0,0,0,0,0,0,0,0,6,1,1,1,1,1,1,1,1,1,1,1,1,1,1,1,6
0,0,0,0,0,0,0,0,0,0,0,0,0,0,0,0,0,0,0,0,0,6,6,6,6,6,6,6,6,6,6,6,6,6,6,6,6,6
endlayer

layer
0,0,0,0,0,0,0,0,0,0,0,0,0,0,0,0,0,0,0,0,0,6,6,6,6,6,6,6,6,6,6,6,6,6,6,6,6,6
0,0,0,0,0,0,0,0,0,0,0,0,0,0,0,0,0,0,0,0,0,6,6,6,6,6,6,6,6,6,6,6,6,6,6,6,6,6
0,0,0,0,0,0,0,0,0,0,0,0,0,0,0,0,0,0,0,0,0,6,6,1,1,1,1,1,1,1,1,1,1,1,1,1,6,6
0,0,0,0,0,0,0,0,0,0,0,0,0,0,0,0,0,0,0,0,0,6,6,1,0,0,0,0,1,1,0,0,0,0,1,1,6,6
0,0,0,0,0,0,0,0,0,0,0,0,0,0,0,0,0,0,0,0,0,6,6,1,0,1,1,1,0,0,0,0,1,1,0,1,6,6
0,0,0,0,0,0,0,0,0,0,0,0,0,0,0,0,0,0,0,0,0,6,6,1,0,1,1,1,12,1,1,1,1,1,0,1,6,6
0,0,0,0,0,0,0,0,0,0,0,0,0,0,0,0,0,0,0,0,0,6,6,1,0,1,1,1,1,1,1,1,1,1,0,1,6,6
0,0,0,0,0,0,0,0,0,0,0,0,0,0,0,0,0,0,0,0,0,6,6,1,0,1,1,1,0,0,0,1,1,1,0,1,6,6
0,0,0,0,0,0,0,0,0,0,0,0,0,0,0,0,0,0,0,0,0,6,6,1,0,1,1,1,0,0,0,1,1,1,0,1,6,6
0,0,0,0,0,0,0,0,0,0,0,0,0,0,0,0,0,0,0,0,0,6,6,1,0,1,1,1,0,0,0,1,1,1,0,1,6,6
0,0,0,0,0,0,0,0,0,0,0,0,0,0,0,0,0,0,0,0,0,6,6,1,0,1,1,1,1,1,1,1,1,1,0,1,6,6
0,0,0,0,0,0,0,0,0,0,0,0,0,0,0,0,0,0,0,0,0,6,6,1,0,1,1,1,1,1,1,1,1,1,0,1,6,6
0,0,0,0,0,0,0,0,0,0,0,0,0,0,0,0,0,0,0,0,0,6,6,1,0,1,1,1,1,1,1,1,1,1,0,1,6,6
0,0,0,0,0,0,0,0,0,0,0,0,0,0,0,0,0,0,0,0,0,6,6,1,1,0,0,0,0,0,0,0,0,0,1,1,6,6
0,0,0,0,0,0,0,0,0,0,0,0,0,0,0,0,0,0,0,0,0,6,6,1,1,1,1,1,1,1,1,1,1,1,1,1,6,6
0,0,0,0,0,0,0,0,0,0,0,0,0,0,0,0,0,0,0,0,0,6,6,6,6,6,6,6,6,6,6,6,6,6,6,6,6,6
0,0,0,0,0,0,0,0,0,0,0,0,0,0,0,0,0,0,0,0,0,6,6,6,6,6,6,6,6,6,6,6,6,6,6,6,6,6
endlayer

layer
0,0,0,0,0,0,0,0,0,0,0,0,0,0,0,0,0,0,0,0,0,6,6,6,6,6,6,6,6,6,6,6,6,6,6,6,6,6
0,0,0,0,0,0,0,0,0,0,0,0,0,0,0,0,0,0,0,0,0,6,6,6,6,6,6,6,6,6,6,6,6,6,6,6,6,6
0,0,0,0,0,0,0,0,0,0,0,0,0,0,0,0,0,0,0,0,0,6,6,6,6,6,6,6,6,6,6,6,6,6,6,6,6,6
0,0,0,0,0,0,0,0,0,0,0,0,0,0,0,0,0,0,0,0,0,6,6,6,1,1,1,1,1,1,1,1,1,1,1,6,6,6
0,0,0,0,0,0,0,0,0,0,0,0,0,0,0,0,0,0,0,0,0,6,6,6,1,1,1,0,0,0,0,0,1,1,1,6,6,6
0,0,0,0,0,0,0,0,0,0,0,0,0,0,0,0,0,0,0,0,0,6,6,6,1,1,0,0,0,0,0,0,0,1,1,6,6,6
0,0,0,0,0,0,0,0,0,0,0,0,0,0,0,0,0,0,0,0,0,6,6,6,1,0,0,0,0,0,0,0,0,0,1,6,6,6
0,0,0,0,0,0,0,0,0,0,0,0,0,0,0,0,0,0,0,0,0,6,6,6,1,0,0,0,1,22,1,0,0,0,1,6,6,6
0,0,0,0,0,0,0,0,0,0,0,0,0,0,0,0,0,0,0,0,0,6,6,6,1,0,0,0,21,0,20,0,0,0,1,6,6,6
0,0,0,0,0,0,0,0,0,0,0,0,0,0,0,0,0,0,0,0,0,6,6,6,1,0,0,0,1,23,1,0,0,0,1,6,6,6
0,0,0,0,0,0,0,0,0,0,0,0,0,0,0,0,0,0,0,0,0,6,6,6,1,0,0,0,0,0,17,0,0,0,1,6,6,6
0,0,0,0,0,0,0,0,0,0,0,0,0,0,0,0,0,0,0,0,0,6,6,6,1,1,0,0,0,0,0,0,0,1,1,6,6,6
0,0,0,0,0,0,0,0,0,0,0,0,0,0,0,0,0,0,0,0,0,6,6,6,1,1,1,0,0,0,0,0,1,1,1,6,6,6
0,0,0,0,0,0,0,0,0,0,0,0,0,0,0,0,0,0,0,0,0,6,6,6,1,1,1,1,1,1,1,1,1,1,1,6,6,6
0,0,0,0,0,0,0,0,0,0,0,0,0,0,0,0,0,0,0,0,0,6,6,6,6,6,6,6,6,6,6,6,6,6,6,6,6,6
0,0,0,0,0,0,0,0,0,0,0,0,0,0,0,0,0,0,0,0,0,6,6,6,6,6,6,6,6,6,6,6,6,6,6,6,6,6
0,0,0,0,0,0,0,0,0,0,0,0,0,0,0,0,0,0,0,0,0,6,6,6,6,6,6,6,6,6,6,6,6,6,6,6,6,6
endlayer

layer
0,0,0,0,0,0,0,0,0,0,0,0,0,0,0,0,0,0,0,0,0,6,6,6,6,6,6,6,6,6,6,6,6,6,6,6,6,6
0,0,0,0,0,0,0,0,0,0,0,0,0,0,0,0,0,0,0,0,0,6,6,6,6,6,6,6,6,6,6,6,6,6,6,6,6,6
0,0,0,0,0,0,0,0,0,0,0,0,0,0,0,0,0,0,0,0,0,6,6,6,6,6,6,6,6,6,6,6,6,6,6,6,6,6
0,0,0,0,0,0,0,0,0,0,0,0,0,0,0,0,0,0,0,0,0,6,6,6,6,6,6,13,15,1,13,15,6,6,6,6,6,6
0,0,0,0,0,0,0,0,0,0,0,0,0,0,0,0,0,0,0,0,0,6,6,6,6,1,1,0,0,0,0,0,1,1,6,6,6,6
0,0,0,0,0,0,0,0,0,0,0,0,0,0,0,0,0,0,0,0,0,6,6,6,6,1,0,0,0,0,0,0,0,1,6,6,6,6
0,0,0,0,0,0,0,0,0,0,0,0,0,0,0,0,0,0,0,0,0,6,6,6,17,0,0,0,0,0,0,0,0,0,17,6,6,6
0,0,0,0,0,0,0,0,0,0,0,0,0,0,0,0,0,0,0,0,0,6,6,6,12,0,0,0,0,0,1,0,0,0,12,6,6,6
0,0,0,0,0,0,0,0,0,0,0,0,0,0,0,0,0,0,0,0,0,6,6,6,1,0,0,0,0,0,1,0,0,0,1,6,6,6
0,0,0,0,0,0,0,0,0,0,0,0,0,0,0,0,0,0,0,0,0,6,6,6,17,0,0,0,0,0,17,0,0,0,17,6,6,6
0,0,0,0,0,0,0,0,0,0,0,0,0,0,0,0,0,0,0,0,0,6,6,6,12,0,0,0,0,0,0,0,0,0,12,6,6,6
0,0,0,0,0,0,0,0,0,0,0,0,0,0,0,0,0,0,0,0,0,6,6,6,6,1,0,0,0,0,0,0,0,1,6,6,6,6
0,0,0,0,0,0,0,0,0,0,0,0,0,0,0,0,0,0,0,0,0,6,6,6,6,1,1,0,0,0,0,0,1,1,6,6,6,6
0,0,0,0,0,0,0,0,0,0,0,0,0,0,0,0,0,0,0,0,0,6,6,6,6,6,6,13,15,1,13,15,6,6,6,6,6,6
0,0,0,0,0,0,0,0,0,0,0,0,0,0,0,0,0,0,0,0,0,6,6,6,6,6,6,6,6,6,6,6,6,6,6,6,6,6
0,0,0,0,0,0,0,0,0,0,0,0,0,0,0,0,0,0,0,0,0,6,6,6,6,6,6,6,6,6,6,6,6,6,6,6,6,6
0,0,0,0,0,0,0,0,0,0,0,0,0,0,0,0,0,0,0,0,0,6,6,6,6,6,6,6,6,6,6,6,6,6,6,6,6,6
endlayer

layer
0,0,0,0,0,0,0,0,0,0,0,0,0,0,0,0,0,0,0,0,0,6,6,6,6,6,6,6,6,6,6,6,6,6,6,6,6,6
0,0,0,0,0,0,0,0,0,0,0,0,0,0,0,0,0,0,0,0,0,6,6,6,6,6,6,6,6,6,6,6,6,6,6,6,6,6
0,0,0,0,0,0,0,0,0,0,0,0,0,0,0,0,0,0,0,0,0,6,6,6,6,6,6,6,6,6,6,6,6,6,6,6,6,6
0,0,0,0,0,0,0,0,0,0,0,0,0,0,0,0,0,0,0,0,0,6,6,6,6,6,6,6,6,6,6,6,6,6,6,6,6,6
0,0,0,0,0,0,0,0,0,0,0,0,0,0,0,0,0,0,0,0,0,6,6,6,6,1,1,1,1,1,1,1,1,1,6,6,6,6
0,0,0,0,0,0,0,0,0,0,0,0,0,0,0,0,0,0,0,0,0,6,6,6,6,1,0,0,0,0,0,0,0,1,6,6,6,6
0,0,0,0,0,0,0,0,0,0,0,0,0,0,0,0,0,0,0,0,0,6,6,6,6,1,0,0,0,0,0,0,0,1,6,6,6,6
0,0,0,0,0,0,0,0,0,0,0,0,0,0,0,0,0,0,0,0,0,6,6,6,6,1,0,0,0,1,1,0,0,1,6,6,6,6
0,0,0,0,0,0,0,0,0,0,0,0,0,0,0,0,0,0,0,0,0,6,6,6,6,1,0,0,0,30,17,0,0,1,6,6,6,6
0,0,0,0,0,0,0,0,0,0,0,0,0,0,0,0,0,0,0,0,0,6,6,6,6,1,0,0,0,0,0,0,0,1,6,6,6,6
0,0,0,0,0,0,0,0,0,0,0,0,0,0,0,0,0,0,0,0,0,6,6,6,6,1,0,0,0,0,0,0,0,1,6,6,6,6
0,0,0,0,0,0,0,0,0,0,0,0,0,0,0,0,0,0,0,0,0,6,6,6,6,1,0,0,0,0,0,0,0,1,6,6,6,6
0,0,0,0,0,0,0,0,0,0,0,0,0,0,0,0,0,0,0,0,0,6,6,6,6,1,1,1,1,1,1,1,1,1,6,6,6,6
0,0,0,0,0,0,0,0,0,0,0,0,0,0,0,0,0,0,0,0,0,6,6,6,6,6,6,6,6,6,6,6,6,6,6,6,6,6
0,0,0,0,0,0,0,0,0,0,0,0,0,0,0,0,0,0,0,0,0,6,6,6,6,6,6,6,6,6,6,6,6,6,6,6,6,6
0,0,0,0,0,0,0,0,0,0,0,0,0,0,0,0,0,0,0,0,0,6,6,6,6,6,6,6,6,6,6,6,6,6,6,6,6,6
0,0,0,0,0,0,0,0,0,0,0,0,0,0,0,0,0,0,0,0,0,6,6,6,6,6,6,6,6,6,6,6,6,6,6,6,6,6
endlayer

layer
0,0,0,0,0,0,0,0,0,0,0,0,0,0,0,0,0,0,0,0,0,6,6,6,6,6,6,6,6,6,6,6,6,6,6,6,6,6
0,0,0,0,0,0,0,0,0,0,0,0,0,0,0,0,0,0,0,0,0,6,6,6,6,6,6,6,6,6,6,6,6,6,6,6,6,6
0,0,0,0,0,0,0,0,0,0,0,0,0,0,0,0,0,0,0,0,0,6,6,6,6,6,6,6,6,6,6,6,6,6,6,6,6,6
0,0,0,0,0,0,0,0,0,0,0,0,0,0,0,0,0,0,0,0,0,6,6,6,6,6,6,6,6,6,6,6,6,6,6,6,6,6
0,0,0,0,0,0,0,0,0,0,0,0,0,0,0,0,0,0,0,0,0,6,6,6,6,6,6,6,6,6,6,6,6,6,6,6,6,6
0,0,0,0,0,0,0,0,0,0,0,0,0,0,0,0,0,0,0,0,0,6,6,6,6,6,1,1,1,1,1,1,1,6,6,6,6,6
0,0,0,0,0,0,0,0,0,0,0,0,0,0,0,0,0,0,0,0,0,6,6,6,6,6,1,0,0,0,0,0,1,6,6,6,6,6
0,0,0,0,0,0,0,0,0,0,0,0,0,0,0,0,0,0,0,0,0,6,6,6,6,6,1,0,1,13,0,0,1,6,6,6,6,6
0,0,0,0,0,0,0,0,0,0,0,0,0,0,0,0,0,0,0,0,0,6,6,6,6,6,1,0,1,31,0,0,1,6,6,6,6,6
0,0,0,0,0,0,0,0,0,0,0,0,0,0,0,0,0,0,0,0,0,6,6,6,6,6,1,0,0,0,0,0,1,6,6,6,6,6
0,0,0,0,0,0,0,0,0,0,0,0,0,0,0,0,0,0,0,0,0,6,6,6,6,6,1,0,0,0,0,0,1,6,6,6,6,6
0,0,0,0,0,0,0,0,0,0,0,0,0,0,0,0,0,0,0,0,0,6,6,6,6,6,1,1,1,1,1,1,1,6,6,6,6,6
0,0,0,0,0,0,0,0,0,0,0,0,0,0,0,0,0,0,0,0,0,6,6,6,6,6,6,6,6,6,6,6,6,6,6,6,6,6
0,0,0,0,0,0,0,0,0,0,0,0,0,0,0,0,0,0,0,0,0,6,6,6,6,6,6,6,6,6,6,6,6,6,6,6,6,6
0,0,0,0,0,0,0,0,0,0,0,0,0,0,0,0,0,0,0,0,0,6,6,6,6,6,6,6,6,6,6,6,6,6,6,6,6,6
0,0,0,0,0,0,0,0,0,0,0,0,0,0,0,0,0,0,0,0,0,6,6,6,6,6,6,6,6,6,6,6,6,6,6,6,6,6
0,0,0,0,0,0,0,0,0,0,0,0,0,0,0,0,0,0,0,0,0,6,6,6,6,6,6,6,6,6,6,6,6,6,6,6,6,6
endlayer

layer
0,0,0,0,0,0,0,0,0,0,0,0,0,0,0,0,0,0,0,0,0,6,6,6,6,6,6,6,6,6,6,6,6,6,6,6,6,6
0,0,0,0,0,0,0,0,0,0,0,0,0,0,0,0,0,0,0,0,0,6,4,6,4,6,4,6,4,6,4,6,4,6,4,6,4,6
0,0,0,0,0,0,0,0,0,0,0,0,0,0,0,0,0,0,0,0,0,6,6,6,6,6,6,6,6,6,6,6,6,6,6,6,6,6
0,0,0,0,0,0,0,0,0,0,0,0,0,0,0,0,0,0,0,0,0,6,4,6,6,6,6,6,6,6,6,6,6,6,6,6,4,6
0,0,0,0,0,0,0,0,0,0,0,0,0,0,0,0,0,0,0,0,0,6,6,6,6,6,6,6,6,6,6,6,6,6,6,6,6,6
0,0,0,0,0,0,0,0,0,0,0,0,0,0,0,0,0,0,0,0,0,6,4,6,6,6,6,6,6,6,6,6,6,6,6,6,4,6
0,0,0,0,0,0,0,0,0,0,0,0,0,0,0,0,0,0,0,0,0,6,6,6,6,6,6,1,1,1,1,1,6,6,6,6,6,6
0,0,0,0,0,0,0,0,0,0,0,0,0,0,0,0,0,0,0,0,0,6,4,6,6,6,6,1,0,0,0,1,6,6,6,6,4,6
0,0,0,0,0,0,0,0,0,0,0,0,0,0,0,0,0,0,0,0,0,6,6,6,6,6,6,1,12,0,0,1,6,6,6,6,6,6
0,0,0,0,0,0,0,0,0,0,0,0,0,0,0,0,0,0,0,0,0,6,4,6,6,6,6,1,1,0,0,1,6,6,6,6,4,6
0,0,0,0,0,0,0,0,0,0,0,0,0,0,0,0,0,0,0,0,0,6,6,6,6,6,6,1,1,1,1,1,6,6,6,6,6,6
0,0,0,0,0,0,0,0,0,0,0,0,0,0,0,0,0,0,0,0,0,6,4,6,6,6,6,6,6,6,6,6,6,6,6,6,4,6
0,0,0,0,0,0,0,0,0,0,0,0,0,0,0,0,0,0,0,0,0,6,6,6,6,6,6,6,6,6,6,6,6,6,6,6,6,6
0,0,0,0,0,0,0,0,0,0,0,0,0,0,0,0,0,0,0,0,0,6,4,6,6,6,6,6,6,6,6,6,6,6,6,6,4,6
0,0,0,0,0,0,0,0,0,0,0,0,0,0,0,0,0,0,0,0,0,6,6,6,6,6,6,6,6,6,6,6,6,6,6,6,6,6
0,0,0,0,0,0,0,0,0,0,0,0,0,0,0,0,0,0,0,0,0,6,4,6,4,6,4,6,4,6,4,6,4,6,4,6,4,6
0,0,0,0,0,0,0,0,0,0,0,0,0,0,0,0,0,0,0,0,0,6,6,6,6,6,6,6,6,6,6,6,6,6,6,6,6,6
endlayer

layer
0,0,0,0,0,0,0,0,0,0,0,0,0,0,0,0,0,0,0,0,0,6,6,6,6,6,6,6,6,6,6,6,6,6,6,6,6,6
0,0,0,0,0,0,0,0,0,0,0,0,0,0,0,0,0,0,0,0,0,6,4,6,4,6,4,6,4,6,4,6,4,6,4,6,4,6
0,0,0,0,0,0,0,0,0,0,0,0,0,0,0,0,0,0,0,0,0,6,6,6,6,6,6,6,6,6,6,6,6,6,6,6,6,6
0,0,0,0,0,0,0,0,0,0,0,0,0,0,0,0,0,0,0,0,0,6,4,6,4,6,4,6,4,6,4,6,4,6,4,6,4,6
0,0,0,0,0,0,0,0,0,0,0,0,0,0,0,0,0,0,0,0,0,6,6,6,6,6,6,6,6,6,6,6,6,6,6,6,6,6
0,0,0,0,0,0,0,0,0,0,0,0,0,0,0,0,0,0,0,0,0,6,4,6,4,6,6,6,6,6,6,6,6,6,4,6,4,6
0,0,0,0,0,0,0,0,0,0,0,0,0,0,0,0,0,0,0,0,0,6,6,6,6,6,6,6,1,1,1,6,6,6,6,6,6,6
0,0,0,0,0,0,0,0,0,0,0,0,0,0,0,0,0,0,0,0,0,6,4,6,4,6,6,1,0,0,0,1,6,6,4,6,4,6
0,0,0,0,0,0,0,0,0,0,0,0,0,0,0,0,0,0,0,0,0,6,6,6,6,6,6,1,0,0,0,1,6,6,6,6,6,6
0,0,0,0,0,0,0,0,0,0,0,0,0,0,0,0,0,0,0,0,0,6,4,6,4,6,6,1,0,15,1,1,6,6,4,6,4,6
0,0,0,0,0,0,0,0,0,0,0,0,0,0,0,0,0,0,0,0,0,6,6,6,6,6,6,6,1,1,1,6,6,6,6,6,6,6
0,0,0,0,0,0,0,0,0,0,0,0,0,0,0,0,0,0,0,0,0,6,4,6,4,6,6,6,6,6,6,6,6,6,4,6,4,6
0,0,0,0,0,0,0,0,0,0,0,0,0,0,0,0,0,0,0,0,0,6,6,6,6,6,6,6,6,6,6,6,6,6,6,6,6,6
0,0,0,0,0,0,0,0,0,0,0,0,0,0,0,0,0,0,0,0,0,6,4,6,4,6,4,6,4,6,4,6,4,6,4,6,4,6
0,0,0,0,0,0,0,0,0,0,0,0,0,0,0,0,0,0,0,0,0,6,6,6,6,6,6,6,6,6,6,6,6,6,6,6,6,6
0,0,0,0,0,0,0,0,0,0,0,0,0,0,0,0,0,0,0,0,0,6,4,6,4,6,4,6,4,6,4,6,4,6,4,6,4,6
0,0,0,0,0,0,0,0,0,0,0,0,0,0,0,0,0,0,0,0,0,6,6,6,6,6,6,6,6,6,6,6,6,6,6,6,6,6
endlayer

layer
0,0,0,0,0,0,0,0,0,0,0,0,0,0,0,0,0,0,0,0,0,6,6,6,6,6,6,6,6,6,6,6,6,6,6,6,6,6
0,0,0,0,0,0,0,0,0,0,0,0,0,0,0,0,0,0,0,0,0,6,14,6,14,6,14,6,14,6,14,6,14,6,14,6,14,6
0,0,0,0,0,0,0,0,0,0,0,0,0,0,0,0,0,0,0,0,0,6,6,6,6,6,6,6,6,6,6,6,6,6,6,6,6,6
0,0,0,0,0,0,0,0,0,0,0,0,0,0,0,0,0,0,0,0,0,6,14,6,14,6,14,6,14,6,14,6,14,6,14,6,14,6
0,0,0,0,0,0,0,0,0,0,0,0,0,0,0,0,0,0,0,0,0,6,6,6,6,6,6,6,6,6,6,6,6,6,6,6,6,6
0,0,0,0,0,0,0,0,0,0,0,0,0,0,0,0,0,0,0,0,0,6,14,6,14,6,14,6,14,6,14,6,14,6,14,6,14,6
0,0,0,0,0,0,0,0,0,0,0,0,0,0,0,0,0,0,0,0,0,6,6,6,6,6,6,6,1,1,1,6,6,6,6,6,6,6
0,0,0,0,0,0,0,0,0,0,0,0,0,0,0,0,0,0,0,0,0,6,14,6,14,6,14,1,0,0,1,1,14,6,14,6,14,6
0,0,0,0,0,0,0,0,0,0,0,0,0,0,0,0,0,0,0,0,0,6,6,6,6,6,6,1,0,0,17,1,6,6,6,6,6,6
0,0,0,0,0,0,0,0,0,0,0,0,0,0,0,0,0,0,0,0,0,6,14,6,14,6,14,1,0,0,0,1,14,6,14,6,14,6
0,0,0,0,0,0,0,0,0,0,0,0,0,0,0,0,0,0,0,0,0,6,6,6,6,6,6,6,1,1,1,6,6,6,6,6,6,6
0,0,0,0,0,0,0,0,0,0,0,0,0,0,0,0,0,0,0,0,0,6,14,6,14,6,14,6,14,6,14,6,14,6,14,6,14,6
0,0,0,0,0,0,0,0,0,0,0,0,0,0,0,0,0,0,0,0,0,6,6,6,6,6,6,6,6,6,6,6,6,6,6,6,6,6
0,0,0,0,0,0,0,0,0,0,0,0,0,0,0,0,0,0,0,0,0,6,14,6,14,6,14,6,14,6,14,6,14,6,14,6,14,6
0,0,0,0,0,0,0,0,0,0,0,0,0,0,0,0,0,0,0,0,0,6,6,6,6,6,6,6,6,6,6,6,6,6,6,6,6,6
0,0,0,0,0,0,0,0,0,0,0,0,0,0,0,0,0,0,0,0,0,6,14,6,14,6,14,6,14,6,14,6,14,6,14,6,14,6
0,0,0,0,0,0,0,0,0,0,0,0,0,0,0,0,0,0,0,0,0,6,6,6,6,6,6,6,6,6,6,6,6,6,6,6,6,6
endlayer

layer
0,0,0,0,0,0,0,0,0,0,0,0,0,0,0,0,0,0,0,0,0,6,6,6,6,6,6,6,6,6,6,6,6,6,6,6,6,6
0,0,0,0,0,0,0,0,0,0,0,0,0,0,0,0,0,0,0,0,0,6,6,6,6,6,6,6,6,6,6,6,6,6,6,6,6,6
0,0,0,0,0,0,0,0,0,0,0,0,0,0,0,0,0,0,0,0,0,6,6,6,6,6,6,6,6,6,6,6,6,6,6,6,6,6
0,0,0,0,0,0,0,0,0,0,0,0,0,0,0,0,0,0,0,0,0,6,6,6,6,6,6,6,6,6,6,6,6,6,6,6,6,6
0,0,0,0,0,0,0,0,0,0,0,0,0,0,0,0,0,0,0,0,0,6,6,6,6,6,6,6,6,6,6,6,6,6,6,6,6,6
0,0,0,0,0,0,0,0,0,0,0,0,0,0,0,0,0,0,0,0,0,6,6,6,6,6,6,6,6,6,6,6,6,6,6,6,6,6
0,0,0,0,0,0,0,0,0,0,0,0,0,0,0,0,0,0,0,0,0,6,6,6,6,6,6,6,1,1,1,6,6,6,6,6,6,6
0,0,0,0,0,0,0,0,0,0,0,0,0,0,0,0,0,0,0,0,0,6,6,6,6,6,6,1,1,13,0,1,6,6,6,6,6,6
0,0,0,0,0,0,0,0,0,0,0,0,0,0,0,0,0,0,0,0,0,6,6,6,6,6,6,1,0,0,0,1,6,6,6,6,6,6
0,0,0,0,0,0,0,0,0,0,0,0,0,0,0,0,0,0,0,0,0,6,6,6,6,6,6,1,0,0,0,1,6,6,6,6,6,6
0,0,0,0,0,0,0,0,0,0,0,0,0,0,0,0,0,0,0,0,0,6,6,6,6,6,6,6,1,1,1,6,6,6,6,6,6,6
0,0,0,0,0,0,0,0,0,0,0,0,0,0,0,0,0,0,0,0,0,6,6,6,6,6,6,6,6,6,6,6,6,6,6,6,6,6
0,0,0,0,0,0,0,0,0,0,0,0,0,0,0,0,0,0,0,0,0,6,6,6,6,6,6,6,6,6,6,6,6,6,6,6,6,6
0,0,0,0,0,0,0,0,0,0,0,0,0,0,0,0,0,0,0,0,0,6,6,6,6,6,6,6,6,6,6,6,6,6,6,6,6,6
0,0,0,0,0,0,0,0,0,0,0,0,0,0,0,0,0,0,0,0,0,6,6,6,6,6,6,6,6,6,6,6,6,6,6,6,6,6
0,0,0,0,0,0,0,0,0,0,0,0,0,0,0,0,0,0,0,0,0,6,6,6,6,6,6,6,6,6,6,6,6,6,6,6,6,6
0,0,0,0,0,0,0,0,0,0,0,0,0,0,0,0,0,0,0,0,0,6,6,6,6,6,6,6,6,6,6,6,6,6,6,6,6,6
endlayer

layer
0,0,0,0,0,0,0,0,0,0,0,0,0,0,0,0,0,0,0,0,0,6,6,6,6,6,6,6,6,6,6,6,6,6,6,6,6,6
0,0,0,0,0,0,0,0,0,0,0,0,0,0,0,0,0,0,0,0,0,6,6,6,6,6,6,6,6,6,6,6,6,6,6,6,6,6
0,0,0,0,0,0,0,0,0,0,0,0,0,0,0,0,0,0,0,0,0,6,6,6,6,6,6,6,6,6,6,6,6,6,6,6,6,6
0,0,0,0,0,0,0,0,0,0,0,0,0,0,0,0,0,0,0,0,0,6,6,6,6,6,6,6,6,6,6,6,6,6,6,6,6,6
0,0,0,0,0,0,0,0,0,0,0,0,0,0,0,0,0,0,0,0,0,6,6,6,6,6,6,6,6,6,6,6,6,6,6,6,6,6
0,0,0,0,0,0,0,0,0,0,0,0,0,0,0,0,0,0,0,0,0,6,6,6,6,6,6,6,6,6,6,6,6,6,6,6,6,6
0,0,0,0,0,0,0,0,0,0,0,0,0,0,0,0,0,0,0,0,0,6,6,6,6,6,6,6,1,1,1,6,6,6,6,6,6,6
0,0,0,0,0,0,0,0,0,0,0,0,0,0,0,0,0,0,0,0,0,6,6,6,6,6,6,1,0,0,0,1,6,6,6,6,6,6
0,0,0,0,0,0,0,0,0,0,0,0,0,0,0,0,0,0,0,0,0,6,6,6,6,6,6,1,12,0,0,1,6,6,6,6,6,6
0,0,0,0,0,0,0,0,0,0,0,0,0,0,0,0,0,0,0,0,0,6,6,6,6,6,6,1,1,0,0,1,6,6,6,6,6,6
0,0,0,0,0,0,0,0,0,0,0,0,0,0,0,0,0,0,0,0,0,6,6,6,6,6,6,6,1,1,1,6,6,6,6,6,6,6
0,0,0,0,0,0,0,0,0,0,0,0,0,0,0,0,0,0,0,0,0,6,6,6,6,6,6,6,6,6,6,6,6,6,6,6,6,6
0,0,0,0,0,0,0,0,0,0,0,0,0,0,0,0,0,0,0,0,0,6,6,6,6,6,6,6,6,6,6,6,6,6,6,6,6,6
0,0,0,0,0,0,0,0,0,0,0,0,0,0,0,0,0,0,0,0,0,6,6,6,6,6,6,6,6,6,6,6,6,6,6,6,6,6
0,0,0,0,0,0,0,0,0,0,0,0,0,0,0,0,0,0,0,0,0,6,6,6,6,6,6,6,6,6,6,6,6,6,6,6,6,6
0,0,0,0,0,0,0,0,0,0,0,0,0,0,0,0,0,0,0,0,0,6,6,6,6,6,6,6,6,6,6,6,6,6,6,6,6,6
0,0,0,0,0,0,0,0,0,0,0,0,0,0,0,0,0,0,0,0,0,6,6,6,6,6,6,6,6,6,6,6,6,6,6,6,6,6
endlayer

layer
0,0,0,0,0,0,0,0,0,0,0,0,0,0,0,0,0,0,0,0,0,6,6,6,6,6,6,6,6,6,6,6,6,6,6,6,6,6
0,0,0,0,0,0,0,0,0,0,0,0,0,0,0,0,0,0,0,0,0,6,6,6,6,6,6,6,6,6,6,6,6,6,6,6,6,6
0,0,0,0,0,0,0,0,0,0,0,0,0,0,0,0,0,0,0,0,0,6,6,6,6,6,6,6,6,6,6,6,6,6,6,6,6,6
0,0,0,0,0,0,0,0,0,0,0,0,0,0,0,0,0,0,0,0,0,6,6,6,6,6,6,6,6,6,6,6,6,6,6,6,6,6
0,0,0,0,0,0,0,0,0,0,0,0,0,0,0,0,0,0,0,0,0,6,6,6,6,6,6,6,6,6,6,6,6,6,6,6,6,6
0,0,0,0,0,0,0,0,0,0,0,0,0,0,0,0,0,0,0,0,0,6,6,6,6,6,6,6,6,6,6,6,6,6,6,6,6,6
0,0,0,0,0,0,0,0,0,0,0,0,0,0,0,0,0,0,0,0,0,6,6,6,6,6,6,6,1,1,1,6,6,6,6,6,6,6
0,0,0,0,0,0,0,0,0,0,0,0,0,0,0,0,0,0,0,0,0,6,6,6,6,6,6,1,0,0,0,1,6,6,6,6,6,6
0,0,0,0,0,0,0,0,0,0,0,0,0,0,0,0,0,0,0,0,0,6,6,6,6,6,6,1,0,0,0,1,6,6,6,6,6,6
0,0,0,0,0,0,0,0,0,0,0,0,0,0,0,0,0,0,0,0,0,6,6,6,6,6,6,1,0,15,1,1,6,6,6,6,6,6
0,0,0,0,0,0,0,0,0,0,0,0,0,0,0,0,0,0,0,0,0,6,6,6,6,6,6,6,1,1,1,6,6,6,6,6,6,6
0,0,0,0,0,0,0,0,0,0,0,0,0,0,0,0,0,0,0,0,0,6,6,6,6,6,6,6,6,6,6,6,6,6,6,6,6,6
0,0,0,0,0,0,0,0,0,0,0,0,0,0,0,0,0,0,0,0,0,6,6,6,6,6,6,6,6,6,6,6,6,6,6,6,6,6
0,0,0,0,0,0,0,0,0,0,0,0,0,0,0,0,0,0,0,0,0,6,6,6,6,6,6,6,6,6,6,6,6,6,6,6,6,6
0,0,0,0,0,0,0,0,0,0,0,0,0,0,0,0,0,0,0,0,0,6,6,6,6,6,6,6,6,6,6,6,6,6,6,6,6,6
0,0,0,0,0,0,0,0,0,0,0,0,0,0,0,0,0,0,0,0,0,6,6,6,6,6,6,6,6,6,6,6,6,6,6,6,6,6
0,0,0,0,0,0,0,0,0,0,0,0,0,0,0,0,0,0,0,0,0,6,6,6,6,6,6,6,6,6,6,6,6,6,6,6,6,6
endlayer

layer
0,0,0,0,0,0,0,0,0,0,0,0,0,0,0,0,0,0,0,0,0,6,6,6,6,6,6,6,6,6,6,6,6,6,6,6,6,6
0,0,0,0,0,0,0,0,0,0,0,0,0,0,0,0,0,0,0,0,0,6,6,6,6,6,6,6,6,6,6,6,6,6,6,6,6,6
0,0,0,0,0,0,0,0,0,0,0,0,0,0,0,0,0,0,0,0,0,6,6,6,6,6,6,6,6,6,6,6,6,6,6,6,6,6
0,0,0,0,0,0,0,0,0,0,0,0,0,0,0,0,0,0,0,0,0,6,6,6,6,6,6,6,6,6,6,6,6,6,6,6,6,6
0,0,0,0,0,0,0,0,0,0,0,0,0,0,0,0,0,0,0,0,0,6,6,6,6,6,6,6,6,6,6,6,6,6,6,0,6,6
0,0,0,0,0,0,0,0,0,0,0,0,0,0,0,0,0,0,0,0,0,6,6,6,6,6,6,6,6,6,6,6,6,6,6,6,6,6
0,0,0,0,0,0,0,0,0,0,0,0,0,0,0,0,0,0,0,0,0,6,6,6,6,6,6,6,1,1,1,6,6,6,6,6,6,6
0,0,0,0,0,0,0,0,0,0,0,0,0,0,0,0,0,0,0,0,0,6,6,6,6,6,6,1,0,0,1,1,6,6,6,6,6,6
0,0,0,0,0,0,0,0,0,0,0,0,0,0,0,0,0,0,0,0,0,6,6,6,6,6,6,1,0,0,17,1,6,6,6,6,6,6
0,0,0,0,0,0,0,0,0,0,0,0,0,0,0,0,0,0,0,0,0,6,6,6,6,6,6,1,0,0,0,1,6,6,6,6,6,6
0,0,0,0,0,0,0,0,0,0,0,0,0,0,0,0,0,0,0,0,0,6,6,6,6,6,6,6,1,1,1,6,6,6,6,6,6,6
0,0,0,0,0,0,0,0,0,0,0,0,0,0,0,0,0,0,0,0,0,6,6,6,6,6,6,6,6,6,6,6,6,6,6,6,6,6
0,0,0,0,0,0,0,0,0,0,0,0,0,0,0,0,0,0,0,0,0,6,6,6,6,6,6,6,6,6,6,6,6,6,6,6,6,6
0,0,0,0,0,0,0,0,0,0,0,0,0,0,0,0,0,0,0,0,0,6,6,6,6,6,6,6,6,6,6,6,6,6,6,6,6,6
0,0,0,0,0,0,0,0,0,0,0,0,0,0,0,0,0,0,0,0,0,6,6,6,6,6,6,6,6,6,6,6,6,6,6,6,6,6
0,0,0,0,0,0,0,0,0,0,0,0,0,0,0,0,0,0,0,0,0,6,6,6,6,6,6,6,6,6,6,6,6,6,6,6,6,6
0,0,0,0,0,0,0,0,0,0,0,0,0,0,0,0,0,0,0,0,0,6,6,6,6,6,6,6,6,6,6,6,6,6,6,6,6,6
endlayer

layer
0,0,0,0,0,0,0,0,0,0,0,0,0,0,0,0,0,0,0,0,0,6,6,6,6,6,6,6,6,6,6,6,6,6,6,6,6,6
0,0,0,0,0,0,0,0,0,0,0,0,0,0,0,0,0,0,0,0,0,6,6,6,6,6,6,6,6,6,6,6,6,6,6,6,6,6
0,0,0,0,0,0,0,0,0,0,0,0,0,0,0,0,0,0,0,0,0,6,6,6,6,6,6,6,6,6,6,6,6,6,6,6,6,6
0,0,0,0,0,0,0,0,0,0,0,0,0,0,0,0,0,0,0,0,0,6,6,6,6,6,6,6,6,6,6,6,6,6,6,6,6,6
0,0,0,0,0,0,0,0,0,0,0,0,0,0,0,0,0,0,0,0,0,6,6,6,6,6,6,6,6,6,6,6,6,6,6,6,6,6
0,0,0,0,0,0,0,0,0,0,0,0,0,0,0,0,0,0,0,0,0,6,6,6,6,6,6,6,6,6,6,6,6,6,6,6,6,6
0,0,0,0,0,0,0,0,0,0,0,0,0,0,0,0,0,0,0,0,0,6,6,6,6,6,6,6,1,1,1,6,6,6,6,6,6,6
0,0,0,0,0,0,0,0,0,0,0,0,0,0,0,0,0,0,0,0,0,6,6,6,6,6,6,1,1,13,0,1,6,6,6,6,6,6
0,0,0,0,0,0,0,0,0,0,0,0,0,0,0,0,0,0,0,0,0,6,6,6,6,6,6,1,0,0,0,1,6,6,6,6,6,6
0,0,0,0,0,0,0,0,0,0,0,0,0,0,0,0,0,0,0,0,0,6,6,6,6,6,6,1,0,0,0,1,6,6,6,6,6,6
0,0,0,0,0,0,0,0,0,0,0,0,0,0,0,0,0,0,0,0,0,6,6,6,6,6,6,6,1,1,1,6,6,6,6,6,6,6
0,0,0,0,0,0,0,0,0,0,0,0,0,0,0,0,0,0,0,0,0,6,6,6,6,6,6,6,6,6,6,6,6,6,6,6,6,6
0,0,0,0,0,0,0,0,0,0,0,0,0,0,0,0,0,0,0,0,0,6,6,6,6,6,6,6,6,6,6,6,6,6,6,6,6,6
0,0,0,0,0,0,0,0,0,0,0,0,0,0,0,0,0,0,0,0,0,6,6,6,6,6,6,6,6,6,6,6,6,6,6,6,6,6
0,0,0,0,0,0,0,0,0,0,0,0,0,0,0,0,0,0,0,0,0,6,6,6,6,6,6,6,6,6,6,6,6,6,6,6,6,6
0,0,0,0,0,0,0,0,0,0,0,0,0,0,0,0,0,0,0,0,0,6,6,6,6,6,6,6,6,6,6,6,6,6,6,6,6,6
0,0,0,0,0,0,0,0,0,0,0,0,0,0,0,0,0,0,0,0,0,6,6,6,6,6,6,6,6,6,6,6,6,6,6,6,6,6
endlayer

layer
0,0,0,0,0,0,0,0,0,0,0,0,0,0,0,0,0,0,0,0,0,6,6,6,6,6,6,6,6,6,6,6,6,6,6,6,6,6
0,0,0,0,0,0,0,0,0,0,0,0,0,0,0,0,0,0,0,0,0,6,6,6,6,6,6,6,6,6,6,6,6,6,6,6,6,6
0,0,0,0,0,0,0,0,0,0,0,0,0,0,0,0,0,0,0,0,0,6,6,6,6,6,6,6,6,6,6,6,6,6,6,6,6,6
0,0,0,0,0,0,0,0,0,0,0,0,0,0,0,0,0,0,0,0,0,6,6,6,6,6,6,6,6,6,6,6,6,6,6,6,6,6
0,0,0,0,0,0,0,0,0,0,0,0,0,0,0,0,0,0,0,0,0,6,6,6,6,6,6,6,6,6,6,6,6,6,6,6,6,6
0,0,0,0,0,0,0,0,0,0,0,0,0,0,0,0,0,0,0,0,0,6,6,6,6,6,6,6,6,6,6,6,6,6,6,6,6,6
0,0,0,0,0,0,0,0,0,0,0,0,0,0,0,0,0,0,0,0,0,6,6,6,6,6,6,6,1,1,1,6,6,6,6,6,6,6
0,0,0,0,0,0,0,0,0,0,0,0,0,0,0,0,0,0,0,0,0,6,6,6,6,6,6,1,0,0,0,1,6,6,6,6,6,6
0,0,0,0,0,0,0,0,0,0,0,0,0,0,0,0,0,0,0,0,0,6,6,6,6,6,6,1,12,0,0,1,6,6,6,6,6,6
0,0,0,0,0,0,0,0,0,0,0,0,0,0,0,0,0,0,0,0,0,6,6,6,6,6,6,1,1,0,0,1,6,6,6,6,6,6
0,0,0,0,0,0,0,0,0,0,0,0,0,0,0,0,0,0,0,0,0,6,6,6,6,6,6,6,1,1,1,6,6,6,6,6,6,6
0,0,0,0,0,0,0,0,0,0,0,0,0,0,0,0,0,0,0,0,0,6,6,6,6,6,6,6,6,6,6,6,6,6,6,6,6,6
0,0,0,0,0,0,0,0,0,0,0,0,0,0,0,0,0,0,0,0,0,6,6,6,6,6,6,6,6,6,6,6,6,6,6,6,6,6
0,0,0,0,0,0,0,0,0,0,0,0,0,0,0,0,0,0,0,0,0,6,6,6,6,6,6,6,6,6,6,6,6,6,6,6,6,6
0,0,0,0,0,0,0,0,0,0,0,0,0,0,0,0,0,0,0,0,0,6,6,6,6,6,6,6,6,6,6,6,6,6,6,6,6,6
0,0,0,0,0,0,0,0,0,0,0,0,0,0,0,0,0,0,0,0,0,6,6,6,6,6,6,6,6,6,6,6,6,6,6,6,6,6
0,0,0,0,0,0,0,0,0,0,0,0,0,0,0,0,0,0,0,0,0,6,6,6,6,6,6,6,6,6,6,6,6,6,6,6,6,6
endlayer

layer
0,0,0,0,0,0,0,0,0,0,0,0,0,0,0,0,0,0,0,0,0,6,6,6,6,6,6,6,6,6,6,6,6,6,6,6,6,6
0,0,0,0,0,0,0,0,0,0,0,0,0,0,0,0,0,0,0,0,0,6,6,6,6,6,6,6,6,6,6,6,6,6,6,6,6,6
0,0,0,0,0,0,0,0,0,0,0,0,0,0,0,0,0,0,0,0,0,6,6,6,6,6,6,6,6,6,6,6,6,6,6,6,6,6
0,0,0,0,0,0,0,0,0,0,0,0,0,0,0,0,0,0,0,0,0,6,6,6,6,6,6,6,6,6,6,6,6,6,6,6,6,6
0,0,0,0,0,0,0,0,0,0,0,0,0,0,0,0,0,0,0,0,0,6,6,6,6,6,6,6,6,6,6,6,6,6,6,6,6,6
0,0,0,0,0,0,0,0,0,0,0,0,0,0,0,0,0,0,0,0,0,6,6,6,6,6,6,6,0,0,0,6,6,6,6,6,6,6
0,0,0,0,0,0,0,0,0,0,0,0,0,0,0,0,0,0,0,0,0,6,6,6,6,6,6,6,1,1,1,6,6,6,6,6,6,6
0,0,0,0,0,0,0,0,0,0,0,0,0,0,0,0,0,0,0,0,0,6,6,6,6,6,0,1,0,0,0,1,0,6,6,6,6,6
0,0,0,0,0,0,0,0,0,0,0,0,0,0,0,0,0,0,0,0,0,6,6,6,6,6,0,1,0,0,0,1,0,6,6,6,6,6
0,0,0,0,0,0,0,0,0,0,0,0,0,0,0,0,0,0,0,0,0,6,6,6,6,6,0,1,0,15,1,1,0,6,6,6,6,6
0,0,0,0,0,0,0,0,0,0,0,0,0,0,0,0,0,0,0,0,0,6,6,6,6,6,6,6,1,1,1,6,6,6,6,6,6,6
0,0,0,0,0,0,0,0,0,0,0,0,0,0,0,0,0,0,0,0,0,6,6,6,6,6,6,6,0,0,0,6,6,6,6,6,6,6
0,0,0,0,0,0,0,0,0,0,0,0,0,0,0,0,0,0,0,0,0,6,6,6,6,6,6,6,6,6,6,6,6,6,6,6,6,6
0,0,0,0,0,0,0,0,0,0,0,0,0,0,0,0,0,0,0,0,0,6,6,6,6,6,6,6,6,6,6,6,6,6,6,6,6,6
0,0,0,0,0,0,0,0,0,0,0,0,0,0,0,0,0,0,0,0,0,6,6,6,6,6,6,6,6,6,6,6,6,6,6,6,6,6
0,0,0,0,0,0,0,0,0,0,0,0,0,0,0,0,0,0,0,0,0,6,6,6,6,6,6,6,6,6,6,6,6,6,6,6,6,6
0,0,0,0,0,0,0,0,0,0,0,0,0,0,0,0,0,0,0,0,0,6,6,6,6,6,6,6,6,6,6,6,6,6,6,6,6,6
endlayer

layer
0,0,0,0,0,0,0,0,0,0,0,0,0,0,0,0,0,0,0,0,0,6,6,6,6,6,6,6,6,6,6,6,6,6,6,6,6,6
0,0,0,0,0,0,0,0,0,0,0,0,0,0,0,0,0,0,0,0,0,6,6,6,6,6,6,6,6,6,6,6,6,6,6,6,6,6
0,0,0,0,0,0,0,0,0,0,0,0,0,0,0,0,0,0,0,0,0,6,6,6,6,6,6,6,6,6,6,6,6,6,6,6,6,6
0,0,0,0,0,0,0,0,0,0,0,0,0,0,0,0,0,0,0,0,0,6,6,6,0,0,0,0,0,0,0,0,0,0,0,6,6,6
0,0,0,0,0,0,0,0,0,0,0,0,0,0,0,0,0,0,0,0,0,6,6,6,0,0,0,0,0,0,0,0,0,0,0,6,6,6
0,0,0,0,0,0,0,0,0,0,0,0,0,0,0,0,0,0,0,0,0,6,6,6,0,0,0,0,0,0,0,0,0,0,0,6,6,6
0,0,0,0,0,0,0,0,0,0,0,0,0,0,0,0,0,0,0,0,0,6,6,6,0,0,0,6,1,1,1,6,0,0,0,6,6,6
0,0,0,0,0,0,0,0,0,0,0,0,0,0,0,0,0,0,0,0,0,6,6,6,0,0,0,1,0,0,1,1,0,0,0,6,6,6
0,0,0,0,0,0,0,0,0,0,0,0,0,0,0,0,0,0,0,0,0,6,6,6,0,0,0,1,0,0,17,1,0,0,0,6,6,6
0,0,0,0,0,0,0,0,0,0,0,0,0,0,0,0,0,0,0,0,0,6,6,6,0,0,0,1,0,0,0,1,0,0,0,6,6,6
0,0,0,0,0,0,0,0,0,0,0,0,0,0,0,0,0,0,0,0,0,6,6,6,0,0,0,6,1,1,1,6,0,0,0,6,6,6
0,0,0,0,0,0,0,0,0,0,0,0,0,0,0,0,0,0,0,0,0,6,6,6,0,0,0,0,0,0,0,0,0,0,0,6,6,6
0,0,0,0,0,0,0,0,0,0,0,0,0,0,0,0,0,0,0,0,0,6,6,6,0,0,0,0,0,0,0,0,0,0,0,6,6,6
0,0,0,0,0,0,0,0,0,0,0,0,0,0,0,0,0,0,0,0,0,6,6,6,0,0,0,0,0,0,0,0,0,0,0,6,6,6
0,0,0,0,0,0,0,0,0,0,0,0,0,0,0,0,0,0,0,0,0,6,6,6,6,6,6,6,6,6,6,6,6,6,6,6,6,6
0,0,0,0,0,0,0,0,0,0,0,0,0,0,0,0,0,0,0,0,0,6,6,6,6,6,6,6,6,6,6,6,6,6,6,6,6,6
0,0,0,0,0,0,0,0,0,0,0,0,0,0,0,0,0,0,0,0,0,6,6,6,6,6,6,6,6,6,6,6,6,6,6,6,6,6
endlayer

layer
0,0,0,0,0,0,0,0,0,0,0,0,0,0,0,0,0,0,0,0,0,6,6,6,6,6,6,6,6,6,6,6,6,6,6,6,6,6
0,0,0,0,0,0,0,0,0,0,0,0,0,0,0,0,0,0,0,0,0,6,0,0,0,0,0,0,0,0,0,0,0,0,0,0,0,6
0,0,0,0,0,0,0,0,0,0,0,0,0,0,0,0,0,0,0,0,0,6,0,0,0,0,0,0,0,0,0,0,0,0,0,0,0,6
0,0,0,0,0,0,0,0,0,0,0,0,0,0,0,0,0,0,0,0,0,6,0,0,0,0,0,0,0,0,0,0,0,0,0,0,0,6
0,0,0,0,0,0,0,0,0,0,0,0,0,0,0,0,0,0,0,0,0,6,0,0,0,0,0,0,0,0,0,0,0,0,0,0,0,6
0,0,0,0,0,0,0,0,0,0,0,0,0,0,0,0,0,0,0,0,0,6,0,0,0,0,0,0,0,0,0,0,0,0,0,0,0,6
0,0,0,0,0,0,0,0,0,0,0,0,0,0,0,0,0,0,0,0,0,6,0,0,0,0,0,6,1,1,1,6,0,0,0,0,0,6
0,0,0,0,0,0,0,0,0,0,0,0,0,0,0,0,0,0,0,0,0,6,0,0,0,0,0,1,1,13,0,1,0,0,0,0,0,6
0,0,0,0,0,0,0,0,0,0,0,0,0,0,0,0,0,0,0,0,0,6,0,0,0,0,0,1,0,0,0,1,0,0,0,0,0,6
0,0,0,0,0,0,0,0,0,0,0,0,0,0,0,0,0,0,0,0,0,6,0,0,0,0,0,1,0,0,0,1,0,0,0,0,0,6
0,0,0,0,0,0,0,0,0,0,0,0,0,0,0,0,0,0,0,0,0,6,0,0,0,0,0,6,1,1,1,6,0,0,0,0,0,6
0,0,0,0,0,0,0,0,0,0,0,0,0,0,0,0,0,0,0,0,0,6,0,0,0,0,0,0,0,0,0,0,0,0,0,0,0,6
0,0,0,0,0,0,0,0,0,0,0,0,0,0,0,0,0,0,0,0,0,6,0,0,0,0,0,0,0,0,0,0,0,0,0,0,0,6
0,0,0,0,0,0,0,0,0,0,0,0,0,0,0,0,0,0,0,0,0,6,0,0,0,0,0,0,0,0,0,0,0,0,0,0,0,6
0,0,0,0,0,0,0,0,0,0,0,0,0,0,0,0,0,0,0,0,0,6,0,0,0,0,0,0,0,0,0,0,0,0,0,0,0,6
0,0,0,0,0,0,0,0,0,0,0,0,0,0,0,0,0,0,0,0,0,6,0,0,0,0,0,0,0,0,0,0,0,0,0,0,0,6
0,0,0,0,0,0,0,0,0,0,0,0,0,0,0,0,0,0,0,0,0,6,6,6,6,6,6,6,6,6,6,6,6,6,6,6,6,6
endlayer

layer
0,0,0,0,0,0,0,0,0,0,0,0,0,0,0,0,0,0,0,0,0,0,0,0,0,0,0,0,0,0,0,0,0,0,0,0,0,0
0,0,0,0,0,0,0,0,0,0,0,0,0,0,0,0,0,0,0,0,0,0,0,0,0,0,0,0,0,0,0,0,0,0,0,0,0,0
0,0,0,0,0,0,0,0,0,0,0,0,0,0,0,0,0,0,0,0,0,0,0,0,0,0,0,0,0,0,0,0,0,0,0,0,0,0
0,0,0,0,0,0,0,0,0,0,0,0,0,0,0,0,0,0,0,0,0,0,0,0,0,0,0,0,0,0,0,0,0,0,0,0,0,0
0,0,0,0,0,0,0,0,0,0,0,0,0,0,0,0,0,0,0,0,0,0,0,0,0,0,0,0,0,0,0,0,0,0,0,0,0,0
0,0,0,0,0,0,0,0,0,0,0,0,0,0,0,0,0,0,0,0,0,0,0,0,0,0,0,0,0,0,0,0,0,0,0,0,0,0
0,0,0,0,0,0,0,0,0,0,0,0,0,0,0,0,0,0,0,0,0,0,0,0,0,0,0,6,1,1,1,6,0,0,0,0,0,0
0,0,0,0,0,0,0,0,0,0,0,0,0,0,0,0,0,0,0,0,0,0,0,0,0,0,0,1,0,0,0,1,0,0,0,0,0,0
0,0,0,0,0,0,0,0,0,0,0,0,0,0,0,0,0,0,0,0,0,0,0,0,0,0,0,1,12,0,0,1,0,0,0,0,0,0
0,0,0,0,0,0,0,0,0,0,0,0,0,0,0,0,0,0,0,0,0,0,0,0,0,0,0,1,1,0,0,1,0,0,0,0,0,0
0,0,0,0,0,0,0,0,0,0,0,0,0,0,0,0,0,0,0,0,0,0,0,0,0,0,0,6,1,1,1,6,0,0,0,0,0,0
0,0,0,0,0,0,0,0,0,0,0,0,0,0,0,0,0,0,0,0,0,0,0,0,0,0,0,0,0,0,0,0,0,0,0,0,0,0
0,0,0,0,0,0,0,0,0,0,0,0,0,0,0,0,0,0,0,0,0,0,0,0,0,0,0,0,0,0,0,0,0,0,0,0,0,0
0,0,0,0,0,0,0,0,0,0,0,0,0,0,0,0,0,0,0,0,0,0,0,0,0,0,0,0,0,0,0,0,0,0,0,0,0,0
0,0,0,0,0,0,0,0,0,0,0,0,0,0,0,0,0,0,0,0,0,0,0,0,0,0,0,0,0,0,0,0,0,0,0,0,0,0
0,0,0,0,0,0,0,0,0,0,0,0,0,0,0,0,0,0,0,0,0,0,0,0,0,0,0,0,0,0,0,0,0,0,0,0,0,0
0,0,0,0,0,0,0,0,0,0,0,0,0,0,0,0,0,0,0,0,0,0,0,0,0,0,0,0,0,0,0,0,0,0,0,0,0,0
endlayer

layer
0,0,0,0,0,0,0,0,0,0,0,0,0,0,0,0,0,0,0,0,0,0,0,0,0,0,0,0,0,0,0,0,0,0,0,0,0,0
0,0,0,0,0,0,0,0,0,0,0,0,0,0,0,0,0,0,0,0,0,0,0,0,0,0,0,0,0,0,0,0,0,0,0,0,0,0
0,0,0,0,0,0,0,0,0,0,0,0,0,0,0,0,0,0,0,0,0,0,0,0,0,0,0,0,0,0,0,0,0,0,0,0,0,0
0,0,0,0,0,0,0,0,0,0,0,0,0,0,0,0,0,0,0,0,0,0,0,0,0,0,0,0,0,0,0,0,0,0,0,0,0,0
0,0,0,0,0,0,0,0,0,0,0,0,0,0,0,0,0,0,0,0,0,0,0,0,0,0,0,0,0,0,0,0,0,0,0,0,0,0
0,0,0,0,0,0,0,0,0,0,0,0,0,0,0,0,0,0,0,0,0,0,0,0,0,0,0,0,0,0,0,0,0,0,0,0,0,0
0,0,0,0,0,0,0,0,0,0,0,0,0,0,0,0,0,0,0,0,0,0,0,0,0,0,0,6,1,1,1,6,0,0,0,0,0,0
0,0,0,0,0,0,0,0,0,0,0,0,0,0,0,0,0,0,0,0,0,0,0,0,0,0,0,1,0,0,0,1,0,0,0,0,0,0
0,0,0,0,0,0,0,0,0,0,0,0,0,0,0,0,0,0,0,0,0,0,0,0,0,0,0,1,0,0,0,1,0,0,0,0,0,0
0,0,0,0,0,0,0,0,0,0,0,0,0,0,0,0,0,0,0,0,0,0,0,0,0,0,0,1,0,15,1,1,0,0,0,0,0,0
0,0,0,0,0,0,0,0,0,0,0,0,0,0,0,0,0,0,0,0,0,0,0,0,0,0,0,6,1,1,1,6,0,0,0,0,0,0
0,0,0,0,0,0,0,0,0,0,0,0,0,0,0,0,0,0,0,0,0,0,0,0,0,0,0,0,0,0,0,0,0,0,0,0,0,0
0,0,0,0,0,0,0,0,0,0,0,0,0,0,0,0,0,0,0,0,0,0,0,0,0,0,0,0,0,0,0,0,0,0,0,0,0,0
0,0,0,0,0,0,0,0,0,0,0,0,0,0,0,0,0,0,0,0,0,0,0,0,0,0,0,0,0,0,0,0,0,0,0,0,0,0
0,0,0,0,0,0,0,0,0,0,0,0,0,0,0,0,0,0,0,0,0,0,0,0,0,0,0,0,0,0,0,0,0,0,0,0,0,0
0,0,0,0,0,0,0,0,0,0,0,0,0,0,0,0,0,0,0,0,0,0,0,0,0,0,0,0,0,0,0,0,0,0,0,0,0,0
0,0,0,0,0,0,0,0,0,0,0,0,0,0,0,0,0,0,0,0,0,0,0,0,0,0,0,0,0,0,0,0,0,0,0,0,0,0
endlayer

layer
0,0,0,0,0,0,0,0,0,0,0,0,0,0,0,0,0,0,0,0,0,0,0,0,0,0,0,0,0,0,0,0,0,0,0,0,0,0
0,0,0,0,0,0,0,0,0,0,0,0,0,0,0,0,0,0,0,0,0,0,0,0,0,0,0,0,0,0,0,0,0,0,0,0,0,0
0,0,0,0,0,0,0,0,0,0,0,0,0,0,0,0,0,0,0,0,0,0,0,0,0,0,0,0,0,0,0,0,0,0,0,0,0,0
0,0,0,0,0,0,0,0,0,0,0,0,0,0,0,0,0,0,0,0,0,0,0,0,0,0,0,0,0,0,0,0,0,0,0,0,0,0
0,0,0,0,0,0,0,0,0,0,0,0,0,0,0,0,0,0,0,0,0,0,0,0,0,0,0,0,0,0,0,0,0,0,0,0,0,0
0,0,0,0,0,0,0,0,0,0,0,0,0,0,0,0,0,0,0,0,0,0,0,0,0,0,0,0,0,0,0,0,0,0,0,0,0,0
0,0,0,0,0,0,0,0,0,0,0,0,0,0,0,0,0,0,0,0,0,0,0,0,0,0,0,6,1,1,1,6,0,0,0,0,0,0
0,0,0,0,0,0,0,0,0,0,0,0,0,0,0,0,0,0,0,0,0,0,0,0,0,0,0,1,0,0,1,1,0,0,0,0,0,0
0,0,0,0,0,0,0,0,0,0,0,0,0,0,0,0,0,0,0,0,0,0,0,0,0,0,0,1,0,0,17,1,0,0,0,0,0,0
0,0,0,0,0,0,0,0,0,0,0,0,0,0,0,0,0,0,0,0,0,0,0,0,0,0,0,1,0,0,0,1,0,0,0,0,0,0
0,0,0,0,0,0,0,0,0,0,0,0,0,0,0,0,0,0,0,0,0,0,0,0,0,0,0,6,1,1,1,6,0,0,0,0,0,0
0,0,0,0,0,0,0,0,0,0,0,0,0,0,0,0,0,0,0,0,0,0,0,0,0,0,0,0,0,0,0,0,0,0,0,0,0,0
0,0,0,0,0,0,0,0,0,0,0,0,0,0,0,0,0,0,0,0,0,0,0,0,0,0,0,0,0,0,0,0,0,0,0,0,0,0
0,0,0,0,0,0,0,0,0,0,0,0,0,0,0,0,0,0,0,0,0,0,0,0,0,0,0,0,0,0,0,0,0,0,0,0,0,0
0,0,0,0,0,0,0,0,0,0,0,0,0,0,0,0,0,0,0,0,0,0,0,0,0,0,0,0,0,0,0,0,0,0,0,0,0,0
0,0,0,0,0,0,0,0,0,0,0,0,0,0,0,0,0,0,0,0,0,0,0,0,0,0,0,0,0,0,0,0,0,0,0,0,0,0
0,0,0,0,0,0,0,0,0,0,0,0,0,0,0,0,0,0,0,0,0,0,0,0,0,0,0,0,0,0,0,0,0,0,0,0,0,0
endlayer

layer
0,0,0,0,0,0,0,0,0,0,0,0,0,0,0,0,0,0,0,0,0,0,0,0,0,0,0,0,0,0,0,0,0,0,0,0,0,0
0,0,0,0,0,0,0,0,0,0,0,0,0,0,0,0,0,0,0,0,0,0,0,0,0,0,0,0,0,0,0,0,0,0,0,0,0,0
0,0,0,0,0,0,0,0,0,0,0,0,0,0,0,0,0,0,0,0,0,0,0,0,0,0,0,0,0,0,0,0,0,0,0,0,0,0
0,0,0,0,0,0,0,0,0,0,0,0,0,0,0,0,0,0,0,0,0,0,0,0,0,0,0,0,0,0,0,0,0,0,0,0,0,0
0,0,0,0,0,0,0,0,0,0,0,0,0,0,0,0,0,0,0,0,0,0,0,0,0,0,0,0,0,0,0,0,0,0,0,0,0,0
0,0,0,0,0,0,0,0,0,0,0,0,0,0,0,0,0,0,0,0,0,0,0,0,0,0,0,0,0,0,0,0,0,0,0,0,0,0
0,0,0,0,0,0,0,0,0,0,0,0,0,0,0,0,0,0,0,0,0,0,0,0,0,0,0,6,1,1,1,6,0,0,0,0,0,0
0,0,0,0,0,0,0,0,0,0,0,0,0,0,0,0,0,0,0,0,0,0,0,0,0,0,0,1,1,13,0,1,0,0,0,0,0,0
0,0,0,0,0,0,0,0,0,0,0,0,0,0,0,0,0,0,0,0,0,0,0,0,0,0,0,1,0,0,0,1,0,0,0,0,0,0
0,0,0,0,0,0,0,0,0,0,0,0,0,0,0,0,0,0,0,0,0,0,0,0,0,0,0,1,0,0,0,1,0,0,0,0,0,0
0,0,0,0,0,0,0,0,0,0,0,0,0,0,0,0,0,0,0,0,0,0,0,0,0,0,0,6,1,1,1,6,0,0,0,0,0,0
0,0,0,0,0,0,0,0,0,0,0,0,0,0,0,0,0,0,0,0,0,0,0,0,0,0,0,0,0,0,0,0,0,0,0,0,0,0
0,0,0,0,0,0,0,0,0,0,0,0,0,0,0,0,0,0,0,0,0,0,0,0,0,0,0,0,0,0,0,0,0,0,0,0,0,0
0,0,0,0,0,0,0,0,0,0,0,0,0,0,0,0,0,0,0,0,0,0,0,0,0,0,0,0,0,0,0,0,0,0,0,0,0,0
0,0,0,0,0,0,0,0,0,0,0,0,0,0,0,0,0,0,0,0,0,0,0,0,0,0,0,0,0,0,0,0,0,0,0,0,0,0
0,0,0,0,0,0,0,0,0,0,0,0,0,0,0,0,0,0,0,0,0,0,0,0,0,0,0,0,0,0,0,0,0,0,0,0,0,0
0,0,0,0,0,0,0,0,0,0,0,0,0,0,0,0,0,0,0,0,0,0,0,0,0,0,0,0,0,0,0,0,0,0,0,0,0,0
endlayer

