
# Created by Ruins mod version 14.1 Ingame Parser
# authoring Player: Divineaspect

weight=100
embed_into_distance=8
acceptable_target_blocks=dirt,stone,grass,sand,sandstone,gravel
unacceptable_target_blocks=
dimensions=13,13,13
allowable_overhang=0
max_leveling=2
leveling_buffer=0
preserve_water=0
preserve_lava=0

rule1=0,99,minecraft:cobblestone-0
rule2=0,99,minecraft:gravel-0
rule3=0,100,ChestGenHook:dungeonChest:5-4
rule4=0,100,ChestGenHook:dungeonChest:5-5
rule5=0,100,minecraft:ladder-2
rule6=0,100,minecraft:stone_stairs-2
rule7=0,100,minecraft:redstone_wire-15
rule8=2,100,minecraft:redstone_torch-2
rule9=2,100,minecraft:redstone_torch-4
rule10=2,100,minecraft:redstone_torch-3
rule11=2,100,minecraft:redstone_torch-1
rule12=0,100,minecraft:unlit_redstone_torch-5
rule13=0,100,minecraft:redstone_wire-0
rule14=0,100,minecraft:stone_stairs-7
rule15=0,100,minecraft:trapped_chest-2
rule16=0,100,minecraft:piston-2
rule17=0,100,minecraft:ladder-4
rule18=0,100,minecraft:piston-5
rule19=0,50,MobSpawner:primitivemobs.Summoner
rule20=0,50,MobSpawner:Zombie
rule21=0,100,minecraft:piston-3
rule22=0,100,minecraft:stone_pressure_plate-0
rule23=0,80,MobSpawner:Skeleton
rule24=0,100,minecraft:piston-4
rule25=0,100,minecraft:lava-0
rule26=0,100,minecraft:glass-0
rule27=0,100,minecraft:iron_ore-0
rule28=2,100,WallSign:null:null:null:null-5
rule29=2,100,WallSign:null:null:null:null-3
rule30=0,100,minecraft:water-0
rule31=2,100,WallSign:null:null:null:null-2
rule32=2,100,WallSign:null:null:null:null-4
rule33=0,100,minecraft:stone_stairs-0
rule34=0,100,minecraft:stone_stairs-3
rule35=0,100,minecraft:stone_stairs-1
rule36=0,100,minecraft:netherrack-0
rule37=0,100,minecraft:water-0
rule38=0,100,minecraft:fire-15

layer
1,1,1,1,1,1,1,1,1,1,1,1,1
1,2,1,2,1,2,1,2,1,2,1,2,1
1,1,1,1,1,1,1,1,1,1,1,1,1
1,2,1,2,1,2,1,2,1,2,1,2,1
1,1,1,1,1,1,1,1,1,1,1,1,1
1,2,1,2,1,2,1,2,1,2,1,2,1
1,1,1,1,1,1,1,1,1,1,1,1,1
1,2,1,2,1,2,1,2,1,2,1,2,1
1,1,1,1,1,1,1,1,1,1,1,1,1
1,2,1,2,1,2,1,2,1,2,1,2,1
1,1,1,1,1,1,1,1,1,1,1,1,1
1,2,1,2,1,2,1,2,1,2,1,2,1
1,1,1,1,1,1,1,1,1,1,1,1,1
endlayer

layer
1,1,1,1,1,1,1,1,1,1,1,1,1
1,0,0,0,0,0,1,0,0,0,0,0,1
1,0,0,0,0,0,0,0,0,0,0,0,1
1,0,0,0,0,0,1,0,0,0,0,0,1
1,0,0,0,3,0,1,0,3,0,0,0,1
1,0,0,0,0,0,1,0,0,0,0,0,1
1,1,0,1,1,1,1,1,1,1,0,1,1
1,0,0,0,0,0,1,0,0,0,0,0,1
1,5,0,0,4,0,1,0,4,0,0,0,1
1,0,0,0,0,0,1,0,0,0,0,0,1
1,0,0,0,0,0,0,0,0,0,0,0,1
1,0,0,0,0,0,1,0,0,6,0,0,1
1,1,1,1,1,1,1,1,1,1,1,1,1
endlayer

layer
1,1,1,1,1,1,1,1,1,1,1,1,1
1,0,0,0,0,0,1,0,0,0,0,0,1
1,0,0,0,0,0,0,0,0,0,0,0,1
1,0,0,0,0,0,1,0,0,0,0,0,1
1,0,0,0,0,0,1,0,0,0,0,0,1
1,0,0,0,0,0,1,0,0,0,0,0,1
1,1,0,1,1,1,1,1,1,1,0,1,1
1,0,0,0,0,0,1,0,0,0,0,0,1
1,5,0,0,0,0,1,0,0,0,0,0,1
1,0,0,0,0,0,1,0,0,0,0,0,1
1,0,0,0,0,0,0,0,0,0,0,0,1
1,0,0,0,0,0,1,0,6,0,0,0,1
1,1,1,1,1,1,1,1,1,1,1,1,1
endlayer

layer
1,1,1,1,1,1,1,1,1,1,1,1,1
1,0,0,0,0,0,1,0,0,0,0,0,1
1,0,0,0,0,0,1,0,0,0,0,0,1
1,0,0,0,0,0,1,0,0,0,0,0,1
1,0,0,0,0,1,7,1,0,0,0,0,1
1,0,0,0,1,1,8,1,1,0,0,0,1
1,1,0,1,7,10,1,9,7,1,1,1,1
1,0,0,0,1,1,11,1,1,0,0,0,1
1,5,0,0,0,1,7,1,0,0,0,0,1
1,0,0,0,0,0,1,0,0,0,0,0,1
1,0,0,0,0,0,1,0,0,0,0,0,1
1,0,0,0,0,0,1,6,0,0,0,0,1
1,1,1,1,1,1,1,1,1,1,1,1,1
endlayer

layer
1,1,1,1,1,1,1,1,1,1,1,1,1
1,1,1,1,1,1,1,1,1,1,1,1,1
1,1,1,1,1,1,1,1,1,1,1,1,1
1,1,1,1,1,1,12,1,1,1,1,1,1
1,1,1,1,1,1,0,1,1,1,1,1,1
1,1,1,1,1,1,0,1,1,1,1,1,1
1,1,1,12,0,0,13,0,0,12,1,1,1
1,1,1,1,1,1,0,0,1,1,1,1,1
1,5,1,1,1,1,0,1,0,0,1,1,1
1,1,1,1,1,1,12,1,0,0,1,1,1
1,1,1,1,1,1,1,1,1,1,1,1,1
1,1,1,1,1,1,6,0,0,0,14,0,1
1,1,1,1,1,1,1,1,1,1,1,1,1
endlayer

layer
1,1,1,1,1,1,1,1,1,1,1,1,1
1,0,0,0,0,0,0,0,0,0,0,0,1
1,0,0,0,0,1,1,1,0,0,0,0,1
1,0,0,1,1,1,1,1,1,1,0,0,1
1,0,0,1,1,1,1,1,1,1,0,0,1
1,0,1,1,1,1,1,1,1,1,1,0,1
1,0,1,1,1,1,1,1,1,1,1,0,1
1,0,1,1,1,1,1,1,1,1,1,0,1
1,0,0,1,1,1,1,1,0,1,1,0,1
1,0,0,1,1,1,1,1,0,1,15,0,1
1,0,0,0,0,1,1,1,1,1,13,1,1
1,0,17,0,0,0,0,0,0,14,16,1,0
1,1,1,1,1,1,1,1,1,1,1,1,1
endlayer

layer
1,1,1,1,1,1,1,1,1,1,1,1,1
1,0,0,0,0,0,0,0,0,0,0,0,1
1,0,0,0,0,1,1,1,0,0,0,0,1
1,0,0,1,1,0,13,0,1,1,0,0,1
1,0,0,1,1,1,18,1,1,1,0,0,1
1,0,1,0,1,20,0,19,1,0,1,0,1
1,0,1,13,16,0,22,0,21,13,1,0,1
1,0,1,0,1,23,0,20,1,0,1,0,1
1,0,0,1,1,1,24,1,1,1,1,0,1
1,0,0,1,1,0,13,0,1,1,0,0,1
1,0,0,0,0,1,1,1,1,1,1,1,1
1,0,17,0,0,0,0,0,14,0,1,25,1
1,1,1,1,1,1,1,1,1,1,1,1,1
endlayer

layer
1,1,1,1,1,1,1,1,1,1,1,1,1
1,26,1,27,27,27,27,27,27,27,1,26,1
1,1,1,1,1,1,1,1,1,1,1,1,1
1,27,1,25,1,1,1,1,1,25,1,27,1
1,27,1,1,1,1,1,1,1,1,1,27,1
1,27,1,1,1,0,28,0,1,1,1,27,1
1,27,1,1,1,31,30,29,1,1,1,27,1
1,27,1,1,1,0,32,0,1,1,1,27,1
1,27,1,1,1,1,1,1,1,1,1,27,1
1,27,1,25,1,1,1,1,1,25,1,27,1
1,1,1,1,1,1,1,1,1,1,1,1,1
1,26,17,27,27,27,27,27,27,27,1,26,1
1,1,1,1,1,1,1,1,1,1,1,1,1
endlayer

layer
0,0,0,0,0,0,0,0,0,0,0,0,0
0,26,0,0,0,0,0,0,0,0,0,26,0
0,0,34,33,33,33,33,33,33,33,33,0,0
0,0,34,0,27,27,27,27,27,0,6,0,0
0,0,34,27,1,1,1,1,1,27,6,0,0
0,0,34,27,1,1,1,1,1,27,6,0,0
0,0,34,27,1,1,30,1,1,27,6,0,0
0,0,34,27,1,1,1,1,1,27,6,0,0
0,0,34,27,1,1,1,1,1,27,6,0,0
0,0,34,0,27,27,27,27,27,0,6,0,0
0,0,35,35,35,35,35,35,35,35,6,0,0
0,26,0,0,0,0,0,0,0,0,0,26,0
0,0,0,0,0,0,0,0,0,0,0,0,0
endlayer

layer
0,0,0,0,0,0,0,0,0,0,0,0,0
0,26,0,0,0,0,0,0,0,0,0,26,0
0,0,0,0,0,0,0,0,0,0,0,0,0
0,0,0,0,0,0,0,0,0,0,0,0,0
0,0,0,0,33,33,0,33,33,0,0,0,0
0,0,0,0,34,27,27,27,6,0,0,0,0
0,0,0,0,0,27,30,27,0,0,0,0,0
0,0,0,0,34,27,27,27,6,0,0,0,0
0,0,0,0,34,35,0,35,35,0,0,0,0
0,0,0,0,0,0,0,0,0,0,0,0,0
0,0,0,0,0,0,0,0,0,0,0,0,0
0,26,0,0,0,0,0,0,0,0,0,26,0
0,0,0,0,0,0,0,0,0,0,0,0,0
endlayer

layer
0,0,0,0,0,0,0,0,0,0,0,0,0
0,26,0,0,0,0,0,0,0,0,0,26,0
0,0,0,0,0,0,0,0,0,0,0,0,0
0,0,0,36,0,0,0,0,0,36,0,0,0
0,0,0,0,0,0,0,0,0,0,0,0,0
0,0,0,0,0,22,22,22,0,0,0,0,0
0,0,0,0,0,22,37,22,0,0,0,0,0
0,0,0,0,0,22,22,22,0,0,0,0,0
0,0,0,0,0,0,0,0,0,0,0,0,0
0,0,0,36,0,0,0,0,0,36,0,0,0
0,0,0,0,0,0,0,0,0,0,0,0,0
0,26,0,0,0,0,0,0,0,0,0,26,0
0,0,0,0,0,0,0,0,0,0,0,0,0
endlayer

layer
0,0,0,0,0,0,0,0,0,0,0,0,0
0,26,0,0,0,0,0,0,0,0,0,26,0
0,0,0,0,0,0,0,0,0,0,0,0,0
0,0,0,38,0,0,0,0,0,38,0,0,0
0,0,0,0,0,0,0,0,0,0,0,0,0
0,0,0,0,0,0,0,0,0,0,0,0,0
0,0,0,0,0,0,0,0,0,0,0,0,0
0,0,0,0,0,0,0,0,0,0,0,0,0
0,0,0,0,0,0,0,0,0,0,0,0,0
0,0,0,38,0,0,0,0,0,38,0,0,0
0,0,0,0,0,0,0,0,0,0,0,0,0
0,26,0,0,0,0,0,0,0,0,0,26,0
0,0,0,0,0,0,0,0,0,0,0,0,0
endlayer

layer
0,0,0,0,0,0,0,0,0,0,0,0,0
0,36,0,0,0,0,0,0,0,0,0,36,0
0,0,0,0,0,0,0,0,0,0,0,0,0
0,0,0,0,0,0,0,0,0,0,0,0,0
0,0,0,0,0,0,0,0,0,0,0,0,0
0,0,0,0,0,0,0,0,0,0,0,0,0
0,0,0,0,0,0,0,0,0,0,0,0,0
0,0,0,0,0,0,0,0,0,0,0,0,0
0,0,0,0,0,0,0,0,0,0,0,0,0
0,0,0,0,0,0,0,0,0,0,0,0,0
0,0,0,0,0,0,0,0,0,0,0,0,0
0,36,0,0,0,0,0,0,0,0,0,36,0
0,0,0,0,0,0,0,0,0,0,0,0,0
endlayer

